Workbook
Name TableLWG: #REF!
Name TableLWG: #REF!
Name TableLWG: #REF!

Sheet 4.4.1.1 (original)
I1: 3.4.1 | J1: 3.4.1 | V1: 3.4.1 321 | Z1: 3.4.1 | AD1: 3.4.1 | AE1: 3.4.1 | AF1: Ch 3.4.1 | AT1: 1084 | AU1: Bo | AV1: 0.19 | AX1: FAk | AY1: 1.3
X2: 1.6 * PLjk=6 | AG2: (Ijk * CPjk) + (0.045 * MCjk=6) | AI2: (Ijk * ((1 - DMDjk) + (0.04 * Ijk))) * ( 1 - A ) | AL2: VSjk * BO * MMSm * MCFim * 𝜌 | AN2: VSjk * BO * MMSm * MCFim * 𝜌 | AO2: SUM SUM SUM (Njk * Mjkm * Dj) * 10^-3 | AT2: 1087 | AU2: A | AV2: 0.08
H3: 1071 | I3: 342 | J3: 323 | L3: 1075 | M3: 1078 | O3: 1077 | Q3: 1081 | S3: 1085 | U3: 1082 | V3: 1004 | W3: 990 | X3: 988 | Y3: 351 | Z3: 314 | AA3: 302 | AC3: 349 | AD3: 308 | AE3: 296 | AF3: 946 | AG3: 983 | AH3: 1087 | AI3: 945 | AJ3: 1084 | AK3: 1086 | AL3: 930 | AN3: 930 | AO3: 922 | AU3: Dj | AV3: 91.25
H4: input | L4: constant | M4: constant | O4: constant | Q4: constant | S4: constant | U4: constant | V4: constant | W4: expression | X4: expression | Y4: constant | Z4: expression | AA4: expression | AC4: constant | AD4: expression | AE4: expression | AF4: expression | AG4: expression | AH4: constant | AI4: expression | AJ4: constant | AK4: constant | AL4: expression | AN4: expression | AO4: expression | AT4: 1094 | AU4: FracLEACH | AV4: 0.24
L5: input | M5: input | O5: input | Q5: input | U5: input | AC5: input | AT5: 1093 | AU5: FracGASMSoil | AV5: 0.21
AT6: 1095 | AU6: EFLeach | AV6: 0.011
AT7: 1088 | AU7: CN2O | AV7: =44/28 -> 1.5714286
H8: head | L8: days | M8: d | O8: d | Q8: kg | S8: d | U8: d | V8: d | W8: d | X8: kg / head / day | AF8: kg DM/head/day | AG8: kg/head/day | AH8: d | AI8: kg/head/day | AJ8: m3 CH4/kgVS | AK8: kg/m3 | AL8: kg CH4/head/day | AN8: kg CH4/head/day | AO8: kg CH4
H9: number of sheep in each time period and class | I9: Lambing rate | J9: Lamb marking rate | L9: number of days in each time period | M9: crude protein content of feed intake | O9: dry matter digestibility | Q9: liveweight | S9: fraction of waste in each MMS | U9: methane conversion factor for temperate zone and MMS | V9: proportion of ewes lactating each season or time period | W9: Proportion of lambs born in the time period | X9: Milk intake | AF9: dry matter intake | AG9: crude protein intake | AH9: ash content of feed intake | AI9: volatile solid production | AJ9: emisions potential | AK9: density of methane | AL9: methane produced from manure | AN9: methane produced from manure | AO9: annual methane production from manure | AV9: MCF | AX9: Lagoon
A10: Scenario | B10: State | C10: State | D10: No unfenced water | E10: Class | G10: Month | H10: Njk | I10: LR | J10: LMR | K10: Custom Dj | L10: Dj | M10: CPjk | N10: Custom DMD | O10: DMDjk | P10: Custom liveweight | Q10: Wjk | R10: MMSm=1 | S10: MMSm=14 | T10: MCFim=1 | U10: MCFim=14 | V10: LEjk=3,4 | W10: PLjk=6 | X10: MCjk=6 | Y10: FAk | Z10: MAjk | AA10: qmjk | AB10: Custom DMA | AC10: DMAjk | AD10: RIjk | AE10: PIjk | AF10: Ijk | AG10: CPIjk | AH10: A | AI10: VSjk | AJ10: BO | AK10: 𝜌 | AL10: Mjkm=1 | AM10: Mjkm=14 | AN10: Mjk | AO10: ECH4 | AP10: ECH4 | AU10: PRP | AV10: 0.0047 | AW10: ACT | AX10: 0.72
A11: Baseline | B11: ACT | C11: ACT/NSW | D11: yes | E11: Breeding ewes | F11: Spring | H11: 100 | I11: 95 | J11: 90 | L11: =$AV$3 -> 91.25 | M11: {=_xludf.DROP(_xludf.XLOOKUP($C11,#REF!,#REF!),1)} -> #NAME? | O11: {=_xludf.DROP(_xludf.XLOOKUP($C11,#REF!,#REF!),1)} -> #NAME? | Q11: {=_xludf.DROP(_xludf.XLOOKUP($C11,#REF!,#REF!),1)} -> #NAME? | R11: =1-S11 -> 0 | S11: =IF($D$11="yes", 1, VLOOKUP($B$11, $AU$26:$AW$32, 1)) -> 1 | T11: =VLOOKUP($B$11,$AW$10:$AX$16, 2, FALSE) -> 0.72 | U11: =$AV$10 -> 0.0047 | V11: =(I11/100)*(MIN(J11,100)/100) -> 0.855 | W11: 0 | X11: =1.6 * W11 -> 0 | Y11: =$AY$1 -> 1.3 | Z11: =V11*Y11+(1-V11) -> 1.2565 | AA11: =(0.795*O11)-0.0014 -> #NAME? | AC11: {=_xludf.DROP(_xludf.XLOOKUP($C11,#REF!,#REF!),1)} -> #NAME? | AD11: =1 - EXP(-2*(AC11^2)) -> #NAME? | AE11: =(104.7*AA11+0.307*Q11-15)*(Q11^0.75)*10^-3 -> #NAME? | AF11: =AE11*AD11*Z11 -> #NAME? | AG11: =(AF11 * M11) + (0.045 * X11) -> #NAME? | AH11: =$AV$2 -> 0.08 | AI11: =(AF11 * ((1 - O11) + (0.04 * AF11))) * ( 1 - AH11 ) -> #NAME? | AJ11: =$AV$1 -> 0.19 | AK11: =$AW$20 -> 0.6784 | AL11: =AI11 * AJ11 * R11 * T11 * AK11 -> #NAME? | AM11: =AI11*AJ11*S11*U11*AK11 -> #NAME? | AN11: =AL11+AM11 -> #NAME? | AO11: =H11*AN11*L11 -> #NAME? | AP11: =SUM(AO11:AO34)*10^-3 -> #NAME? | AW11: NSW | AX11: 0.75
F12: Summer | H12: 70 | I12: 0 | J12: 0 | L12: =$AV$3 -> 91.25 | R12: =1-S12 -> 0 | S12: =IF($D$11="yes", 1, VLOOKUP($B$11, $AU$26:$AW$32, 1)) -> 1 | T12: =VLOOKUP($B$11,$AW$10:$AX$16, 2, FALSE) -> 0.72 | U12: =$AV$10 -> 0.0047 | V12: =(I12/100)*(MIN(J12,100)/100) -> 0 | W12: 0 | X12: =1.6 * W12 -> 0 | Y12: =$AY$1 -> 1.3 | Z12: =V12*Y12+(1-V12) -> 1 | AA12: =(0.795*O12)-0.0014 -> -0.0014 | AD12: =1 - EXP(-2*(AC12^2)) -> 0 | AE12: =(104.7*AA12+0.307*Q12-15)*(Q12^0.75)*10^-3 -> 0 | AF12: =AE12*AD12*Z12 -> 0 | AG12: =(AF12 * M12) + (0.045 * X12) -> 0 | AH12: =$AV$2 -> 0.08 | AI12: =(AF12 * ((1 - O12) + (0.04 * AF12))) * ( 1 - AH12 ) -> 0 | AJ12: =$AV$1 -> 0.19 | AK12: =$AW$20 -> 0.6784 | AL12: =AI12 * AJ12 * R12 * T12 * AK12 -> 0 | AM12: =AI12*AJ12*S12*U12*AK12 -> 0 | AN12: =AL12+AM12 -> 0 | AO12: =H12*AN12*L12 -> 0 | AW12: QLD | AX12: 0.78
F13: Autumn | H13: 65 | I13: 0 | J13: 0 | L13: =$AV$3 -> 91.25 | R13: =1-S13 -> 0 | S13: =IF($D$11="yes", 1, VLOOKUP($B$11, $AU$26:$AW$32, 1)) -> 1 | T13: =VLOOKUP($B$11,$AW$10:$AX$16, 2, FALSE) -> 0.72 | U13: =$AV$10 -> 0.0047 | V13: =(I13/100)*(MIN(J13,100)/100) -> 0 | W13: 0 | X13: =1.6 * W13 -> 0 | Y13: =$AY$1 -> 1.3 | Z13: =V13*Y13+(1-V13) -> 1 | AA13: =(0.795*O13)-0.0014 -> -0.0014 | AD13: =1 - EXP(-2*(AC13^2)) -> 0 | AE13: =(104.7*AA13+0.307*Q13-15)*(Q13^0.75)*10^-3 -> 0 | AF13: =AE13*AD13*Z13 -> 0 | AG13: =(AF13 * M13) + (0.045 * X13) -> 0 | AH13: =$AV$2 -> 0.08 | AI13: =(AF13 * ((1 - O13) + (0.04 * AF13))) * ( 1 - AH13 ) -> 0 | AJ13: =$AV$1 -> 0.19 | AK13: =$AW$20 -> 0.6784 | AL13: =AI13 * AJ13 * R13 * T13 * AK13 -> 0 | AM13: =AI13*AJ13*S13*U13*AK13 -> 0 | AN13: =AL13+AM13 -> 0 | AO13: =H13*AN13*L13 -> 0 | AW13: SA | AX13: 0.74
F14: Winter | H14: 80 | I14: 0 | J14: 0 | L14: =$AV$3 -> 91.25 | R14: =1-S14 -> 0 | S14: =IF($D$11="yes", 1, VLOOKUP($B$11, $AU$26:$AW$32, 1)) -> 1 | T14: =VLOOKUP($B$11,$AW$10:$AX$16, 2, FALSE) -> 0.72 | U14: =$AV$10 -> 0.0047 | V14: =(I14/100)*(MIN(J14,100)/100) -> 0 | W14: 0 | X14: =1.6 * W14 -> 0 | Y14: =$AY$1 -> 1.3 | Z14: =V14*Y14+(1-V14) -> 1 | AA14: =(0.795*O14)-0.0014 -> -0.0014 | AD14: =1 - EXP(-2*(AC14^2)) -> 0 | AE14: =(104.7*AA14+0.307*Q14-15)*(Q14^0.75)*10^-3 -> 0 | AF14: =AE14*AD14*Z14 -> 0 | AG14: =(AF14 * M14) + (0.045 * X14) -> 0 | AH14: =$AV$2 -> 0.08 | AI14: =(AF14 * ((1 - O14) + (0.04 * AF14))) * ( 1 - AH14 ) -> 0 | AJ14: =$AV$1 -> 0.19 | AK14: =$AW$20 -> 0.6784 | AL14: =AI14 * AJ14 * R14 * T14 * AK14 -> 0 | AM14: =AI14*AJ14*S14*U14*AK14 -> 0 | AN14: =AL14+AM14 -> 0 | AO14: =H14*AN14*L14 -> 0 | AW14: TAS | AX14: 0.69
E15: Lambs and hoggets | F15: Spring | H15: 200 | I15: 0 | J15: 0 | L15: =$AV$3 -> 91.25 | R15: =1-S15 -> 0 | S15: =IF($D$11="yes", 1, VLOOKUP($B$11, $AU$26:$AW$32, 1)) -> 1 | T15: =VLOOKUP($B$11,$AW$10:$AX$16, 2, FALSE) -> 0.72 | U15: =$AV$10 -> 0.0047 | V15: =(I15/100)*(MIN(J15,100)/100) -> 0 | W15: 1 | X15: =1.6 * W15 -> 1.6 | Y15: =$AY$1 -> 1.3 | Z15: =V15*Y15+(1-V15) -> 1 | AA15: =(0.795*O15)-0.0014 -> -0.0014 | AD15: =1 - EXP(-2*(AC15^2)) -> 0 | AE15: =(104.7*AA15+0.307*Q15-15)*(Q15^0.75)*10^-3 -> 0 | AF15: =AE15*AD15*Z15 -> 0 | AG15: =(AF15 * M15) + (0.045 * X15) -> 0.072 | AH15: =$AV$2 -> 0.08 | AI15: =(AF15 * ((1 - O15) + (0.04 * AF15))) * ( 1 - AH15 ) -> 0 | AJ15: =$AV$1 -> 0.19 | AK15: =$AW$20 -> 0.6784 | AL15: =AI15 * AJ15 * R15 * T15 * AK15 -> 0 | AM15: =AI15*AJ15*S15*U15*AK15 -> 0 | AN15: =AL15+AM15 -> 0 | AO15: =H15*AN15*L15 -> 0 | AW15: VIC | AX15: 0.73
F16: Summer | H16: 210 | I16: 0 | J16: 0 | L16: =$AV$3 -> 91.25 | R16: =1-S16 -> 0 | S16: =IF($D$11="yes", 1, VLOOKUP($B$11, $AU$26:$AW$32, 1)) -> 1 | T16: =VLOOKUP($B$11,$AW$10:$AX$16, 2, FALSE) -> 0.72 | U16: =$AV$10 -> 0.0047 | V16: =(I16/100)*(MIN(J16,100)/100) -> 0 | W16: 0 | X16: =1.6 * W16 -> 0 | Y16: =$AY$1 -> 1.3 | Z16: =V16*Y16+(1-V16) -> 1 | AA16: =(0.795*O16)-0.0014 -> -0.0014 | AD16: =1 - EXP(-2*(AC16^2)) -> 0 | AE16: =(104.7*AA16+0.307*Q16-15)*(Q16^0.75)*10^-3 -> 0 | AF16: =AE16*AD16*Z16 -> 0 | AG16: =(AF16 * M16) + (0.045 * X16) -> 0 | AH16: =$AV$2 -> 0.08 | AI16: =(AF16 * ((1 - O16) + (0.04 * AF16))) * ( 1 - AH16 ) -> 0 | AJ16: =$AV$1 -> 0.19 | AK16: =$AW$20 -> 0.6784 | AL16: =AI16 * AJ16 * R16 * T16 * AK16 -> 0 | AM16: =AI16*AJ16*S16*U16*AK16 -> 0 | AN16: =AL16+AM16 -> 0 | AO16: =H16*AN16*L16 -> 0 | AW16: WA | AX16: 0.76
F17: Autumn | H17: 170 | I17: 0 | J17: 0 | L17: =$AV$3 -> 91.25 | R17: =1-S17 -> 0 | S17: =IF($D$11="yes", 1, VLOOKUP($B$11, $AU$26:$AW$32, 1)) -> 1 | T17: =VLOOKUP($B$11,$AW$10:$AX$16, 2, FALSE) -> 0.72 | U17: =$AV$10 -> 0.0047 | V17: =(I17/100)*(MIN(J17,100)/100) -> 0 | W17: 0 | X17: =1.6 * W17 -> 0 | Y17: =$AY$1 -> 1.3 | Z17: =V17*Y17+(1-V17) -> 1 | AA17: =(0.795*O17)-0.0014 -> -0.0014 | AD17: =1 - EXP(-2*(AC17^2)) -> 0 | AE17: =(104.7*AA17+0.307*Q17-15)*(Q17^0.75)*10^-3 -> 0 | AF17: =AE17*AD17*Z17 -> 0 | AG17: =(AF17 * M17) + (0.045 * X17) -> 0 | AH17: =$AV$2 -> 0.08 | AI17: =(AF17 * ((1 - O17) + (0.04 * AF17))) * ( 1 - AH17 ) -> 0 | AJ17: =$AV$1 -> 0.19 | AK17: =$AW$20 -> 0.6784 | AL17: =AI17 * AJ17 * R17 * T17 * AK17 -> 0 | AM17: =AI17*AJ17*S17*U17*AK17 -> 0 | AN17: =AL17+AM17 -> 0 | AO17: =H17*AN17*L17 -> 0
F18: Winter | H18: 200 | I18: 0 | J18: 0 | L18: =$AV$3 -> 91.25 | R18: =1-S18 -> 0 | S18: =IF($D$11="yes", 1, VLOOKUP($B$11, $AU$26:$AW$32, 1)) -> 1 | T18: =VLOOKUP($B$11,$AW$10:$AX$16, 2, FALSE) -> 0.72 | U18: =$AV$10 -> 0.0047 | V18: =(I18/100)*(MIN(J18,100)/100) -> 0 | W18: 0 | X18: =1.6 * W18 -> 0 | Y18: =$AY$1 -> 1.3 | Z18: =V18*Y18+(1-V18) -> 1 | AA18: =(0.795*O18)-0.0014 -> -0.0014 | AD18: =1 - EXP(-2*(AC18^2)) -> 0 | AE18: =(104.7*AA18+0.307*Q18-15)*(Q18^0.75)*10^-3 -> 0 | AF18: =AE18*AD18*Z18 -> 0 | AG18: =(AF18 * M18) + (0.045 * X18) -> 0 | AH18: =$AV$2 -> 0.08 | AI18: =(AF18 * ((1 - O18) + (0.04 * AF18))) * ( 1 - AH18 ) -> 0 | AJ18: =$AV$1 -> 0.19 | AK18: =$AW$20 -> 0.6784 | AL18: =AI18 * AJ18 * R18 * T18 * AK18 -> 0 | AM18: =AI18*AJ18*S18*U18*AK18 -> 0 | AN18: =AL18+AM18 -> 0 | AO18: =H18*AN18*L18 -> 0 | AV18: EFPRP | AW18: wet | AX18: 0.006
E19: Maiden ewes | F19: Spring | H19: 100 | I19: 95 | J19: 92 | L19: =$AV$3 -> 91.25 | R19: =1-S19 -> 0 | S19: =IF($D$11="yes", 1, VLOOKUP($B$11, $AU$26:$AW$32, 1)) -> 1 | T19: =VLOOKUP($B$11,$AW$10:$AX$16, 2, FALSE) -> 0.72 | U19: =$AV$10 -> 0.0047 | V19: =(I19/100)*(MIN(J19,100)/100) -> 0.874 | W19: 0 | X19: =1.6 * W19 -> 0 | Y19: =$AY$1 -> 1.3 | Z19: =V19*Y19+(1-V19) -> 1.2622 | AA19: =(0.795*O19)-0.0014 -> -0.0014 | AD19: =1 - EXP(-2*(AC19^2)) -> 0 | AE19: =(104.7*AA19+0.307*Q19-15)*(Q19^0.75)*10^-3 -> 0 | AF19: =AE19*AD19*Z19 -> 0 | AG19: =(AF19 * M19) + (0.045 * X19) -> 0 | AH19: =$AV$2 -> 0.08 | AI19: =(AF19 * ((1 - O19) + (0.04 * AF19))) * ( 1 - AH19 ) -> 0 | AJ19: =$AV$1 -> 0.19 | AK19: =$AW$20 -> 0.6784 | AL19: =AI19 * AJ19 * R19 * T19 * AK19 -> 0 | AM19: =AI19*AJ19*S19*U19*AK19 -> 0 | AN19: =AL19+AM19 -> 0 | AO19: =H19*AN19*L19 -> 0 | AW19: dry | AX19: 0.002
F20: Summer | H20: 140 | I20: 0 | J20: 0 | L20: =$AV$3 -> 91.25 | R20: =1-S20 -> 0 | S20: =IF($D$11="yes", 1, VLOOKUP($B$11, $AU$26:$AW$32, 1)) -> 1 | T20: =VLOOKUP($B$11,$AW$10:$AX$16, 2, FALSE) -> 0.72 | U20: =$AV$10 -> 0.0047 | V20: =(I20/100)*(MIN(J20,100)/100) -> 0 | W20: 0 | X20: =1.6 * W20 -> 0 | Y20: =$AY$1 -> 1.3 | Z20: =V20*Y20+(1-V20) -> 1 | AA20: =(0.795*O20)-0.0014 -> -0.0014 | AD20: =1 - EXP(-2*(AC20^2)) -> 0 | AE20: =(104.7*AA20+0.307*Q20-15)*(Q20^0.75)*10^-3 -> 0 | AF20: =AE20*AD20*Z20 -> 0 | AG20: =(AF20 * M20) + (0.045 * X20) -> 0 | AH20: =$AV$2 -> 0.08 | AI20: =(AF20 * ((1 - O20) + (0.04 * AF20))) * ( 1 - AH20 ) -> 0 | AJ20: =$AV$1 -> 0.19 | AK20: =$AW$20 -> 0.6784 | AL20: =AI20 * AJ20 * R20 * T20 * AK20 -> 0 | AM20: =AI20*AJ20*S20*U20*AK20 -> 0 | AN20: =AL20+AM20 -> 0 | AO20: =H20*AN20*L20 -> 0 | AV20: p | AW20: 0.6784
F21: Autumn | H21: 135 | I21: 0 | J21: 0 | L21: =$AV$3 -> 91.25 | R21: =1-S21 -> 0 | S21: =IF($D$11="yes", 1, VLOOKUP($B$11, $AU$26:$AW$32, 1)) -> 1 | T21: =VLOOKUP($B$11,$AW$10:$AX$16, 2, FALSE) -> 0.72 | U21: =$AV$10 -> 0.0047 | V21: =(I21/100)*(MIN(J21,100)/100) -> 0 | W21: 0 | X21: =1.6 * W21 -> 0 | Y21: =$AY$1 -> 1.3 | Z21: =V21*Y21+(1-V21) -> 1 | AA21: =(0.795*O21)-0.0014 -> -0.0014 | AD21: =1 - EXP(-2*(AC21^2)) -> 0 | AE21: =(104.7*AA21+0.307*Q21-15)*(Q21^0.75)*10^-3 -> 0 | AF21: =AE21*AD21*Z21 -> 0 | AG21: =(AF21 * M21) + (0.045 * X21) -> 0 | AH21: =$AV$2 -> 0.08 | AI21: =(AF21 * ((1 - O21) + (0.04 * AF21))) * ( 1 - AH21 ) -> 0 | AJ21: =$AV$1 -> 0.19 | AK21: =$AW$20 -> 0.6784 | AL21: =AI21 * AJ21 * R21 * T21 * AK21 -> 0 | AM21: =AI21*AJ21*S21*U21*AK21 -> 0 | AN21: =AL21+AM21 -> 0 | AO21: =H21*AN21*L21 -> 0
F22: Winter | H22: 130 | I22: 0 | J22: 0 | L22: =$AV$3 -> 91.25 | R22: =1-S22 -> 0 | S22: =IF($D$11="yes", 1, VLOOKUP($B$11, $AU$26:$AW$32, 1)) -> 1 | T22: =VLOOKUP($B$11,$AW$10:$AX$16, 2, FALSE) -> 0.72 | U22: =$AV$10 -> 0.0047 | V22: =(I22/100)*(MIN(J22,100)/100) -> 0 | W22: 0 | X22: =1.6 * W22 -> 0 | Y22: =$AY$1 -> 1.3 | Z22: =V22*Y22+(1-V22) -> 1 | AA22: =(0.795*O22)-0.0014 -> -0.0014 | AD22: =1 - EXP(-2*(AC22^2)) -> 0 | AE22: =(104.7*AA22+0.307*Q22-15)*(Q22^0.75)*10^-3 -> 0 | AF22: =AE22*AD22*Z22 -> 0 | AG22: =(AF22 * M22) + (0.045 * X22) -> 0 | AH22: =$AV$2 -> 0.08 | AI22: =(AF22 * ((1 - O22) + (0.04 * AF22))) * ( 1 - AH22 ) -> 0 | AJ22: =$AV$1 -> 0.19 | AK22: =$AW$20 -> 0.6784 | AL22: =AI22 * AJ22 * R22 * T22 * AK22 -> 0 | AM22: =AI22*AJ22*S22*U22*AK22 -> 0 | AN22: =AL22+AM22 -> 0 | AO22: =H22*AN22*L22 -> 0
E23: Other ewes | F23: Spring | H23: 200 | I23: 0 | J23: 0 | L23: =$AV$3 -> 91.25 | R23: =1-S23 -> 0 | S23: =IF($D$11="yes", 1, VLOOKUP($B$11, $AU$26:$AW$32, 1)) -> 1 | T23: =VLOOKUP($B$11,$AW$10:$AX$16, 2, FALSE) -> 0.72 | U23: =$AV$10 -> 0.0047 | V23: =(I23/100)*(MIN(J23,100)/100) -> 0 | W23: 0 | X23: =1.6 * W23 -> 0 | Y23: =$AY$1 -> 1.3 | Z23: =V23*Y23+(1-V23) -> 1 | AA23: =(0.795*O23)-0.0014 -> -0.0014 | AD23: =1 - EXP(-2*(AC23^2)) -> 0 | AE23: =(104.7*AA23+0.307*Q23-15)*(Q23^0.75)*10^-3 -> 0 | AF23: =AE23*AD23*Z23 -> 0 | AG23: =(AF23 * M23) + (0.045 * X23) -> 0 | AH23: =$AV$2 -> 0.08 | AI23: =(AF23 * ((1 - O23) + (0.04 * AF23))) * ( 1 - AH23 ) -> 0 | AJ23: =$AV$1 -> 0.19 | AK23: =$AW$20 -> 0.6784 | AL23: =AI23 * AJ23 * R23 * T23 * AK23 -> 0 | AM23: =AI23*AJ23*S23*U23*AK23 -> 0 | AN23: =AL23+AM23 -> 0 | AO23: =H23*AN23*L23 -> 0
F24: Summer | H24: 210 | I24: 0 | J24: 0 | L24: =$AV$3 -> 91.25 | R24: =1-S24 -> 0 | S24: =IF($D$11="yes", 1, VLOOKUP($B$11, $AU$26:$AW$32, 1)) -> 1 | T24: =VLOOKUP($B$11,$AW$10:$AX$16, 2, FALSE) -> 0.72 | U24: =$AV$10 -> 0.0047 | V24: =(I24/100)*(MIN(J24,100)/100) -> 0 | W24: 0 | X24: =1.6 * W24 -> 0 | Y24: =$AY$1 -> 1.3 | Z24: =V24*Y24+(1-V24) -> 1 | AA24: =(0.795*O24)-0.0014 -> -0.0014 | AD24: =1 - EXP(-2*(AC24^2)) -> 0 | AE24: =(104.7*AA24+0.307*Q24-15)*(Q24^0.75)*10^-3 -> 0 | AF24: =AE24*AD24*Z24 -> 0 | AG24: =(AF24 * M24) + (0.045 * X24) -> 0 | AH24: =$AV$2 -> 0.08 | AI24: =(AF24 * ((1 - O24) + (0.04 * AF24))) * ( 1 - AH24 ) -> 0 | AJ24: =$AV$1 -> 0.19 | AK24: =$AW$20 -> 0.6784 | AL24: =AI24 * AJ24 * R24 * T24 * AK24 -> 0 | AM24: =AI24*AJ24*S24*U24*AK24 -> 0 | AN24: =AL24+AM24 -> 0 | AO24: =H24*AN24*L24 -> 0
F25: Autumn | H25: 190 | I25: 0 | J25: 0 | L25: =$AV$3 -> 91.25 | R25: =1-S25 -> 0 | S25: =IF($D$11="yes", 1, VLOOKUP($B$11, $AU$26:$AW$32, 1)) -> 1 | T25: =VLOOKUP($B$11,$AW$10:$AX$16, 2, FALSE) -> 0.72 | U25: =$AV$10 -> 0.0047 | V25: =(I25/100)*(MIN(J25,100)/100) -> 0 | W25: 0 | X25: =1.6 * W25 -> 0 | Y25: =$AY$1 -> 1.3 | Z25: =V25*Y25+(1-V25) -> 1 | AA25: =(0.795*O25)-0.0014 -> -0.0014 | AD25: =1 - EXP(-2*(AC25^2)) -> 0 | AE25: =(104.7*AA25+0.307*Q25-15)*(Q25^0.75)*10^-3 -> 0 | AF25: =AE25*AD25*Z25 -> 0 | AG25: =(AF25 * M25) + (0.045 * X25) -> 0 | AH25: =$AV$2 -> 0.08 | AI25: =(AF25 * ((1 - O25) + (0.04 * AF25))) * ( 1 - AH25 ) -> 0 | AJ25: =$AV$1 -> 0.19 | AK25: =$AW$20 -> 0.6784 | AL25: =AI25 * AJ25 * R25 * T25 * AK25 -> 0 | AM25: =AI25*AJ25*S25*U25*AK25 -> 0 | AN25: =AL25+AM25 -> 0 | AO25: =H25*AN25*L25 -> 0 | AU25: MMS
F26: Winter | H26: 180 | I26: 0 | J26: 0 | L26: =$AV$3 -> 91.25 | R26: =1-S26 -> 0 | S26: =IF($D$11="yes", 1, VLOOKUP($B$11, $AU$26:$AW$32, 1)) -> 1 | T26: =VLOOKUP($B$11,$AW$10:$AX$16, 2, FALSE) -> 0.72 | U26: =$AV$10 -> 0.0047 | V26: =(I26/100)*(MIN(J26,100)/100) -> 0 | W26: 0 | X26: =1.6 * W26 -> 0 | Y26: =$AY$1 -> 1.3 | Z26: =V26*Y26+(1-V26) -> 1 | AA26: =(0.795*O26)-0.0014 -> -0.0014 | AD26: =1 - EXP(-2*(AC26^2)) -> 0 | AE26: =(104.7*AA26+0.307*Q26-15)*(Q26^0.75)*10^-3 -> 0 | AF26: =AE26*AD26*Z26 -> 0 | AG26: =(AF26 * M26) + (0.045 * X26) -> 0 | AH26: =$AV$2 -> 0.08 | AI26: =(AF26 * ((1 - O26) + (0.04 * AF26))) * ( 1 - AH26 ) -> 0 | AJ26: =$AV$1 -> 0.19 | AK26: =$AW$20 -> 0.6784 | AL26: =AI26 * AJ26 * R26 * T26 * AK26 -> 0 | AM26: =AI26*AJ26*S26*U26*AK26 -> 0 | AN26: =AL26+AM26 -> 0 | AO26: =H26*AN26*L26 -> 0 | AU26: ACT | AV26: 99.25 | AW26: 0.75
E27: Rams | F27: Spring | H27: 50 | I27: 0 | J27: 0 | L27: =$AV$3 -> 91.25 | R27: =1-S27 -> 0 | S27: =IF($D$11="yes", 1, VLOOKUP($B$11, $AU$26:$AW$32, 1)) -> 1 | T27: =VLOOKUP($B$11,$AW$10:$AX$16, 2, FALSE) -> 0.72 | U27: =$AV$10 -> 0.0047 | V27: =(I27/100)*(MIN(J27,100)/100) -> 0 | W27: 0 | X27: =1.6 * W27 -> 0 | Y27: =$AY$1 -> 1.3 | Z27: =V27*Y27+(1-V27) -> 1 | AA27: =(0.795*O27)-0.0014 -> -0.0014 | AD27: =1 - EXP(-2*(AC27^2)) -> 0 | AE27: =(104.7*AA27+0.307*Q27-15)*(Q27^0.75)*10^-3 -> 0 | AF27: =AE27*AD27*Z27 -> 0 | AG27: =(AF27 * M27) + (0.045 * X27) -> 0 | AH27: =$AV$2 -> 0.08 | AI27: =(AF27 * ((1 - O27) + (0.04 * AF27))) * ( 1 - AH27 ) -> 0 | AJ27: =$AV$1 -> 0.19 | AK27: =$AW$20 -> 0.6784 | AL27: =AI27 * AJ27 * R27 * T27 * AK27 -> 0 | AM27: =AI27*AJ27*S27*U27*AK27 -> 0 | AN27: =AL27+AM27 -> 0 | AO27: =H27*AN27*L27 -> 0 | AU27: NSW | AV27: 99.55 | AW27: 0.45
F28: Summer | H28: 55 | I28: 0 | J28: 0 | L28: =$AV$3 -> 91.25 | R28: =1-S28 -> 0 | S28: =IF($D$11="yes", 1, VLOOKUP($B$11, $AU$26:$AW$32, 1)) -> 1 | T28: =VLOOKUP($B$11,$AW$10:$AX$16, 2, FALSE) -> 0.72 | U28: =$AV$10 -> 0.0047 | V28: =(I28/100)*(MIN(J28,100)/100) -> 0 | W28: 0 | X28: =1.6 * W28 -> 0 | Y28: =$AY$1 -> 1.3 | Z28: =V28*Y28+(1-V28) -> 1 | AA28: =(0.795*O28)-0.0014 -> -0.0014 | AD28: =1 - EXP(-2*(AC28^2)) -> 0 | AE28: =(104.7*AA28+0.307*Q28-15)*(Q28^0.75)*10^-3 -> 0 | AF28: =AE28*AD28*Z28 -> 0 | AG28: =(AF28 * M28) + (0.045 * X28) -> 0 | AH28: =$AV$2 -> 0.08 | AI28: =(AF28 * ((1 - O28) + (0.04 * AF28))) * ( 1 - AH28 ) -> 0 | AJ28: =$AV$1 -> 0.19 | AK28: =$AW$20 -> 0.6784 | AL28: =AI28 * AJ28 * R28 * T28 * AK28 -> 0 | AM28: =AI28*AJ28*S28*U28*AK28 -> 0 | AN28: =AL28+AM28 -> 0 | AO28: =H28*AN28*L28 -> 0 | AU28: QLD | AV28: 99.91 | AW28: 0.09
F29: Autumn | H29: 60 | I29: 0 | J29: 0 | L29: =$AV$3 -> 91.25 | R29: =1-S29 -> 0 | S29: =IF($D$11="yes", 1, VLOOKUP($B$11, $AU$26:$AW$32, 1)) -> 1 | T29: =VLOOKUP($B$11,$AW$10:$AX$16, 2, FALSE) -> 0.72 | U29: =$AV$10 -> 0.0047 | V29: =(I29/100)*(MIN(J29,100)/100) -> 0 | W29: 0 | X29: =1.6 * W29 -> 0 | Y29: =$AY$1 -> 1.3 | Z29: =V29*Y29+(1-V29) -> 1 | AA29: =(0.795*O29)-0.0014 -> -0.0014 | AD29: =1 - EXP(-2*(AC29^2)) -> 0 | AE29: =(104.7*AA29+0.307*Q29-15)*(Q29^0.75)*10^-3 -> 0 | AF29: =AE29*AD29*Z29 -> 0 | AG29: =(AF29 * M29) + (0.045 * X29) -> 0 | AH29: =$AV$2 -> 0.08 | AI29: =(AF29 * ((1 - O29) + (0.04 * AF29))) * ( 1 - AH29 ) -> 0 | AJ29: =$AV$1 -> 0.19 | AK29: =$AW$20 -> 0.6784 | AL29: =AI29 * AJ29 * R29 * T29 * AK29 -> 0 | AM29: =AI29*AJ29*S29*U29*AK29 -> 0 | AN29: =AL29+AM29 -> 0 | AO29: =H29*AN29*L29 -> 0 | AU29: SA | AV29: 99.74 | AW29: 0.26
F30: Winter | H30: 65 | I30: 0 | J30: 0 | L30: =$AV$3 -> 91.25 | R30: =1-S30 -> 0 | S30: =IF($D$11="yes", 1, VLOOKUP($B$11, $AU$26:$AW$32, 1)) -> 1 | T30: =VLOOKUP($B$11,$AW$10:$AX$16, 2, FALSE) -> 0.72 | U30: =$AV$10 -> 0.0047 | V30: =(I30/100)*(MIN(J30,100)/100) -> 0 | W30: 0 | X30: =1.6 * W30 -> 0 | Y30: =$AY$1 -> 1.3 | Z30: =V30*Y30+(1-V30) -> 1 | AA30: =(0.795*O30)-0.0014 -> -0.0014 | AD30: =1 - EXP(-2*(AC30^2)) -> 0 | AE30: =(104.7*AA30+0.307*Q30-15)*(Q30^0.75)*10^-3 -> 0 | AF30: =AE30*AD30*Z30 -> 0 | AG30: =(AF30 * M30) + (0.045 * X30) -> 0 | AH30: =$AV$2 -> 0.08 | AI30: =(AF30 * ((1 - O30) + (0.04 * AF30))) * ( 1 - AH30 ) -> 0 | AJ30: =$AV$1 -> 0.19 | AK30: =$AW$20 -> 0.6784 | AL30: =AI30 * AJ30 * R30 * T30 * AK30 -> 0 | AM30: =AI30*AJ30*S30*U30*AK30 -> 0 | AN30: =AL30+AM30 -> 0 | AO30: =H30*AN30*L30 -> 0 | AU30: TAS | AV30: 99.5 | AW30: 0.5
E31: Wethers | F31: Spring | H31: 50 | I31: 0 | J31: 0 | L31: =$AV$3 -> 91.25 | R31: =1-S31 -> 0 | S31: =IF($D$11="yes", 1, VLOOKUP($B$11, $AU$26:$AW$32, 1)) -> 1 | T31: =VLOOKUP($B$11,$AW$10:$AX$16, 2, FALSE) -> 0.72 | U31: =$AV$10 -> 0.0047 | V31: =(I31/100)*(MIN(J31,100)/100) -> 0 | W31: 0 | X31: =1.6 * W31 -> 0 | Y31: =$AY$1 -> 1.3 | Z31: =V31*Y31+(1-V31) -> 1 | AA31: =(0.795*O31)-0.0014 -> -0.0014 | AD31: =1 - EXP(-2*(AC31^2)) -> 0 | AE31: =(104.7*AA31+0.307*Q31-15)*(Q31^0.75)*10^-3 -> 0 | AF31: =AE31*AD31*Z31 -> 0 | AG31: =(AF31 * M31) + (0.045 * X31) -> 0 | AH31: =$AV$2 -> 0.08 | AI31: =(AF31 * ((1 - O31) + (0.04 * AF31))) * ( 1 - AH31 ) -> 0 | AJ31: =$AV$1 -> 0.19 | AK31: =$AW$20 -> 0.6784 | AL31: =AI31 * AJ31 * R31 * T31 * AK31 -> 0 | AM31: =AI31*AJ31*S31*U31*AK31 -> 0 | AN31: =AL31+AM31 -> 0 | AO31: =H31*AN31*L31 -> 0 | AU31: VIC | AV31: 99.17 | AW31: 0.83
F32: Summer | H32: 100 | I32: 0 | J32: 0 | L32: =$AV$3 -> 91.25 | R32: =1-S32 -> 0 | S32: =IF($D$11="yes", 1, VLOOKUP($B$11, $AU$26:$AW$32, 1)) -> 1 | T32: =VLOOKUP($B$11,$AW$10:$AX$16, 2, FALSE) -> 0.72 | U32: =$AV$10 -> 0.0047 | V32: =(I32/100)*(MIN(J32,100)/100) -> 0 | W32: 0 | X32: =1.6 * W32 -> 0 | Y32: =$AY$1 -> 1.3 | Z32: =V32*Y32+(1-V32) -> 1 | AA32: =(0.795*O32)-0.0014 -> -0.0014 | AD32: =1 - EXP(-2*(AC32^2)) -> 0 | AE32: =(104.7*AA32+0.307*Q32-15)*(Q32^0.75)*10^-3 -> 0 | AF32: =AE32*AD32*Z32 -> 0 | AG32: =(AF32 * M32) + (0.045 * X32) -> 0 | AH32: =$AV$2 -> 0.08 | AI32: =(AF32 * ((1 - O32) + (0.04 * AF32))) * ( 1 - AH32 ) -> 0 | AJ32: =$AV$1 -> 0.19 | AK32: =$AW$20 -> 0.6784 | AL32: =AI32 * AJ32 * R32 * T32 * AK32 -> 0 | AM32: =AI32*AJ32*S32*U32*AK32 -> 0 | AN32: =AL32+AM32 -> 0 | AO32: =H32*AN32*L32 -> 0 | AU32: WA | AV32: 99.59 | AW32: 0.41
F33: Autumn | H33: 90 | I33: 0 | J33: 0 | L33: =$AV$3 -> 91.25 | R33: =1-S33 -> 0 | S33: =IF($D$11="yes", 1, VLOOKUP($B$11, $AU$26:$AW$32, 1)) -> 1 | T33: =VLOOKUP($B$11,$AW$10:$AX$16, 2, FALSE) -> 0.72 | U33: =$AV$10 -> 0.0047 | V33: =(I33/100)*(MIN(J33,100)/100) -> 0 | W33: 0 | X33: =1.6 * W33 -> 0 | Y33: =$AY$1 -> 1.3 | Z33: =V33*Y33+(1-V33) -> 1 | AA33: =(0.795*O33)-0.0014 -> -0.0014 | AD33: =1 - EXP(-2*(AC33^2)) -> 0 | AE33: =(104.7*AA33+0.307*Q33-15)*(Q33^0.75)*10^-3 -> 0 | AF33: =AE33*AD33*Z33 -> 0 | AG33: =(AF33 * M33) + (0.045 * X33) -> 0 | AH33: =$AV$2 -> 0.08 | AI33: =(AF33 * ((1 - O33) + (0.04 * AF33))) * ( 1 - AH33 ) -> 0 | AJ33: =$AV$1 -> 0.19 | AK33: =$AW$20 -> 0.6784 | AL33: =AI33 * AJ33 * R33 * T33 * AK33 -> 0 | AM33: =AI33*AJ33*S33*U33*AK33 -> 0 | AN33: =AL33+AM33 -> 0 | AO33: =H33*AN33*L33 -> 0
F34: Winter | H34: 80 | I34: 0 | J34: 0 | L34: =$AV$3 -> 91.25 | R34: =1-S34 -> 0 | S34: =IF($D$11="yes", 1, VLOOKUP($B$11, $AU$26:$AW$32, 1)) -> 1 | T34: =VLOOKUP($B$11,$AW$10:$AX$16, 2, FALSE) -> 0.72 | U34: =$AV$10 -> 0.0047 | V34: =(I34/100)*(MIN(J34,100)/100) -> 0 | W34: 0 | X34: =1.6 * W34 -> 0 | Y34: =$AY$1 -> 1.3 | Z34: =V34*Y34+(1-V34) -> 1 | AA34: =(0.795*O34)-0.0014 -> -0.0014 | AD34: =1 - EXP(-2*(AC34^2)) -> 0 | AE34: =(104.7*AA34+0.307*Q34-15)*(Q34^0.75)*10^-3 -> 0 | AF34: =AE34*AD34*Z34 -> 0 | AG34: =(AF34 * M34) + (0.045 * X34) -> 0 | AH34: =$AV$2 -> 0.08 | AI34: =(AF34 * ((1 - O34) + (0.04 * AF34))) * ( 1 - AH34 ) -> 0 | AJ34: =$AV$1 -> 0.19 | AK34: =$AW$20 -> 0.6784 | AL34: =AI34 * AJ34 * R34 * T34 * AK34 -> 0 | AM34: =AI34*AJ34*S34*U34*AK34 -> 0 | AN34: =AL34+AM34 -> 0 | AO34: =H34*AN34*L34 -> 0
AU36: EFN2O
AU37: Irrigated pasture | AV37: 0.0059
AU38: Irrigated crop | AV38: 0.007
AU39: Non-irrigated pasture | AV39: 0.0018
AU40: Non-irrigated crop (low rainfall) | AV40: 0.0029
A41: NSW | B41: NSW | C41: ACT/NSW | D41: no | E41: Breeding ewes | F41: Spring | H41: 100 | I41: 95 | J41: 90 | L41: =$AV$3 -> 91.25 | M41: {=_xludf.DROP(_xludf.XLOOKUP($C41,#REF!,#REF!),1)} -> #NAME? | O41: {=_xludf.DROP(_xludf.XLOOKUP($C41,#REF!,#REF!),1)} -> #NAME? | Q41: {=_xludf.DROP(_xludf.XLOOKUP($C41,#REF!,#REF!),1)} -> #NAME? | R41: =1-S41 -> 0.0045 | S41: =IF($D41="yes", 1, VLOOKUP($B41, $AU$26:$AW$32, 2, FALSE)/100) -> 0.9955 | T41: =VLOOKUP($B41,$AW$10:$AX$16, 2, FALSE) -> 0.75 | U41: =$AV$10 -> 0.0047 | V41: =(I41/100)*(MIN(J41,100)/100) -> 0.855 | W41: 0 | X41: =1.6 * W41 -> 0 | Y41: =$AY$1 -> 1.3 | Z41: =V41*Y41+(1-V41) -> 1.2565 | AA41: =(0.795*O41)-0.0014 -> #NAME? | AC41: {=_xludf.DROP(_xludf.XLOOKUP($C41,#REF!,#REF!),1)} -> #NAME? | AD41: =1 - EXP(-2*(AC41^2)) -> #NAME? | AE41: =(104.7*AA41+0.307*Q41-15)*(Q41^0.75)*10^-3 -> #NAME? | AF41: =AE41*AD41*Z41 -> #NAME? | AG41: =(AF41 * M41) + (0.045 * X41) -> #NAME? | AH41: =$AV$2 -> 0.08 | AI41: =(AF41 * ((1 - O41) + (0.04 * AF41))) * ( 1 - AH41 ) -> #NAME? | AJ41: =$AV$1 -> 0.19 | AK41: =$AW$20 -> 0.6784 | AL41: =AI41 * AJ41 * R41 * T41 * AK41 -> #NAME? | AM41: =AI41*AJ41*S41*U41*AK41 -> #NAME? | AN41: =AL41+AM41 -> #NAME? | AO41: =H41*AN41*L41 -> #NAME? | AP41: =SUM(AO41:AO64)*10^-3 -> #NAME? | AU41: Non-irrigated crop (high rainfall) | AV41: 0.008
...

Sheet 4.4.1.1
I1: 3.4.1 | J1: 3.4.1 | V1: 3.4.1 321 | Z1: 3.4.1 | AD1: 3.4.1 | AE1: 3.4.1 | AF1: Ch 3.4.1
X2: 1.6 * PLjk=6 | AG2: (Ijk * CPjk) + (0.045 * MCjk=6) | AI2: (Ijk * ((1 - DMDjk) + (0.04 * Ijk))) * ( 1 - A ) | AL2: VSjk * BO * MMSm * MCFim * 𝜌 | AN2: VSjk * BO * MMSm * MCFim * 𝜌 | AO2: SUM SUM SUM (Njk * Mjkm * Dj) * 10^-3 | AS2: Mleach * EFleach * CN2O * 10^-3 | AU2: AE * FracGASMsoil | AW2: Mvol * EFN2O * CN2O * 10^-3 | BA2: LEjk=3,4 * 1.6 | BB2: (GWk * Yk) / 365 | BC2: LWGjk * 0.92 | BE2: Wjk / SRWk | BF2: ((0.045 * MPjk=3,4) + (WPk * 0.84) + (EBGjk * ((212 - 4 * ((EBGjk * 1000)/(4* SRWk^0.75) - 1)) - ((140 - 4 * (((EBGjk * 1000)/4 * SRWk ^0.75) - 1))/(1 + e ^ (-6 * (Zjk - 0.4)))))) * 10^-3) / 6.25 | BG2: 1.6 * PLjk=6 | BH2: (CPIjk / 6.25 ) - NRjk | BI2: SUM SUM (Njk * NEjk * Dj) | BL2: AE * EFprp * CN2O * 10^-3 | BM2: AE * FracWet * FracLEACH
H3: 1071 | I3: 342 | J3: 323 | L3: 1075 | M3: 1078 | O3: 1077 | Q3: 1081 | S3: 1085 | U3: 1082 | V3: 1004 | W3: 990 | X3: 988 | Y3: 351 | Z3: 314 | AA3: 302 | AC3: 349 | AD3: 308 | AE3: 296 | AF3: 946 | AG3: 983 | AH3: 1087 | AI3: 945 | AJ3: 1084 | AK3: 1086 | AL3: 930 | AN3: 930 | AO3: 922 | AQ3: 1092 | AR3: 1094 | AS3: 1056 | AT3: 1093 | AU3: 1045 | AV3: 1091 | AW3: 1037 | AX3: 1080 | AY3: 1072 | AZ3: 1073 | BA3: 1003 | BB3: 1011 | BC3: 1017 | BD3: 1089 | BE3: 1021 | BF3: 994 | BG3: 988 | BH3: 978 | BI3: 970 | BJ3: 1090 | BK3: 1088 | BL3: 963 | BM3: 1062 | BN3: 1095
H4: input | L4: constant | M4: constant | O4: constant | Q4: constant | S4: constant | U4: constant | V4: constant | W4: expression | X4: expression | Y4: constant | Z4: expression | AA4: expression | AC4: constant | AD4: expression | AE4: expression | AF4: expression | AG4: expression | AH4: constant | AI4: expression | AJ4: constant | AK4: constant | AL4: expression | AN4: expression | AO4: expression | AQ4: constant | AR4: constant | AS4: expression | AT4: constant | AU4: expression | AV4: constant | AW4: expression | AX4: constant | AY4: input | AZ4: input | BA4: expression | BB4: expression | BC4: expression | BD4: constant | BE4: expression | BF4: expression | BG4: expression | BH4: expression | BI4: expression | BJ4: constant | BK4: constant | BL4: expression | BM4: expression | BN4: constant
L5: input | M5: input | O5: input | Q5: input | U5: input | AC5: input | AX5: input
H8: head | L8: days | M8: d | O8: d | Q8: kg | S8: d | U8: d | V8: d | W8: d | X8: kg / head / day | AF8: kg DM/head/day | AG8: kg/head/day | AH8: d | AI8: kg/head/day | AJ8: m3 CH4/kgVS | AK8: kg/m3 | AL8: kg CH4/head/day | AN8: kg CH4/head/day | AO8: kg CH4 | AQ8: fraction | AR8: fraction | AS8: t N2O | AT8: kg NH3-N + NOx-N / kg N | AU8: kg N | AV8: kg N2O-N / kg N | AW8: t N2O | AX8: kg | AY8: kg / head | AZ8: fraction | BA8: kg/head/day | BB8: kg/head/day | BC8: kg | BD8: kg | BE8: d | BF8: kg N / head / day | BG8: kg / head / day | BH8: kg N/head/day | BI8: kg N | BJ8: kg N2O-N/kg N | BK8: d | BL8: t N2O | BM8: kg N | BN8: kg N2O-N / kg N
H9: number of sheep in each time period and class | I9: Lambing rate | J9: Lamb marking rate | L9: number of days in each time period | M9: crude protein content of feed intake | O9: dry matter digestibility | Q9: liveweight | S9: fraction of waste in each MMS | U9: methane conversion factor for temperate zone and MMS | V9: proportion of ewes lactating each season or time period | W9: Proportion of lambs born in the time period | X9: Milk intake | AF9: dry matter intake | AG9: crude protein intake | AH9: ash content of feed intake | AI9: volatile solid production | AJ9: emisions potential | AK9: density of methane | AL9: methane produced from manure | AN9: methane produced from manure | AO9: annual methane production from manure | AQ9: fraction of N that is available for leaching and runoff | AR9: fraction of all N that is lost through leaching and runoff | AS9: Leaching and runoff emissions from urine and dung deposited on pasture | AT9: fraction of nitrogen volatilised from urine and faeces deposited on pasture | AU9: mass of nitrogen volatilised from urine and faeces deposited on pasture | AV9: nitrous oxide emission factor for atmospheric deposition | AW9: Annual atmospheric deposition emissions from urine and dung deposited on pasture | AX9: liveweight gain | AY9: greasy wool production per sheep class | AZ9: average clean wool yield per sheep class | BA9: milk production | BB9: clean wool production | BC9: empty body gain | BD9: standard reference weight | BE9: relative size | BF9: the amount of nitrogen retained by the body | BG9: milk intake for sheep | BH9: nitrogen excreted in each time-period and by each class | BI9: total mass of nitrogen excreted on PRP by sheep | BJ9: emission factor for nitrous oxide from urine and dung deposited to soil | BK9: factor to convert elemental mass of nitrous oxide to molecular mass | BL9: Total annual direct nitrous oxide emissions from agricultural soils from deposition of urine and dung | BM9: mass of nitrogen lost to leaching and runoff | BN9: emission factor for leaching and run off
A10: Scenario | B10: State | C10: State | D10: No unfenced water | E10: Class | G10: Month | H10: Njk | I10: LR | J10: LMR | K10: Custom Dj | L10: Dj | M10: CPjk | N10: Custom DMD | O10: DMDjk | P10: Custom liveweight | Q10: Wjk | R10: MMSm=1 | S10: MMSm=14 | T10: MCFim=1 | U10: MCFim=14 | V10: LEjk=3,4 | W10: PLjk=6 | X10: MCjk=6 | Y10: FAk | Z10: MAjk | AA10: qmjk | AB10: Custom DMA | AC10: DMAjk | AD10: RIjk | AE10: PIjk | AF10: Ijk | AG10: CPIjk | AH10: A | AI10: VSjk | AJ10: BO | AK10: 𝜌 | AL10: Mjkm=1 | AM10: Mjkm=14 | AN10: Mjk | AO10: ECH4 | AP10: ECH4 | AQ10: FracWet | AR10: FracLEACH | AS10: ESN2O,leach | AT10: FracGASMsoil | AU10: Mvol | AV10: EFN2O | AW10: EN2O,ad | AX10: LWGjk | AY10: GWk | AZ10: Yk | BA10: MPjk=3,4 | BB10: WPk | BC10: EBGjk | BD10: SRWk | BE10: Zjk | BF10: NRijk | BG10: MCjk=6 | BH10: NEjk | BI10: AE | BJ10: EFprp | BK10: CN2O | BL10: EN2O,dir | BM10: Mleach | BN10: EFleach
A11: Baseline | B11: ACT | C11: ACT/NSW | D11: yes | E11: Breeding ewes | F11: Spring | H11: 100 | I11: 95 | J11: 90 | L11: =$AV$3 -> 1091 | M11: {=_xludf.DROP(_xludf.XLOOKUP($C11,#REF!,#REF!),1)} -> #NAME? | O11: {=_xludf.DROP(_xludf.XLOOKUP($C11,#REF!,#REF!),1)} -> #NAME? | Q11: {=_xludf.DROP(_xludf.XLOOKUP($C11,#REF!,#REF!),1)} -> #NAME? | R11: =1-S11 -> 0 | S11: =IF($D$11="yes", 1, VLOOKUP($B$11, $AU$26:$AW$32, 1)) -> 1 | T11: =VLOOKUP($B$11,$AW$10:$AX$16, 2, FALSE) -> #N/A | U11: =$AV$10 -> EFN2O | V11: =(I11/100)*(MIN(J11,100)/100) -> 0.855 | W11: 0 | X11: =1.6 * W11 -> 0 | Y11: =$AY$1 -> 0 | Z11: =V11*Y11+(1-V11) -> 0.145 | AA11: =(0.795*O11)-0.0014 -> #NAME? | AC11: {=_xludf.DROP(_xludf.XLOOKUP($C11,#REF!,#REF!),1)} -> #NAME? | AD11: =1 - EXP(-2*(AC11^2)) -> #NAME? | AE11: =(104.7*AA11+0.307*Q11-15)*(Q11^0.75)*10^-3 -> #NAME? | AF11: =AE11*AD11*Z11 -> #NAME? | AG11: =(AF11 * M11) + (0.045 * X11) -> #NAME? | AH11: =$AV$2 -> 0 | AI11: =(AF11 * ((1 - O11) + (0.04 * AF11))) * ( 1 - AH11 ) -> #NAME? | AJ11: =$AV$1 -> 0 | AK11: =$AW$20 -> 0 | AL11: =AI11 * AJ11 * R11 * T11 * AK11 -> #NAME? | AM11: =AI11*AJ11*S11*U11*AK11 -> #NAME? | AN11: =AL11+AM11 -> #NAME? | AO11: =H11*AN11*L11 -> #NAME? | AP11: =SUM(AO11:AO34)*10^-3 -> #NAME? | AS11: =BM11 * BN11 * BK11 * 10^-3 -> #NAME? | AU11: =BI11 * AT11 -> 0 | AW11: =AU11 * AV11 * BK11 * 10^-3 -> 0 | BA11: =O11 * 1.6 -> #NAME? | BB11: =(AY11 * AZ11) / 365 -> 0 | BC11: =AX11 * 0.92 -> 0 | BE11: =L11 / BD11 -> #DIV/0! | BF11: =((0.045 * BA11) + (BB11 * 0.84) + (BC11 * ((212 - 4 * ((BC11 * 1000)/(4* BD11^0.75) - 1)) - ((140 - 4 * (((BC11 * 1000)/4 * BD11 ^0.75) - 1))/(1 + e ^ (-6 * (BE11 - 0.4)))))) * 10^-3) / 6.25 -> #NAME? | BG11: =1.6 * P11 -> 0 | BH11: =(R11 / 6.25 ) - NRjk -> #NAME? | BL11: =BI11 * BJ11 * BK11 * 10^-3 -> 0 | BM11: =BI11 * AM11 * AR11 -> #NAME?
F12: Summer | H12: 70 | I12: 0 | J12: 0 | L12: =$AV$3 -> 1091 | R12: =1-S12 -> 0 | S12: =IF($D$11="yes", 1, VLOOKUP($B$11, $AU$26:$AW$32, 1)) -> 1 | T12: =VLOOKUP($B$11,$AW$10:$AX$16, 2, FALSE) -> #N/A | U12: =$AV$10 -> EFN2O | V12: =(I12/100)*(MIN(J12,100)/100) -> 0 | W12: 0 | X12: =1.6 * W12 -> 0 | Y12: =$AY$1 -> 0 | Z12: =V12*Y12+(1-V12) -> 1 | AA12: =(0.795*O12)-0.0014 -> -0.0014 | AD12: =1 - EXP(-2*(AC12^2)) -> 0 | AE12: =(104.7*AA12+0.307*Q12-15)*(Q12^0.75)*10^-3 -> 0 | AF12: =AE12*AD12*Z12 -> 0 | AG12: =(AF12 * M12) + (0.045 * X12) -> 0 | AH12: =$AV$2 -> 0 | AI12: =(AF12 * ((1 - O12) + (0.04 * AF12))) * ( 1 - AH12 ) -> 0 | AJ12: =$AV$1 -> 0 | AK12: =$AW$20 -> 0 | AL12: =AI12 * AJ12 * R12 * T12 * AK12 -> #N/A | AM12: =AI12*AJ12*S12*U12*AK12 -> #VALUE! | AN12: =AL12+AM12 -> #N/A | AO12: =H12*AN12*L12 -> #N/A
F13: Autumn | H13: 65 | I13: 0 | J13: 0 | L13: =$AV$3 -> 1091 | R13: =1-S13 -> 0 | S13: =IF($D$11="yes", 1, VLOOKUP($B$11, $AU$26:$AW$32, 1)) -> 1 | T13: =VLOOKUP($B$11,$AW$10:$AX$16, 2, FALSE) -> #N/A | U13: =$AV$10 -> EFN2O | V13: =(I13/100)*(MIN(J13,100)/100) -> 0 | W13: 0 | X13: =1.6 * W13 -> 0 | Y13: =$AY$1 -> 0 | Z13: =V13*Y13+(1-V13) -> 1 | AA13: =(0.795*O13)-0.0014 -> -0.0014 | AD13: =1 - EXP(-2*(AC13^2)) -> 0 | AE13: =(104.7*AA13+0.307*Q13-15)*(Q13^0.75)*10^-3 -> 0 | AF13: =AE13*AD13*Z13 -> 0 | AG13: =(AF13 * M13) + (0.045 * X13) -> 0 | AH13: =$AV$2 -> 0 | AI13: =(AF13 * ((1 - O13) + (0.04 * AF13))) * ( 1 - AH13 ) -> 0 | AJ13: =$AV$1 -> 0 | AK13: =$AW$20 -> 0 | AL13: =AI13 * AJ13 * R13 * T13 * AK13 -> #N/A | AM13: =AI13*AJ13*S13*U13*AK13 -> #VALUE! | AN13: =AL13+AM13 -> #N/A | AO13: =H13*AN13*L13 -> #N/A
F14: Winter | H14: 80 | I14: 0 | J14: 0 | L14: =$AV$3 -> 1091 | R14: =1-S14 -> 0 | S14: =IF($D$11="yes", 1, VLOOKUP($B$11, $AU$26:$AW$32, 1)) -> 1 | T14: =VLOOKUP($B$11,$AW$10:$AX$16, 2, FALSE) -> #N/A | U14: =$AV$10 -> EFN2O | V14: =(I14/100)*(MIN(J14,100)/100) -> 0 | W14: 0 | X14: =1.6 * W14 -> 0 | Y14: =$AY$1 -> 0 | Z14: =V14*Y14+(1-V14) -> 1 | AA14: =(0.795*O14)-0.0014 -> -0.0014 | AD14: =1 - EXP(-2*(AC14^2)) -> 0 | AE14: =(104.7*AA14+0.307*Q14-15)*(Q14^0.75)*10^-3 -> 0 | AF14: =AE14*AD14*Z14 -> 0 | AG14: =(AF14 * M14) + (0.045 * X14) -> 0 | AH14: =$AV$2 -> 0 | AI14: =(AF14 * ((1 - O14) + (0.04 * AF14))) * ( 1 - AH14 ) -> 0 | AJ14: =$AV$1 -> 0 | AK14: =$AW$20 -> 0 | AL14: =AI14 * AJ14 * R14 * T14 * AK14 -> #N/A | AM14: =AI14*AJ14*S14*U14*AK14 -> #VALUE! | AN14: =AL14+AM14 -> #N/A | AO14: =H14*AN14*L14 -> #N/A
E15: Lambs and hoggets | F15: Spring | H15: 200 | I15: 0 | J15: 0 | L15: =$AV$3 -> 1091 | R15: =1-S15 -> 0 | S15: =IF($D$11="yes", 1, VLOOKUP($B$11, $AU$26:$AW$32, 1)) -> 1 | T15: =VLOOKUP($B$11,$AW$10:$AX$16, 2, FALSE) -> #N/A | U15: =$AV$10 -> EFN2O | V15: =(I15/100)*(MIN(J15,100)/100) -> 0 | W15: 1 | X15: =1.6 * W15 -> 1.6 | Y15: =$AY$1 -> 0 | Z15: =V15*Y15+(1-V15) -> 1 | AA15: =(0.795*O15)-0.0014 -> -0.0014 | AD15: =1 - EXP(-2*(AC15^2)) -> 0 | AE15: =(104.7*AA15+0.307*Q15-15)*(Q15^0.75)*10^-3 -> 0 | AF15: =AE15*AD15*Z15 -> 0 | AG15: =(AF15 * M15) + (0.045 * X15) -> 0.072 | AH15: =$AV$2 -> 0 | AI15: =(AF15 * ((1 - O15) + (0.04 * AF15))) * ( 1 - AH15 ) -> 0 | AJ15: =$AV$1 -> 0 | AK15: =$AW$20 -> 0 | AL15: =AI15 * AJ15 * R15 * T15 * AK15 -> #N/A | AM15: =AI15*AJ15*S15*U15*AK15 -> #VALUE! | AN15: =AL15+AM15 -> #N/A | AO15: =H15*AN15*L15 -> #N/A
F16: Summer | H16: 210 | I16: 0 | J16: 0 | L16: =$AV$3 -> 1091 | R16: =1-S16 -> 0 | S16: =IF($D$11="yes", 1, VLOOKUP($B$11, $AU$26:$AW$32, 1)) -> 1 | T16: =VLOOKUP($B$11,$AW$10:$AX$16, 2, FALSE) -> #N/A | U16: =$AV$10 -> EFN2O | V16: =(I16/100)*(MIN(J16,100)/100) -> 0 | W16: 0 | X16: =1.6 * W16 -> 0 | Y16: =$AY$1 -> 0 | Z16: =V16*Y16+(1-V16) -> 1 | AA16: =(0.795*O16)-0.0014 -> -0.0014 | AD16: =1 - EXP(-2*(AC16^2)) -> 0 | AE16: =(104.7*AA16+0.307*Q16-15)*(Q16^0.75)*10^-3 -> 0 | AF16: =AE16*AD16*Z16 -> 0 | AG16: =(AF16 * M16) + (0.045 * X16) -> 0 | AH16: =$AV$2 -> 0 | AI16: =(AF16 * ((1 - O16) + (0.04 * AF16))) * ( 1 - AH16 ) -> 0 | AJ16: =$AV$1 -> 0 | AK16: =$AW$20 -> 0 | AL16: =AI16 * AJ16 * R16 * T16 * AK16 -> #N/A | AM16: =AI16*AJ16*S16*U16*AK16 -> #VALUE! | AN16: =AL16+AM16 -> #N/A | AO16: =H16*AN16*L16 -> #N/A
F17: Autumn | H17: 170 | I17: 0 | J17: 0 | L17: =$AV$3 -> 1091 | R17: =1-S17 -> 0 | S17: =IF($D$11="yes", 1, VLOOKUP($B$11, $AU$26:$AW$32, 1)) -> 1 | T17: =VLOOKUP($B$11,$AW$10:$AX$16, 2, FALSE) -> #N/A | U17: =$AV$10 -> EFN2O | V17: =(I17/100)*(MIN(J17,100)/100) -> 0 | W17: 0 | X17: =1.6 * W17 -> 0 | Y17: =$AY$1 -> 0 | Z17: =V17*Y17+(1-V17) -> 1 | AA17: =(0.795*O17)-0.0014 -> -0.0014 | AD17: =1 - EXP(-2*(AC17^2)) -> 0 | AE17: =(104.7*AA17+0.307*Q17-15)*(Q17^0.75)*10^-3 -> 0 | AF17: =AE17*AD17*Z17 -> 0 | AG17: =(AF17 * M17) + (0.045 * X17) -> 0 | AH17: =$AV$2 -> 0 | AI17: =(AF17 * ((1 - O17) + (0.04 * AF17))) * ( 1 - AH17 ) -> 0 | AJ17: =$AV$1 -> 0 | AK17: =$AW$20 -> 0 | AL17: =AI17 * AJ17 * R17 * T17 * AK17 -> #N/A | AM17: =AI17*AJ17*S17*U17*AK17 -> #VALUE! | AN17: =AL17+AM17 -> #N/A | AO17: =H17*AN17*L17 -> #N/A
F18: Winter | H18: 200 | I18: 0 | J18: 0 | L18: =$AV$3 -> 1091 | R18: =1-S18 -> 0 | S18: =IF($D$11="yes", 1, VLOOKUP($B$11, $AU$26:$AW$32, 1)) -> 1 | T18: =VLOOKUP($B$11,$AW$10:$AX$16, 2, FALSE) -> #N/A | U18: =$AV$10 -> EFN2O | V18: =(I18/100)*(MIN(J18,100)/100) -> 0 | W18: 0 | X18: =1.6 * W18 -> 0 | Y18: =$AY$1 -> 0 | Z18: =V18*Y18+(1-V18) -> 1 | AA18: =(0.795*O18)-0.0014 -> -0.0014 | AD18: =1 - EXP(-2*(AC18^2)) -> 0 | AE18: =(104.7*AA18+0.307*Q18-15)*(Q18^0.75)*10^-3 -> 0 | AF18: =AE18*AD18*Z18 -> 0 | AG18: =(AF18 * M18) + (0.045 * X18) -> 0 | AH18: =$AV$2 -> 0 | AI18: =(AF18 * ((1 - O18) + (0.04 * AF18))) * ( 1 - AH18 ) -> 0 | AJ18: =$AV$1 -> 0 | AK18: =$AW$20 -> 0 | AL18: =AI18 * AJ18 * R18 * T18 * AK18 -> #N/A | AM18: =AI18*AJ18*S18*U18*AK18 -> #VALUE! | AN18: =AL18+AM18 -> #N/A | AO18: =H18*AN18*L18 -> #N/A
E19: Maiden ewes | F19: Spring | H19: 100 | I19: 95 | J19: 92 | L19: =$AV$3 -> 1091 | R19: =1-S19 -> 0 | S19: =IF($D$11="yes", 1, VLOOKUP($B$11, $AU$26:$AW$32, 1)) -> 1 | T19: =VLOOKUP($B$11,$AW$10:$AX$16, 2, FALSE) -> #N/A | U19: =$AV$10 -> EFN2O | V19: =(I19/100)*(MIN(J19,100)/100) -> 0.874 | W19: 0 | X19: =1.6 * W19 -> 0 | Y19: =$AY$1 -> 0 | Z19: =V19*Y19+(1-V19) -> 0.126 | AA19: =(0.795*O19)-0.0014 -> -0.0014 | AD19: =1 - EXP(-2*(AC19^2)) -> 0 | AE19: =(104.7*AA19+0.307*Q19-15)*(Q19^0.75)*10^-3 -> 0 | AF19: =AE19*AD19*Z19 -> 0 | AG19: =(AF19 * M19) + (0.045 * X19) -> 0 | AH19: =$AV$2 -> 0 | AI19: =(AF19 * ((1 - O19) + (0.04 * AF19))) * ( 1 - AH19 ) -> 0 | AJ19: =$AV$1 -> 0 | AK19: =$AW$20 -> 0 | AL19: =AI19 * AJ19 * R19 * T19 * AK19 -> #N/A | AM19: =AI19*AJ19*S19*U19*AK19 -> #VALUE! | AN19: =AL19+AM19 -> #N/A | AO19: =H19*AN19*L19 -> #N/A
F20: Summer | H20: 140 | I20: 0 | J20: 0 | L20: =$AV$3 -> 1091 | R20: =1-S20 -> 0 | S20: =IF($D$11="yes", 1, VLOOKUP($B$11, $AU$26:$AW$32, 1)) -> 1 | T20: =VLOOKUP($B$11,$AW$10:$AX$16, 2, FALSE) -> #N/A | U20: =$AV$10 -> EFN2O | V20: =(I20/100)*(MIN(J20,100)/100) -> 0 | W20: 0 | X20: =1.6 * W20 -> 0 | Y20: =$AY$1 -> 0 | Z20: =V20*Y20+(1-V20) -> 1 | AA20: =(0.795*O20)-0.0014 -> -0.0014 | AD20: =1 - EXP(-2*(AC20^2)) -> 0 | AE20: =(104.7*AA20+0.307*Q20-15)*(Q20^0.75)*10^-3 -> 0 | AF20: =AE20*AD20*Z20 -> 0 | AG20: =(AF20 * M20) + (0.045 * X20) -> 0 | AH20: =$AV$2 -> 0 | AI20: =(AF20 * ((1 - O20) + (0.04 * AF20))) * ( 1 - AH20 ) -> 0 | AJ20: =$AV$1 -> 0 | AK20: =$AW$20 -> 0 | AL20: =AI20 * AJ20 * R20 * T20 * AK20 -> #N/A | AM20: =AI20*AJ20*S20*U20*AK20 -> #VALUE! | AN20: =AL20+AM20 -> #N/A | AO20: =H20*AN20*L20 -> #N/A
F21: Autumn | H21: 135 | I21: 0 | J21: 0 | L21: =$AV$3 -> 1091 | R21: =1-S21 -> 0 | S21: =IF($D$11="yes", 1, VLOOKUP($B$11, $AU$26:$AW$32, 1)) -> 1 | T21: =VLOOKUP($B$11,$AW$10:$AX$16, 2, FALSE) -> #N/A | U21: =$AV$10 -> EFN2O | V21: =(I21/100)*(MIN(J21,100)/100) -> 0 | W21: 0 | X21: =1.6 * W21 -> 0 | Y21: =$AY$1 -> 0 | Z21: =V21*Y21+(1-V21) -> 1 | AA21: =(0.795*O21)-0.0014 -> -0.0014 | AD21: =1 - EXP(-2*(AC21^2)) -> 0 | AE21: =(104.7*AA21+0.307*Q21-15)*(Q21^0.75)*10^-3 -> 0 | AF21: =AE21*AD21*Z21 -> 0 | AG21: =(AF21 * M21) + (0.045 * X21) -> 0 | AH21: =$AV$2 -> 0 | AI21: =(AF21 * ((1 - O21) + (0.04 * AF21))) * ( 1 - AH21 ) -> 0 | AJ21: =$AV$1 -> 0 | AK21: =$AW$20 -> 0 | AL21: =AI21 * AJ21 * R21 * T21 * AK21 -> #N/A | AM21: =AI21*AJ21*S21*U21*AK21 -> #VALUE! | AN21: =AL21+AM21 -> #N/A | AO21: =H21*AN21*L21 -> #N/A
F22: Winter | H22: 130 | I22: 0 | J22: 0 | L22: =$AV$3 -> 1091 | R22: =1-S22 -> 0 | S22: =IF($D$11="yes", 1, VLOOKUP($B$11, $AU$26:$AW$32, 1)) -> 1 | T22: =VLOOKUP($B$11,$AW$10:$AX$16, 2, FALSE) -> #N/A | U22: =$AV$10 -> EFN2O | V22: =(I22/100)*(MIN(J22,100)/100) -> 0 | W22: 0 | X22: =1.6 * W22 -> 0 | Y22: =$AY$1 -> 0 | Z22: =V22*Y22+(1-V22) -> 1 | AA22: =(0.795*O22)-0.0014 -> -0.0014 | AD22: =1 - EXP(-2*(AC22^2)) -> 0 | AE22: =(104.7*AA22+0.307*Q22-15)*(Q22^0.75)*10^-3 -> 0 | AF22: =AE22*AD22*Z22 -> 0 | AG22: =(AF22 * M22) + (0.045 * X22) -> 0 | AH22: =$AV$2 -> 0 | AI22: =(AF22 * ((1 - O22) + (0.04 * AF22))) * ( 1 - AH22 ) -> 0 | AJ22: =$AV$1 -> 0 | AK22: =$AW$20 -> 0 | AL22: =AI22 * AJ22 * R22 * T22 * AK22 -> #N/A | AM22: =AI22*AJ22*S22*U22*AK22 -> #VALUE! | AN22: =AL22+AM22 -> #N/A | AO22: =H22*AN22*L22 -> #N/A
E23: Other ewes | F23: Spring | H23: 200 | I23: 0 | J23: 0 | L23: =$AV$3 -> 1091 | R23: =1-S23 -> 0 | S23: =IF($D$11="yes", 1, VLOOKUP($B$11, $AU$26:$AW$32, 1)) -> 1 | T23: =VLOOKUP($B$11,$AW$10:$AX$16, 2, FALSE) -> #N/A | U23: =$AV$10 -> EFN2O | V23: =(I23/100)*(MIN(J23,100)/100) -> 0 | W23: 0 | X23: =1.6 * W23 -> 0 | Y23: =$AY$1 -> 0 | Z23: =V23*Y23+(1-V23) -> 1 | AA23: =(0.795*O23)-0.0014 -> -0.0014 | AD23: =1 - EXP(-2*(AC23^2)) -> 0 | AE23: =(104.7*AA23+0.307*Q23-15)*(Q23^0.75)*10^-3 -> 0 | AF23: =AE23*AD23*Z23 -> 0 | AG23: =(AF23 * M23) + (0.045 * X23) -> 0 | AH23: =$AV$2 -> 0 | AI23: =(AF23 * ((1 - O23) + (0.04 * AF23))) * ( 1 - AH23 ) -> 0 | AJ23: =$AV$1 -> 0 | AK23: =$AW$20 -> 0 | AL23: =AI23 * AJ23 * R23 * T23 * AK23 -> #N/A | AM23: =AI23*AJ23*S23*U23*AK23 -> #VALUE! | AN23: =AL23+AM23 -> #N/A | AO23: =H23*AN23*L23 -> #N/A
F24: Summer | H24: 210 | I24: 0 | J24: 0 | L24: =$AV$3 -> 1091 | R24: =1-S24 -> 0 | S24: =IF($D$11="yes", 1, VLOOKUP($B$11, $AU$26:$AW$32, 1)) -> 1 | T24: =VLOOKUP($B$11,$AW$10:$AX$16, 2, FALSE) -> #N/A | U24: =$AV$10 -> EFN2O | V24: =(I24/100)*(MIN(J24,100)/100) -> 0 | W24: 0 | X24: =1.6 * W24 -> 0 | Y24: =$AY$1 -> 0 | Z24: =V24*Y24+(1-V24) -> 1 | AA24: =(0.795*O24)-0.0014 -> -0.0014 | AD24: =1 - EXP(-2*(AC24^2)) -> 0 | AE24: =(104.7*AA24+0.307*Q24-15)*(Q24^0.75)*10^-3 -> 0 | AF24: =AE24*AD24*Z24 -> 0 | AG24: =(AF24 * M24) + (0.045 * X24) -> 0 | AH24: =$AV$2 -> 0 | AI24: =(AF24 * ((1 - O24) + (0.04 * AF24))) * ( 1 - AH24 ) -> 0 | AJ24: =$AV$1 -> 0 | AK24: =$AW$20 -> 0 | AL24: =AI24 * AJ24 * R24 * T24 * AK24 -> #N/A | AM24: =AI24*AJ24*S24*U24*AK24 -> #VALUE! | AN24: =AL24+AM24 -> #N/A | AO24: =H24*AN24*L24 -> #N/A
F25: Autumn | H25: 190 | I25: 0 | J25: 0 | L25: =$AV$3 -> 1091 | R25: =1-S25 -> 0 | S25: =IF($D$11="yes", 1, VLOOKUP($B$11, $AU$26:$AW$32, 1)) -> 1 | T25: =VLOOKUP($B$11,$AW$10:$AX$16, 2, FALSE) -> #N/A | U25: =$AV$10 -> EFN2O | V25: =(I25/100)*(MIN(J25,100)/100) -> 0 | W25: 0 | X25: =1.6 * W25 -> 0 | Y25: =$AY$1 -> 0 | Z25: =V25*Y25+(1-V25) -> 1 | AA25: =(0.795*O25)-0.0014 -> -0.0014 | AD25: =1 - EXP(-2*(AC25^2)) -> 0 | AE25: =(104.7*AA25+0.307*Q25-15)*(Q25^0.75)*10^-3 -> 0 | AF25: =AE25*AD25*Z25 -> 0 | AG25: =(AF25 * M25) + (0.045 * X25) -> 0 | AH25: =$AV$2 -> 0 | AI25: =(AF25 * ((1 - O25) + (0.04 * AF25))) * ( 1 - AH25 ) -> 0 | AJ25: =$AV$1 -> 0 | AK25: =$AW$20 -> 0 | AL25: =AI25 * AJ25 * R25 * T25 * AK25 -> #N/A | AM25: =AI25*AJ25*S25*U25*AK25 -> #VALUE! | AN25: =AL25+AM25 -> #N/A | AO25: =H25*AN25*L25 -> #N/A
F26: Winter | H26: 180 | I26: 0 | J26: 0 | L26: =$AV$3 -> 1091 | R26: =1-S26 -> 0 | S26: =IF($D$11="yes", 1, VLOOKUP($B$11, $AU$26:$AW$32, 1)) -> 1 | T26: =VLOOKUP($B$11,$AW$10:$AX$16, 2, FALSE) -> #N/A | U26: =$AV$10 -> EFN2O | V26: =(I26/100)*(MIN(J26,100)/100) -> 0 | W26: 0 | X26: =1.6 * W26 -> 0 | Y26: =$AY$1 -> 0 | Z26: =V26*Y26+(1-V26) -> 1 | AA26: =(0.795*O26)-0.0014 -> -0.0014 | AD26: =1 - EXP(-2*(AC26^2)) -> 0 | AE26: =(104.7*AA26+0.307*Q26-15)*(Q26^0.75)*10^-3 -> 0 | AF26: =AE26*AD26*Z26 -> 0 | AG26: =(AF26 * M26) + (0.045 * X26) -> 0 | AH26: =$AV$2 -> 0 | AI26: =(AF26 * ((1 - O26) + (0.04 * AF26))) * ( 1 - AH26 ) -> 0 | AJ26: =$AV$1 -> 0 | AK26: =$AW$20 -> 0 | AL26: =AI26 * AJ26 * R26 * T26 * AK26 -> #N/A | AM26: =AI26*AJ26*S26*U26*AK26 -> #VALUE! | AN26: =AL26+AM26 -> #N/A | AO26: =H26*AN26*L26 -> #N/A
E27: Rams | F27: Spring | H27: 50 | I27: 0 | J27: 0 | L27: =$AV$3 -> 1091 | R27: =1-S27 -> 0 | S27: =IF($D$11="yes", 1, VLOOKUP($B$11, $AU$26:$AW$32, 1)) -> 1 | T27: =VLOOKUP($B$11,$AW$10:$AX$16, 2, FALSE) -> #N/A | U27: =$AV$10 -> EFN2O | V27: =(I27/100)*(MIN(J27,100)/100) -> 0 | W27: 0 | X27: =1.6 * W27 -> 0 | Y27: =$AY$1 -> 0 | Z27: =V27*Y27+(1-V27) -> 1 | AA27: =(0.795*O27)-0.0014 -> -0.0014 | AD27: =1 - EXP(-2*(AC27^2)) -> 0 | AE27: =(104.7*AA27+0.307*Q27-15)*(Q27^0.75)*10^-3 -> 0 | AF27: =AE27*AD27*Z27 -> 0 | AG27: =(AF27 * M27) + (0.045 * X27) -> 0 | AH27: =$AV$2 -> 0 | AI27: =(AF27 * ((1 - O27) + (0.04 * AF27))) * ( 1 - AH27 ) -> 0 | AJ27: =$AV$1 -> 0 | AK27: =$AW$20 -> 0 | AL27: =AI27 * AJ27 * R27 * T27 * AK27 -> #N/A | AM27: =AI27*AJ27*S27*U27*AK27 -> #VALUE! | AN27: =AL27+AM27 -> #N/A | AO27: =H27*AN27*L27 -> #N/A
F28: Summer | H28: 55 | I28: 0 | J28: 0 | L28: =$AV$3 -> 1091 | R28: =1-S28 -> 0 | S28: =IF($D$11="yes", 1, VLOOKUP($B$11, $AU$26:$AW$32, 1)) -> 1 | T28: =VLOOKUP($B$11,$AW$10:$AX$16, 2, FALSE) -> #N/A | U28: =$AV$10 -> EFN2O | V28: =(I28/100)*(MIN(J28,100)/100) -> 0 | W28: 0 | X28: =1.6 * W28 -> 0 | Y28: =$AY$1 -> 0 | Z28: =V28*Y28+(1-V28) -> 1 | AA28: =(0.795*O28)-0.0014 -> -0.0014 | AD28: =1 - EXP(-2*(AC28^2)) -> 0 | AE28: =(104.7*AA28+0.307*Q28-15)*(Q28^0.75)*10^-3 -> 0 | AF28: =AE28*AD28*Z28 -> 0 | AG28: =(AF28 * M28) + (0.045 * X28) -> 0 | AH28: =$AV$2 -> 0 | AI28: =(AF28 * ((1 - O28) + (0.04 * AF28))) * ( 1 - AH28 ) -> 0 | AJ28: =$AV$1 -> 0 | AK28: =$AW$20 -> 0 | AL28: =AI28 * AJ28 * R28 * T28 * AK28 -> #N/A | AM28: =AI28*AJ28*S28*U28*AK28 -> #VALUE! | AN28: =AL28+AM28 -> #N/A | AO28: =H28*AN28*L28 -> #N/A
F29: Autumn | H29: 60 | I29: 0 | J29: 0 | L29: =$AV$3 -> 1091 | R29: =1-S29 -> 0 | S29: =IF($D$11="yes", 1, VLOOKUP($B$11, $AU$26:$AW$32, 1)) -> 1 | T29: =VLOOKUP($B$11,$AW$10:$AX$16, 2, FALSE) -> #N/A | U29: =$AV$10 -> EFN2O | V29: =(I29/100)*(MIN(J29,100)/100) -> 0 | W29: 0 | X29: =1.6 * W29 -> 0 | Y29: =$AY$1 -> 0 | Z29: =V29*Y29+(1-V29) -> 1 | AA29: =(0.795*O29)-0.0014 -> -0.0014 | AD29: =1 - EXP(-2*(AC29^2)) -> 0 | AE29: =(104.7*AA29+0.307*Q29-15)*(Q29^0.75)*10^-3 -> 0 | AF29: =AE29*AD29*Z29 -> 0 | AG29: =(AF29 * M29) + (0.045 * X29) -> 0 | AH29: =$AV$2 -> 0 | AI29: =(AF29 * ((1 - O29) + (0.04 * AF29))) * ( 1 - AH29 ) -> 0 | AJ29: =$AV$1 -> 0 | AK29: =$AW$20 -> 0 | AL29: =AI29 * AJ29 * R29 * T29 * AK29 -> #N/A | AM29: =AI29*AJ29*S29*U29*AK29 -> #VALUE! | AN29: =AL29+AM29 -> #N/A | AO29: =H29*AN29*L29 -> #N/A
F30: Winter | H30: 65 | I30: 0 | J30: 0 | L30: =$AV$3 -> 1091 | R30: =1-S30 -> 0 | S30: =IF($D$11="yes", 1, VLOOKUP($B$11, $AU$26:$AW$32, 1)) -> 1 | T30: =VLOOKUP($B$11,$AW$10:$AX$16, 2, FALSE) -> #N/A | U30: =$AV$10 -> EFN2O | V30: =(I30/100)*(MIN(J30,100)/100) -> 0 | W30: 0 | X30: =1.6 * W30 -> 0 | Y30: =$AY$1 -> 0 | Z30: =V30*Y30+(1-V30) -> 1 | AA30: =(0.795*O30)-0.0014 -> -0.0014 | AD30: =1 - EXP(-2*(AC30^2)) -> 0 | AE30: =(104.7*AA30+0.307*Q30-15)*(Q30^0.75)*10^-3 -> 0 | AF30: =AE30*AD30*Z30 -> 0 | AG30: =(AF30 * M30) + (0.045 * X30) -> 0 | AH30: =$AV$2 -> 0 | AI30: =(AF30 * ((1 - O30) + (0.04 * AF30))) * ( 1 - AH30 ) -> 0 | AJ30: =$AV$1 -> 0 | AK30: =$AW$20 -> 0 | AL30: =AI30 * AJ30 * R30 * T30 * AK30 -> #N/A | AM30: =AI30*AJ30*S30*U30*AK30 -> #VALUE! | AN30: =AL30+AM30 -> #N/A | AO30: =H30*AN30*L30 -> #N/A
E31: Wethers | F31: Spring | H31: 50 | I31: 0 | J31: 0 | L31: =$AV$3 -> 1091 | R31: =1-S31 -> 0 | S31: =IF($D$11="yes", 1, VLOOKUP($B$11, $AU$26:$AW$32, 1)) -> 1 | T31: =VLOOKUP($B$11,$AW$10:$AX$16, 2, FALSE) -> #N/A | U31: =$AV$10 -> EFN2O | V31: =(I31/100)*(MIN(J31,100)/100) -> 0 | W31: 0 | X31: =1.6 * W31 -> 0 | Y31: =$AY$1 -> 0 | Z31: =V31*Y31+(1-V31) -> 1 | AA31: =(0.795*O31)-0.0014 -> -0.0014 | AD31: =1 - EXP(-2*(AC31^2)) -> 0 | AE31: =(104.7*AA31+0.307*Q31-15)*(Q31^0.75)*10^-3 -> 0 | AF31: =AE31*AD31*Z31 -> 0 | AG31: =(AF31 * M31) + (0.045 * X31) -> 0 | AH31: =$AV$2 -> 0 | AI31: =(AF31 * ((1 - O31) + (0.04 * AF31))) * ( 1 - AH31 ) -> 0 | AJ31: =$AV$1 -> 0 | AK31: =$AW$20 -> 0 | AL31: =AI31 * AJ31 * R31 * T31 * AK31 -> #N/A | AM31: =AI31*AJ31*S31*U31*AK31 -> #VALUE! | AN31: =AL31+AM31 -> #N/A | AO31: =H31*AN31*L31 -> #N/A
F32: Summer | H32: 100 | I32: 0 | J32: 0 | L32: =$AV$3 -> 1091 | R32: =1-S32 -> 0 | S32: =IF($D$11="yes", 1, VLOOKUP($B$11, $AU$26:$AW$32, 1)) -> 1 | T32: =VLOOKUP($B$11,$AW$10:$AX$16, 2, FALSE) -> #N/A | U32: =$AV$10 -> EFN2O | V32: =(I32/100)*(MIN(J32,100)/100) -> 0 | W32: 0 | X32: =1.6 * W32 -> 0 | Y32: =$AY$1 -> 0 | Z32: =V32*Y32+(1-V32) -> 1 | AA32: =(0.795*O32)-0.0014 -> -0.0014 | AD32: =1 - EXP(-2*(AC32^2)) -> 0 | AE32: =(104.7*AA32+0.307*Q32-15)*(Q32^0.75)*10^-3 -> 0 | AF32: =AE32*AD32*Z32 -> 0 | AG32: =(AF32 * M32) + (0.045 * X32) -> 0 | AH32: =$AV$2 -> 0 | AI32: =(AF32 * ((1 - O32) + (0.04 * AF32))) * ( 1 - AH32 ) -> 0 | AJ32: =$AV$1 -> 0 | AK32: =$AW$20 -> 0 | AL32: =AI32 * AJ32 * R32 * T32 * AK32 -> #N/A | AM32: =AI32*AJ32*S32*U32*AK32 -> #VALUE! | AN32: =AL32+AM32 -> #N/A | AO32: =H32*AN32*L32 -> #N/A
F33: Autumn | H33: 90 | I33: 0 | J33: 0 | L33: =$AV$3 -> 1091 | R33: =1-S33 -> 0 | S33: =IF($D$11="yes", 1, VLOOKUP($B$11, $AU$26:$AW$32, 1)) -> 1 | T33: =VLOOKUP($B$11,$AW$10:$AX$16, 2, FALSE) -> #N/A | U33: =$AV$10 -> EFN2O | V33: =(I33/100)*(MIN(J33,100)/100) -> 0 | W33: 0 | X33: =1.6 * W33 -> 0 | Y33: =$AY$1 -> 0 | Z33: =V33*Y33+(1-V33) -> 1 | AA33: =(0.795*O33)-0.0014 -> -0.0014 | AD33: =1 - EXP(-2*(AC33^2)) -> 0 | AE33: =(104.7*AA33+0.307*Q33-15)*(Q33^0.75)*10^-3 -> 0 | AF33: =AE33*AD33*Z33 -> 0 | AG33: =(AF33 * M33) + (0.045 * X33) -> 0 | AH33: =$AV$2 -> 0 | AI33: =(AF33 * ((1 - O33) + (0.04 * AF33))) * ( 1 - AH33 ) -> 0 | AJ33: =$AV$1 -> 0 | AK33: =$AW$20 -> 0 | AL33: =AI33 * AJ33 * R33 * T33 * AK33 -> #N/A | AM33: =AI33*AJ33*S33*U33*AK33 -> #VALUE! | AN33: =AL33+AM33 -> #N/A | AO33: =H33*AN33*L33 -> #N/A
F34: Winter | H34: 80 | I34: 0 | J34: 0 | L34: =$AV$3 -> 1091 | R34: =1-S34 -> 0 | S34: =IF($D$11="yes", 1, VLOOKUP($B$11, $AU$26:$AW$32, 1)) -> 1 | T34: =VLOOKUP($B$11,$AW$10:$AX$16, 2, FALSE) -> #N/A | U34: =$AV$10 -> EFN2O | V34: =(I34/100)*(MIN(J34,100)/100) -> 0 | W34: 0 | X34: =1.6 * W34 -> 0 | Y34: =$AY$1 -> 0 | Z34: =V34*Y34+(1-V34) -> 1 | AA34: =(0.795*O34)-0.0014 -> -0.0014 | AD34: =1 - EXP(-2*(AC34^2)) -> 0 | AE34: =(104.7*AA34+0.307*Q34-15)*(Q34^0.75)*10^-3 -> 0 | AF34: =AE34*AD34*Z34 -> 0 | AG34: =(AF34 * M34) + (0.045 * X34) -> 0 | AH34: =$AV$2 -> 0 | AI34: =(AF34 * ((1 - O34) + (0.04 * AF34))) * ( 1 - AH34 ) -> 0 | AJ34: =$AV$1 -> 0 | AK34: =$AW$20 -> 0 | AL34: =AI34 * AJ34 * R34 * T34 * AK34 -> #N/A | AM34: =AI34*AJ34*S34*U34*AK34 -> #VALUE! | AN34: =AL34+AM34 -> #N/A | AO34: =H34*AN34*L34 -> #N/A
A41: NSW | B41: NSW | C41: ACT/NSW | D41: no | E41: Breeding ewes | F41: Spring | H41: 100 | I41: 95 | J41: 90 | L41: =$AV$3 -> 1091 | M41: {=_xludf.DROP(_xludf.XLOOKUP($C41,#REF!,#REF!),1)} -> #NAME? | O41: {=_xludf.DROP(_xludf.XLOOKUP($C41,#REF!,#REF!),1)} -> #NAME? | Q41: {=_xludf.DROP(_xludf.XLOOKUP($C41,#REF!,#REF!),1)} -> #NAME? | R41: =1-S41 -> #N/A | S41: =IF($D41="yes", 1, VLOOKUP($B41, $AU$26:$AW$32, 2, FALSE)/100) -> #N/A | T41: =VLOOKUP($B41,$AW$10:$AX$16, 2, FALSE) -> #N/A | U41: =$AV$10 -> EFN2O | V41: =(I41/100)*(MIN(J41,100)/100) -> 0.855 | W41: 0 | X41: =1.6 * W41 -> 0 | Y41: =$AY$1 -> 0 | Z41: =V41*Y41+(1-V41) -> 0.145 | AA41: =(0.795*O41)-0.0014 -> #NAME? | AC41: {=_xludf.DROP(_xludf.XLOOKUP($C41,#REF!,#REF!),1)} -> #NAME? | AD41: =1 - EXP(-2*(AC41^2)) -> #NAME? | AE41: =(104.7*AA41+0.307*Q41-15)*(Q41^0.75)*10^-3 -> #NAME? | AF41: =AE41*AD41*Z41 -> #NAME? | AG41: =(AF41 * M41) + (0.045 * X41) -> #NAME? | AH41: =$AV$2 -> 0 | AI41: =(AF41 * ((1 - O41) + (0.04 * AF41))) * ( 1 - AH41 ) -> #NAME? | AJ41: =$AV$1 -> 0 | AK41: =$AW$20 -> 0 | AL41: =AI41 * AJ41 * R41 * T41 * AK41 -> #NAME? | AM41: =AI41*AJ41*S41*U41*AK41 -> #NAME? | AN41: =AL41+AM41 -> #NAME? | AO41: =H41*AN41*L41 -> #NAME? | AP41: =SUM(AO41:AO64)*10^-3 -> #NAME?
F42: Summer | H42: 70 | I42: 0 | J42: 0 | L42: =$AV$3 -> 1091 | R42: =1-S42 -> #N/A | S42: =S41 -> #N/A | T42: =T41 -> #N/A | U42: =$AV$10 -> EFN2O | V42: =(I42/100)*(MIN(J42,100)/100) -> 0 | W42: 0 | X42: =1.6 * W42 -> 0 | Y42: =$AY$1 -> 0 | Z42: =V42*Y42+(1-V42) -> 1 | AA42: =(0.795*O42)-0.0014 -> -0.0014 | AD42: =1 - EXP(-2*(AC42^2)) -> 0 | AE42: =(104.7*AA42+0.307*Q42-15)*(Q42^0.75)*10^-3 -> 0 | AF42: =AE42*AD42*Z42 -> 0 | AG42: =(AF42 * M42) + (0.045 * X42) -> 0 | AH42: =$AV$2 -> 0 | AI42: =(AF42 * ((1 - O42) + (0.04 * AF42))) * ( 1 - AH42 ) -> 0 | AJ42: =$AV$1 -> 0 | AK42: =$AW$20 -> 0 | AL42: =AI42 * AJ42 * R42 * T42 * AK42 -> #N/A | AM42: =AI42*AJ42*S42*U42*AK42 -> #N/A | AN42: =AL42+AM42 -> #N/A | AO42: =H42*AN42*L42 -> #N/A
F43: Autumn | H43: 65 | I43: 0 | J43: 0 | L43: =$AV$3 -> 1091 | R43: =1-S43 -> #N/A | S43: =S41 -> #N/A | T43: =T41 -> #N/A | U43: =$AV$10 -> EFN2O | V43: =(I43/100)*(MIN(J43,100)/100) -> 0 | W43: 0 | X43: =1.6 * W43 -> 0 | Y43: =$AY$1 -> 0 | Z43: =V43*Y43+(1-V43) -> 1 | AA43: =(0.795*O43)-0.0014 -> -0.0014 | AD43: =1 - EXP(-2*(AC43^2)) -> 0 | AE43: =(104.7*AA43+0.307*Q43-15)*(Q43^0.75)*10^-3 -> 0 | AF43: =AE43*AD43*Z43 -> 0 | AG43: =(AF43 * M43) + (0.045 * X43) -> 0 | AH43: =$AV$2 -> 0 | AI43: =(AF43 * ((1 - O43) + (0.04 * AF43))) * ( 1 - AH43 ) -> 0 | AJ43: =$AV$1 -> 0 | AK43: =$AW$20 -> 0 | AL43: =AI43 * AJ43 * R43 * T43 * AK43 -> #N/A | AM43: =AI43*AJ43*S43*U43*AK43 -> #N/A | AN43: =AL43+AM43 -> #N/A | AO43: =H43*AN43*L43 -> #N/A
F44: Winter | H44: 80 | I44: 0 | J44: 0 | L44: =$AV$3 -> 1091 | R44: =1-S44 -> #N/A | S44: =S41 -> #N/A | T44: =T41 -> #N/A | U44: =$AV$10 -> EFN2O | V44: =(I44/100)*(MIN(J44,100)/100) -> 0 | W44: 0 | X44: =1.6 * W44 -> 0 | Y44: =$AY$1 -> 0 | Z44: =V44*Y44+(1-V44) -> 1 | AA44: =(0.795*O44)-0.0014 -> -0.0014 | AD44: =1 - EXP(-2*(AC44^2)) -> 0 | AE44: =(104.7*AA44+0.307*Q44-15)*(Q44^0.75)*10^-3 -> 0 | AF44: =AE44*AD44*Z44 -> 0 | AG44: =(AF44 * M44) + (0.045 * X44) -> 0 | AH44: =$AV$2 -> 0 | AI44: =(AF44 * ((1 - O44) + (0.04 * AF44))) * ( 1 - AH44 ) -> 0 | AJ44: =$AV$1 -> 0 | AK44: =$AW$20 -> 0 | AL44: =AI44 * AJ44 * R44 * T44 * AK44 -> #N/A | AM44: =AI44*AJ44*S44*U44*AK44 -> #N/A | AN44: =AL44+AM44 -> #N/A | AO44: =H44*AN44*L44 -> #N/A
E45: Lambs and hoggets | F45: Spring | H45: 200 | I45: 0 | J45: 0 | L45: =$AV$3 -> 1091 | R45: =1-S45 -> #N/A | S45: =S41 -> #N/A | T45: =T41 -> #N/A | U45: =$AV$10 -> EFN2O | V45: =(I45/100)*(MIN(J45,100)/100) -> 0 | W45: 1 | X45: =1.6 * W45 -> 1.6 | Y45: =$AY$1 -> 0 | Z45: =V45*Y45+(1-V45) -> 1 | AA45: =(0.795*O45)-0.0014 -> -0.0014 | AD45: =1 - EXP(-2*(AC45^2)) -> 0 | AE45: =(104.7*AA45+0.307*Q45-15)*(Q45^0.75)*10^-3 -> 0 | AF45: =AE45*AD45*Z45 -> 0 | AG45: =(AF45 * M45) + (0.045 * X45) -> 0.072 | AH45: =$AV$2 -> 0 | AI45: =(AF45 * ((1 - O45) + (0.04 * AF45))) * ( 1 - AH45 ) -> 0 | AJ45: =$AV$1 -> 0 | AK45: =$AW$20 -> 0 | AL45: =AI45 * AJ45 * R45 * T45 * AK45 -> #N/A | AM45: =AI45*AJ45*S45*U45*AK45 -> #N/A | AN45: =AL45+AM45 -> #N/A | AO45: =H45*AN45*L45 -> #N/A
F46: Summer | H46: 210 | I46: 0 | J46: 0 | L46: =$AV$3 -> 1091 | R46: =1-S46 -> #N/A | S46: =S41 -> #N/A | T46: =T41 -> #N/A | U46: =$AV$10 -> EFN2O | V46: =(I46/100)*(MIN(J46,100)/100) -> 0 | W46: 0 | X46: =1.6 * W46 -> 0 | Y46: =$AY$1 -> 0 | Z46: =V46*Y46+(1-V46) -> 1 | AA46: =(0.795*O46)-0.0014 -> -0.0014 | AD46: =1 - EXP(-2*(AC46^2)) -> 0 | AE46: =(104.7*AA46+0.307*Q46-15)*(Q46^0.75)*10^-3 -> 0 | AF46: =AE46*AD46*Z46 -> 0 | AG46: =(AF46 * M46) + (0.045 * X46) -> 0 | AH46: =$AV$2 -> 0 | AI46: =(AF46 * ((1 - O46) + (0.04 * AF46))) * ( 1 - AH46 ) -> 0 | AJ46: =$AV$1 -> 0 | AK46: =$AW$20 -> 0 | AL46: =AI46 * AJ46 * R46 * T46 * AK46 -> #N/A | AM46: =AI46*AJ46*S46*U46*AK46 -> #N/A | AN46: =AL46+AM46 -> #N/A | AO46: =H46*AN46*L46 -> #N/A
F47: Autumn | H47: 170 | I47: 0 | J47: 0 | L47: =$AV$3 -> 1091 | R47: =1-S47 -> #N/A | S47: =S41 -> #N/A | T47: =T41 -> #N/A | U47: =$AV$10 -> EFN2O | V47: =(I47/100)*(MIN(J47,100)/100) -> 0 | W47: 0 | X47: =1.6 * W47 -> 0 | Y47: =$AY$1 -> 0 | Z47: =V47*Y47+(1-V47) -> 1 | AA47: =(0.795*O47)-0.0014 -> -0.0014 | AD47: =1 - EXP(-2*(AC47^2)) -> 0 | AE47: =(104.7*AA47+0.307*Q47-15)*(Q47^0.75)*10^-3 -> 0 | AF47: =AE47*AD47*Z47 -> 0 | AG47: =(AF47 * M47) + (0.045 * X47) -> 0 | AH47: =$AV$2 -> 0 | AI47: =(AF47 * ((1 - O47) + (0.04 * AF47))) * ( 1 - AH47 ) -> 0 | AJ47: =$AV$1 -> 0 | AK47: =$AW$20 -> 0 | AL47: =AI47 * AJ47 * R47 * T47 * AK47 -> #N/A | AM47: =AI47*AJ47*S47*U47*AK47 -> #N/A | AN47: =AL47+AM47 -> #N/A | AO47: =H47*AN47*L47 -> #N/A
F48: Winter | H48: 200 | I48: 0 | J48: 0 | L48: =$AV$3 -> 1091 | R48: =1-S48 -> #N/A | S48: =S41 -> #N/A | T48: =T41 -> #N/A | U48: =$AV$10 -> EFN2O | V48: =(I48/100)*(MIN(J48,100)/100) -> 0 | W48: 0 | X48: =1.6 * W48 -> 0 | Y48: =$AY$1 -> 0 | Z48: =V48*Y48+(1-V48) -> 1 | AA48: =(0.795*O48)-0.0014 -> -0.0014 | AD48: =1 - EXP(-2*(AC48^2)) -> 0 | AE48: =(104.7*AA48+0.307*Q48-15)*(Q48^0.75)*10^-3 -> 0 | AF48: =AE48*AD48*Z48 -> 0 | AG48: =(AF48 * M48) + (0.045 * X48) -> 0 | AH48: =$AV$2 -> 0 | AI48: =(AF48 * ((1 - O48) + (0.04 * AF48))) * ( 1 - AH48 ) -> 0 | AJ48: =$AV$1 -> 0 | AK48: =$AW$20 -> 0 | AL48: =AI48 * AJ48 * R48 * T48 * AK48 -> #N/A | AM48: =AI48*AJ48*S48*U48*AK48 -> #N/A | AN48: =AL48+AM48 -> #N/A | AO48: =H48*AN48*L48 -> #N/A
...

Sheet Tables
M1: 3.4.1 | N1: 3.4.1 | AC1: 3.4.1 321 | AP1: 3.4.1 | AS1: 3.4.1 | AT1: 3.4.1 | AU1: Ch 3.4.1 | BQ1: 1084 | BR1: Bo | BS1: 0.24 | BU1: FAk | BV1: 1.3
AD2: LEjk=3,4 * 1.6 | AE2: GWk * Yk / 365 | AF2: LWGjk * 0.92 | AH2: Wjk / SRWk | AJ2: 1.6 * PLjk=6 | AK2: ((0.045 * MPjk=3,4) + (WPk * 0.84) + (EBGjk * ((212 - 4 * ((EBGjk * 1000) / (4 * SRWk ^0.75) - 1)) - (140 - 4 * (EBGjk * 1000)) / (1 + e^-6 * (Zjk - 0.4)) * 10^-3) / 6.25 | AL2: (CPIjk ÷ 6.25 ) - NRjk | AV2: (Ijk * CPjk) + (0.045 * MCjk=6) | AX2: (Ijk * ((1 - DMDjk) + (0.04 * Ijk))) * ( 1 - A ) | BA2: VSjk * BO * MMSm * MCFim * 𝜌 | BC2: VSjk * BO * MMSm * MCFim * 𝜌 | BD2: SUM SUM SUM (Njk * Mjkm * Dj) * 10^-3 | BF2: SUM SUM (Njk * NEjk * Dj) | BH2: AE * FracGASMsoil | BI2: AE * FracWet * FracLEACH | BJ2: AE * EFPRP * CN2O * 10^-3 | BK2: Mvol * EFN2O * CN2O * 10^-3 | BL2: Mleach * EFleach * CN2O * 10^-3 | BQ2: 1087 | BR2: A | BS2: 0.08
