Workbook
Name TableLWG: TableLWG235[]
Name TableLWG: TableLWG2[]

Sheet 4.4.1.1
I1: 3.4.1 | J1: 3.4.1 | Y1: 3.4.1 321 | AC1: 3.4.1 | AG1: 3.4.1 | AH1: 3.4.1 | AI1: Ch 3.4.1 | BX1: 1084 | BY1: Bo | BZ1: 0.19 | CB1: FAk | CC1: 1.3
AA2: 1.6 * PLjk=6 | AJ2: (Ijk * CPjk) + (0.045 * MCjk=6) | AL2: (Ijk * ((1 - DMDjk) + (0.04 * Ijk))) * ( 1 - A ) | AO2: VSjk * BO * MMSm * MCFim * 𝜌 | AQ2: VSjk * BO * MMSm * MCFim * 𝜌 | AR2: SUM SUM SUM (Njk * Mjkm * Dj) * 10^-3 | BC2: LEjk=3,4 * 1.6 | BD2: (GWk * Yk) / 365 | BE2: LWGjk * 0.92 | BG2: Wjk / SRWk | BH2: ((0.045 * MPjk=3,4) + (WPk * 0.84) + (EBGjk * ((212 - 4 * ((EBGjk * 1000)/(4* SRWk^0.75) - 1)) - ((140 - 4 * (((EBGjk * 1000)/4 * SRWk ^0.75) - 1))/(1 + e ^ (-6 * (Zjk - 0.4)))))) * 10^-3) / 6.25 | BI2: (CPIjk / 6.25 ) - NRjk | BJ2: SUM SUM (Njk * NEjk * Dj) | BL2: AE * FracWet * FracLEACH | BM2: AE * FracGASMsoil | BP2: Mvol * EFN2O * CN2O * 10^-3 | BQ2: AE * FracWet * FracLEACH | BS2: AE * EFprp * CN2O * 10^-3 | BT2: Mleach * EFleach * CN2O * 10^-3 | BX2: 1087 | BY2: A | BZ2: 0.08
H3: 1071 | I3: 342 | J3: 323 | L3: 1075 | N3: 1080 | P3: 1078 | R3: 1077 | T3: 1081 | V3: 1085 | X3: 1082 | Y3: 1004 | Z3: 990 | AA3: 988 | AB3: 351 | AC3: 314 | AD3: 302 | AF3: 349 | AG3: 308 | AH3: 296 | AI3: 946 | AJ3: 983 | AK3: 1087 | AL3: 945 | AM3: 1084 | AN3: 1086 | AO3: 930 | AQ3: 930 | AR3: 922 | AU3: 1092 | AV3: 1094 | AX3: 1090 | AY3: 1088 | AZ3: 1093 | BA3: 1072 | BB3: 1073 | BC3: 1003 | BD3: 1011 | BE3: 1017 | BF3: 1089 | BG3: 1021 | BH3: 994 | BI3: 978 | BJ3: 970 | BL3: 1062 | BM3: 1045 | BO3: 1091 | BP3: 1037 | BQ3: 1062 | BR3: 1095 | BS3: 963 | BT3: 1056 | BY3: Dj | BZ3: 91.25
H4: input | L4: constant | N4: constant | P4: constant | R4: constant | T4: constant | V4: constant | X4: constant | Y4: constant | Z4: expression | AA4: expression | AB4: constant | AC4: expression | AD4: expression | AF4: constant | AG4: expression | AH4: expression | AI4: expression | AJ4: expression | AK4: constant | AL4: expression | AM4: constant | AN4: constant | AO4: expression | AQ4: expression | AR4: expression | AU4: constant | AV4: constant | AX4: constant | AY4: constant | AZ4: constant | BA4: input | BB4: input | BC4: expression | BD4: expression | BE4: expression | BF4: constant | BG4: expression | BH4: expression | BI4: expression | BJ4: expression | BL4: expression | BM4: expression | BO4: constant | BP4: expression | BQ4: expression | BR4: constant | BS4: expression | BT4: expression | BX4: 1094 | BY4: FracLEACH | BZ4: 0.24
L5: input | N5: input | P5: input | R5: input | T5: input | X5: input | AF5: input | BX5: 1093 | BY5: FracGASMSoil | BZ5: 0.21
BX6: 1095 | BY6: EFLeach | BZ6: 0.011
BX7: 1088 | BY7: CN2O | BZ7: =[1]!common_cn2o -> 1.57
H8: head | L8: days | N8: kg | P8: d | R8: d | T8: kg | V8: d | X8: d | Y8: d | Z8: d | AA8: kg / head / day | AI8: kg DM/head/day | AJ8: kg/head/day | AK8: d | AL8: kg/head/day | AM8: m3 CH4/kgVS | AN8: kg/m3 | AO8: kg CH4/head/day | AQ8: kg CH4/head/day | AR8: kg CH4 | AU8: fraction | AV8: fraction | AX8: kg N2O-N/kg N | AY8: d | AZ8: kg NH3-N + NOx-N / kg N | BA8: kg / head | BB8: fraction | BC8: kg/head/day | BD8: kg/head/day | BE8: kg | BF8: kg | BG8: d | BH8: kg N / head / day | BI8: kg N/head/day | BJ8: kg N | BL8: kg N | BM8: kg N | BO8: kg N2O-N / kg N | BP8: t N2O | BQ8: kg N | BR8: kg N2O-N / kg N | BS8: t N2O | BT8: t N2O
H9: number of sheep in each time period and class | I9: Lambing rate | J9: Lamb marking rate | L9: number of days in each time period | N9: liveweight gain | P9: crude protein content of feed intake | R9: dry matter digestibility | T9: liveweight | V9: fraction of waste in each MMS | X9: methane conversion factor for temperate zone and MMS | Y9: proportion of ewes lactating each season or time period | Z9: Proportion of lambs born in the time period | AA9: Milk intake | AI9: dry matter intake | AJ9: crude protein intake | AK9: ash content of feed intake | AL9: volatile solid production | AM9: emisions potential | AN9: density of methane | AO9: methane produced from manure | AQ9: methane produced from manure | AR9: annual methane production from manure | AU9: fraction of N that is available for leaching and runoff | AV9: fraction of all N that is lost through leaching and runoff | AX9: emission factor for nitrous oxide from urine and dung deposited to soil | AY9: factor to convert elemental mass of nitrous oxide to molecular mass | AZ9: fraction of nitrogen volatilised from urine and faeces deposited on pasture | BA9: greasy wool production per sheep class | BB9: average clean wool yield per sheep class | BC9: milk production | BD9: clean wool production | BE9: empty body gain | BF9: standard reference weight | BG9: relative size | BH9: the amount of nitrogen retained by the body | BI9: nitrogen excreted in each time-period and by each class | BJ9: total mass of nitrogen excreted on PRP by sheep | BL9: mass of nitrogen lost to leaching and runoff | BM9: mass of nitrogen volatilised from urine and faeces deposited on pasture | BO9: nitrous oxide emission factor for atmospheric deposition | BP9: Annual atmospheric deposition emissions from urine and dung deposited on pasture | BQ9: mass of nitrogen lost to leaching and runoff | BR9: emission factor for leaching and run off | BS9: Total annual direct nitrous oxide emissions from agricultural soils from deposition of urine and dung | BT9: Leaching and runoff emissions from urine and dung deposited on pasture | BZ9: MCF | CB9: Lagoon
A10: Scenario | B10: State | C10: State | D10: No unfenced water | E10: Class | G10: Month | H10: Njk | I10: LR | J10: LMR | K10: Custom Dj | L10: Dj | M10: Custom LWG | N10: LWGjk | O10: Custom CP | P10: CPjk | Q10: Custom DMD | R10: DMDjk | S10: Custom liveweight | T10: Wjk | U10: MMSm=1 | V10: MMSm=14 | W10: MCFim=1 | X10: MCFim=14 | Y10: LEjk=3,4 | Z10: PLjk=6 | AA10: MCjk=6 | AB10: FAk | AC10: MAjk | AD10: qmjk | AE10: Custom DMA | AF10: DMAjk | AG10: RIjk | AH10: PIjk | AI10: Ijk | AJ10: CPIjk | AK10: A | AL10: VSjk | AM10: BO | AN10: 𝜌 | AO10: Mjkm=1 | AP10: Mjkm=14 | AQ10: Mjk | AR10: ECH4 | AS10: ECH4 | AT10: Leaching zone | AU10: FracWet | AV10: FracLEACH | AW10: Climate zone | AX10: EFprp | AY10: CN2O | AZ10: FracGASMsoil | BA10: GWk | BB10: Yk | BC10: MPjk=3,4 | BD10: WPk | BE10: EBGjk | BF10: SRWk | BG10: Zjk | BH10: NRijk | BI10: NEjk | BJ10: AE | BK10: AE | BL10: Mleach | BM10: Mvol | BN10: Production system | BO10: EFN2O | BP10: EN2O,ad | BQ10: Mleach | BR10: EFleach | BS10: EN2O,dir | BT10: ESN2O,leach | BY10: PRP | BZ10: 0.0047 | CA10: ACT | CB10: 0.72
A11: Baseline | B11: ACT | C11: ACT/NSW | D11: yes | E11: Breeding ewes | F11: Spring | H11: 100 | I11: 95 | J11: 90 | L11: =$BZ$3 -> 91.25 | N11: {=_xlfn.DROP(_xlfn.XLOOKUP($C11,TableLWG2_1[[#Headers],[ACT/NSW]:[WA]],TableLWG2_1[[#All],[ACT/NSW]:[WA]]),1)} -> 0.04 | P11: {=_xlfn.DROP(_xlfn.XLOOKUP($C11,QueryCP[[#Headers],[ACT/NSW]:[WA]],QueryCP[[#All],[ACT/NSW]:[WA]]),1)} -> 0.2 | R11: {=_xlfn.DROP(_xlfn.XLOOKUP($C11,QueryDMD[[#Headers],[ACT/NSW]:[WA]],QueryDMD[[#All],[ACT/NSW]:[WA]]),1)} -> 0.75 | T11: {=_xlfn.DROP(_xlfn.XLOOKUP($C11,QueryW[[#Headers],[ACT/NSW]:[WA]],QueryW[[#All],[ACT/NSW]:[WA]]),1)} -> 54 | U11: =1-V11 -> 0 | V11: =IF($D$11="yes", 1, VLOOKUP($B$11, $BY$26:$CA$32, 1)) -> 1 | W11: =VLOOKUP($B$11,$CA$10:$CB$16, 2, FALSE) -> 0.72 | X11: =$BZ$10 -> 0.0047 | Y11: =(I11/100)*(MIN(J11,100)/100) -> 0.855 | Z11: 0 | AA11: =1.6 * Z11 -> 0 | AB11: =$CC$1 -> 1.3 | AC11: =Y11*AB11+(1-Y11) -> 1.2565 | AD11: =(0.795*R11)-0.0014 -> 0.59485 | AF11: {=_xlfn.DROP(_xlfn.XLOOKUP($C11,QueryDMA[[#Headers],[ACT/NSW]:[WA]],QueryDMA[[#All],[ACT/NSW]:[WA]]),1)} -> 2.9 | AG11: =1 - EXP(-2*(AF11^2)) -> 0.99999995 | AH11: =(104.7*AD11+0.307*T11-15)*(T11^0.75)*10^-3 -> 1.2720847 | AI11: =AH11*AG11*AC11 -> 1.5983744 | AJ11: =(AI11 * P11) + (0.045 * AA11) -> 0.31967488 | AK11: =$BZ$2 -> 0.08 | AL11: =(AI11 * ((1 - R11) + (0.04 * AI11))) * ( 1 - AK11 ) -> 0.46164277 | AM11: =$BZ$1 -> 0.19 | AN11: =$CA$20 -> 0.6784 | AO11: =AL11 * AM11 * U11 * W11 * AN11 -> 0 | AP11: =AL11*AM11*V11*X11*AN11 -> 0.00027966836 | AQ11: =AO11+AP11 -> 0.00027966836 | AR11: =H11*AQ11*L11 -> 2.5519738 | AS11: =SUM(AR11:AR34)*10^-3 -> 0.053906997 | AT11: yes | AU11: =IF(AT11="yes", 1,0) -> 1 | AV11: =$BZ$4 -> 0.24 | AW11: Warm temperate moist | AX11: =VLOOKUP(AW11,$CD$37:$CF$46,2, FALSE) -> 0.006 | AY11: =$BZ$7 -> 1.57 | AZ11: =$BZ$5 -> 0.21 | BA11: 20 | BB11: 0.8 | BC11: =Y11 * 1.6 -> 1.368 | BD11: =(BA11 * BB11) / 365 -> 0.043835616 | BE11: =N11 * 0.92 -> 0.0368 | BF11: {=_xlfn.DROP(_xlfn.XLOOKUP($C11,QuerySRW[[#Headers],[ACT/NSW]:[WA]],QuerySRW[[#All],[ACT/NSW]:[WA]]),1)} -> 57 | BG11: =T11 / BF11 -> 0.94736842 | BH11: =((0.045 * BC11) + (BD11 * 0.84) + (BE11 * ((212 - 4 * ((BE11 * 1000)/(4* (BF11^0.75)) - 1)) - ((140 - 4 * (((BE11 * 1000)/(4 * BF11 ^0.75)) - 1))/(1 + EXP(-6 * (BG11 - 0.4)))))) * 10^-3) / 6.25 -> 0.016195288 | BI11: =MAX((AJ11 / 6.25 ) - BH11, 0) -> 0.034952692 | BJ11: =H11*BI11*L11 -> 318.94332 | BK11: =SUM(BJ11:BJ34) -> 5093.7808 | BL11: =BK11*$AU$11*$AV$11 -> 1222.5074 | BM11: =BK11 * AZ11 -> 1069.694 | BN11: Non-irrigated pasture | BO11: =VLOOKUP(BN11, $BY$37:$BZ$49, 2, FALSE) -> 0.0018 | BP11: =BM11 * BO11 * AY11 * 10^-3 -> 0.0030229551 | BQ11: =BK11 * AU11 * AV11 -> 1222.5074 | BR11: =$BZ$6 -> 0.011 | BS11: =BK11 * AX11 * AY11 * 10^-3 -> 0.047983415 | BT11: =BQ11 * BR11 * AY11 * 10^-3 -> 0.021112702 | CA11: NSW | CB11: 0.75
F12: Summer | H12: 70 | I12: 0 | J12: 0 | L12: =$BZ$3 -> 91.25 | N12: -0.05 | P12: 0.1 | R12: 0.61 | T12: 49 | U12: =1-V12 -> 0 | V12: =$V$11 -> 1 | W12: =VLOOKUP($B$11,$CA$10:$CB$16, 2, FALSE) -> 0.72 | X12: =$BZ$10 -> 0.0047 | Y12: =(I12/100)*(MIN(J12,100)/100) -> 0 | Z12: 0 | AA12: =1.6 * Z12 -> 0 | AB12: =$AB$11 -> 1.3 | AC12: =Y12*AB12+(1-Y12) -> 1 | AD12: =(0.795*R12)-0.0014 -> 0.48355 | AF12: 2.5 | AG12: =1 - EXP(-2*(AF12^2)) -> 0.99999627 | AH12: =(104.7*AD12+0.307*T12-15)*(T12^0.75)*10^-3 -> 0.93843422 | AI12: =AH12*AG12*AC12 -> 0.93843072 | AJ12: =(AI12 * P12) + (0.045 * AA12) -> 0.093843072 | AK12: =$BZ$2 -> 0.08 | AL12: =(AI12 * ((1 - R12) + (0.04 * AI12))) * ( 1 - AK12 ) -> 0.36911694 | AM12: =$BZ$1 -> 0.19 | AN12: =$CA$20 -> 0.6784 | AO12: =AL12 * AM12 * U12 * W12 * AN12 -> 0 | AP12: =AL12*AM12*V12*X12*AN12 -> 0.00022361518 | AQ12: =AO12+AP12 -> 0.00022361518 | AR12: =H12*AQ12*L12 -> 1.428342 | BA12: =BA11 -> 20 | BC12: =Y12 * 1.6 -> 0 | BD12: =BD11 -> 0.043835616 | BE12: =N12 * 0.92 -> -0.046 | BF12: 57 | BG12: =T12 / BF12 -> 0.85964912 | BH12: =((0.045 * BC12) + (BD$11 * 0.84) + (BE12 * ((212 - 4 * ((BE12 * 1000)/(4* (BF12^0.75)) - 1)) - ((140 - 4 * (((BE12 * 1000)/(4 * BF12 ^0.75)) - 1))/(1 + EXP(-6 * (BG12 - 0.4)))))) * 10^-3) / 6.25 -> 0.0052974021 | BI12: =MAX((AJ12 / 6.25 ) - BH12, 0) -> 0.0097174894 | BJ12: =H12*BI12*L12 -> 62.070464 | CA12: QLD | CB12: 0.78
F13: Autumn | H13: 65 | I13: 0 | J13: 0 | L13: =$BZ$3 -> 91.25 | N13: 0.01 | P13: 0.12 | R13: 0.64 | T13: 50 | U13: =1-V13 -> 0 | V13: =$V$11 -> 1 | W13: =VLOOKUP($B$11,$CA$10:$CB$16, 2, FALSE) -> 0.72 | X13: =$BZ$10 -> 0.0047 | Y13: =(I13/100)*(MIN(J13,100)/100) -> 0 | Z13: 0 | AA13: =1.6 * Z13 -> 0 | AB13: =$AB$11 -> 1.3 | AC13: =Y13*AB13+(1-Y13) -> 1 | AD13: =(0.795*R13)-0.0014 -> 0.5074 | AF13: 1.6 | AG13: =1 - EXP(-2*(AF13^2)) -> 0.99402398 | AH13: =(104.7*AD13+0.307*T13-15)*(T13^0.75)*10^-3 -> 1.0054871 | AI13: =AH13*AG13*AC13 -> 0.9994783 | AJ13: =(AI13 * P13) + (0.045 * AA13) -> 0.1199374 | AK13: =$BZ$2 -> 0.08 | AL13: =(AI13 * ((1 - R13) + (0.04 * AI13))) * ( 1 - AK13 ) -> 0.36778883 | AM13: =$BZ$1 -> 0.19 | AN13: =$CA$20 -> 0.6784 | AO13: =AL13 * AM13 * U13 * W13 * AN13 -> 0 | AP13: =AL13*AM13*V13*X13*AN13 -> 0.00022281059 | AQ13: =AO13+AP13 -> 0.00022281059 | AR13: =H13*AQ13*L13 -> 1.3215453 | BA13: =BA11 -> 20 | BC13: =Y13 * 1.6 -> 0 | BD13: =BD11 -> 0.043835616 | BE13: =N13 * 0.92 -> 0.0092 | BF13: 57 | BG13: =T13 / BF13 -> 0.87719298 | BH13: =((0.045 * BC13) + (BD$11 * 0.84) + (BE13 * ((212 - 4 * ((BE13 * 1000)/(4* (BF13^0.75)) - 1)) - ((140 - 4 * (((BE13 * 1000)/(4 * BF13 ^0.75)) - 1))/(1 + EXP(-6 * (BG13 - 0.4)))))) * 10^-3) / 6.25 -> 0.006008903 | BI13: =MAX((AJ13 / 6.25 ) - BH13, 0) -> 0.01318108 | BJ13: =H13*BI13*L13 -> 78.180283 | CA13: SA | CB13: 0.74
F14: Winter | H14: 80 | I14: 0 | J14: 0 | L14: =$BZ$3 -> 91.25 | N14: 0 | P14: 0.18 | R14: 0.72 | T14: 50 | U14: =1-V14 -> 0 | V14: =$V$11 -> 1 | W14: =VLOOKUP($B$11,$CA$10:$CB$16, 2, FALSE) -> 0.72 | X14: =$BZ$10 -> 0.0047 | Y14: =(I14/100)*(MIN(J14,100)/100) -> 0 | Z14: 0 | AA14: =1.6 * Z14 -> 0 | AB14: =$AB$11 -> 1.3 | AC14: =Y14*AB14+(1-Y14) -> 1 | AD14: =(0.795*R14)-0.0014 -> 0.571 | AF14: 1.7 | AG14: =1 - EXP(-2*(AF14^2)) -> 0.99691128 | AH14: =(104.7*AD14+0.307*T14-15)*(T14^0.75)*10^-3 -> 1.1306949 | AI14: =AH14*AG14*AC14 -> 1.1272025 | AJ14: =(AI14 * P14) + (0.045 * AA14) -> 0.20289645 | AK14: =$BZ$2 -> 0.08 | AL14: =(AI14 * ((1 - R14) + (0.04 * AI14))) * ( 1 - AK14 ) -> 0.33712491 | AM14: =$BZ$1 -> 0.19 | AN14: =$CA$20 -> 0.6784 | AO14: =AL14 * AM14 * U14 * W14 * AN14 -> 0 | AP14: =AL14*AM14*V14*X14*AN14 -> 0.00020423405 | AQ14: =AO14+AP14 -> 0.00020423405 | AR14: =H14*AQ14*L14 -> 1.4909085 | BA14: =BA11 -> 20 | BC14: =Y14 * 1.6 -> 0 | BD14: =BD11 -> 0.043835616 | BE14: =N14 * 0.92 -> 0 | BF14: 57 | BG14: =T14 / BF14 -> 0.87719298 | BH14: =((0.045 * BC14) + (BD$11 * 0.84) + (BE14 * ((212 - 4 * ((BE14 * 1000)/(4* (BF14^0.75)) - 1)) - ((140 - 4 * (((BE14 * 1000)/(4 * BF14 ^0.75)) - 1))/(1 + EXP(-6 * (BG14 - 0.4)))))) * 10^-3) / 6.25 -> 0.0058915068 | BI14: =MAX((AJ14 / 6.25 ) - BH14, 0) -> 0.026571925 | BJ14: =H14*BI14*L14 -> 193.97505 | CA14: TAS | CB14: 0.69
E15: Lambs and hoggets | F15: Spring | H15: 200 | I15: 0 | J15: 0 | L15: =$BZ$3 -> 91.25 | N15: 0.16 | P15: 0.2 | R15: 0.75 | T15: 20 | U15: =1-V15 -> 0 | V15: =$V$11 -> 1 | W15: =VLOOKUP($B$11,$CA$10:$CB$16, 2, FALSE) -> 0.72 | X15: =$BZ$10 -> 0.0047 | Y15: =(I15/100)*(MIN(J15,100)/100) -> 0 | Z15: 1 | AA15: =1.6 * Z15 -> 1.6 | AB15: =$AB$11 -> 1.3 | AC15: =Y15*AB15+(1-Y15) -> 1 | AD15: =(0.795*R15)-0.0014 -> 0.59485 | AF15: 2.9 | AG15: =1 - EXP(-2*(AF15^2)) -> 0.99999995 | AH15: =(104.7*AD15+0.307*T15-15)*(T15^0.75)*10^-3 -> 0.50522269 | AI15: =AH15*AG15*AC15 -> 0.50522266 | AJ15: =(AI15 * P15) + (0.045 * AA15) -> 0.17304453 | AK15: =$BZ$2 -> 0.08 | AL15: =(AI15 * ((1 - R15) + (0.04 * AI15))) * ( 1 - AK15 ) -> 0.12559441 | AM15: =$BZ$1 -> 0.19 | AN15: =$CA$20 -> 0.6784 | AO15: =AL15 * AM15 * U15 * W15 * AN15 -> 0 | AP15: =AL15*AM15*V15*X15*AN15 -> 7.60865e-05 | AQ15: =AO15+AP15 -> 7.60865e-05 | AR15: =H15*AQ15*L15 -> 1.3885786 | BA15: 15 | BB15: 0.85 | BC15: =Y15 * 1.6 -> 0 | BD15: =(BA15 * BB15) / 365 -> 0.034931507 | BE15: =N15 * 0.92 -> 0.1472 | BF15: 60 | BG15: =T15 / BF15 -> 0.33333333 | BH15: =((0.045 * BC15) + (BD$15 * 0.84) + (BE15 * ((212 - 4 * ((BE15 * 1000)/(4* (BF15^0.75)) - 1)) - ((140 - 4 * (((BE15 * 1000)/(4 * BF15 ^0.75)) - 1))/(1 + EXP(-6 * (BG15 - 0.4)))))) * 10^-3) / 6.25 -> 0.0083247036 | BI15: =MAX((AJ15 / 6.25 ) - BH15, 0) -> 0.019362422 | BJ15: =H15*BI15*L15 -> 353.36419 | CA15: VIC | CB15: 0.73
F16: Summer | H16: 210 | I16: 0 | J16: 0 | L16: =$BZ$3 -> 91.25 | N16: 0.08 | P16: 0.1 | R16: 0.61 | T16: 27 | U16: =1-V16 -> 0 | V16: =$V$11 -> 1 | W16: =VLOOKUP($B$11,$CA$10:$CB$16, 2, FALSE) -> 0.72 | X16: =$BZ$10 -> 0.0047 | Y16: =(I16/100)*(MIN(J16,100)/100) -> 0 | Z16: 0 | AA16: =1.6 * Z16 -> 0 | AB16: =$AB$11 -> 1.3 | AC16: =Y16*AB16+(1-Y16) -> 1 | AD16: =(0.795*R16)-0.0014 -> 0.48355 | AF16: 2.5 | AG16: =1 - EXP(-2*(AF16^2)) -> 0.99999627 | AH16: =(104.7*AD16+0.307*T16-15)*(T16^0.75)*10^-3 -> 0.52017847 | AI16: =AH16*AG16*AC16 -> 0.52017653 | AJ16: =(AI16 * P16) + (0.045 * AA16) -> 0.052017653 | AK16: =$BZ$2 -> 0.08 | AL16: =(AI16 * ((1 - R16) + (0.04 * AI16))) * ( 1 - AK16 ) -> 0.19659682 | AM16: =$BZ$1 -> 0.19 | AN16: =$CA$20 -> 0.6784 | AO16: =AL16 * AM16 * U16 * W16 * AN16 -> 0 | AP16: =AL16*AM16*V16*X16*AN16 -> 0.00011910055 | AQ16: =AO16+AP16 -> 0.00011910055 | AR16: =H16*AQ16*L16 -> 2.2822644 | BA16: =BA15 -> 15 | BC16: =Y16 * 1.6 -> 0 | BD16: =BD15 -> 0.034931507 | BE16: =N16 * 0.92 -> 0.0736 | BF16: 60 | BG16: =T16 / BF16 -> 0.45 | BH16: =((0.045 * BC16) + (BD16 * 0.84) + (BE16 * ((212 - 4 * ((BE16 * 1000)/(4* (BF16^0.75)) - 1)) - ((140 - 4 * (((BE16 * 1000)/(4 * BF16 ^0.75)) - 1))/(1 + EXP(-6 * (BG16 - 0.4)))))) * 10^-3) / 6.25 -> 0.0062471942 | BI16: =MAX((AJ16 / 6.25 ) - BH16, 0) -> 0.0020756303 | BJ16: =H16*BI16*L16 -> 39.774265 | CA16: WA | CB16: 0.76
F17: Autumn | H17: 170 | I17: 0 | J17: 0 | L17: =$BZ$3 -> 91.25 | N17: 0.05 | P17: 0.12 | R17: 0.64 | T17: 32 | U17: =1-V17 -> 0 | V17: =$V$11 -> 1 | W17: =VLOOKUP($B$11,$CA$10:$CB$16, 2, FALSE) -> 0.72 | X17: =$BZ$10 -> 0.0047 | Y17: =(I17/100)*(MIN(J17,100)/100) -> 0 | Z17: 0 | AA17: =1.6 * Z17 -> 0 | AB17: =$AB$11 -> 1.3 | AC17: =Y17*AB17+(1-Y17) -> 1 | AD17: =(0.795*R17)-0.0014 -> 0.5074 | AF17: 1.6 | AG17: =1 - EXP(-2*(AF17^2)) -> 0.99402398 | AH17: =(104.7*AD17+0.307*T17-15)*(T17^0.75)*10^-3 -> 0.64511932 | AI17: =AH17*AG17*AC17 -> 0.64126407 | AJ17: =(AI17 * P17) + (0.045 * AA17) -> 0.076951688 | AK17: =$BZ$2 -> 0.08 | AL17: =(AI17 * ((1 - R17) + (0.04 * AI17))) * ( 1 - AK17 ) -> 0.22751954 | AM17: =$BZ$1 -> 0.19 | AN17: =$CA$20 -> 0.6784 | AO17: =AL17 * AM17 * U17 * W17 * AN17 -> 0 | AP17: =AL17*AM17*V17*X17*AN17 -> 0.00013783389 | AQ17: =AO17+AP17 -> 0.00013783389 | AR17: =H17*AQ17*L17 -> 2.1381482 | BA17: =BA15 -> 15 | BC17: =Y17 * 1.6 -> 0 | BD17: =BD15 -> 0.034931507 | BE17: =N17 * 0.92 -> 0.046 | BF17: 60 | BG17: =T17 / BF17 -> 0.53333333 | BH17: =((0.045 * BC17) + (BD17 * 0.84) + (BE17 * ((212 - 4 * ((BE17 * 1000)/(4* (BF17^0.75)) - 1)) - ((140 - 4 * (((BE17 * 1000)/(4 * BF17 ^0.75)) - 1))/(1 + EXP(-6 * (BG17 - 0.4)))))) * 10^-3) / 6.25 -> 0.0055484232 | BI17: =MAX((AJ17 / 6.25 ) - BH17, 0) -> 0.0067638469 | BJ17: =H17*BI17*L17 -> 104.92418
F18: Winter | H18: 200 | I18: 0 | J18: 0 | L18: =$BZ$3 -> 91.25 | N18: 0.04 | P18: 0.18 | R18: 0.72 | T18: 34 | U18: =1-V18 -> 0 | V18: =$V$11 -> 1 | W18: =VLOOKUP($B$11,$CA$10:$CB$16, 2, FALSE) -> 0.72 | X18: =$BZ$10 -> 0.0047 | Y18: =(I18/100)*(MIN(J18,100)/100) -> 0 | Z18: 0 | AA18: =1.6 * Z18 -> 0 | AB18: =$AB$11 -> 1.3 | AC18: =Y18*AB18+(1-Y18) -> 1 | AD18: =(0.795*R18)-0.0014 -> 0.571 | AF18: 1.7 | AG18: =1 - EXP(-2*(AF18^2)) -> 0.99691128 | AH18: =(104.7*AD18+0.307*T18-15)*(T18^0.75)*10^-3 -> 0.77753323 | AI18: =AH18*AG18*AC18 -> 0.77513165 | AJ18: =(AI18 * P18) + (0.045 * AA18) -> 0.1395237 | AK18: =$BZ$2 -> 0.08 | AL18: =(AI18 * ((1 - R18) + (0.04 * AI18))) * ( 1 - AK18 ) -> 0.22178442 | AM18: =$BZ$1 -> 0.19 | AN18: =$CA$20 -> 0.6784 | AO18: =AL18 * AM18 * U18 * W18 * AN18 -> 0 | AP18: =AL18*AM18*V18*X18*AN18 -> 0.00013435949 | AQ18: =AO18+AP18 -> 0.00013435949 | AR18: =H18*AQ18*L18 -> 2.4520607 | BA18: =BA15 -> 15 | BC18: =Y18 * 1.6 -> 0 | BD18: =BD15 -> 0.034931507 | BE18: =N18 * 0.92 -> 0.0368 | BF18: 60 | BG18: =T18 / BF18 -> 0.56666667 | BH18: =((0.045 * BC18) + (BD18 * 0.84) + (BE18 * ((212 - 4 * ((BE18 * 1000)/(4* (BF18^0.75)) - 1)) - ((140 - 4 * (((BE18 * 1000)/(4 * BF18 ^0.75)) - 1))/(1 + EXP(-6 * (BG18 - 0.4)))))) * 10^-3) / 6.25 -> 0.0053440553 | BI18: =MAX((AJ18 / 6.25 ) - BH18, 0) -> 0.016979736 | BJ18: =H18*BI18*L18 -> 309.88019 | BZ18: EFPRP | CA18: wet | CB18: 0.006
E19: Maiden ewes | F19: Spring | H19: 100 | I19: 95 | J19: 92 | L19: =$BZ$3 -> 91.25 | N19: 0.07 | P19: 0.2 | R19: 0.75 | T19: 44 | U19: =1-V19 -> 0 | V19: =$V$11 -> 1 | W19: =VLOOKUP($B$11,$CA$10:$CB$16, 2, FALSE) -> 0.72 | X19: =$BZ$10 -> 0.0047 | Y19: =(I19/100)*(MIN(J19,100)/100) -> 0.874 | Z19: 0 | AA19: =1.6 * Z19 -> 0 | AB19: =$AB$11 -> 1.3 | AC19: =Y19*AB19+(1-Y19) -> 1.2622 | AD19: =(0.795*R19)-0.0014 -> 0.59485 | AF19: 2.9 | AG19: =1 - EXP(-2*(AF19^2)) -> 0.99999995 | AH19: =(104.7*AD19+0.307*T19-15)*(T19^0.75)*10^-3 -> 1.0385156 | AI19: =AH19*AG19*AC19 -> 1.3108144 | AJ19: =(AI19 * P19) + (0.045 * AA19) -> 0.26216288 | AK19: =$BZ$2 -> 0.08 | AL19: =(AI19 * ((1 - R19) + (0.04 * AI19))) * ( 1 - AK19 ) -> 0.36471833 | AM19: =$BZ$1 -> 0.19 | AN19: =$CA$20 -> 0.6784 | AO19: =AL19 * AM19 * U19 * W19 * AN19 -> 0 | AP19: =AL19*AM19*V19*X19*AN19 -> 0.00022095045 | AQ19: =AO19+AP19 -> 0.00022095045 | AR19: =H19*AQ19*L19 -> 2.0161728 | BA19: 18 | BB19: 0.8 | BC19: =Y19 * 1.6 -> 1.3984 | BD19: =(BA19 * BB19) / 365 -> 0.039452055 | BE19: =N19 * 0.92 -> 0.0644 | BF19: 57 | BG19: =T19 / BF19 -> 0.77192982 | BH19: =((0.045 * BC19) + (BD19 * 0.84) + (BE19 * ((212 - 4 * ((BE19 * 1000)/(4* (BF19^0.75)) - 1)) - ((140 - 4 * (((BE19 * 1000)/(4 * BF19 ^0.75)) - 1))/(1 + EXP(-6 * (BG19 - 0.4)))))) * 10^-3) / 6.25 -> 0.016253475 | BI19: =MAX((AJ19 / 6.25 ) - BH19, 0) -> 0.025692585 | BJ19: =H19*BI19*L19 -> 234.44483 | CA19: dry | CB19: 0.002
F20: Summer | H20: 140 | I20: 0 | J20: 0 | L20: =$BZ$3 -> 91.25 | N20: 0 | P20: 0.1 | R20: 0.61 | T20: 42 | U20: =1-V20 -> 0 | V20: =$V$11 -> 1 | W20: =VLOOKUP($B$11,$CA$10:$CB$16, 2, FALSE) -> 0.72 | X20: =$BZ$10 -> 0.0047 | Y20: =(I20/100)*(MIN(J20,100)/100) -> 0 | Z20: 0 | AA20: =1.6 * Z20 -> 0 | AB20: =$AB$11 -> 1.3 | AC20: =Y20*AB20+(1-Y20) -> 1 | AD20: =(0.795*R20)-0.0014 -> 0.48355 | AF20: 2.5 | AG20: =1 - EXP(-2*(AF20^2)) -> 0.99999627 | AH20: =(104.7*AD20+0.307*T20-15)*(T20^0.75)*10^-3 -> 0.80052121 | AI20: =AH20*AG20*AC20 -> 0.80051822 | AJ20: =(AI20 * P20) + (0.045 * AA20) -> 0.080051822 | AK20: =$BZ$2 -> 0.08 | AL20: =(AI20 * ((1 - R20) + (0.04 * AI20))) * ( 1 - AK20 ) -> 0.31080846 | AM20: =$BZ$1 -> 0.19 | AN20: =$CA$20 -> 0.6784 | AO20: =AL20 * AM20 * U20 * W20 * AN20 -> 0 | AP20: =AL20*AM20*V20*X20*AN20 -> 0.00018829125 | AQ20: =AO20+AP20 -> 0.00018829125 | AR20: =H20*AQ20*L20 -> 2.4054207 | BA20: =BA19 -> 18 | BC20: =Y20 * 1.6 -> 0 | BD20: =BD19 -> 0.039452055 | BE20: =N20 * 0.92 -> 0 | BF20: 57 | BG20: =T20 / BF20 -> 0.73684211 | BH20: =((0.045 * BC20) + (BD20 * 0.84) + (BE20 * ((212 - 4 * ((BE20 * 1000)/(4* (BF20^0.75)) - 1)) - ((140 - 4 * (((BE20 * 1000)/(4 * BF20 ^0.75)) - 1))/(1 + EXP(-6 * (BG20 - 0.4)))))) * 10^-3) / 6.25 -> 0.0053023562 | BI20: =MAX((AJ20 / 6.25 ) - BH20, 0) -> 0.0075059354 | BJ20: =H20*BI20*L20 -> 95.888325 | BZ20: p | CA20: 0.6784
F21: Autumn | H21: 135 | I21: 0 | J21: 0 | L21: =$BZ$3 -> 91.25 | N21: 0 | P21: 0.12 | R21: 0.64 | T21: 43 | U21: =1-V21 -> 0 | V21: =$V$11 -> 1 | W21: =VLOOKUP($B$11,$CA$10:$CB$16, 2, FALSE) -> 0.72 | X21: =$BZ$10 -> 0.0047 | Y21: =(I21/100)*(MIN(J21,100)/100) -> 0 | Z21: 0 | AA21: =1.6 * Z21 -> 0 | AB21: =$AB$11 -> 1.3 | AC21: =Y21*AB21+(1-Y21) -> 1 | AD21: =(0.795*R21)-0.0014 -> 0.5074 | AF21: 1.6 | AG21: =1 - EXP(-2*(AF21^2)) -> 0.99402398 | AH21: =(104.7*AD21+0.307*T21-15)*(T21^0.75)*10^-3 -> 0.86186035 | AI21: =AH21*AG21*AC21 -> 0.85670985 | AJ21: =(AI21 * P21) + (0.045 * AA21) -> 0.10280518 | AK21: =$BZ$2 -> 0.08 | AL21: =(AI21 * ((1 - R21) + (0.04 * AI21))) * ( 1 - AK21 ) -> 0.31075173 | AM21: =$BZ$1 -> 0.19 | AN21: =$CA$20 -> 0.6784 | AO21: =AL21 * AM21 * U21 * W21 * AN21 -> 0 | AP21: =AL21*AM21*V21*X21*AN21 -> 0.00018825688 | AQ21: =AO21+AP21 -> 0.00018825688 | AR21: =H21*AQ21*L21 -> 2.3190894 | BA21: =BA19 -> 18 | BC21: =Y21 * 1.6 -> 0 | BD21: =BD19 -> 0.039452055 | BE21: =N21 * 0.92 -> 0 | BF21: 57 | BG21: =T21 / BF21 -> 0.75438596 | BH21: =((0.045 * BC21) + (BD21 * 0.84) + (BE21 * ((212 - 4 * ((BE21 * 1000)/(4* (BF21^0.75)) - 1)) - ((140 - 4 * (((BE21 * 1000)/(4 * BF21 ^0.75)) - 1))/(1 + EXP(-6 * (BG21 - 0.4)))))) * 10^-3) / 6.25 -> 0.0053023562 | BI21: =MAX((AJ21 / 6.25 ) - BH21, 0) -> 0.011146473 | BJ21: =H21*BI21*L21 -> 137.31061
F22: Winter | H22: 130 | I22: 0 | J22: 0 | L22: =$BZ$3 -> 91.25 | N22: 0.02 | P22: 0.18 | R22: 0.72 | T22: 45 | U22: =1-V22 -> 0 | V22: =$V$11 -> 1 | W22: =VLOOKUP($B$11,$CA$10:$CB$16, 2, FALSE) -> 0.72 | X22: =$BZ$10 -> 0.0047 | Y22: =(I22/100)*(MIN(J22,100)/100) -> 0 | Z22: 0 | AA22: =1.6 * Z22 -> 0 | AB22: =$AB$11 -> 1.3 | AC22: =Y22*AB22+(1-Y22) -> 1 | AD22: =(0.795*R22)-0.0014 -> 0.571 | AF22: 1.7 | AG22: =1 - EXP(-2*(AF22^2)) -> 0.99691128 | AH22: =(104.7*AD22+0.307*T22-15)*(T22^0.75)*10^-3 -> 1.0181162 | AI22: =AH22*AG22*AC22 -> 1.0149716 | AJ22: =(AI22 * P22) + (0.045 * AA22) -> 0.18269488 | AK22: =$BZ$2 -> 0.08 | AL22: =(AI22 * ((1 - R22) + (0.04 * AI22))) * ( 1 - AK22 ) -> 0.29936683 | AM22: =$BZ$1 -> 0.19 | AN22: =$CA$20 -> 0.6784 | AO22: =AL22 * AM22 * U22 * W22 * AN22 -> 0 | AP22: =AL22*AM22*V22*X22*AN22 -> 0.00018135978 | AQ22: =AO22+AP22 -> 0.00018135978 | AR22: =H22*AQ22*L22 -> 2.1513804 | BA22: =BA19 -> 18 | BC22: =Y22 * 1.6 -> 0 | BD22: =BD19 -> 0.039452055 | BE22: =N22 * 0.92 -> 0.0184 | BF22: 57 | BG22: =T22 / BF22 -> 0.78947368 | BH22: =((0.045 * BC22) + (BD22 * 0.84) + (BE22 * ((212 - 4 * ((BE22 * 1000)/(4* (BF22^0.75)) - 1)) - ((140 - 4 * (((BE22 * 1000)/(4 * BF22 ^0.75)) - 1))/(1 + EXP(-6 * (BG22 - 0.4)))))) * 10^-3) / 6.25 -> 0.0055514502 | BI22: =MAX((AJ22 / 6.25 ) - BH22, 0) -> 0.023679731 | BJ22: =H22*BI22*L22 -> 280.90081
E23: Other ewes | F23: Spring | H23: 200 | I23: 0 | J23: 0 | L23: =$BZ$3 -> 91.25 | N23: 0.05 | P23: 0.2 | R23: 0.75 | T23: 56 | U23: =1-V23 -> 0 | V23: =$V$11 -> 1 | W23: =VLOOKUP($B$11,$CA$10:$CB$16, 2, FALSE) -> 0.72 | X23: =$BZ$10 -> 0.0047 | Y23: =(I23/100)*(MIN(J23,100)/100) -> 0 | Z23: 0 | AA23: =1.6 * Z23 -> 0 | AB23: =$AB$11 -> 1.3 | AC23: =Y23*AB23+(1-Y23) -> 1 | AD23: =(0.795*R23)-0.0014 -> 0.59485 | AF23: 2.9 | AG23: =1 - EXP(-2*(AF23^2)) -> 0.99999995 | AH23: =(104.7*AD23+0.307*T23-15)*(T23^0.75)*10^-3 -> 1.3198285 | AI23: =AH23*AG23*AC23 -> 1.3198285 | AJ23: =(AI23 * P23) + (0.045 * AA23) -> 0.2639657 | AK23: =$BZ$2 -> 0.08 | AL23: =(AI23 * ((1 - R23) + (0.04 * AI23))) * ( 1 - AK23 ) -> 0.36766421 | AM23: =$BZ$1 -> 0.19 | AN23: =$CA$20 -> 0.6784 | AO23: =AL23 * AM23 * U23 * W23 * AN23 -> 0 | AP23: =AL23*AM23*V23*X23*AN23 -> 0.0002227351 | AQ23: =AO23+AP23 -> 0.0002227351 | AR23: =H23*AQ23*L23 -> 4.0649155 | BA23: 20 | BB23: 0.8 | BC23: =Y23 * 1.6 -> 0 | BD23: =(BA23 * BB23) / 365 -> 0.043835616 | BE23: =N23 * 0.92 -> 0.046 | BF23: 57 | BG23: =T23 / BF23 -> 0.98245614 | BH23: =((0.045 * BC23) + (BD23 * 0.84) + (BE23 * ((212 - 4 * ((BE23 * 1000)/(4* (BF23^0.75)) - 1)) - ((140 - 4 * (((BE23 * 1000)/(4 * BF23 ^0.75)) - 1))/(1 + EXP(-6 * (BG23 - 0.4)))))) * 10^-3) / 6.25 -> 0.0064521714 | BI23: =MAX((AJ23 / 6.25 ) - BH23, 0) -> 0.03578234 | BJ23: =H23*BI23*L23 -> 653.02771
F24: Summer | H24: 210 | I24: 0 | J24: 0 | L24: =$BZ$3 -> 91.25 | N24: -0.05 | P24: 0.1 | R24: 0.61 | T24: 51 | U24: =1-V24 -> 0 | V24: =$V$11 -> 1 | W24: =VLOOKUP($B$11,$CA$10:$CB$16, 2, FALSE) -> 0.72 | X24: =$BZ$10 -> 0.0047 | Y24: =(I24/100)*(MIN(J24,100)/100) -> 0 | Z24: 0 | AA24: =1.6 * Z24 -> 0 | AB24: =$AB$11 -> 1.3 | AC24: =Y24*AB24+(1-Y24) -> 1 | AD24: =(0.795*R24)-0.0014 -> 0.48355 | AF24: 2.5 | AG24: =1 - EXP(-2*(AF24^2)) -> 0.99999627 | AH24: =(104.7*AD24+0.307*T24-15)*(T24^0.75)*10^-3 -> 0.97873546 | AI24: =AH24*AG24*AC24 -> 0.97873182 | AJ24: =(AI24 * P24) + (0.045 * AA24) -> 0.097873182 | AK24: =$BZ$2 -> 0.08 | AL24: =(AI24 * ((1 - R24) + (0.04 * AI24))) * ( 1 - AK24 ) -> 0.38642028 | AM24: =$BZ$1 -> 0.19 | AN24: =$CA$20 -> 0.6784 | AO24: =AL24 * AM24 * U24 * W24 * AN24 -> 0 | AP24: =AL24*AM24*V24*X24*AN24 -> 0.00023409774 | AQ24: =AO24+AP24 -> 0.00023409774 | AR24: =H24*AQ24*L24 -> 4.4858979 | BA24: =BA23 -> 20 | BC24: =Y24 * 1.6 -> 0 | BD24: =BD23 -> 0.043835616 | BE24: =N24 * 0.92 -> -0.046 | BF24: 57 | BG24: =T24 / BF24 -> 0.89473684 | BH24: =((0.045 * BC24) + (BD24 * 0.84) + (BE24 * ((212 - 4 * ((BE24 * 1000)/(4* (BF24^0.75)) - 1)) - ((140 - 4 * (((BE24 * 1000)/(4 * BF24 ^0.75)) - 1))/(1 + EXP(-6 * (BG24 - 0.4)))))) * 10^-3) / 6.25 -> 0.0053089916 | BI24: =MAX((AJ24 / 6.25 ) - BH24, 0) -> 0.010350717 | BJ24: =H24*BI24*L24 -> 198.34562
F25: Autumn | H25: 190 | I25: 0 | J25: 0 | L25: =$BZ$3 -> 91.25 | N25: -0.01 | P25: 0.12 | R25: 0.64 | T25: 50 | U25: =1-V25 -> 0 | V25: =$V$11 -> 1 | W25: =VLOOKUP($B$11,$CA$10:$CB$16, 2, FALSE) -> 0.72 | X25: =$BZ$10 -> 0.0047 | Y25: =(I25/100)*(MIN(J25,100)/100) -> 0 | Z25: 0 | AA25: =1.6 * Z25 -> 0 | AB25: =$AB$11 -> 1.3 | AC25: =Y25*AB25+(1-Y25) -> 1 | AD25: =(0.795*R25)-0.0014 -> 0.5074 | AF25: 1.6 | AG25: =1 - EXP(-2*(AF25^2)) -> 0.99402398 | AH25: =(104.7*AD25+0.307*T25-15)*(T25^0.75)*10^-3 -> 1.0054871 | AI25: =AH25*AG25*AC25 -> 0.9994783 | AJ25: =(AI25 * P25) + (0.045 * AA25) -> 0.1199374 | AK25: =$BZ$2 -> 0.08 | AL25: =(AI25 * ((1 - R25) + (0.04 * AI25))) * ( 1 - AK25 ) -> 0.36778883 | AM25: =$BZ$1 -> 0.19 | AN25: =$CA$20 -> 0.6784 | AO25: =AL25 * AM25 * U25 * W25 * AN25 -> 0 | AP25: =AL25*AM25*V25*X25*AN25 -> 0.00022281059 | AQ25: =AO25+AP25 -> 0.00022281059 | AR25: =H25*AQ25*L25 -> 3.8629786 | BA25: =BA23 -> 20 | BC25: =Y25 * 1.6 -> 0 | BD25: =BD23 -> 0.043835616 | BE25: =N25 * 0.92 -> -0.0092 | BF25: 57 | BG25: =T25 / BF25 -> 0.87719298 | BH25: =((0.045 * BC25) + (BD25 * 0.84) + (BE25 * ((212 - 4 * ((BE25 * 1000)/(4* (BF25^0.75)) - 1)) - ((140 - 4 * (((BE25 * 1000)/(4 * BF25 ^0.75)) - 1))/(1 + EXP(-6 * (BG25 - 0.4)))))) * 10^-3) / 6.25 -> 0.0057740402 | BI25: =MAX((AJ25 / 6.25 ) - BH25, 0) -> 0.013415943 | BJ25: =H25*BI25*L25 -> 232.59891 | BY25: MMS
F26: Winter | H26: 180 | I26: 0 | J26: 0 | L26: =$BZ$3 -> 91.25 | N26: 0.01 | P26: 0.18 | R26: 0.72 | T26: 51 | U26: =1-V26 -> 0 | V26: =$V$11 -> 1 | W26: =VLOOKUP($B$11,$CA$10:$CB$16, 2, FALSE) -> 0.72 | X26: =$BZ$10 -> 0.0047 | Y26: =(I26/100)*(MIN(J26,100)/100) -> 0 | Z26: 0 | AA26: =1.6 * Z26 -> 0 | AB26: =$AB$11 -> 1.3 | AC26: =Y26*AB26+(1-Y26) -> 1 | AD26: =(0.795*R26)-0.0014 -> 0.571 | AF26: 1.7 | AG26: =1 - EXP(-2*(AF26^2)) -> 0.99691128 | AH26: =(104.7*AD26+0.307*T26-15)*(T26^0.75)*10^-3 -> 1.1534722 | AI26: =AH26*AG26*AC26 -> 1.1499094 | AJ26: =(AI26 * P26) + (0.045 * AA26) -> 0.20698369 | AK26: =$BZ$2 -> 0.08 | AL26: =(AI26 * ((1 - R26) + (0.04 * AI26))) * ( 1 - AK26 ) -> 0.344877 | AM26: =$BZ$1 -> 0.19 | AN26: =$CA$20 -> 0.6784 | AO26: =AL26 * AM26 * U26 * W26 * AN26 -> 0 | AP26: =AL26*AM26*V26*X26*AN26 -> 0.00020893035 | AQ26: =AO26+AP26 -> 0.00020893035 | AR26: =H26*AQ26*L26 -> 3.431681 | BA26: =BA23 -> 20 | BC26: =Y26 * 1.6 -> 0 | BD26: =BD23 -> 0.043835616 | BE26: =N26 * 0.92 -> 0.0092 | BF26: 57 | BG26: =T26 / BF26 -> 0.89473684 | BH26: =((0.045 * BC26) + (BD26 * 0.84) + (BE26 * ((212 - 4 * ((BE26 * 1000)/(4* (BF26^0.75)) - 1)) - ((140 - 4 * (((BE26 * 1000)/(4 * BF26 ^0.75)) - 1))/(1 + EXP(-6 * (BG26 - 0.4)))))) * 10^-3) / 6.25 -> 0.0060078185 | BI26: =MAX((AJ26 / 6.25 ) - BH26, 0) -> 0.027109573 | BJ26: =H26*BI26*L26 -> 445.27473 | BY26: ACT | BZ26: 99.25 | CA26: 0.75
E27: Rams | F27: Spring | H27: 50 | I27: 0 | J27: 0 | L27: =$BZ$3 -> 91.25 | N27: 0.07 | P27: 0.2 | R27: 0.75 | T27: 75 | U27: =1-V27 -> 0 | V27: =$V$11 -> 1 | W27: =VLOOKUP($B$11,$CA$10:$CB$16, 2, FALSE) -> 0.72 | X27: =$BZ$10 -> 0.0047 | Y27: =(I27/100)*(MIN(J27,100)/100) -> 0 | Z27: 0 | AA27: =1.6 * Z27 -> 0 | AB27: =$AB$11 -> 1.3 | AC27: =Y27*AB27+(1-Y27) -> 1 | AD27: =(0.795*R27)-0.0014 -> 0.59485 | AF27: 2.9 | AG27: =1 - EXP(-2*(AF27^2)) -> 0.99999995 | AH27: =(104.7*AD27+0.307*T27-15)*(T27^0.75)*10^-3 -> 1.7917898 | AI27: =AH27*AG27*AC27 -> 1.7917898 | AJ27: =(AI27 * P27) + (0.045 * AA27) -> 0.35835795 | AK27: =$BZ$2 -> 0.08 | AL27: =(AI27 * ((1 - R27) + (0.04 * AI27))) * ( 1 - AK27 ) -> 0.53025843 | AM27: =$BZ$1 -> 0.19 | AN27: =$CA$20 -> 0.6784 | AO27: =AL27 * AM27 * U27 * W27 * AN27 -> 0 | AP27: =AL27*AM27*V27*X27*AN27 -> 0.0003212365 | AQ27: =AO27+AP27 -> 0.0003212365 | AR27: =H27*AQ27*L27 -> 1.4656415 | BA27: 15 | BB27: 0.85 | BC27: =Y27 * 1.6 -> 0 | BD27: =(BA27 * BB27) / 365 -> 0.034931507 | BE27: =N27 * 0.92 -> 0.0644 | BF27: 78 | BG27: =T27 / BF27 -> 0.96153846 | BH27: =((0.045 * BC27) + (BD27 * 0.84) + (BE27 * ((212 - 4 * ((BE27 * 1000)/(4* (BF27^0.75)) - 1)) - ((140 - 4 * (((BE27 * 1000)/(4 * BF27 ^0.75)) - 1))/(1 + EXP(-6 * (BG27 - 0.4)))))) * 10^-3) / 6.25 -> 0.0054852081 | BI27: =MAX((AJ27 / 6.25 ) - BH27, 0) -> 0.051852064 | BJ27: =H27*BI27*L27 -> 236.57504 | BY27: NSW | BZ27: 99.55 | CA27: 0.45
F28: Summer | H28: 55 | I28: 0 | J28: 0 | L28: =$BZ$3 -> 91.25 | N28: 0 | P28: 0.1 | R28: 0.61 | T28: 75 | U28: =1-V28 -> 0 | V28: =$V$11 -> 1 | W28: =VLOOKUP($B$11,$CA$10:$CB$16, 2, FALSE) -> 0.72 | X28: =$BZ$10 -> 0.0047 | Y28: =(I28/100)*(MIN(J28,100)/100) -> 0 | Z28: 0 | AA28: =1.6 * Z28 -> 0 | AB28: =$AB$11 -> 1.3 | AC28: =Y28*AB28+(1-Y28) -> 1 | AD28: =(0.795*R28)-0.0014 -> 0.48355 | AF28: 2.5 | AG28: =1 - EXP(-2*(AF28^2)) -> 0.99999627 | AH28: =(104.7*AD28+0.307*T28-15)*(T28^0.75)*10^-3 -> 1.4948026 | AI28: =AH28*AG28*AC28 -> 1.494797 | AJ28: =(AI28 * P28) + (0.045 * AA28) -> 0.1494797 | AK28: =$BZ$2 -> 0.08 | AL28: =(AI28 * ((1 - R28) + (0.04 * AI28))) * ( 1 - AK28 ) -> 0.61855976 | AM28: =$BZ$1 -> 0.19 | AN28: =$CA$20 -> 0.6784 | AO28: =AL28 * AM28 * U28 * W28 * AN28 -> 0 | AP28: =AL28*AM28*V28*X28*AN28 -> 0.00037473043 | AQ28: =AO28+AP28 -> 0.00037473043 | AR28: =H28*AQ28*L28 -> 1.8806784 | BA28: =BA27 -> 15 | BC28: =Y28 * 1.6 -> 0 | BD28: =BD27 -> 0.034931507 | BE28: =N28 * 0.92 -> 0 | BF28: 78 | BG28: =T28 / BF28 -> 0.96153846 | BH28: =((0.045 * BC28) + (BD28 * 0.84) + (BE28 * ((212 - 4 * ((BE28 * 1000)/(4* (BF28^0.75)) - 1)) - ((140 - 4 * (((BE28 * 1000)/(4 * BF28 ^0.75)) - 1))/(1 + EXP(-6 * (BG28 - 0.4)))))) * 10^-3) / 6.25 -> 0.0046947945 | BI28: =MAX((AJ28 / 6.25 ) - BH28, 0) -> 0.019221958 | BJ28: =H28*BI28*L28 -> 96.470202 | BY28: QLD | BZ28: 99.91 | CA28: 0.09
F29: Autumn | H29: 60 | I29: 0 | J29: 0 | L29: =$BZ$3 -> 91.25 | N29: -0.07 | P29: 0.12 | R29: 0.64 | T29: 69 | U29: =1-V29 -> 0 | V29: =$V$11 -> 1 | W29: =VLOOKUP($B$11,$CA$10:$CB$16, 2, FALSE) -> 0.72 | X29: =$BZ$10 -> 0.0047 | Y29: =(I29/100)*(MIN(J29,100)/100) -> 0 | Z29: 0 | AA29: =1.6 * Z29 -> 0 | AB29: =$AB$11 -> 1.3 | AC29: =Y29*AB29+(1-Y29) -> 1 | AD29: =(0.795*R29)-0.0014 -> 0.5074 | AF29: 1.6 | AG29: =1 - EXP(-2*(AF29^2)) -> 0.99402398 | AH29: =(104.7*AD29+0.307*T29-15)*(T29^0.75)*10^-3 -> 1.4198697 | AI29: =AH29*AG29*AC29 -> 1.4113845 | AJ29: =(AI29 * P29) + (0.045 * AA29) -> 0.16936614 | AK29: =$BZ$2 -> 0.08 | AL29: =(AI29 * ((1 - R29) + (0.04 * AI29))) * ( 1 - AK29 ) -> 0.54075638 | AM29: =$BZ$1 -> 0.19 | AN29: =$CA$20 -> 0.6784 | AO29: =AL29 * AM29 * U29 * W29 * AN29 -> 0 | AP29: =AL29*AM29*V29*X29*AN29 -> 0.00032759627 | AQ29: =AO29+AP29 -> 0.00032759627 | AR29: =H29*AQ29*L29 -> 1.7935896 | BA29: =BA27 -> 15 | BC29: =Y29 * 1.6 -> 0 | BD29: =BD27 -> 0.034931507 | BE29: =N29 * 0.92 -> -0.0644 | BF29: 78 | BG29: =T29 / BF29 -> 0.88461538 | BH29: =((0.045 * BC29) + (BD29 * 0.84) + (BE29 * ((212 - 4 * ((BE29 * 1000)/(4* (BF29^0.75)) - 1)) - ((140 - 4 * (((BE29 * 1000)/(4 * BF29 ^0.75)) - 1))/(1 + EXP(-6 * (BG29 - 0.4)))))) * 10^-3) / 6.25 -> 0.0038747756 | BI29: =MAX((AJ29 / 6.25 ) - BH29, 0) -> 0.023223807 | BJ29: =H29*BI29*L29 -> 127.15034 | BY29: SA | BZ29: 99.74 | CA29: 0.26
F30: Winter | H30: 65 | I30: 0 | J30: 0 | L30: =$BZ$3 -> 91.25 | N30: 0 | P30: 0.18 | R30: 0.72 | T30: 69 | U30: =1-V30 -> 0 | V30: =$V$11 -> 1 | W30: =VLOOKUP($B$11,$CA$10:$CB$16, 2, FALSE) -> 0.72 | X30: =$BZ$10 -> 0.0047 | Y30: =(I30/100)*(MIN(J30,100)/100) -> 0 | Z30: 0 | AA30: =1.6 * Z30 -> 0 | AB30: =$AB$11 -> 1.3 | AC30: =Y30*AB30+(1-Y30) -> 1 | AD30: =(0.795*R30)-0.0014 -> 0.571 | AF30: 1.7 | AG30: =1 - EXP(-2*(AF30^2)) -> 0.99691128 | AH30: =(104.7*AD30+0.307*T30-15)*(T30^0.75)*10^-3 -> 1.5792889 | AI30: =AH30*AG30*AC30 -> 1.5744109 | AJ30: =(AI30 * P30) + (0.045 * AA30) -> 0.28339396 | AK30: =$BZ$2 -> 0.08 | AL30: =(AI30 * ((1 - R30) + (0.04 * AI30))) * ( 1 - AK30 ) -> 0.49678697 | AM30: =$BZ$1 -> 0.19 | AN30: =$CA$20 -> 0.6784 | AO30: =AL30 * AM30 * U30 * W30 * AN30 -> 0 | AP30: =AL30*AM30*V30*X30*AN30 -> 0.00030095911 | AQ30: =AO30+AP30 -> 0.00030095911 | AR30: =H30*AQ30*L30 -> 1.7850637 | BA30: =BA27 -> 15 | BC30: =Y30 * 1.6 -> 0 | BD30: =BD27 -> 0.034931507 | BE30: =N30 * 0.92 -> 0 | BF30: 78 | BG30: =T30 / BF30 -> 0.88461538 | BH30: =((0.045 * BC30) + (BD30 * 0.84) + (BE30 * ((212 - 4 * ((BE30 * 1000)/(4* (BF30^0.75)) - 1)) - ((140 - 4 * (((BE30 * 1000)/(4 * BF30 ^0.75)) - 1))/(1 + EXP(-6 * (BG30 - 0.4)))))) * 10^-3) / 6.25 -> 0.0046947945 | BI30: =MAX((AJ30 / 6.25 ) - BH30, 0) -> 0.04064824 | BJ30: =H30*BI30*L30 -> 241.09487 | BY30: TAS | BZ30: 99.5 | CA30: 0.5
E31: Wethers | F31: Spring | H31: 50 | I31: 0 | J31: 0 | L31: =$BZ$3 -> 91.25 | N31: 0.08 | P31: 0.2 | R31: 0.75 | T31: 62 | U31: =1-V31 -> 0 | V31: =$V$11 -> 1 | W31: =VLOOKUP($B$11,$CA$10:$CB$16, 2, FALSE) -> 0.72 | X31: =$BZ$10 -> 0.0047 | Y31: =(I31/100)*(MIN(J31,100)/100) -> 0 | Z31: 0 | AA31: =1.6 * Z31 -> 0 | AB31: =$AB$11 -> 1.3 | AC31: =Y31*AB31+(1-Y31) -> 1 | AD31: =(0.795*R31)-0.0014 -> 0.59485 | AF31: 2.9 | AG31: =1 - EXP(-2*(AF31^2)) -> 0.99999995 | AH31: =(104.7*AD31+0.307*T31-15)*(T31^0.75)*10^-3 -> 1.4652246 | AI31: =AH31*AG31*AC31 -> 1.4652245 | AJ31: =(AI31 * P31) + (0.045 * AA31) -> 0.2930449 | AK31: =$BZ$2 -> 0.08 | AL31: =(AI31 * ((1 - R31) + (0.04 * AI31))) * ( 1 - AK31 ) -> 0.41600693 | AM31: =$BZ$1 -> 0.19 | AN31: =$CA$20 -> 0.6784 | AO31: =AL31 * AM31 * U31 * W31 * AN31 -> 0 | AP31: =AL31*AM31*V31*X31*AN31 -> 0.00025202166 | AQ31: =AO31+AP31 -> 0.00025202166 | AR31: =H31*AQ31*L31 -> 1.1498488 | BA31: 18 | BB31: 0.8 | BC31: =Y31 * 1.6 -> 0 | BD31: =(BA31 * BB31) / 365 -> 0.039452055 | BE31: =N31 * 0.92 -> 0.0736 | BF31: 62 | BG31: =T31 / BF31 -> 1 | BH31: =((0.045 * BC31) + (BD31 * 0.84) + (BE31 * ((212 - 4 * ((BE31 * 1000)/(4* (BF31^0.75)) - 1)) - ((140 - 4 * (((BE31 * 1000)/(4 * BF31 ^0.75)) - 1))/(1 + EXP(-6 * (BG31 - 0.4)))))) * 10^-3) / 6.25 -> 0.0061942865 | BI31: =MAX((AJ31 / 6.25 ) - BH31, 0) -> 0.040692898 | BJ31: =H31*BI31*L31 -> 185.66135 | BY31: VIC | BZ31: 99.17 | CA31: 0.83
F32: Summer | H32: 100 | I32: 0 | J32: 0 | L32: =$BZ$3 -> 91.25 | N32: -0.08 | P32: 0.1 | R32: 0.61 | T32: 55 | U32: =1-V32 -> 0 | V32: =$V$11 -> 1 | W32: =VLOOKUP($B$11,$CA$10:$CB$16, 2, FALSE) -> 0.72 | X32: =$BZ$10 -> 0.0047 | Y32: =(I32/100)*(MIN(J32,100)/100) -> 0 | Z32: 0 | AA32: =1.6 * Z32 -> 0 | AB32: =$AB$11 -> 1.3 | AC32: =Y32*AB32+(1-Y32) -> 1 | AD32: =(0.795*R32)-0.0014 -> 0.48355 | AF32: 2.5 | AG32: =1 - EXP(-2*(AF32^2)) -> 0.99999627 | AH32: =(104.7*AD32+0.307*T32-15)*(T32^0.75)*10^-3 -> 1.0605624 | AI32: =AH32*AG32*AC32 -> 1.0605585 | AJ32: =(AI32 * P32) + (0.045 * AA32) -> 0.10605585 | AK32: =$BZ$2 -> 0.08 | AL32: =(AI32 * ((1 - R32) + (0.04 * AI32))) * ( 1 - AK32 ) -> 0.42192045 | AM32: =$BZ$1 -> 0.19 | AN32: =$CA$20 -> 0.6784 | AO32: =AL32 * AM32 * U32 * W32 * AN32 -> 0 | AP32: =AL32*AM32*V32*X32*AN32 -> 0.00025560413 | AQ32: =AO32+AP32 -> 0.00025560413 | AR32: =H32*AQ32*L32 -> 2.3323877 | BA32: =BA31 -> 18 | BC32: =Y32 * 1.6 -> 0 | BD32: =BD31 -> 0.039452055 | BE32: =N32 * 0.92 -> -0.0736 | BF32: 62 | BG32: =T32 / BF32 -> 0.88709677 | BH32: =((0.045 * BC32) + (BD32 * 0.84) + (BE32 * ((212 - 4 * ((BE32 * 1000)/(4* (BF32^0.75)) - 1)) - ((140 - 4 * (((BE32 * 1000)/(4 * BF32 ^0.75)) - 1))/(1 + EXP(-6 * (BG32 - 0.4)))))) * 10^-3) / 6.25 -> 0.0043659164 | BI32: =MAX((AJ32 / 6.25 ) - BH32, 0) -> 0.012603019 | BJ32: =H32*BI32*L32 -> 115.00255 | BY32: WA | BZ32: 99.59 | CA32: 0.41
F33: Autumn | H33: 90 | I33: 0 | J33: 0 | L33: =$BZ$3 -> 91.25 | N33: 0 | P33: 0.12 | R33: 0.64 | T33: 55 | U33: =1-V33 -> 0 | V33: =$V$11 -> 1 | W33: =VLOOKUP($B$11,$CA$10:$CB$16, 2, FALSE) -> 0.72 | X33: =$BZ$10 -> 0.0047 | Y33: =(I33/100)*(MIN(J33,100)/100) -> 0 | Z33: 0 | AA33: =1.6 * Z33 -> 0 | AB33: =$AB$11 -> 1.3 | AC33: =Y33*AB33+(1-Y33) -> 1 | AD33: =(0.795*R33)-0.0014 -> 0.5074 | AF33: 1.6 | AG33: =1 - EXP(-2*(AF33^2)) -> 0.99402398 | AH33: =(104.7*AD33+0.307*T33-15)*(T33^0.75)*10^-3 -> 1.1109945 | AI33: =AH33*AG33*AC33 -> 1.1043552 | AJ33: =(AI33 * P33) + (0.045 * AA33) -> 0.13252263 | AK33: =$BZ$2 -> 0.08 | AL33: =(AI33 * ((1 - R33) + (0.04 * AI33))) * ( 1 - AK33 ) -> 0.41064374 | AM33: =$BZ$1 -> 0.19 | AN33: =$CA$20 -> 0.6784 | AO33: =AL33 * AM33 * U33 * W33 * AN33 -> 0 | AP33: =AL33*AM33*V33*X33*AN33 -> 0.00024877258 | AQ33: =AO33+AP33 -> 0.00024877258 | AR33: =H33*AQ33*L33 -> 2.0430448 | BA33: =BA31 -> 18 | BC33: =Y33 * 1.6 -> 0 | BD33: =BD31 -> 0.039452055 | BE33: =N33 * 0.92 -> 0 | BF33: 62 | BG33: =T33 / BF33 -> 0.88709677 | BH33: =((0.045 * BC33) + (BD33 * 0.84) + (BE33 * ((212 - 4 * ((BE33 * 1000)/(4* (BF33^0.75)) - 1)) - ((140 - 4 * (((BE33 * 1000)/(4 * BF33 ^0.75)) - 1))/(1 + EXP(-6 * (BG33 - 0.4)))))) * 10^-3) / 6.25 -> 0.0053023562 | BI33: =MAX((AJ33 / 6.25 ) - BH33, 0) -> 0.015901264 | BJ33: =H33*BI33*L33 -> 130.58913
F34: Winter | H34: 80 | I34: 0 | J34: 0 | L34: =$BZ$3 -> 91.25 | N34: 0 | P34: 0.18 | R34: 0.72 | T34: 55 | U34: =1-V34 -> 0 | V34: =$V$11 -> 1 | W34: =VLOOKUP($B$11,$CA$10:$CB$16, 2, FALSE) -> 0.72 | X34: =$BZ$10 -> 0.0047 | Y34: =(I34/100)*(MIN(J34,100)/100) -> 0 | Z34: 0 | AA34: =1.6 * Z34 -> 0 | AB34: =$AB$11 -> 1.3 | AC34: =Y34*AB34+(1-Y34) -> 1 | AD34: =(0.795*R34)-0.0014 -> 0.571 | AF34: 1.7 | AG34: =1 - EXP(-2*(AF34^2)) -> 0.99691128 | AH34: =(104.7*AD34+0.307*T34-15)*(T34^0.75)*10^-3 -> 1.2454802 | AI34: =AH34*AG34*AC34 -> 1.2416332 | AJ34: =(AI34 * P34) + (0.045 * AA34) -> 0.22349398 | AK34: =$BZ$2 -> 0.08 | AL34: =(AI34 * ((1 - R34) + (0.04 * AI34))) * ( 1 - AK34 ) -> 0.37657755 | AM34: =$BZ$1 -> 0.19 | AN34: =$CA$20 -> 0.6784 | AO34: =AL34 * AM34 * U34 * W34 * AN34 -> 0 | AP34: =AL34*AM34*V34*X34*AN34 -> 0.0002281349 | AQ34: =AO34+AP34 -> 0.0002281349 | AR34: =H34*AQ34*L34 -> 1.6653847 | BA34: =BA31 -> 18 | BC34: =Y34 * 1.6 -> 0 | BD34: =BD31 -> 0.039452055 | BE34: =N34 * 0.92 -> 0 | BF34: 62 | BG34: =T34 / BF34 -> 0.88709677 | BH34: =((0.045 * BC34) + (BD34 * 0.84) + (BE34 * ((212 - 4 * ((BE34 * 1000)/(4* (BF34^0.75)) - 1)) - ((140 - 4 * (((BE34 * 1000)/(4 * BF34 ^0.75)) - 1))/(1 + EXP(-6 * (BG34 - 0.4)))))) * 10^-3) / 6.25 -> 0.0053023562 | BI34: =MAX((AJ34 / 6.25 ) - BH34, 0) -> 0.03045668 | BJ34: =H34*BI34*L34 -> 222.33377
BY36: EFN2O
BY37: Irrigated pasture | BZ37: 0.0059 | CD37: Tropical montane | CE37: 0.006 | CF37: wet
BY38: Irrigated crop | BZ38: 0.007 | CD38: Tropical wet | CE38: 0.006 | CF38: wet
BY39: Non-irrigated pasture | BZ39: 0.0018 | CD39: Tropical moist | CE39: 0.006 | CF39: wet
BY40: Non-irrigated crop (low rainfall) | BZ40: 0.0029 | CD40: Warm temperate moist | CE40: 0.006 | CF40: wet
A41: NSW | B41: NSW | C41: ACT/NSW | D41: no | E41: Breeding ewes | F41: Spring | H41: 100 | I41: 95 | J41: 90 | L41: =$BZ$3 -> 91.25 | N41: {=_xlfn.DROP(_xlfn.XLOOKUP($C41,TableLWG2_1[[#Headers],[ACT/NSW]:[WA]],TableLWG2_1[[#All],[ACT/NSW]:[WA]]),1)} -> 0.04 | P41: {=_xlfn.DROP(_xlfn.XLOOKUP($C41,QueryCP[[#Headers],[ACT/NSW]:[WA]],QueryCP[[#All],[ACT/NSW]:[WA]]),1)} -> 0.2 | R41: {=_xlfn.DROP(_xlfn.XLOOKUP($C41,QueryDMD[[#Headers],[ACT/NSW]:[WA]],QueryDMD[[#All],[ACT/NSW]:[WA]]),1)} -> 0.75 | T41: {=_xlfn.DROP(_xlfn.XLOOKUP($C41,QueryW[[#Headers],[ACT/NSW]:[WA]],QueryW[[#All],[ACT/NSW]:[WA]]),1)} -> 54 | U41: =1-V41 -> 0.0045 | V41: =IF($D41="yes", 1, VLOOKUP($B41, $BY$26:$CA$32, 2, FALSE)/100) -> 0.9955 | W41: =VLOOKUP($B41,$CA$10:$CB$16, 2, FALSE) -> 0.75 | X41: =$BZ$10 -> 0.0047 | Y41: =(I41/100)*(MIN(J41,100)/100) -> 0.855 | Z41: 0 | AA41: =1.6 * Z41 -> 0 | AB41: =$CC$1 -> 1.3 | AC41: =Y41*AB41+(1-Y41) -> 1.2565 | AD41: =(0.795*R41)-0.0014 -> 0.59485 | AF41: {=_xlfn.DROP(_xlfn.XLOOKUP($C41,QueryDMA[[#Headers],[ACT/NSW]:[WA]],QueryDMA[[#All],[ACT/NSW]:[WA]]),1)} -> 2.9 | AG41: =1 - EXP(-2*(AF41^2)) -> 0.99999995 | AH41: =(104.7*AD41+0.307*T41-15)*(T41^0.75)*10^-3 -> 1.2720847 | AI41: =AH41*AG41*AC41 -> 1.5983744 | AJ41: =(AI41 * P41) + (0.045 * AA41) -> 0.31967488 | AK41: =$BZ$2 -> 0.08 | AL41: =(AI41 * ((1 - R41) + (0.04 * AI41))) * ( 1 - AK41 ) -> 0.46164277 | AM41: =$BZ$1 -> 0.19 | AN41: =$CA$20 -> 0.6784 | AO41: =AL41 * AM41 * U41 * W41 * AN41 -> 0.00020082569 | AP41: =AL41*AM41*V41*X41*AN41 -> 0.00027840985 | AQ41: =AO41+AP41 -> 0.00047923554 | AR41: =H41*AQ41*L41 -> 4.3730243 | AS41: =SUM(AR41:AR64)*10^-3 -> 0.092374227 | AT41: no | AU41: =IF(AT41="yes", 1,0) -> 0 | AV41: =$BZ$4 -> 0.24 | AW41: Tropical dry | AX41: =VLOOKUP(AW41,$CD$37:$CF$46,2, FALSE) -> 0.002 | AY41: =$BZ$7 -> 1.57 | AZ41: =$BZ$5 -> 0.21 | BA41: 20 | BB41: 0.8 | BC41: =Y41 * 1.6 -> 1.368 | BD41: =(BA41 * BB41) / 365 -> 0.043835616 | BE41: =N41 * 0.92 -> 0.0368 | BF41: {=_xlfn.DROP(_xlfn.XLOOKUP($C41,QuerySRW[[#Headers],[ACT/NSW]:[WA]],QuerySRW[[#All],[ACT/NSW]:[WA]]),1)} -> 57 | BG41: =T41 / BF41 -> 0.94736842 | BH41: =((0.045 * BC41) + (BD41 * 0.84) + (BE41 * ((212 - 4 * ((BE41 * 1000)/(4* (BF41^0.75)) - 1)) - ((140 - 4 * (((BE41 * 1000)/(4 * BF41 ^0.75)) - 1))/(1 + EXP(-6 * (BG41 - 0.4)))))) * 10^-3) / 6.25 -> 0.016195288 | BI41: =MAX((AJ41 / 6.25 ) - BH41, 0) -> 0.034952692 | BJ41: =H41*BI41*L41 -> 318.94332 | BK41: =SUM(BJ41:BJ64) -> 5093.7808 | BL41: =BK41*$AU$11*$AV$11 -> 1222.5074 | BM41: =BK41 * AZ41 -> 1069.694 | BN41: Non-irrigated crop (low rainfall) | BO41: =VLOOKUP(BN41, $BY$37:$BZ$49, 2, FALSE) -> 0.0029 | BP41: =BM41 * BO41 * AY41 * 10^-3 -> 0.0048703166 | BQ41: =BK41 * AU41 * AV41 -> 0 | BR41: =$BZ$6 -> 0.011 | BS41: =BK41 * AX41 * AY41 * 10^-3 -> 0.015994472 | BT41: =BQ41 * BR41 * AY41 * 10^-3 -> 0 | BY41: Non-irrigated crop (high rainfall) | BZ41: 0.008 | CD41: Cool temperate moist | CE41: 0.006 | CF41: wet
...

Sheet Tables
M1: 3.4.1 | N1: 3.4.1 | AC1: 3.4.1 321 | AP1: 3.4.1 | AS1: 3.4.1 | AT1: 3.4.1 | AU1: Ch 3.4.1 | BQ1: 1084 | BR1: Bo | BS1: 0.24 | BU1: FAk | BV1: 1.3
AD2: LEjk=3,4 * 1.6 | AE2: GWk * Yk / 365 | AF2: LWGjk * 0.92 | AH2: Wjk / SRWk | AJ2: 1.6 * PLjk=6 | AK2: ((0.045 * MPjk=3,4) + (WPk * 0.84) + (EBGjk * ((212 - 4 * ((EBGjk * 1000) / (4 * SRWk ^0.75) - 1)) - (140 - 4 * (EBGjk * 1000)) / (1 + e^-6 * (Zjk - 0.4)) * 10^-3) / 6.25 | AL2: (CPIjk ÷ 6.25 ) - NRjk | AV2: (Ijk * CPjk) + (0.045 * MCjk=6) | AX2: (Ijk * ((1 - DMDjk) + (0.04 * Ijk))) * ( 1 - A ) | BA2: VSjk * BO * MMSm * MCFim * 𝜌 | BC2: VSjk * BO * MMSm * MCFim * 𝜌 | BD2: SUM SUM SUM (Njk * Mjkm * Dj) * 10^-3 | BF2: SUM SUM (Njk * NEjk * Dj) | BH2: AE * FracGASMsoil | BI2: AE * FracWet * FracLEACH | BJ2: AE * EFPRP * CN2O * 10^-3 | BK2: Mvol * EFN2O * CN2O * 10^-3 | BL2: Mleach * EFleach * CN2O * 10^-3 | BQ2: 1087 | BR2: A | BS2: 0.08
J3: 1072 | K3: 1073 | L3: 1071 | M3: 342 | N3: 323 | O3: 1075 | P3: 1079 | Q3: 1078 | R3: 1077 | S3: 1081 | U3: 1085 | W3: 1082 | X3: 1092 | Y3: 1094 | Z3: 1095 | AA3: 1093 | AB3: 1091 | AC3: 1004 | AD3: 1003 | AE3: 1011 | AF3: 1017 | AG3: 1089 | AH3: 1021 | AI3: 990 | AJ3: 988 | AK3: 994 | AL3: 978 | AM3: 1090 | AN3: 1088 | AO3: 351 | AP3: 314 | AQ3: 302 | AR3: 349 | AS3: 308 | AT3: 296 | AU3: 946 | AV3: 983 | AW3: 1087 | AX3: 945 | AY3: 1084 | AZ3: 1086 | BA3: 930 | BC3: 930 | BD3: 922 | BF3: 970 | BH3: 1045 | BI3: 1062 | BJ3: 963 | BK3: 1037 | BL3: 1056 | BR3: Dj | BS3: 91.25
J4: input | K4: input | L4: input | O4: constant | P4: constant | Q4: constant | R4: constant | S4: constant | U4: constant | W4: constant | X4: constant | Y4: constant | Z4: constant | AA4: constant | AB4: constant | AC4: constant | AD4: expression | AE4: expression | AF4: expression | AG4: constant | AH4: expression | AI4: expression | AJ4: expression | AK4: expression | AL4: expression | AM4: constant | AN4: constant | AO4: constant | AP4: expression | AQ4: expression | AR4: constant | AS4: expression | AT4: expression | AU4: expression | AV4: expression | AW4: constant | AX4: expression | AY4: constant | AZ4: constant | BA4: expression | BC4: expression | BD4: expression | BF4: expression | BH4: expression | BI4: expression | BJ4: expression | BK4: expression | BL4: expression | BQ4: 1094 | BR4: FracLEACH | BS4: 0.24
O5: input | P5: input | Q5: input | R5: input | S5: input | W5: input | AR5: input | BQ5: 1093 | BR5: FracGASMSoil | BS5: 0.21 | BW5: A.1.4.5 | BX5: LWGjk
BQ6: 1095 | BR6: EFLeach | BS6: 0.011 | BW6: Season | BX6: Class | BY6: ACT/NSW | BZ6: QLD | CA6: SA | CB6: TAS | CC6: VIC | CD6: WA | CE6: SeasonOrder | CH6: Column1 | CI6: Column2 | CJ6: Column3 | CK6: Column4 | CL6: Column5 | CM6: Column6 | CN6: Column7 | CO6: Column8
BQ7: 1088 | BR7: CN2O | BS7: =[1]!common_cn2o -> 1.57 | BW7: Spring | BX7: Breeding ewes | BY7: 0.04 | BZ7: -0.02 | CA7: 0 | CB7: -0.02 | CC7: 0.11 | CD7: 0.05 | CE7: 1 | CH7: State | CI7: Season | CJ7: Rams | CK7: Wethers | CL7: Maiden ewes | CM7: Breeding ewes | CN7: Other ewes | CO7: Lambs and hoggets
J8: kg / head | K8: d | L8: head | O8: days | P8: kg | Q8: d | R8: d | S8: kg | U8: d | W8: d | X8: d | Y8: d | Z8: kg N2O-N / kg N | AA8: kg volatilised N/kg N | AB8: kg N2O-N/kg N | AC8: d | AD8: kg/head/day | AE8: kg/head/day | AF8: kg | AG8: kg | AH8: d | AI8: d | AJ8: kg / head / day | AK8: kg N/head/day | AL8: kg N/head/day | AM8: kg N2O-N/kg N deposited | AN8: d | AU8: kg DM/head/day | AV8: kg/head/day | AW8: d | AX8: kg/head/day | AY8: m3 CH4/kgVS | AZ8: kg/m3 | BA8: kg CH4/head/day | BC8: kg CH4/head/day | BD8: kg CH4 | BF8: kg N | BH8: kg N | BI8: kg N | BJ8: t N2O | BK8: t N2O | BL8: t N2O | BW8: Summer | BX8: Breeding ewes | BY8: -0.05 | BZ8: 0.05 | CA8: 0 | CB8: 0 | CC8: -0.05 | CD8: -0.05 | CE8: 2 | CH8: ACT/NSW | CI8: Spring | CJ8: 0.07 | CK8: 0.08 | CL8: 0.07 | CM8: 0.04 | CN8: 0.05 | CO8: 0.16
J9: greasy wool production per class | K9: average clean wool yield per class | L9: number of sheep in each time period and class | M9: Lambing rate | N9: Lamb marking rate | O9: number of days in each time period | P9: liveweight gain | Q9: crude protein content of feed intake | R9: dry matter digestibility | S9: liveweight | U9: fraction of waste in each MMS | W9: methane conversion factor for temperate zone and MMS | X9: fraction of N that is available for leaching and runoff | Y9: fraction of all N that is lost through leaching and runoff | Z9: emissions factor for leaching and runoff | AA9: fraction of nitrogen volatilised from urine and dung on pasture | AB9: NO2 emission factor for atmospheric deposition | AC9: proportion of ewes lactating each season or time period | AD9: milk production | AE9: clean wool production | AF9: empty body gain | AG9: standard reference weight | AH9: relative size | AI9: Proportion of lambs born in the time period | AJ9: Milk intake | AK9: amount of nitrogen retained by the body | AL9: Nitrogen excreted in each time period | AM9: Emissions factor for nitrous oxide from urine and dung | AN9: Factor to convert elemental mass of NO2 to molecular mass | AU9: dry matter intake | AV9: crude protein intake | AW9: ash content of feed intake | AX9: volatile solid production | AY9: emisions potential | AZ9: density of methane | BA9: methane produced from manure | BC9: methane produced from manure | BD9: annual methane production from manure | BF9: Total mass of nitrogen excreted on PRP | BH9: Mass of nitrogen volatilised | BI9: mass of nitrogen lost ot leaching and runoff | BJ9: annual direct NO2 from soils from deposition of urine and dung | BK9: annual atmospheric deposition emissions from urine and dung on pasture | BL9: Leaching and runoff emissions from urine and dung deposited on pasture | BS9: MCF | BU9: Lagoon | BW9: Autumn | BX9: Breeding ewes | BY9: 0.01 | BZ9: 0 | CA9: 0 | CB9: 0 | CC9: -0.02 | CD9: -0.05 | CE9: 3 | CI9: Summer | CJ9: 0 | CK9: -0.08 | CL9: 0 | CM9: -0.05 | CN9: -0.05 | CO9: 0.08
A10: Scenario | B10: State | C10: State | D10: No unfenced water | E10: Leaching zone | F10: Production system | G10: Climate zone | H10: Class | J10: GWk | K10: Yk | L10: Njk | M10: LR | N10: LMR | O10: Dj | P10: LWGjk | Q10: CPjk | R10: DMDjk | S10: Wjk | T10: MMSm=1 | U10: MMSm=14 | V10: MCFim=1 | W10: MCFim=14 | X10: FracWet | Y10: FracLEACH | Z10: EFleach | AA10: FracGASMsoil | AB10: EFN2O | AC10: LEjk=3,4 | AD10: MPjk=3,4 | AE10: WPk | AF10: EBGjk | AG10: SRWk | AH10: Zjk | AI10: PLjk=6 | AJ10: MCjk=6 | AK10: NRjk | AL10: NEjk | AM10: EFPRP | AN10: CN2O | AO10: FAk | AP10: MAjk | AQ10: qmjk | AR10: DMAjk | AS10: RIjk | AT10: PIjk | AU10: Ijk | AV10: CPIjk | AW10: A | AX10: VSjk | AY10: BO | AZ10: 𝜌 | BA10: Mjkm=1 | BB10: Mjkm=14 | BC10: Mjk | BD10: ECH4 | BE10: ECH4 | BF10: AE | BG10: AE | BH10: Mvol | BI10: Mleach | BJ10: EN2O,dir | BK10: EN2O,ad | BL10: ESN2O,leach | BR10: PRP | BS10: 0.0047 | BT10: ACT | BU10: 0.72 | BW10: Winter | BX10: Breeding ewes | BY10: 0 | BZ10: -0.03 | CA10: 0 | CB10: 0.02 | CC10: -0.03 | CD10: 0.05 | CE10: 4 | CI10: Autumn | CJ10: -0.07 | CK10: 0 | CL10: 0 | CM10: 0.01 | CN10: -0.01 | CO10: 0.05
A11: Baseline | B11: ACT | C11: ACT/NSW | D11: yes | E11: yes | F11: Irrigated pasture | G11: wet | H11: Breeding ewes | I11: Spring | J11: 4 | K11: 0.65 | L11: 100 | M11: 95 | N11: 90 | O11: =$BS$3 -> 91.25 | P11: {=_xlfn.DROP(_xlfn.XLOOKUP($C11,TableLWG2_1[[#Headers],[ACT/NSW]:[WA]],TableLWG2_1[[#All],[ACT/NSW]:[WA]]),1)} -> 0.04 | Q11: {=_xlfn.DROP(_xlfn.XLOOKUP($C11,QueryCP[[#Headers],[ACT/NSW]:[WA]],QueryCP[[#All],[ACT/NSW]:[WA]]),1)} -> 0.2 | R11: {=_xlfn.DROP(_xlfn.XLOOKUP($C11,QueryDMD[[#Headers],[ACT/NSW]:[WA]],QueryDMD[[#All],[ACT/NSW]:[WA]]),1)} -> 0.75 | S11: {=_xlfn.DROP(_xlfn.XLOOKUP($C11,QueryW[[#Headers],[ACT/NSW]:[WA]],QueryW[[#All],[ACT/NSW]:[WA]]),1)} -> 54 | T11: =1-U11 -> 0 | U11: =IF($D$11="yes", 1, VLOOKUP(B11, $BR$26:$BT$32, 1)) -> 1 | V11: =VLOOKUP($B$11,$BT$10:$BU$16, 2, FALSE) -> 0.72 | W11: =$BS$10 -> 0.0047 | X11: =IF(E11="yes",1,0) -> 1 | Y11: =$BS$4 -> 0.24 | Z11: =$BS$6 -> 0.011 | AA11: =$BS$5 -> 0.21 | AB11: =VLOOKUP($F$11,$BR$37:$BS$49,2,FALSE) -> 0.0059 | AC11: =(M11/100)*(MIN(N11,100)/100) -> 0.855 | AD11: =AC11 * 1.6 -> 1.368 | AE11: =J11 * K11 / 365 -> 0.0071232877 | AF11: =P11 * 0.92 -> 0.0368 | AG11: {=_xlfn.DROP(_xlfn.XLOOKUP($C11,QuerySRW[[#Headers],[ACT/NSW]:[WA]],QuerySRW[[#All],[ACT/NSW]:[WA]]),1)} -> 57 | AH11: =S11 / AG11 -> 0.94736842 | AI11: 0 | AJ11: =1.6 * AI11 -> 0 | AK11: =(0.045*AD11+AE11*0.84+ (AF11* ( (212 - 4*(AF11*1000/(4*AG11^0.75)-1))-((140 - 4 * (AF11*1000/(4*AG11^0.75)-1))/(1+EXP(-6*(AH11-0.4)))) ) )*10^-3 )/6.25 -> 0.011261151 | AL11: =(AV11 / 6.25 ) - AK11 -> 0.039886829 | AM11: =IF($G$11="wet",$BU$18,$BU$19) -> 0.006 | AN11: =$BS$7 -> 1.57 | AO11: =$BV$1 -> 1.3 | AP11: =AC11*AO11+(1-AC11) -> 1.2565 | AQ11: =(0.795*R11)-0.0014 -> 0.59485 | AR11: {=_xlfn.DROP(_xlfn.XLOOKUP($C11,QueryDMA[[#Headers],[ACT/NSW]:[WA]],QueryDMA[[#All],[ACT/NSW]:[WA]]),1)} -> 2.9 | AS11: =1 - EXP(-2*(AR11^2)) -> 0.99999995 | AT11: =(104.7*AQ11+0.307*S11-15)*(S11^0.75)*10^-3 -> 1.2720847 | AU11: =AT11*AS11*AP11 -> 1.5983744 | AV11: =(AU11 * Q11) + (0.045 * AJ11) -> 0.31967488 | AW11: =$BS$2 -> 0.08 | AX11: =(AU11 * ((1 - R11) + (0.04 * AU11))) * ( 1 - AW11 ) -> 0.46164277 | AY11: =$BS$1 -> 0.24 | AZ11: =$BT$20 -> 0.6784 | BA11: =AX11 * AY11 * T11 * V11 * AZ11 -> 0 | BB11: =AX11*AY11*U11*W11*AZ11 -> 0.0003532653 | BC11: =BA11+BB11 -> 0.0003532653 | BD11: =L11*BC11*O11 -> 3.2235459 | BE11: =SUM(BD11:BD34)*10^-3 -> 0.068147172 | BF11: =L11*AL11*O11 -> 363.96732 | BG11: =SUM(BF11:BF34) -> 6371.2697 | BH11: =BF11 * AA11 -> 76.433136 | BI11: =BF11 * X11 * Y11 -> 87.352156 | BJ11: =BF11 * AM11 * AN11 * 10^-3 -> 0.0034285721 | BK11: =BH11 * AB11 * AN11 * 10^-3 -> 0.00070800014 | BL11: =BI11 * Z11 * AN11 * 10^-3 -> 0.0015085717 | BT11: NSW | BU11: 0.75 | BW11: Spring | BX11: Lambs and hoggets | BY11: 0.16 | BZ11: 0.2 | CA11: 0.11 | CB11: 0.15 | CC11: 0.15 | CD11: 0.11 | CE11: 1 | CI11: Winter | CJ11: 0 | CK11: 0 | CL11: 0.02 | CM11: 0 | CN11: 0.01 | CO11: 0.04
I12: Summer | J12: =J11 -> 4 | K12: =K11 -> 0.65 | L12: 70 | M12: 0 | N12: 0 | O12: =$BS$3 -> 91.25 | P12: -0.05 | Q12: 0.1 | R12: 0.61 | S12: 49 | T12: =1-U12 -> 0 | U12: =IF($D$11="yes", 1, VLOOKUP(B12, $BR$26:$BT$32, 1)) -> 1 | V12: =VLOOKUP($B$11,$BT$10:$BU$16, 2, FALSE) -> 0.72 | W12: =$BS$10 -> 0.0047 | X12: =IF(E12="yes",1,0) -> 0 | Y12: =$BS$4 -> 0.24 | Z12: =$BS$6 -> 0.011 | AA12: =$BS$5 -> 0.21 | AB12: =VLOOKUP($F$11,$BR$37:$BS$49,2,FALSE) -> 0.0059 | AC12: =(M12/100)*(MIN(N12,100)/100) -> 0 | AD12: =AC12 * 1.6 -> 0 | AE12: =J12 * K12 / 365 -> 0.0071232877 | AF12: =P12 * 0.92 -> -0.046 | AG12: 57 | AH12: =S12 / AG12 -> 0.85964912 | AI12: 0 | AJ12: =1.6 * AI12 -> 0 | AK12: =(0.045*AD12+AE12*0.84+ (AF12* ( (212 - 4*(AF12*1000/(4*AG12^0.75)-1))-((140 - 4 * (AF12*1000/(4*AG12^0.75)-1))/(1+EXP(-6*(AH12-0.4)))) ) )*10^-3 )/6.25 -> 0.00036326515 | AL12: =(AV12 / 6.25 ) - AK12 -> 0.014651626 | AM12: =IF($G$11="wet",$BU$18,$BU$19) -> 0.006 | AN12: =$BS$7 -> 1.57 | AO12: =$BV$1 -> 1.3 | AP12: =AC12*AO12+(1-AC12) -> 1 | AQ12: =(0.795*R12)-0.0014 -> 0.48355 | AR12: 2.5 | AS12: =1 - EXP(-2*(AR12^2)) -> 0.99999627 | AT12: =(104.7*AQ12+0.307*S12-15)*(S12^0.75)*10^-3 -> 0.93843422 | AU12: =AT12*AS12*AP12 -> 0.93843072 | AV12: =(AU12 * Q12) + (0.045 * AJ12) -> 0.093843072 | AW12: =$BS$2 -> 0.08 | AX12: =(AU12 * ((1 - R12) + (0.04 * AU12))) * ( 1 - AW12 ) -> 0.36911694 | AY12: =$BS$1 -> 0.24 | AZ12: =$BT$20 -> 0.6784 | BA12: =AX12 * AY12 * T12 * V12 * AZ12 -> 0 | BB12: =AX12*AY12*U12*W12*AZ12 -> 0.00028246128 | BC12: =BA12+BB12 -> 0.00028246128 | BD12: =L12*BC12*O12 -> 1.8042214 | BF12: =L12*AL12*O12 -> 93.587264 | BT12: QLD | BU12: 0.78 | BW12: Summer | BX12: Lambs and hoggets | BY12: 0.08 | BZ12: 0.05 | CA12: 0.05 | CB12: 0.11 | CC12: 0.07 | CD12: 0 | CE12: 2 | CH12: Queensland | CI12: Spring | CJ12: -0.02 | CK12: 0 | CL12: 0 | CM12: -0.02 | CN12: -0.03 | CO12: 0.2
I13: Autumn | J13: =J12 -> 4 | K13: =K11 -> 0.65 | L13: 65 | M13: 0 | N13: 0 | O13: =$BS$3 -> 91.25 | P13: 0.01 | Q13: 0.12 | R13: 0.64 | S13: 50 | T13: =1-U13 -> 0 | U13: =IF($D$11="yes", 1, VLOOKUP(B13, $BR$26:$BT$32, 1)) -> 1 | V13: =VLOOKUP($B$11,$BT$10:$BU$16, 2, FALSE) -> 0.72 | W13: =$BS$10 -> 0.0047 | X13: =IF(E13="yes",1,0) -> 0 | Y13: =$BS$4 -> 0.24 | Z13: =$BS$6 -> 0.011 | AA13: =$BS$5 -> 0.21 | AB13: =VLOOKUP($F$11,$BR$37:$BS$49,2,FALSE) -> 0.0059 | AC13: =(M13/100)*(MIN(N13,100)/100) -> 0 | AD13: =AC13 * 1.6 -> 0 | AE13: =J13 * K13 / 365 -> 0.0071232877 | AF13: =P13 * 0.92 -> 0.0092 | AG13: 57 | AH13: =S13 / AG13 -> 0.87719298 | AI13: 0 | AJ13: =1.6 * AI13 -> 0 | AK13: =(0.045*AD13+AE13*0.84+ (AF13* ( (212 - 4*(AF13*1000/(4*AG13^0.75)-1))-((140 - 4 * (AF13*1000/(4*AG13^0.75)-1))/(1+EXP(-6*(AH13-0.4)))) ) )*10^-3 )/6.25 -> 0.001074766 | AL13: =(AV13 / 6.25 ) - AK13 -> 0.018115217 | AM13: =IF($G$11="wet",$BU$18,$BU$19) -> 0.006 | AN13: =$BS$7 -> 1.57 | AO13: =$BV$1 -> 1.3 | AP13: =AC13*AO13+(1-AC13) -> 1 | AQ13: =(0.795*R13)-0.0014 -> 0.5074 | AR13: 1.6 | AS13: =1 - EXP(-2*(AR13^2)) -> 0.99402398 | AT13: =(104.7*AQ13+0.307*S13-15)*(S13^0.75)*10^-3 -> 1.0054871 | AU13: =AT13*AS13*AP13 -> 0.9994783 | AV13: =(AU13 * Q13) + (0.045 * AJ13) -> 0.1199374 | AW13: =$BS$2 -> 0.08 | AX13: =(AU13 * ((1 - R13) + (0.04 * AU13))) * ( 1 - AW13 ) -> 0.36778883 | AY13: =$BS$1 -> 0.24 | AZ13: =$BT$20 -> 0.6784 | BA13: =AX13 * AY13 * T13 * V13 * AZ13 -> 0 | BB13: =AX13*AY13*U13*W13*AZ13 -> 0.00028144496 | BC13: =BA13+BB13 -> 0.00028144496 | BD13: =L13*BC13*O13 -> 1.6693204 | BF13: =L13*AL13*O13 -> 107.44588 | BT13: SA | BU13: 0.74 | BW13: Autumn | BX13: Lambs and hoggets | BY13: 0.05 | BZ13: 0.2 | CA13: 0.16 | CB13: 0.13 | CC13: 0.05 | CD13: 0.11 | CE13: 3 | CI13: Summer | CJ13: 0.03 | CK13: 0.05 | CL13: 0.05 | CM13: 0.05 | CN13: 0.05 | CO13: 0.05
