Workbook

Sheet 4.6.1.1
A2: Method 1
A4: input | C4: input | D4: input | E4: input | F4: input | G4: input | H4: input | I4: constant | K4: constant | L4: constant | M4: input | N4: input | O4: input | P4: input | AF4: expression | AG4: constant | AH4: constant | AI4: constant | AO4: constant | AP4: expression | AU4: partial | AZ4: partial | BA4: constant | BF4: partial | BG4: expression | BL4: expression | BQ4: partial | BT4: expression
AF5: 4.6.1.1 (5) | AP5: 4.6.1.1 (2)
AP6: 𝑀𝑗𝑘𝑚 𝑇=1 = 𝑉𝑆𝑗𝑘 × 𝐵𝑜𝑗 × 𝑀𝑀𝑆𝑗𝑚 𝑇=1 × 𝑀𝐶𝐹𝑖𝑚 × 𝜌 | BD6: 𝑉𝑆𝑇𝑖𝑗𝑚𝑇=2 = 𝑉𝑆𝑗𝑘 × 𝑀𝑀𝑆𝑗𝑚𝑇=1 × ( 1 − 𝑉𝑆𝐿𝑚𝑇=1) | BH6: 𝑉𝑆𝑇𝑗𝑘 × 𝐵𝑂 × 𝑀𝑀𝑆𝑗𝑚𝑇=2 × 𝑀𝐶𝐹𝑖𝑚 × 𝜌 | BT6: ∑ ∑ ∑ ∑ (𝐷𝑗𝑘 × 𝑀𝑗𝑘𝑚𝑇 × 𝑁𝑗𝑘) × 10−3
A8: State | B8: MAT | C8: Production system | D8: Climate Zone | E8: Leaching zone | F8: Poultry class/subclass | G8: Number of poultry in each class j and subclass k | H8: Duration of stay for each class and subclass of poultry | I8: Dry Matter Intake | J8: Dry Matter Digestibility | K8: Crude Protein | L8: Nitrogen Retention Rate | M8: Allocation (stage 1) | N8: Allocation (stage 1) | Q8: Allocation (stage 2) FROM m=10 | V8: Allocation (stage 2) FROM m=11a | AA8: Allocation (stage 2) | AF8: Volatile Solids | AG8: Ash Content | AH8: Emissions Potential
A10: i | B10: i | D10: (wet or dry) | E10: (true or false) | F10: jk | G10: Njk | H10: Djk | I10: Ijk | J10: DMDjk | K10: CPjk | L10: NRjk | M10: MMSjm=10T=1 | N10: MMSjm=11aT=1 | O10: MMSjm=11bT=1 | P10: MMSjm=14T=1 | Q10: MMSm=4T=2 | R10: MMSm=6T=2 | S10: MMSm=7T=2 | T10: MMSm=12T=2 | U10: MMSm=13T=2 | V10: MMSm=4T=2 | W10: MMSm=6T=2 | X10: MMSm=7T=2 | Y10: MMSm=12T=2 | Z10: MMSm=13T=2 | AA10: MMSm=4T=2 | AB10: MMSm=6T=2 | AC10: MMSm=7T=2 | AD10: MMSm=12T=2 | AE10: MMSm=13T=2 | AF10: VSjk | AG10: Ajk | AH10: Boj | AI10: MCFim=10 | AJ10: MCFim=11a | AK10: MCFim=11b | AL10: MCFim=14 | AM10: Mjm=10T=1 | AN10: Mjm=11aT=1 | AO10: Mjm=11bT=1 | AP10: Mjm=14T=1 | AQ10: ECH4jm=10 | AR10: ECH4jm=11a | AS10: ECH4jm=11b | AT10: ECH4jm=14 | AU10: ECH4jm (T=1) | AV10: MCFim=4 | AW10: MCFim=6 | AX10: MCFim=7 | AY10: MCFim=12 | AZ10: MCFim=13 | BA10: VSLm=10T=1 | BB10: VSLm=11aT=1 | BC10: VSLm=11bT=1 | BD10: VSTjm=10T=2 | BE10: VSTjm=11aT=2 | BF10: VSTjm=11bT=2 | BG10: VSTj | BH10: Mjm=4T=2 | BI10: Mjm=6T=2 | BJ10: Mjm=7T=2 | BK10: Mjm=12T=2 | BL10: Mjm=13T=2 | BM10: ECH4 (j) m=4 | BN10: ECH4 (j) m=6 | BO10: ECH4 (j) m=7 | BP10: ECH4 (j) m=12 | BQ10: ECH4 (j) m=13 | BR10: ECH4jm (T=2) | BS10: ECH4j | BT10: ECH4
A11: ='Input Scenarios'!A8 -> NSW | B11: ='Input Scenarios'!B8 -> 0 | C11: ='Input Scenarios'!C8 -> Non-irrigated pasture | D11: ='Input Scenarios'!D8 -> wet | E11: ='Input Scenarios'!E8 -> TRUE | F11: ='Input Scenarios'!F8 -> layers | G11: ='Input Scenarios'!G8 -> 5000 | H11: ='Input Scenarios'!H8 -> 50 | I11: =IF('Input Scenarios'!I8<>"", 'Input Scenarios'!I8,_xlfn.XLOOKUP($F11,Constants!$A$2:$A$5,Constants!B$2:B$5)) -> 0.086 | J11: =IF('Input Scenarios'!J8<>"", 'Input Scenarios'!J8,_xlfn.XLOOKUP($F11,Constants!$A$2:$A$5,Constants!C$2:C$5)) -> 0.8 | K11: =IF('Input Scenarios'!K8<>"", 'Input Scenarios'!K8,_xlfn.XLOOKUP($F11,Constants!$A$2:$A$5,Constants!D$2:D$5)) -> 0.19 | L11: =IF('Input Scenarios'!L8<>"", 'Input Scenarios'!L8,_xlfn.XLOOKUP($F11,Constants!$A$2:$A$5,Constants!E$2:E$5)) -> 0.35 | M11: ='Input Scenarios'!M8 -> 0.1 | N11: ='Input Scenarios'!N8 -> 0.2 | O11: ='Input Scenarios'!O8 -> 0.3 | P11: ='Input Scenarios'!P8 -> 0.4 | Q11: ='Input Scenarios'!Q8 -> 0.15 | R11: ='Input Scenarios'!R8 -> 0.2 | S11: ='Input Scenarios'!S8 -> 0.25 | T11: ='Input Scenarios'!T8 -> 0.17 | ... AE11: ='Input Scenarios'!AE8 -> 0.23 | AF11: =I11*(1-J11)*(1-AG11) -> 0.014104 | AG11: =IF(F11="", "",_xlfn.XLOOKUP(F11,Constants!$A$2:$A$5,Constants!F$2:F$5)) -> 0.18 | AH11: =IF(F11="", "",_xlfn.XLOOKUP(F11,Constants!$A$2:$A$5,Constants!G$2:G$5)) -> 0.39 | AI11: =_xlfn.XLOOKUP($A11, Constants!$F$8:$M$8,Constants!$F$9:$M$9) -> 0.015 | AJ11: =_xlfn.XLOOKUP($A11, Constants!$F$8:$M$8,Constants!$F$10:$M$10) -> 0.015 | AK11: =_xlfn.XLOOKUP($A11, Constants!$F$8:$M$8,Constants!$F$11:$M$11) -> 0.015 | AL11: =_xlfn.XLOOKUP($A11, Constants!$F$8:$M$8,Constants!$F$16:$M$16) -> 0.01 | AM11: =$AF11*$AH11*M11*AI11*Constants!$I$2 -> 5.5973699e-06 | AN11: =$AF11*$AH11*N11*AJ11*Constants!$I$2 -> 1.119474e-05 | AO11: =$AF11*$AH11*O11*AK11*Constants!$I$2 -> 1.679211e-05 | AP11: =$AF11*$AH11*P11*AL11*Constants!$I$2 -> 1.492632e-05 | AQ11: =AM11*$G11*$H11 -> 1.3993425 | AR11: =AN11*$G11*$H11 -> 2.7986849 | AS11: =AO11*$G11*$H11 -> 4.1980274 | AT11: =AP11*$G11*$H11 -> 3.7315799 | AU11: =SUM(AQ11:AT11) -> 12.127635 | AV11: =_xlfn.XLOOKUP($A11, Constants!$F$8:$M$8,Constants!$F$12:$M$12) -> 0.02 | AW11: =_xlfn.XLOOKUP($A11, Constants!$F$8:$M$8,Constants!$F$13:$M$13) -> 0.01 | AX11: =_xlfn.XLOOKUP($A11, Constants!$F$8:$M$8,Constants!$F$15:$M$15) -> 0.1 | AY11: =_xlfn.XLOOKUP($A11, Constants!$F$8:$M$8,Constants!$F$14:$M$14) -> 0 | AZ11: =_xlfn.XLOOKUP($A11, Constants!$F$8:$M$8,Constants!$F$17:$M$17) -> 0 | BA11: =Constants!$E$9 -> 0.15 | BB11: =Constants!$E$10 -> 0 | BC11: =Constants!$E$11 -> 0.2 | BD11: =$AF11*M11*(1-BA11) -> 0.00119884 | BE11: =$AF11*N11*(1-BB11) -> 0.0028208 | BF11: =$AF11*O11*(1-BC11) -> 0.00338496 | BG11: =SUM(BD11:BF11) -> 0.0074046 | BH11: =(($BD11*Q11)+($BE11*V11)+($BF11*AA11))*AV11*$AH11*Constants!$I$2 -> 5.8772383e-06 | BI11: =(($BD11*R11)+($BE11*W11)+($BF11*AB11))*AW11*$AH11*Constants!$I$2 -> 3.9181589e-06 | BJ11: =(($BD11*S11)+($BE11*X11)+($BF11*AC11))*AX11*$AH11*Constants!$I$2 -> 4.8976986e-05 | BK11: =(($BD11*T11)+($BE11*Y11)+($BF11*AD11))*AY11*$AH11*Constants!$I$2 -> 0 | BL11: =(($BD11*U11)+($BE11*Z11)+($BF11*AE11))*AZ11*$AH11*Constants!$I$2 -> 0 | BM11: =$G11*$H11*BH11 -> 1.4693096 | BN11: =$G11*$H11*BI11 -> 0.97953972 | BO11: =$G11*$H11*BJ11 -> 12.244247 | BP11: =$G11*$H11*BK11 -> 0 | BQ11: =$G11*$H11*BL11 -> 0 | BR11: =SUM(BM11:BQ11) -> 14.693096 | BS11: =AU11+BR11 -> 26.820731 | BT11: =SUM(BS11:BS14)/1000 -> 0.11197675
A12: ='Input Scenarios'!A9 -> NSW | B12: ='Input Scenarios'!B9 -> 0 | C12: ='Input Scenarios'!C9 -> Non-irrigated pasture | D12: ='Input Scenarios'!D9 -> wet | E12: ='Input Scenarios'!E9 -> TRUE | F12: ='Input Scenarios'!F9 -> meatChickenBreeder | G12: ='Input Scenarios'!G9 -> 5000 | H12: ='Input Scenarios'!H9 -> 50 | I12: =IF('Input Scenarios'!I9<>"", 'Input Scenarios'!I9,_xlfn.XLOOKUP($F12,Constants!$A$2:$A$5,Constants!B$2:B$5)) -> 0.103 | J12: =IF('Input Scenarios'!J9<>"", 'Input Scenarios'!J9,_xlfn.XLOOKUP($F12,Constants!$A$2:$A$5,Constants!C$2:C$5)) -> 0.8 | K12: =IF('Input Scenarios'!K9<>"", 'Input Scenarios'!K9,_xlfn.XLOOKUP($F12,Constants!$A$2:$A$5,Constants!D$2:D$5)) -> 0.19 | L12: =IF('Input Scenarios'!L9<>"", 'Input Scenarios'!L9,_xlfn.XLOOKUP($F12,Constants!$A$2:$A$5,Constants!E$2:E$5)) -> 0.32 | M12: ='Input Scenarios'!M9 -> 0.1 | N12: ='Input Scenarios'!N9 -> 0.2 | O12: ='Input Scenarios'!O9 -> 0.3 | P12: ='Input Scenarios'!P9 -> 0.4 | Q12: ='Input Scenarios'!Q9 -> 0.15 | R12: ='Input Scenarios'!R9 -> 0.2 | S12: ='Input Scenarios'!S9 -> 0.25 | T12: ='Input Scenarios'!T9 -> 0.17 | ... AE12: ='Input Scenarios'!AE9 -> 0.23 | AF12: =I12*(1-J12)*(1-AG12) -> 0.016892 | AG12: =IF(F12="", "",_xlfn.XLOOKUP(F12,Constants!$A$2:$A$5,Constants!F$2:F$5)) -> 0.18 | AH12: =IF(F12="", "",_xlfn.XLOOKUP(F12,Constants!$A$2:$A$5,Constants!G$2:G$5)) -> 0.36 | AI12: =_xlfn.XLOOKUP($A12, Constants!$F$8:$M$8,Constants!$F$9:$M$9) -> 0.015 | AJ12: =_xlfn.XLOOKUP($A12, Constants!$F$8:$M$8,Constants!$F$10:$M$10) -> 0.015 | AK12: =_xlfn.XLOOKUP($A12, Constants!$F$8:$M$8,Constants!$F$11:$M$11) -> 0.015 | AL12: =_xlfn.XLOOKUP($A12, Constants!$F$8:$M$8,Constants!$F$16:$M$16) -> 0.01 | AM12: =$AF12*$AH12*M12*AI12*Constants!$I$2 -> 6.1881477e-06 | AN12: =$AF12*$AH12*N12*AJ12*Constants!$I$2 -> 1.2376295e-05 | AO12: =$AF12*$AH12*O12*AK12*Constants!$I$2 -> 1.8564443e-05 | AP12: =$AF12*$AH12*P12*AL12*Constants!$I$2 -> 1.6501727e-05 | AQ12: =AM12*$G12*$H12 -> 1.5470369 | AR12: =AN12*$G12*$H12 -> 3.0940739 | AS12: =AO12*$G12*$H12 -> 4.6411108 | AT12: =AP12*$G12*$H12 -> 4.1254318 | AU12: =SUM(AQ12:AT12) -> 13.407653 | AV12: =_xlfn.XLOOKUP($A12, Constants!$F$8:$M$8,Constants!$F$12:$M$12) -> 0.02 | AW12: =_xlfn.XLOOKUP($A12, Constants!$F$8:$M$8,Constants!$F$13:$M$13) -> 0.01 | AX12: =_xlfn.XLOOKUP($A12, Constants!$F$8:$M$8,Constants!$F$15:$M$15) -> 0.1 | AY12: =_xlfn.XLOOKUP($A12, Constants!$F$8:$M$8,Constants!$F$14:$M$14) -> 0 | AZ12: =_xlfn.XLOOKUP($A12, Constants!$F$8:$M$8,Constants!$F$17:$M$17) -> 0 | BA12: =Constants!$E$9 -> 0.15 | BB12: =Constants!$E$10 -> 0 | BC12: =Constants!$E$11 -> 0.2 | BD12: =$AF12*M12*(1-BA12) -> 0.00143582 | BE12: =$AF12*N12*(1-BB12) -> 0.0033784 | BF12: =$AF12*O12*(1-BC12) -> 0.00405408 | BG12: =SUM(BD12:BF12) -> 0.0088683 | BH12: =(($BD12*Q12)+($BE12*V12)+($BF12*AA12))*AV12*$AH12*Constants!$I$2 -> 6.4975551e-06 | BI12: =(($BD12*R12)+($BE12*W12)+($BF12*AB12))*AW12*$AH12*Constants!$I$2 -> 4.3317034e-06 | BJ12: =(($BD12*S12)+($BE12*X12)+($BF12*AC12))*AX12*$AH12*Constants!$I$2 -> 5.4146292e-05 | BK12: =(($BD12*T12)+($BE12*Y12)+($BF12*AD12))*AY12*$AH12*Constants!$I$2 -> 0 | BL12: =(($BD12*U12)+($BE12*Z12)+($BF12*AE12))*AZ12*$AH12*Constants!$I$2 -> 0 | BM12: =$G12*$H12*BH12 -> 1.6243888 | BN12: =$G12*$H12*BI12 -> 1.0829258 | BO12: =$G12*$H12*BJ12 -> 13.536573 | BP12: =$G12*$H12*BK12 -> 0 | BQ12: =$G12*$H12*BL12 -> 0 | BR12: =SUM(BM12:BQ12) -> 16.243888 | BS12: =AU12+BR12 -> 29.651541
A13: ='Input Scenarios'!A10 -> NSW | B13: ='Input Scenarios'!B10 -> 0 | C13: ='Input Scenarios'!C10 -> Non-irrigated pasture | D13: ='Input Scenarios'!D10 -> wet | E13: ='Input Scenarios'!E10 -> TRUE | F13: ='Input Scenarios'!F10 -> meatChickenGrowers | G13: ='Input Scenarios'!G10 -> 5000 | H13: ='Input Scenarios'!H10 -> 50 | I13: =IF('Input Scenarios'!I10<>"", 'Input Scenarios'!I10,_xlfn.XLOOKUP($F13,Constants!$A$2:$A$5,Constants!B$2:B$5)) -> 0.093 | J13: =IF('Input Scenarios'!J10<>"", 'Input Scenarios'!J10,_xlfn.XLOOKUP($F13,Constants!$A$2:$A$5,Constants!C$2:C$5)) -> 0.8 | K13: =IF('Input Scenarios'!K10<>"", 'Input Scenarios'!K10,_xlfn.XLOOKUP($F13,Constants!$A$2:$A$5,Constants!D$2:D$5)) -> 0.23 | L13: =IF('Input Scenarios'!L10<>"", 'Input Scenarios'!L10,_xlfn.XLOOKUP($F13,Constants!$A$2:$A$5,Constants!E$2:E$5)) -> 0.47 | M13: ='Input Scenarios'!M10 -> 0.1 | N13: ='Input Scenarios'!N10 -> 0.2 | O13: ='Input Scenarios'!O10 -> 0.3 | P13: ='Input Scenarios'!P10 -> 0.4 | Q13: ='Input Scenarios'!Q10 -> 0.15 | R13: ='Input Scenarios'!R10 -> 0.2 | S13: ='Input Scenarios'!S10 -> 0.25 | T13: ='Input Scenarios'!T10 -> 0.17 | ... AE13: ='Input Scenarios'!AE10 -> 0.23 | AF13: =I13*(1-J13)*(1-AG13) -> 0.01581 | AG13: =IF(F13="", "",_xlfn.XLOOKUP(F13,Constants!$A$2:$A$5,Constants!F$2:F$5)) -> 0.15 | AH13: =IF(F13="", "",_xlfn.XLOOKUP(F13,Constants!$A$2:$A$5,Constants!G$2:G$5)) -> 0.36 | AI13: =_xlfn.XLOOKUP($A13, Constants!$F$8:$M$8,Constants!$F$9:$M$9) -> 0.015 | AJ13: =_xlfn.XLOOKUP($A13, Constants!$F$8:$M$8,Constants!$F$10:$M$10) -> 0.015 | AK13: =_xlfn.XLOOKUP($A13, Constants!$F$8:$M$8,Constants!$F$11:$M$11) -> 0.015 | AL13: =_xlfn.XLOOKUP($A13, Constants!$F$8:$M$8,Constants!$F$16:$M$16) -> 0.01 | AM13: =$AF13*$AH13*M13*AI13*Constants!$I$2 -> 5.7917722e-06 | AN13: =$AF13*$AH13*N13*AJ13*Constants!$I$2 -> 1.1583544e-05 | AO13: =$AF13*$AH13*O13*AK13*Constants!$I$2 -> 1.7375316e-05 | AP13: =$AF13*$AH13*P13*AL13*Constants!$I$2 -> 1.5444726e-05 | AQ13: =AM13*$G13*$H13 -> 1.447943 | AR13: =AN13*$G13*$H13 -> 2.8958861 | AS13: =AO13*$G13*$H13 -> 4.3438291 | AT13: =AP13*$G13*$H13 -> 3.8611814 | AU13: =SUM(AQ13:AT13) -> 12.54884 | AV13: =_xlfn.XLOOKUP($A13, Constants!$F$8:$M$8,Constants!$F$12:$M$12) -> 0.02 | AW13: =_xlfn.XLOOKUP($A13, Constants!$F$8:$M$8,Constants!$F$13:$M$13) -> 0.01 | AX13: =_xlfn.XLOOKUP($A13, Constants!$F$8:$M$8,Constants!$F$15:$M$15) -> 0.1 | AY13: =_xlfn.XLOOKUP($A13, Constants!$F$8:$M$8,Constants!$F$14:$M$14) -> 0 | AZ13: =_xlfn.XLOOKUP($A13, Constants!$F$8:$M$8,Constants!$F$17:$M$17) -> 0 | BA13: =Constants!$E$9 -> 0.15 | BB13: =Constants!$E$10 -> 0 | BC13: =Constants!$E$11 -> 0.2 | BD13: =$AF13*M13*(1-BA13) -> 0.00134385 | BE13: =$AF13*N13*(1-BB13) -> 0.003162 | BF13: =$AF13*O13*(1-BC13) -> 0.0037944 | BG13: =SUM(BD13:BF13) -> 0.00830025 | BH13: =(($BD13*Q13)+($BE13*V13)+($BF13*AA13))*AV13*$AH13*Constants!$I$2 -> 6.0813608e-06 | BI13: =(($BD13*R13)+($BE13*W13)+($BF13*AB13))*AW13*$AH13*Constants!$I$2 -> 4.0542405e-06 | BJ13: =(($BD13*S13)+($BE13*X13)+($BF13*AC13))*AX13*$AH13*Constants!$I$2 -> 5.0678006e-05 | BK13: =(($BD13*T13)+($BE13*Y13)+($BF13*AD13))*AY13*$AH13*Constants!$I$2 -> 0 | BL13: =(($BD13*U13)+($BE13*Z13)+($BF13*AE13))*AZ13*$AH13*Constants!$I$2 -> 0 | BM13: =$G13*$H13*BH13 -> 1.5203402 | BN13: =$G13*$H13*BI13 -> 1.0135601 | BO13: =$G13*$H13*BJ13 -> 12.669502 | BP13: =$G13*$H13*BK13 -> 0 | BQ13: =$G13*$H13*BL13 -> 0 | BR13: =SUM(BM13:BQ13) -> 15.203402 | BS13: =AU13+BR13 -> 27.752242
A14: ='Input Scenarios'!A11 -> NSW | B14: ='Input Scenarios'!B11 -> 0 | C14: ='Input Scenarios'!C11 -> Non-irrigated pasture | D14: ='Input Scenarios'!D11 -> wet | E14: ='Input Scenarios'!E11 -> TRUE | F14: ='Input Scenarios'!F11 -> meatOther | G14: ='Input Scenarios'!G11 -> 5000 | H14: ='Input Scenarios'!H11 -> 50 | I14: =IF('Input Scenarios'!I11<>"", 'Input Scenarios'!I11,_xlfn.XLOOKUP($F14,Constants!$A$2:$A$5,Constants!B$2:B$5)) -> 0.093 | J14: =IF('Input Scenarios'!J11<>"", 'Input Scenarios'!J11,_xlfn.XLOOKUP($F14,Constants!$A$2:$A$5,Constants!C$2:C$5)) -> 0.8 | K14: =IF('Input Scenarios'!K11<>"", 'Input Scenarios'!K11,_xlfn.XLOOKUP($F14,Constants!$A$2:$A$5,Constants!D$2:D$5)) -> 0.23 | L14: =IF('Input Scenarios'!L11<>"", 'Input Scenarios'!L11,_xlfn.XLOOKUP($F14,Constants!$A$2:$A$5,Constants!E$2:E$5)) -> 0.47 | M14: ='Input Scenarios'!M11 -> 0.1 | N14: ='Input Scenarios'!N11 -> 0.2 | O14: ='Input Scenarios'!O11 -> 0.3 | P14: ='Input Scenarios'!P11 -> 0.4 | Q14: ='Input Scenarios'!Q11 -> 0.15 | R14: ='Input Scenarios'!R11 -> 0.2 | S14: ='Input Scenarios'!S11 -> 0.25 | T14: ='Input Scenarios'!T11 -> 0.17 | ... AE14: ='Input Scenarios'!AE11 -> 0.23 | AF14: =I14*(1-J14)*(1-AG14) -> 0.01581 | AG14: =IF(F14="", "",_xlfn.XLOOKUP(F14,Constants!$A$2:$A$5,Constants!F$2:F$5)) -> 0.15 | AH14: =IF(F14="", "",_xlfn.XLOOKUP(F14,Constants!$A$2:$A$5,Constants!G$2:G$5)) -> 0.36 | AI14: =_xlfn.XLOOKUP($A14, Constants!$F$8:$M$8,Constants!$F$9:$M$9) -> 0.015 | AJ14: =_xlfn.XLOOKUP($A14, Constants!$F$8:$M$8,Constants!$F$10:$M$10) -> 0.015 | AK14: =_xlfn.XLOOKUP($A14, Constants!$F$8:$M$8,Constants!$F$11:$M$11) -> 0.015 | AL14: =_xlfn.XLOOKUP($A14, Constants!$F$8:$M$8,Constants!$F$16:$M$16) -> 0.01 | AM14: =$AF14*$AH14*M14*AI14*Constants!$I$2 -> 5.7917722e-06 | AN14: =$AF14*$AH14*N14*AJ14*Constants!$I$2 -> 1.1583544e-05 | AO14: =$AF14*$AH14*O14*AK14*Constants!$I$2 -> 1.7375316e-05 | AP14: =$AF14*$AH14*P14*AL14*Constants!$I$2 -> 1.5444726e-05 | AQ14: =AM14*$G14*$H14 -> 1.447943 | AR14: =AN14*$G14*$H14 -> 2.8958861 | AS14: =AO14*$G14*$H14 -> 4.3438291 | AT14: =AP14*$G14*$H14 -> 3.8611814 | AU14: =SUM(AQ14:AT14) -> 12.54884 | AV14: =_xlfn.XLOOKUP($A14, Constants!$F$8:$M$8,Constants!$F$12:$M$12) -> 0.02 | AW14: =_xlfn.XLOOKUP($A14, Constants!$F$8:$M$8,Constants!$F$13:$M$13) -> 0.01 | AX14: =_xlfn.XLOOKUP($A14, Constants!$F$8:$M$8,Constants!$F$15:$M$15) -> 0.1 | AY14: =_xlfn.XLOOKUP($A14, Constants!$F$8:$M$8,Constants!$F$14:$M$14) -> 0 | AZ14: =_xlfn.XLOOKUP($A14, Constants!$F$8:$M$8,Constants!$F$17:$M$17) -> 0 | BA14: =Constants!$E$9 -> 0.15 | BB14: =Constants!$E$10 -> 0 | BC14: =Constants!$E$11 -> 0.2 | BD14: =$AF14*M14*(1-BA14) -> 0.00134385 | BE14: =$AF14*N14*(1-BB14) -> 0.003162 | BF14: =$AF14*O14*(1-BC14) -> 0.0037944 | BG14: =SUM(BD14:BF14) -> 0.00830025 | BH14: =(($BD14*Q14)+($BE14*V14)+($BF14*AA14))*AV14*$AH14*Constants!$I$2 -> 6.0813608e-06 | BI14: =(($BD14*R14)+($BE14*W14)+($BF14*AB14))*AW14*$AH14*Constants!$I$2 -> 4.0542405e-06 | BJ14: =(($BD14*S14)+($BE14*X14)+($BF14*AC14))*AX14*$AH14*Constants!$I$2 -> 5.0678006e-05 | BK14: =(($BD14*T14)+($BE14*Y14)+($BF14*AD14))*AY14*$AH14*Constants!$I$2 -> 0 | BL14: =(($BD14*U14)+($BE14*Z14)+($BF14*AE14))*AZ14*$AH14*Constants!$I$2 -> 0 | BM14: =$G14*$H14*BH14 -> 1.5203402 | BN14: =$G14*$H14*BI14 -> 1.0135601 | BO14: =$G14*$H14*BJ14 -> 12.669502 | BP14: =$G14*$H14*BK14 -> 0 | BQ14: =$G14*$H14*BL14 -> 0 | BR14: =SUM(BM14:BQ14) -> 15.203402 | BS14: =AU14+BR14 -> 27.752242
A15: ='Input Scenarios'!A12 -> QLD | B15: ='Input Scenarios'!B12 -> 0 | C15: ='Input Scenarios'!C12 -> Irrigated crop | D15: ='Input Scenarios'!D12 -> dry | E15: ='Input Scenarios'!E12 -> TRUE | F15: ='Input Scenarios'!F12 -> layers | G15: ='Input Scenarios'!G12 -> 2250 | H15: ='Input Scenarios'!H12 -> 125 | I15: =IF('Input Scenarios'!I12<>"", 'Input Scenarios'!I12,_xlfn.XLOOKUP($F15,Constants!$A$2:$A$5,Constants!B$2:B$5)) -> 0.086 | J15: =IF('Input Scenarios'!J12<>"", 'Input Scenarios'!J12,_xlfn.XLOOKUP($F15,Constants!$A$2:$A$5,Constants!C$2:C$5)) -> 0.8 | K15: =IF('Input Scenarios'!K12<>"", 'Input Scenarios'!K12,_xlfn.XLOOKUP($F15,Constants!$A$2:$A$5,Constants!D$2:D$5)) -> 0.19 | L15: =IF('Input Scenarios'!L12<>"", 'Input Scenarios'!L12,_xlfn.XLOOKUP($F15,Constants!$A$2:$A$5,Constants!E$2:E$5)) -> 0.35 | M15: ='Input Scenarios'!M12 -> 0.4 | N15: ='Input Scenarios'!N12 -> 0.3 | O15: ='Input Scenarios'!O12 -> 0.2 | P15: ='Input Scenarios'!P12 -> 0.1 | Q15: ='Input Scenarios'!Q12 -> 0.2 | R15: ='Input Scenarios'!R12 -> 0.25 | S15: ='Input Scenarios'!S12 -> 0.2 | T15: ='Input Scenarios'!T12 -> 0.25 | ... AE15: ='Input Scenarios'!AE12 -> 0.1 | AF15: =I15*(1-J15)*(1-AG15) -> 0.014104 | AG15: =IF(F15="", "",_xlfn.XLOOKUP(F15,Constants!$A$2:$A$5,Constants!F$2:F$5)) -> 0.18 | AH15: =IF(F15="", "",_xlfn.XLOOKUP(F15,Constants!$A$2:$A$5,Constants!G$2:G$5)) -> 0.39 | AI15: =_xlfn.XLOOKUP($A15, Constants!$F$8:$M$8,Constants!$F$9:$M$9) -> 0.015 | AJ15: =_xlfn.XLOOKUP($A15, Constants!$F$8:$M$8,Constants!$F$10:$M$10) -> 0.015 | AK15: =_xlfn.XLOOKUP($A15, Constants!$F$8:$M$8,Constants!$F$11:$M$11) -> 0.015 | AL15: =_xlfn.XLOOKUP($A15, Constants!$F$8:$M$8,Constants!$F$16:$M$16) -> 0.03 | AM15: =$AF15*$AH15*M15*AI15*Constants!$I$2 -> 2.2389479e-05 | AN15: =$AF15*$AH15*N15*AJ15*Constants!$I$2 -> 1.679211e-05 | AO15: =$AF15*$AH15*O15*AK15*Constants!$I$2 -> 1.119474e-05 | AP15: =$AF15*$AH15*P15*AL15*Constants!$I$2 -> 1.119474e-05 | AQ15: =AM15*$G15*$H15 -> 6.2970411 | AR15: =AN15*$G15*$H15 -> 4.7227808 | AS15: =AO15*$G15*$H15 -> 3.1485205 | AT15: =AP15*$G15*$H15 -> 3.1485205 | AU15: =SUM(AQ15:AT15) -> 17.316863 | AV15: =_xlfn.XLOOKUP($A15, Constants!$F$8:$M$8,Constants!$F$12:$M$12) -> 0.02 | AW15: =_xlfn.XLOOKUP($A15, Constants!$F$8:$M$8,Constants!$F$13:$M$13) -> 0.01 | AX15: =_xlfn.XLOOKUP($A15, Constants!$F$8:$M$8,Constants!$F$15:$M$15) -> 0.1 | AY15: =_xlfn.XLOOKUP($A15, Constants!$F$8:$M$8,Constants!$F$14:$M$14) -> 0 | AZ15: =_xlfn.XLOOKUP($A15, Constants!$F$8:$M$8,Constants!$F$17:$M$17) -> 0 | BA15: =Constants!$E$9 -> 0.15 | BB15: =Constants!$E$10 -> 0 | BC15: =Constants!$E$11 -> 0.2 | BD15: =$AF15*M15*(1-BA15) -> 0.00479536 | BE15: =$AF15*N15*(1-BB15) -> 0.0042312 | BF15: =$AF15*O15*(1-BC15) -> 0.00225664 | BG15: =SUM(BD15:BF15) -> 0.0112832 | BH15: =(($BD15*Q15)+($BE15*V15)+($BF15*AA15))*AV15*$AH15*Constants!$I$2 -> 1.1941056e-05 | BI15: =(($BD15*R15)+($BE15*W15)+($BF15*AB15))*AW15*$AH15*Constants!$I$2 -> 7.4631598e-06 | BJ15: =(($BD15*S15)+($BE15*X15)+($BF15*AC15))*AX15*$AH15*Constants!$I$2 -> 5.9705278e-05 | BK15: =(($BD15*T15)+($BE15*Y15)+($BF15*AD15))*AY15*$AH15*Constants!$I$2 -> 0 | BL15: =(($BD15*U15)+($BE15*Z15)+($BF15*AE15))*AZ15*$AH15*Constants!$I$2 -> 0 | BM15: =$G15*$H15*BH15 -> 3.3584219 | BN15: =$G15*$H15*BI15 -> 2.0990137 | BO15: =$G15*$H15*BJ15 -> 16.79211 | BP15: =$G15*$H15*BK15 -> 0 | BQ15: =$G15*$H15*BL15 -> 0 | BR15: =SUM(BM15:BQ15) -> 22.249545 | BS15: =AU15+BR15 -> 39.566408 | BT15: =SUM(BS15:BS18)/1000 -> 0.16519006
A16: ='Input Scenarios'!A13 -> QLD | B16: ='Input Scenarios'!B13 -> 0 | C16: ='Input Scenarios'!C13 -> Irrigated crop | D16: ='Input Scenarios'!D13 -> dry | E16: ='Input Scenarios'!E13 -> TRUE | F16: ='Input Scenarios'!F13 -> meatChickenBreeder | G16: ='Input Scenarios'!G13 -> 2250 | H16: ='Input Scenarios'!H13 -> 125 | I16: =IF('Input Scenarios'!I13<>"", 'Input Scenarios'!I13,_xlfn.XLOOKUP($F16,Constants!$A$2:$A$5,Constants!B$2:B$5)) -> 0.103 | J16: =IF('Input Scenarios'!J13<>"", 'Input Scenarios'!J13,_xlfn.XLOOKUP($F16,Constants!$A$2:$A$5,Constants!C$2:C$5)) -> 0.8 | K16: =IF('Input Scenarios'!K13<>"", 'Input Scenarios'!K13,_xlfn.XLOOKUP($F16,Constants!$A$2:$A$5,Constants!D$2:D$5)) -> 0.19 | L16: =IF('Input Scenarios'!L13<>"", 'Input Scenarios'!L13,_xlfn.XLOOKUP($F16,Constants!$A$2:$A$5,Constants!E$2:E$5)) -> 0.32 | M16: ='Input Scenarios'!M13 -> 0.4 | N16: ='Input Scenarios'!N13 -> 0.3 | O16: ='Input Scenarios'!O13 -> 0.2 | P16: ='Input Scenarios'!P13 -> 0.1 | Q16: ='Input Scenarios'!Q13 -> 0.2 | R16: ='Input Scenarios'!R13 -> 0.25 | S16: ='Input Scenarios'!S13 -> 0.2 | T16: ='Input Scenarios'!T13 -> 0.25 | ... AE16: ='Input Scenarios'!AE13 -> 0.1 | AF16: =I16*(1-J16)*(1-AG16) -> 0.016892 | AG16: =IF(F16="", "",_xlfn.XLOOKUP(F16,Constants!$A$2:$A$5,Constants!F$2:F$5)) -> 0.18 | AH16: =IF(F16="", "",_xlfn.XLOOKUP(F16,Constants!$A$2:$A$5,Constants!G$2:G$5)) -> 0.36 | AI16: =_xlfn.XLOOKUP($A16, Constants!$F$8:$M$8,Constants!$F$9:$M$9) -> 0.015 | AJ16: =_xlfn.XLOOKUP($A16, Constants!$F$8:$M$8,Constants!$F$10:$M$10) -> 0.015 | AK16: =_xlfn.XLOOKUP($A16, Constants!$F$8:$M$8,Constants!$F$11:$M$11) -> 0.015 | AL16: =_xlfn.XLOOKUP($A16, Constants!$F$8:$M$8,Constants!$F$16:$M$16) -> 0.03 | AM16: =$AF16*$AH16*M16*AI16*Constants!$I$2 -> 2.4752591e-05 | AN16: =$AF16*$AH16*N16*AJ16*Constants!$I$2 -> 1.8564443e-05 | AO16: =$AF16*$AH16*O16*AK16*Constants!$I$2 -> 1.2376295e-05 | AP16: =$AF16*$AH16*P16*AL16*Constants!$I$2 -> 1.2376295e-05 | AQ16: =AM16*$G16*$H16 -> 6.9616662 | AR16: =AN16*$G16*$H16 -> 5.2212496 | AS16: =AO16*$G16*$H16 -> 3.4808331 | AT16: =AP16*$G16*$H16 -> 3.4808331 | AU16: =SUM(AQ16:AT16) -> 19.144582 | AV16: =_xlfn.XLOOKUP($A16, Constants!$F$8:$M$8,Constants!$F$12:$M$12) -> 0.02 | AW16: =_xlfn.XLOOKUP($A16, Constants!$F$8:$M$8,Constants!$F$13:$M$13) -> 0.01 | AX16: =_xlfn.XLOOKUP($A16, Constants!$F$8:$M$8,Constants!$F$15:$M$15) -> 0.1 | AY16: =_xlfn.XLOOKUP($A16, Constants!$F$8:$M$8,Constants!$F$14:$M$14) -> 0 | AZ16: =_xlfn.XLOOKUP($A16, Constants!$F$8:$M$8,Constants!$F$17:$M$17) -> 0 | BA16: =Constants!$E$9 -> 0.15 | BB16: =Constants!$E$10 -> 0 | BC16: =Constants!$E$11 -> 0.2 | BD16: =$AF16*M16*(1-BA16) -> 0.00574328 | BE16: =$AF16*N16*(1-BB16) -> 0.0050676 | BF16: =$AF16*O16*(1-BC16) -> 0.00270272 | BG16: =SUM(BD16:BF16) -> 0.0135136 | BH16: =(($BD16*Q16)+($BE16*V16)+($BF16*AA16))*AV16*$AH16*Constants!$I$2 -> 1.3201382e-05 | BI16: =(($BD16*R16)+($BE16*W16)+($BF16*AB16))*AW16*$AH16*Constants!$I$2 -> 8.2508636e-06 | BJ16: =(($BD16*S16)+($BE16*X16)+($BF16*AC16))*AX16*$AH16*Constants!$I$2 -> 6.6006909e-05 | BK16: =(($BD16*T16)+($BE16*Y16)+($BF16*AD16))*AY16*$AH16*Constants!$I$2 -> 0 | BL16: =(($BD16*U16)+($BE16*Z16)+($BF16*AE16))*AZ16*$AH16*Constants!$I$2 -> 0 | BM16: =$G16*$H16*BH16 -> 3.7128886 | BN16: =$G16*$H16*BI16 -> 2.3205554 | BO16: =$G16*$H16*BJ16 -> 18.564443 | BP16: =$G16*$H16*BK16 -> 0 | BQ16: =$G16*$H16*BL16 -> 0 | BR16: =SUM(BM16:BQ16) -> 24.597887 | BS16: =AU16+BR16 -> 43.742469
A17: ='Input Scenarios'!A14 -> QLD | B17: ='Input Scenarios'!B14 -> 0 | C17: ='Input Scenarios'!C14 -> Irrigated crop | D17: ='Input Scenarios'!D14 -> dry | E17: ='Input Scenarios'!E14 -> TRUE | F17: ='Input Scenarios'!F14 -> meatChickenGrowers | G17: ='Input Scenarios'!G14 -> 2250 | H17: ='Input Scenarios'!H14 -> 125 | I17: =IF('Input Scenarios'!I14<>"", 'Input Scenarios'!I14,_xlfn.XLOOKUP($F17,Constants!$A$2:$A$5,Constants!B$2:B$5)) -> 0.093 | J17: =IF('Input Scenarios'!J14<>"", 'Input Scenarios'!J14,_xlfn.XLOOKUP($F17,Constants!$A$2:$A$5,Constants!C$2:C$5)) -> 0.8 | K17: =IF('Input Scenarios'!K14<>"", 'Input Scenarios'!K14,_xlfn.XLOOKUP($F17,Constants!$A$2:$A$5,Constants!D$2:D$5)) -> 0.23 | L17: =IF('Input Scenarios'!L14<>"", 'Input Scenarios'!L14,_xlfn.XLOOKUP($F17,Constants!$A$2:$A$5,Constants!E$2:E$5)) -> 0.47 | M17: ='Input Scenarios'!M14 -> 0.4 | N17: ='Input Scenarios'!N14 -> 0.3 | O17: ='Input Scenarios'!O14 -> 0.2 | P17: ='Input Scenarios'!P14 -> 0.1 | Q17: ='Input Scenarios'!Q14 -> 0.2 | R17: ='Input Scenarios'!R14 -> 0.25 | S17: ='Input Scenarios'!S14 -> 0.2 | T17: ='Input Scenarios'!T14 -> 0.25 | ... AE17: ='Input Scenarios'!AE14 -> 0.1 | AF17: =I17*(1-J17)*(1-AG17) -> 0.01581 | AG17: =IF(F17="", "",_xlfn.XLOOKUP(F17,Constants!$A$2:$A$5,Constants!F$2:F$5)) -> 0.15 | AH17: =IF(F17="", "",_xlfn.XLOOKUP(F17,Constants!$A$2:$A$5,Constants!G$2:G$5)) -> 0.36 | AI17: =_xlfn.XLOOKUP($A17, Constants!$F$8:$M$8,Constants!$F$9:$M$9) -> 0.015 | AJ17: =_xlfn.XLOOKUP($A17, Constants!$F$8:$M$8,Constants!$F$10:$M$10) -> 0.015 | AK17: =_xlfn.XLOOKUP($A17, Constants!$F$8:$M$8,Constants!$F$11:$M$11) -> 0.015 | AL17: =_xlfn.XLOOKUP($A17, Constants!$F$8:$M$8,Constants!$F$16:$M$16) -> 0.03 | AM17: =$AF17*$AH17*M17*AI17*Constants!$I$2 -> 2.3167089e-05 | AN17: =$AF17*$AH17*N17*AJ17*Constants!$I$2 -> 1.7375316e-05 | AO17: =$AF17*$AH17*O17*AK17*Constants!$I$2 -> 1.1583544e-05 | AP17: =$AF17*$AH17*P17*AL17*Constants!$I$2 -> 1.1583544e-05 | AQ17: =AM17*$G17*$H17 -> 6.5157437 | AR17: =AN17*$G17*$H17 -> 4.8868078 | AS17: =AO17*$G17*$H17 -> 3.2578718 | AT17: =AP17*$G17*$H17 -> 3.2578718 | AU17: =SUM(AQ17:AT17) -> 17.918295 | AV17: =_xlfn.XLOOKUP($A17, Constants!$F$8:$M$8,Constants!$F$12:$M$12) -> 0.02 | AW17: =_xlfn.XLOOKUP($A17, Constants!$F$8:$M$8,Constants!$F$13:$M$13) -> 0.01 | AX17: =_xlfn.XLOOKUP($A17, Constants!$F$8:$M$8,Constants!$F$15:$M$15) -> 0.1 | AY17: =_xlfn.XLOOKUP($A17, Constants!$F$8:$M$8,Constants!$F$14:$M$14) -> 0 | AZ17: =_xlfn.XLOOKUP($A17, Constants!$F$8:$M$8,Constants!$F$17:$M$17) -> 0 | BA17: =Constants!$E$9 -> 0.15 | BB17: =Constants!$E$10 -> 0 | BC17: =Constants!$E$11 -> 0.2 | BD17: =$AF17*M17*(1-BA17) -> 0.0053754 | BE17: =$AF17*N17*(1-BB17) -> 0.004743 | BF17: =$AF17*O17*(1-BC17) -> 0.0025296 | BG17: =SUM(BD17:BF17) -> 0.012648 | BH17: =(($BD17*Q17)+($BE17*V17)+($BF17*AA17))*AV17*$AH17*Constants!$I$2 -> 1.2355781e-05 | BI17: =(($BD17*R17)+($BE17*W17)+($BF17*AB17))*AW17*$AH17*Constants!$I$2 -> 7.7223629e-06 | BJ17: =(($BD17*S17)+($BE17*X17)+($BF17*AC17))*AX17*$AH17*Constants!$I$2 -> 6.1778903e-05 | BK17: =(($BD17*T17)+($BE17*Y17)+($BF17*AD17))*AY17*$AH17*Constants!$I$2 -> 0 | BL17: =(($BD17*U17)+($BE17*Z17)+($BF17*AE17))*AZ17*$AH17*Constants!$I$2 -> 0 | BM17: =$G17*$H17*BH17 -> 3.4750633 | BN17: =$G17*$H17*BI17 -> 2.1719146 | BO17: =$G17*$H17*BJ17 -> 17.375316 | BP17: =$G17*$H17*BK17 -> 0 | BQ17: =$G17*$H17*BL17 -> 0 | BR17: =SUM(BM17:BQ17) -> 23.022294 | BS17: =AU17+BR17 -> 40.940589
A18: ='Input Scenarios'!A15 -> QLD | B18: ='Input Scenarios'!B15 -> 0 | C18: ='Input Scenarios'!C15 -> Irrigated crop | D18: ='Input Scenarios'!D15 -> dry | E18: ='Input Scenarios'!E15 -> TRUE | F18: ='Input Scenarios'!F15 -> meatOther | G18: ='Input Scenarios'!G15 -> 2250 | H18: ='Input Scenarios'!H15 -> 125 | I18: =IF('Input Scenarios'!I15<>"", 'Input Scenarios'!I15,_xlfn.XLOOKUP($F18,Constants!$A$2:$A$5,Constants!B$2:B$5)) -> 0.093 | J18: =IF('Input Scenarios'!J15<>"", 'Input Scenarios'!J15,_xlfn.XLOOKUP($F18,Constants!$A$2:$A$5,Constants!C$2:C$5)) -> 0.8 | K18: =IF('Input Scenarios'!K15<>"", 'Input Scenarios'!K15,_xlfn.XLOOKUP($F18,Constants!$A$2:$A$5,Constants!D$2:D$5)) -> 0.23 | L18: =IF('Input Scenarios'!L15<>"", 'Input Scenarios'!L15,_xlfn.XLOOKUP($F18,Constants!$A$2:$A$5,Constants!E$2:E$5)) -> 0.47 | M18: ='Input Scenarios'!M15 -> 0.4 | N18: ='Input Scenarios'!N15 -> 0.3 | O18: ='Input Scenarios'!O15 -> 0.2 | P18: ='Input Scenarios'!P15 -> 0.1 | Q18: ='Input Scenarios'!Q15 -> 0.2 | R18: ='Input Scenarios'!R15 -> 0.25 | S18: ='Input Scenarios'!S15 -> 0.2 | T18: ='Input Scenarios'!T15 -> 0.25 | ... AE18: ='Input Scenarios'!AE15 -> 0.1 | AF18: =I18*(1-J18)*(1-AG18) -> 0.01581 | AG18: =IF(F18="", "",_xlfn.XLOOKUP(F18,Constants!$A$2:$A$5,Constants!F$2:F$5)) -> 0.15 | AH18: =IF(F18="", "",_xlfn.XLOOKUP(F18,Constants!$A$2:$A$5,Constants!G$2:G$5)) -> 0.36 | AI18: =_xlfn.XLOOKUP($A18, Constants!$F$8:$M$8,Constants!$F$9:$M$9) -> 0.015 | AJ18: =_xlfn.XLOOKUP($A18, Constants!$F$8:$M$8,Constants!$F$10:$M$10) -> 0.015 | AK18: =_xlfn.XLOOKUP($A18, Constants!$F$8:$M$8,Constants!$F$11:$M$11) -> 0.015 | AL18: =_xlfn.XLOOKUP($A18, Constants!$F$8:$M$8,Constants!$F$16:$M$16) -> 0.03 | AM18: =$AF18*$AH18*M18*AI18*Constants!$I$2 -> 2.3167089e-05 | AN18: =$AF18*$AH18*N18*AJ18*Constants!$I$2 -> 1.7375316e-05 | AO18: =$AF18*$AH18*O18*AK18*Constants!$I$2 -> 1.1583544e-05 | AP18: =$AF18*$AH18*P18*AL18*Constants!$I$2 -> 1.1583544e-05 | AQ18: =AM18*$G18*$H18 -> 6.5157437 | AR18: =AN18*$G18*$H18 -> 4.8868078 | AS18: =AO18*$G18*$H18 -> 3.2578718 | AT18: =AP18*$G18*$H18 -> 3.2578718 | AU18: =SUM(AQ18:AT18) -> 17.918295 | AV18: =_xlfn.XLOOKUP($A18, Constants!$F$8:$M$8,Constants!$F$12:$M$12) -> 0.02 | AW18: =_xlfn.XLOOKUP($A18, Constants!$F$8:$M$8,Constants!$F$13:$M$13) -> 0.01 | AX18: =_xlfn.XLOOKUP($A18, Constants!$F$8:$M$8,Constants!$F$15:$M$15) -> 0.1 | AY18: =_xlfn.XLOOKUP($A18, Constants!$F$8:$M$8,Constants!$F$14:$M$14) -> 0 | AZ18: =_xlfn.XLOOKUP($A18, Constants!$F$8:$M$8,Constants!$F$17:$M$17) -> 0 | BA18: =Constants!$E$9 -> 0.15 | BB18: =Constants!$E$10 -> 0 | BC18: =Constants!$E$11 -> 0.2 | BD18: =$AF18*M18*(1-BA18) -> 0.0053754 | BE18: =$AF18*N18*(1-BB18) -> 0.004743 | BF18: =$AF18*O18*(1-BC18) -> 0.0025296 | BG18: =SUM(BD18:BF18) -> 0.012648 | BH18: =(($BD18*Q18)+($BE18*V18)+($BF18*AA18))*AV18*$AH18*Constants!$I$2 -> 1.2355781e-05 | BI18: =(($BD18*R18)+($BE18*W18)+($BF18*AB18))*AW18*$AH18*Constants!$I$2 -> 7.7223629e-06 | BJ18: =(($BD18*S18)+($BE18*X18)+($BF18*AC18))*AX18*$AH18*Constants!$I$2 -> 6.1778903e-05 | BK18: =(($BD18*T18)+($BE18*Y18)+($BF18*AD18))*AY18*$AH18*Constants!$I$2 -> 0 | BL18: =(($BD18*U18)+($BE18*Z18)+($BF18*AE18))*AZ18*$AH18*Constants!$I$2 -> 0 | BM18: =$G18*$H18*BH18 -> 3.4750633 | BN18: =$G18*$H18*BI18 -> 2.1719146 | BO18: =$G18*$H18*BJ18 -> 17.375316 | BP18: =$G18*$H18*BK18 -> 0 | BQ18: =$G18*$H18*BL18 -> 0 | BR18: =SUM(BM18:BQ18) -> 23.022294 | BS18: =AU18+BR18 -> 40.940589
A19: ='Input Scenarios'!A16 -> TAS | B19: ='Input Scenarios'!B16 -> 0 | C19: ='Input Scenarios'!C16 -> Irrigated pasture | D19: ='Input Scenarios'!D16 -> wet | E19: ='Input Scenarios'!E16 -> TRUE | F19: ='Input Scenarios'!F16 -> layers | G19: ='Input Scenarios'!G16 -> 3333 | H19: ='Input Scenarios'!H16 -> 111 | I19: =IF('Input Scenarios'!I16<>"", 'Input Scenarios'!I16,_xlfn.XLOOKUP($F19,Constants!$A$2:$A$5,Constants!B$2:B$5)) -> 0.086 | J19: =IF('Input Scenarios'!J16<>"", 'Input Scenarios'!J16,_xlfn.XLOOKUP($F19,Constants!$A$2:$A$5,Constants!C$2:C$5)) -> 0.8 | K19: =IF('Input Scenarios'!K16<>"", 'Input Scenarios'!K16,_xlfn.XLOOKUP($F19,Constants!$A$2:$A$5,Constants!D$2:D$5)) -> 0.19 | L19: =IF('Input Scenarios'!L16<>"", 'Input Scenarios'!L16,_xlfn.XLOOKUP($F19,Constants!$A$2:$A$5,Constants!E$2:E$5)) -> 0.35 | M19: ='Input Scenarios'!M16 -> 0 | N19: ='Input Scenarios'!N16 -> 0.9 | O19: ='Input Scenarios'!O16 -> 0 | P19: ='Input Scenarios'!P16 -> 0.1 | Q19: ='Input Scenarios'!Q16 -> 0.34 | R19: ='Input Scenarios'!R16 -> 0.6 | S19: ='Input Scenarios'!S16 -> 0 | T19: ='Input Scenarios'!T16 -> 0 | ... AE19: ='Input Scenarios'!AE16 -> 0.06 | AF19: =I19*(1-J19)*(1-AG19) -> 0.014104 | AG19: =IF(F19="", "",_xlfn.XLOOKUP(F19,Constants!$A$2:$A$5,Constants!F$2:F$5)) -> 0.18 | AH19: =IF(F19="", "",_xlfn.XLOOKUP(F19,Constants!$A$2:$A$5,Constants!G$2:G$5)) -> 0.39 | AI19: =_xlfn.XLOOKUP($A19, Constants!$F$8:$M$8,Constants!$F$9:$M$9) -> 0.015 | AJ19: =_xlfn.XLOOKUP($A19, Constants!$F$8:$M$8,Constants!$F$10:$M$10) -> 0.015 | AK19: =_xlfn.XLOOKUP($A19, Constants!$F$8:$M$8,Constants!$F$11:$M$11) -> 0.015 | AL19: =_xlfn.XLOOKUP($A19, Constants!$F$8:$M$8,Constants!$F$16:$M$16) -> 0.01 | AM19: =$AF19*$AH19*M19*AI19*Constants!$I$2 -> 0 | AN19: =$AF19*$AH19*N19*AJ19*Constants!$I$2 -> 5.0376329e-05 | AO19: =$AF19*$AH19*O19*AK19*Constants!$I$2 -> 0 | AP19: =$AF19*$AH19*P19*AL19*Constants!$I$2 -> 3.7315799e-06 | AQ19: =AM19*$G19*$H19 -> 0 | AR19: =AN19*$G19*$H19 -> 18.637378 | AS19: =AO19*$G19*$H19 -> 0 | AT19: =AP19*$G19*$H19 -> 1.3805465 | AU19: =SUM(AQ19:AT19) -> 20.017924 | AV19: =_xlfn.XLOOKUP($A19, Constants!$F$8:$M$8,Constants!$F$12:$M$12) -> 0.02 | AW19: =_xlfn.XLOOKUP($A19, Constants!$F$8:$M$8,Constants!$F$13:$M$13) -> 0.005 | AX19: =_xlfn.XLOOKUP($A19, Constants!$F$8:$M$8,Constants!$F$15:$M$15) -> 0.1 | AY19: =_xlfn.XLOOKUP($A19, Constants!$F$8:$M$8,Constants!$F$14:$M$14) -> 0 | AZ19: =_xlfn.XLOOKUP($A19, Constants!$F$8:$M$8,Constants!$F$17:$M$17) -> 0 | BA19: =Constants!$E$9 -> 0.15 | BB19: =Constants!$E$10 -> 0 | BC19: =Constants!$E$11 -> 0.2 | BD19: =$AF19*M19*(1-BA19) -> 0 | BE19: =$AF19*N19*(1-BB19) -> 0.0126936 | BF19: =$AF19*O19*(1-BC19) -> 0 | BG19: =SUM(BD19:BF19) -> 0.0126936 | BH19: =(($BD19*Q19)+($BE19*V19)+($BF19*AA19))*AV19*$AH19*Constants!$I$2 -> 2.2837269e-05 | BI19: =(($BD19*R19)+($BE19*W19)+($BF19*AB19))*AW19*$AH19*Constants!$I$2 -> 1.0075266e-05 | BJ19: =(($BD19*S19)+($BE19*X19)+($BF19*AC19))*AX19*$AH19*Constants!$I$2 -> 0 | BK19: =(($BD19*T19)+($BE19*Y19)+($BF19*AD19))*AY19*$AH19*Constants!$I$2 -> 0 | BL19: =(($BD19*U19)+($BE19*Z19)+($BF19*AE19))*AZ19*$AH19*Constants!$I$2 -> 0 | BM19: =$G19*$H19*BH19 -> 8.4489446 | BN19: =$G19*$H19*BI19 -> 3.7274755 | BO19: =$G19*$H19*BJ19 -> 0 | BP19: =$G19*$H19*BK19 -> 0 | BQ19: =$G19*$H19*BL19 -> 0 | BR19: =SUM(BM19:BQ19) -> 12.17642 | BS19: =AU19+BR19 -> 32.194344 | BT19: =SUM(BS19:BS22)/1000 -> 0.13441163
A20: ='Input Scenarios'!A17 -> TAS | B20: ='Input Scenarios'!B17 -> 0 | C20: ='Input Scenarios'!C17 -> Irrigated pasture | D20: ='Input Scenarios'!D17 -> wet | E20: ='Input Scenarios'!E17 -> TRUE | F20: ='Input Scenarios'!F17 -> meatChickenBreeder | G20: ='Input Scenarios'!G17 -> 3333 | H20: ='Input Scenarios'!H17 -> 111 | I20: =IF('Input Scenarios'!I17<>"", 'Input Scenarios'!I17,_xlfn.XLOOKUP($F20,Constants!$A$2:$A$5,Constants!B$2:B$5)) -> 0.103 | J20: =IF('Input Scenarios'!J17<>"", 'Input Scenarios'!J17,_xlfn.XLOOKUP($F20,Constants!$A$2:$A$5,Constants!C$2:C$5)) -> 0.8 | K20: =IF('Input Scenarios'!K17<>"", 'Input Scenarios'!K17,_xlfn.XLOOKUP($F20,Constants!$A$2:$A$5,Constants!D$2:D$5)) -> 0.19 | L20: =IF('Input Scenarios'!L17<>"", 'Input Scenarios'!L17,_xlfn.XLOOKUP($F20,Constants!$A$2:$A$5,Constants!E$2:E$5)) -> 0.32 | M20: ='Input Scenarios'!M17 -> 0 | N20: ='Input Scenarios'!N17 -> 0.9 | O20: ='Input Scenarios'!O17 -> 0 | P20: ='Input Scenarios'!P17 -> 0.1 | Q20: ='Input Scenarios'!Q17 -> 0.34 | R20: ='Input Scenarios'!R17 -> 0.6 | S20: ='Input Scenarios'!S17 -> 0 | T20: ='Input Scenarios'!T17 -> 0 | ... AE20: ='Input Scenarios'!AE17 -> 0.06 | AF20: =I20*(1-J20)*(1-AG20) -> 0.016892 | AG20: =IF(F20="", "",_xlfn.XLOOKUP(F20,Constants!$A$2:$A$5,Constants!F$2:F$5)) -> 0.18 | AH20: =IF(F20="", "",_xlfn.XLOOKUP(F20,Constants!$A$2:$A$5,Constants!G$2:G$5)) -> 0.36 | AI20: =_xlfn.XLOOKUP($A20, Constants!$F$8:$M$8,Constants!$F$9:$M$9) -> 0.015 | AJ20: =_xlfn.XLOOKUP($A20, Constants!$F$8:$M$8,Constants!$F$10:$M$10) -> 0.015 | AK20: =_xlfn.XLOOKUP($A20, Constants!$F$8:$M$8,Constants!$F$11:$M$11) -> 0.015 | AL20: =_xlfn.XLOOKUP($A20, Constants!$F$8:$M$8,Constants!$F$16:$M$16) -> 0.01 | AM20: =$AF20*$AH20*M20*AI20*Constants!$I$2 -> 0 | AN20: =$AF20*$AH20*N20*AJ20*Constants!$I$2 -> 5.5693329e-05 | AO20: =$AF20*$AH20*O20*AK20*Constants!$I$2 -> 0 | AP20: =$AF20*$AH20*P20*AL20*Constants!$I$2 -> 4.1254318e-06 | AQ20: =AM20*$G20*$H20 -> 0 | AR20: =AN20*$G20*$H20 -> 20.604471 | AS20: =AO20*$G20*$H20 -> 0 | AT20: =AP20*$G20*$H20 -> 1.5262571 | AU20: =SUM(AQ20:AT20) -> 22.130728 | AV20: =_xlfn.XLOOKUP($A20, Constants!$F$8:$M$8,Constants!$F$12:$M$12) -> 0.02 | AW20: =_xlfn.XLOOKUP($A20, Constants!$F$8:$M$8,Constants!$F$13:$M$13) -> 0.005 | AX20: =_xlfn.XLOOKUP($A20, Constants!$F$8:$M$8,Constants!$F$15:$M$15) -> 0.1 | AY20: =_xlfn.XLOOKUP($A20, Constants!$F$8:$M$8,Constants!$F$14:$M$14) -> 0 | AZ20: =_xlfn.XLOOKUP($A20, Constants!$F$8:$M$8,Constants!$F$17:$M$17) -> 0 | BA20: =Constants!$E$9 -> 0.15 | BB20: =Constants!$E$10 -> 0 | BC20: =Constants!$E$11 -> 0.2 | BD20: =$AF20*M20*(1-BA20) -> 0 | BE20: =$AF20*N20*(1-BB20) -> 0.0152028 | BF20: =$AF20*O20*(1-BC20) -> 0 | BG20: =SUM(BD20:BF20) -> 0.0152028 | BH20: =(($BD20*Q20)+($BE20*V20)+($BF20*AA20))*AV20*$AH20*Constants!$I$2 -> 2.5247643e-05 | BI20: =(($BD20*R20)+($BE20*W20)+($BF20*AB20))*AW20*$AH20*Constants!$I$2 -> 1.1138666e-05 | BJ20: =(($BD20*S20)+($BE20*X20)+($BF20*AC20))*AX20*$AH20*Constants!$I$2 -> 0 | BK20: =(($BD20*T20)+($BE20*Y20)+($BF20*AD20))*AY20*$AH20*Constants!$I$2 -> 0 | BL20: =(($BD20*U20)+($BE20*Z20)+($BF20*AE20))*AZ20*$AH20*Constants!$I$2 -> 0 | BM20: =$G20*$H20*BH20 -> 9.3406936 | BN20: =$G20*$H20*BI20 -> 4.1208942 | BO20: =$G20*$H20*BJ20 -> 0 | BP20: =$G20*$H20*BK20 -> 0 | BQ20: =$G20*$H20*BL20 -> 0 | BR20: =SUM(BM20:BQ20) -> 13.461588 | BS20: =AU20+BR20 -> 35.592316
A21: ='Input Scenarios'!A18 -> TAS | B21: ='Input Scenarios'!B18 -> 0 | C21: ='Input Scenarios'!C18 -> Irrigated pasture | D21: ='Input Scenarios'!D18 -> wet | E21: ='Input Scenarios'!E18 -> TRUE | F21: ='Input Scenarios'!F18 -> meatChickenGrowers | G21: ='Input Scenarios'!G18 -> 3333 | H21: ='Input Scenarios'!H18 -> 111 | I21: =IF('Input Scenarios'!I18<>"", 'Input Scenarios'!I18,_xlfn.XLOOKUP($F21,Constants!$A$2:$A$5,Constants!B$2:B$5)) -> 0.093 | J21: =IF('Input Scenarios'!J18<>"", 'Input Scenarios'!J18,_xlfn.XLOOKUP($F21,Constants!$A$2:$A$5,Constants!C$2:C$5)) -> 0.8 | K21: =IF('Input Scenarios'!K18<>"", 'Input Scenarios'!K18,_xlfn.XLOOKUP($F21,Constants!$A$2:$A$5,Constants!D$2:D$5)) -> 0.23 | L21: =IF('Input Scenarios'!L18<>"", 'Input Scenarios'!L18,_xlfn.XLOOKUP($F21,Constants!$A$2:$A$5,Constants!E$2:E$5)) -> 0.47 | M21: ='Input Scenarios'!M18 -> 0 | N21: ='Input Scenarios'!N18 -> 0.9 | O21: ='Input Scenarios'!O18 -> 0 | P21: ='Input Scenarios'!P18 -> 0.1 | Q21: ='Input Scenarios'!Q18 -> 0.34 | R21: ='Input Scenarios'!R18 -> 0.6 | S21: ='Input Scenarios'!S18 -> 0 | T21: ='Input Scenarios'!T18 -> 0 | ... AE21: ='Input Scenarios'!AE18 -> 0.06 | AF21: =I21*(1-J21)*(1-AG21) -> 0.01581 | AG21: =IF(F21="", "",_xlfn.XLOOKUP(F21,Constants!$A$2:$A$5,Constants!F$2:F$5)) -> 0.15 | AH21: =IF(F21="", "",_xlfn.XLOOKUP(F21,Constants!$A$2:$A$5,Constants!G$2:G$5)) -> 0.36 | AI21: =_xlfn.XLOOKUP($A21, Constants!$F$8:$M$8,Constants!$F$9:$M$9) -> 0.015 | AJ21: =_xlfn.XLOOKUP($A21, Constants!$F$8:$M$8,Constants!$F$10:$M$10) -> 0.015 | AK21: =_xlfn.XLOOKUP($A21, Constants!$F$8:$M$8,Constants!$F$11:$M$11) -> 0.015 | AL21: =_xlfn.XLOOKUP($A21, Constants!$F$8:$M$8,Constants!$F$16:$M$16) -> 0.01 | AM21: =$AF21*$AH21*M21*AI21*Constants!$I$2 -> 0 | AN21: =$AF21*$AH21*N21*AJ21*Constants!$I$2 -> 5.2125949e-05 | AO21: =$AF21*$AH21*O21*AK21*Constants!$I$2 -> 0 | AP21: =$AF21*$AH21*P21*AL21*Constants!$I$2 -> 3.8611814e-06 | AQ21: =AM21*$G21*$H21 -> 0 | AR21: =AN21*$G21*$H21 -> 19.284673 | AS21: =AO21*$G21*$H21 -> 0 | AT21: =AP21*$G21*$H21 -> 1.4284943 | AU21: =SUM(AQ21:AT21) -> 20.713167 | AV21: =_xlfn.XLOOKUP($A21, Constants!$F$8:$M$8,Constants!$F$12:$M$12) -> 0.02 | AW21: =_xlfn.XLOOKUP($A21, Constants!$F$8:$M$8,Constants!$F$13:$M$13) -> 0.005 | AX21: =_xlfn.XLOOKUP($A21, Constants!$F$8:$M$8,Constants!$F$15:$M$15) -> 0.1 | AY21: =_xlfn.XLOOKUP($A21, Constants!$F$8:$M$8,Constants!$F$14:$M$14) -> 0 | AZ21: =_xlfn.XLOOKUP($A21, Constants!$F$8:$M$8,Constants!$F$17:$M$17) -> 0 | BA21: =Constants!$E$9 -> 0.15 | BB21: =Constants!$E$10 -> 0 | BC21: =Constants!$E$11 -> 0.2 | BD21: =$AF21*M21*(1-BA21) -> 0 | BE21: =$AF21*N21*(1-BB21) -> 0.014229 | BF21: =$AF21*O21*(1-BC21) -> 0 | BG21: =SUM(BD21:BF21) -> 0.014229 | BH21: =(($BD21*Q21)+($BE21*V21)+($BF21*AA21))*AV21*$AH21*Constants!$I$2 -> 2.363043e-05 | BI21: =(($BD21*R21)+($BE21*W21)+($BF21*AB21))*AW21*$AH21*Constants!$I$2 -> 1.042519e-05 | BJ21: =(($BD21*S21)+($BE21*X21)+($BF21*AC21))*AX21*$AH21*Constants!$I$2 -> 0 | BK21: =(($BD21*T21)+($BE21*Y21)+($BF21*AD21))*AY21*$AH21*Constants!$I$2 -> 0 | BL21: =(($BD21*U21)+($BE21*Z21)+($BF21*AE21))*AZ21*$AH21*Constants!$I$2 -> 0 | BM21: =$G21*$H21*BH21 -> 8.7423849 | BN21: =$G21*$H21*BI21 -> 3.8569345 | BO21: =$G21*$H21*BJ21 -> 0 | BP21: =$G21*$H21*BK21 -> 0 | BQ21: =$G21*$H21*BL21 -> 0 | BR21: =SUM(BM21:BQ21) -> 12.599319 | BS21: =AU21+BR21 -> 33.312486
A22: ='Input Scenarios'!A19 -> TAS | B22: ='Input Scenarios'!B19 -> 0 | C22: ='Input Scenarios'!C19 -> Irrigated pasture | D22: ='Input Scenarios'!D19 -> wet | E22: ='Input Scenarios'!E19 -> TRUE | F22: ='Input Scenarios'!F19 -> meatOther | G22: ='Input Scenarios'!G19 -> 3333 | H22: ='Input Scenarios'!H19 -> 111 | I22: =IF('Input Scenarios'!I19<>"", 'Input Scenarios'!I19,_xlfn.XLOOKUP($F22,Constants!$A$2:$A$5,Constants!B$2:B$5)) -> 0.093 | J22: =IF('Input Scenarios'!J19<>"", 'Input Scenarios'!J19,_xlfn.XLOOKUP($F22,Constants!$A$2:$A$5,Constants!C$2:C$5)) -> 0.8 | K22: =IF('Input Scenarios'!K19<>"", 'Input Scenarios'!K19,_xlfn.XLOOKUP($F22,Constants!$A$2:$A$5,Constants!D$2:D$5)) -> 0.23 | L22: =IF('Input Scenarios'!L19<>"", 'Input Scenarios'!L19,_xlfn.XLOOKUP($F22,Constants!$A$2:$A$5,Constants!E$2:E$5)) -> 0.47 | M22: ='Input Scenarios'!M19 -> 0 | N22: ='Input Scenarios'!N19 -> 0.9 | O22: ='Input Scenarios'!O19 -> 0 | P22: ='Input Scenarios'!P19 -> 0.1 | Q22: ='Input Scenarios'!Q19 -> 0.34 | R22: ='Input Scenarios'!R19 -> 0.6 | S22: ='Input Scenarios'!S19 -> 0 | T22: ='Input Scenarios'!T19 -> 0 | ... AE22: ='Input Scenarios'!AE19 -> 0.06 | AF22: =I22*(1-J22)*(1-AG22) -> 0.01581 | AG22: =IF(F22="", "",_xlfn.XLOOKUP(F22,Constants!$A$2:$A$5,Constants!F$2:F$5)) -> 0.15 | AH22: =IF(F22="", "",_xlfn.XLOOKUP(F22,Constants!$A$2:$A$5,Constants!G$2:G$5)) -> 0.36 | AI22: =_xlfn.XLOOKUP($A22, Constants!$F$8:$M$8,Constants!$F$9:$M$9) -> 0.015 | AJ22: =_xlfn.XLOOKUP($A22, Constants!$F$8:$M$8,Constants!$F$10:$M$10) -> 0.015 | AK22: =_xlfn.XLOOKUP($A22, Constants!$F$8:$M$8,Constants!$F$11:$M$11) -> 0.015 | AL22: =_xlfn.XLOOKUP($A22, Constants!$F$8:$M$8,Constants!$F$16:$M$16) -> 0.01 | AM22: =$AF22*$AH22*M22*AI22*Constants!$I$2 -> 0 | AN22: =$AF22*$AH22*N22*AJ22*Constants!$I$2 -> 5.2125949e-05 | AO22: =$AF22*$AH22*O22*AK22*Constants!$I$2 -> 0 | AP22: =$AF22*$AH22*P22*AL22*Constants!$I$2 -> 3.8611814e-06 | AQ22: =AM22*$G22*$H22 -> 0 | AR22: =AN22*$G22*$H22 -> 19.284673 | AS22: =AO22*$G22*$H22 -> 0 | AT22: =AP22*$G22*$H22 -> 1.4284943 | AU22: =SUM(AQ22:AT22) -> 20.713167 | AV22: =_xlfn.XLOOKUP($A22, Constants!$F$8:$M$8,Constants!$F$12:$M$12) -> 0.02 | AW22: =_xlfn.XLOOKUP($A22, Constants!$F$8:$M$8,Constants!$F$13:$M$13) -> 0.005 | AX22: =_xlfn.XLOOKUP($A22, Constants!$F$8:$M$8,Constants!$F$15:$M$15) -> 0.1 | AY22: =_xlfn.XLOOKUP($A22, Constants!$F$8:$M$8,Constants!$F$14:$M$14) -> 0 | AZ22: =_xlfn.XLOOKUP($A22, Constants!$F$8:$M$8,Constants!$F$17:$M$17) -> 0 | BA22: =Constants!$E$9 -> 0.15 | BB22: =Constants!$E$10 -> 0 | BC22: =Constants!$E$11 -> 0.2 | BD22: =$AF22*M22*(1-BA22) -> 0 | BE22: =$AF22*N22*(1-BB22) -> 0.014229 | BF22: =$AF22*O22*(1-BC22) -> 0 | BG22: =SUM(BD22:BF22) -> 0.014229 | BH22: =(($BD22*Q22)+($BE22*V22)+($BF22*AA22))*AV22*$AH22*Constants!$I$2 -> 2.363043e-05 | BI22: =(($BD22*R22)+($BE22*W22)+($BF22*AB22))*AW22*$AH22*Constants!$I$2 -> 1.042519e-05 | BJ22: =(($BD22*S22)+($BE22*X22)+($BF22*AC22))*AX22*$AH22*Constants!$I$2 -> 0 | BK22: =(($BD22*T22)+($BE22*Y22)+($BF22*AD22))*AY22*$AH22*Constants!$I$2 -> 0 | BL22: =(($BD22*U22)+($BE22*Z22)+($BF22*AE22))*AZ22*$AH22*Constants!$I$2 -> 0 | BM22: =$G22*$H22*BH22 -> 8.7423849 | BN22: =$G22*$H22*BI22 -> 3.8569345 | BO22: =$G22*$H22*BJ22 -> 0 | BP22: =$G22*$H22*BK22 -> 0 | BQ22: =$G22*$H22*BL22 -> 0 | BR22: =SUM(BM22:BQ22) -> 12.599319 | BS22: =AU22+BR22 -> 33.312486
A23: ='Input Scenarios'!A20 -> NT | B23: ='Input Scenarios'!B20 -> 0 | C23: ='Input Scenarios'!C20 -> Non-irrigated crop (high rainfall) | D23: ='Input Scenarios'!D20 -> dry | E23: ='Input Scenarios'!E20 -> FALSE | F23: ='Input Scenarios'!F20 -> layers | G23: ='Input Scenarios'!G20 -> 1234 | H23: ='Input Scenarios'!H20 -> 150 | I23: =IF('Input Scenarios'!I20<>"", 'Input Scenarios'!I20,_xlfn.XLOOKUP($F23,Constants!$A$2:$A$5,Constants!B$2:B$5)) -> 0.086 | J23: =IF('Input Scenarios'!J20<>"", 'Input Scenarios'!J20,_xlfn.XLOOKUP($F23,Constants!$A$2:$A$5,Constants!C$2:C$5)) -> 0.8 | K23: =IF('Input Scenarios'!K20<>"", 'Input Scenarios'!K20,_xlfn.XLOOKUP($F23,Constants!$A$2:$A$5,Constants!D$2:D$5)) -> 0.19 | L23: =IF('Input Scenarios'!L20<>"", 'Input Scenarios'!L20,_xlfn.XLOOKUP($F23,Constants!$A$2:$A$5,Constants!E$2:E$5)) -> 0.35 | M23: ='Input Scenarios'!M20 -> 0.1 | N23: ='Input Scenarios'!N20 -> 0 | O23: ='Input Scenarios'!O20 -> 0 | P23: ='Input Scenarios'!P20 -> 0.9 | Q23: ='Input Scenarios'!Q20 -> 0.5 | R23: ='Input Scenarios'!R20 -> 0.25 | S23: ='Input Scenarios'!S20 -> 0.25 | T23: ='Input Scenarios'!T20 -> 0 | ... AE23: ='Input Scenarios'!AE20 -> 0 | AF23: =I23*(1-J23)*(1-AG23) -> 0.014104 | AG23: =IF(F23="", "",_xlfn.XLOOKUP(F23,Constants!$A$2:$A$5,Constants!F$2:F$5)) -> 0.18 | AH23: =IF(F23="", "",_xlfn.XLOOKUP(F23,Constants!$A$2:$A$5,Constants!G$2:G$5)) -> 0.39 | AI23: =_xlfn.XLOOKUP($A23, Constants!$F$8:$M$8,Constants!$F$9:$M$9) -> 0.015 | AJ23: =_xlfn.XLOOKUP($A23, Constants!$F$8:$M$8,Constants!$F$10:$M$10) -> 0.015 | AK23: =_xlfn.XLOOKUP($A23, Constants!$F$8:$M$8,Constants!$F$11:$M$11) -> 0.015 | AL23: =_xlfn.XLOOKUP($A23, Constants!$F$8:$M$8,Constants!$F$16:$M$16) -> 0.03 | AM23: =$AF23*$AH23*M23*AI23*Constants!$I$2 -> 5.5973699e-06 | AN23: =$AF23*$AH23*N23*AJ23*Constants!$I$2 -> 0 | AO23: =$AF23*$AH23*O23*AK23*Constants!$I$2 -> 0 | AP23: =$AF23*$AH23*P23*AL23*Constants!$I$2 -> 0.00010075266 | AQ23: =AM23*$G23*$H23 -> 1.0360732 | AR23: =AN23*$G23*$H23 -> 0 | AS23: =AO23*$G23*$H23 -> 0 | AT23: =AP23*$G23*$H23 -> 18.649317 | AU23: =SUM(AQ23:AT23) -> 19.68539 | AV23: =_xlfn.XLOOKUP($A23, Constants!$F$8:$M$8,Constants!$F$12:$M$12) -> 0.02 | AW23: =_xlfn.XLOOKUP($A23, Constants!$F$8:$M$8,Constants!$F$13:$M$13) -> 0.01 | AX23: =_xlfn.XLOOKUP($A23, Constants!$F$8:$M$8,Constants!$F$15:$M$15) -> 0.1 | AY23: =_xlfn.XLOOKUP($A23, Constants!$F$8:$M$8,Constants!$F$14:$M$14) -> 0 | AZ23: =_xlfn.XLOOKUP($A23, Constants!$F$8:$M$8,Constants!$F$17:$M$17) -> 0 | BA23: =Constants!$E$9 -> 0.15 | BB23: =Constants!$E$10 -> 0 | BC23: =Constants!$E$11 -> 0.2 | BD23: =$AF23*M23*(1-BA23) -> 0.00119884 | BE23: =$AF23*N23*(1-BB23) -> 0 | BF23: =$AF23*O23*(1-BC23) -> 0 | BG23: =SUM(BD23:BF23) -> 0.00119884 | BH23: =(($BD23*Q23)+($BE23*V23)+($BF23*AA23))*AV23*$AH23*Constants!$I$2 -> 3.1718429e-06 | BI23: =(($BD23*R23)+($BE23*W23)+($BF23*AB23))*AW23*$AH23*Constants!$I$2 -> 7.9296073e-07 | BJ23: =(($BD23*S23)+($BE23*X23)+($BF23*AC23))*AX23*$AH23*Constants!$I$2 -> 7.9296073e-06 | BK23: =(($BD23*T23)+($BE23*Y23)+($BF23*AD23))*AY23*$AH23*Constants!$I$2 -> 0 | BL23: =(($BD23*U23)+($BE23*Z23)+($BF23*AE23))*AZ23*$AH23*Constants!$I$2 -> 0 | BM23: =$G23*$H23*BH23 -> 0.58710812 | BN23: =$G23*$H23*BI23 -> 0.14677703 | BO23: =$G23*$H23*BJ23 -> 1.4677703 | BP23: =$G23*$H23*BK23 -> 0 | BQ23: =$G23*$H23*BL23 -> 0 | BR23: =SUM(BM23:BQ23) -> 2.2016555 | BS23: =AU23+BR23 -> 21.887046 | BT23: =SUM(BS23:BS26)/1000 -> 0.091378582
A24: ='Input Scenarios'!A21 -> NT | B24: ='Input Scenarios'!B21 -> 0 | C24: ='Input Scenarios'!C21 -> Non-irrigated crop (high rainfall) | D24: ='Input Scenarios'!D21 -> dry | E24: ='Input Scenarios'!E21 -> FALSE | F24: ='Input Scenarios'!F21 -> meatChickenBreeder | G24: ='Input Scenarios'!G21 -> 1234 | H24: ='Input Scenarios'!H21 -> 150 | I24: =IF('Input Scenarios'!I21<>"", 'Input Scenarios'!I21,_xlfn.XLOOKUP($F24,Constants!$A$2:$A$5,Constants!B$2:B$5)) -> 0.103 | J24: =IF('Input Scenarios'!J21<>"", 'Input Scenarios'!J21,_xlfn.XLOOKUP($F24,Constants!$A$2:$A$5,Constants!C$2:C$5)) -> 0.8 | K24: =IF('Input Scenarios'!K21<>"", 'Input Scenarios'!K21,_xlfn.XLOOKUP($F24,Constants!$A$2:$A$5,Constants!D$2:D$5)) -> 0.19 | L24: =IF('Input Scenarios'!L21<>"", 'Input Scenarios'!L21,_xlfn.XLOOKUP($F24,Constants!$A$2:$A$5,Constants!E$2:E$5)) -> 0.32 | M24: ='Input Scenarios'!M21 -> 0.1 | N24: ='Input Scenarios'!N21 -> 0 | O24: ='Input Scenarios'!O21 -> 0 | P24: ='Input Scenarios'!P21 -> 0.9 | Q24: ='Input Scenarios'!Q21 -> 0.5 | R24: ='Input Scenarios'!R21 -> 0.25 | S24: ='Input Scenarios'!S21 -> 0.25 | T24: ='Input Scenarios'!T21 -> 0 | ... AE24: ='Input Scenarios'!AE21 -> 0 | AF24: =I24*(1-J24)*(1-AG24) -> 0.016892 | AG24: =IF(F24="", "",_xlfn.XLOOKUP(F24,Constants!$A$2:$A$5,Constants!F$2:F$5)) -> 0.18 | AH24: =IF(F24="", "",_xlfn.XLOOKUP(F24,Constants!$A$2:$A$5,Constants!G$2:G$5)) -> 0.36 | AI24: =_xlfn.XLOOKUP($A24, Constants!$F$8:$M$8,Constants!$F$9:$M$9) -> 0.015 | AJ24: =_xlfn.XLOOKUP($A24, Constants!$F$8:$M$8,Constants!$F$10:$M$10) -> 0.015 | AK24: =_xlfn.XLOOKUP($A24, Constants!$F$8:$M$8,Constants!$F$11:$M$11) -> 0.015 | AL24: =_xlfn.XLOOKUP($A24, Constants!$F$8:$M$8,Constants!$F$16:$M$16) -> 0.03 | AM24: =$AF24*$AH24*M24*AI24*Constants!$I$2 -> 6.1881477e-06 | AN24: =$AF24*$AH24*N24*AJ24*Constants!$I$2 -> 0 | AO24: =$AF24*$AH24*O24*AK24*Constants!$I$2 -> 0 | AP24: =$AF24*$AH24*P24*AL24*Constants!$I$2 -> 0.00011138666 | AQ24: =AM24*$G24*$H24 -> 1.1454261 | AR24: =AN24*$G24*$H24 -> 0 | AS24: =AO24*$G24*$H24 -> 0 | AT24: =AP24*$G24*$H24 -> 20.617671 | AU24: =SUM(AQ24:AT24) -> 21.763097 | AV24: =_xlfn.XLOOKUP($A24, Constants!$F$8:$M$8,Constants!$F$12:$M$12) -> 0.02 | AW24: =_xlfn.XLOOKUP($A24, Constants!$F$8:$M$8,Constants!$F$13:$M$13) -> 0.01 | AX24: =_xlfn.XLOOKUP($A24, Constants!$F$8:$M$8,Constants!$F$15:$M$15) -> 0.1 | AY24: =_xlfn.XLOOKUP($A24, Constants!$F$8:$M$8,Constants!$F$14:$M$14) -> 0 | AZ24: =_xlfn.XLOOKUP($A24, Constants!$F$8:$M$8,Constants!$F$17:$M$17) -> 0 | BA24: =Constants!$E$9 -> 0.15 | BB24: =Constants!$E$10 -> 0 | BC24: =Constants!$E$11 -> 0.2 | BD24: =$AF24*M24*(1-BA24) -> 0.00143582 | BE24: =$AF24*N24*(1-BB24) -> 0 | BF24: =$AF24*O24*(1-BC24) -> 0 | BG24: =SUM(BD24:BF24) -> 0.00143582 | BH24: =(($BD24*Q24)+($BE24*V24)+($BF24*AA24))*AV24*$AH24*Constants!$I$2 -> 3.506617e-06 | BI24: =(($BD24*R24)+($BE24*W24)+($BF24*AB24))*AW24*$AH24*Constants!$I$2 -> 8.7665426e-07 | BJ24: =(($BD24*S24)+($BE24*X24)+($BF24*AC24))*AX24*$AH24*Constants!$I$2 -> 8.7665426e-06 | BK24: =(($BD24*T24)+($BE24*Y24)+($BF24*AD24))*AY24*$AH24*Constants!$I$2 -> 0 | BL24: =(($BD24*U24)+($BE24*Z24)+($BF24*AE24))*AZ24*$AH24*Constants!$I$2 -> 0 | BM24: =$G24*$H24*BH24 -> 0.64907481 | BN24: =$G24*$H24*BI24 -> 0.1622687 | BO24: =$G24*$H24*BJ24 -> 1.622687 | BP24: =$G24*$H24*BK24 -> 0 | BQ24: =$G24*$H24*BL24 -> 0 | BR24: =SUM(BM24:BQ24) -> 2.4340306 | BS24: =AU24+BR24 -> 24.197127
A25: ='Input Scenarios'!A22 -> NT | B25: ='Input Scenarios'!B22 -> 0 | C25: ='Input Scenarios'!C22 -> Non-irrigated crop (high rainfall) | D25: ='Input Scenarios'!D22 -> dry | E25: ='Input Scenarios'!E22 -> FALSE | F25: ='Input Scenarios'!F22 -> meatChickenGrowers | G25: ='Input Scenarios'!G22 -> 1234 | H25: ='Input Scenarios'!H22 -> 150 | I25: =IF('Input Scenarios'!I22<>"", 'Input Scenarios'!I22,_xlfn.XLOOKUP($F25,Constants!$A$2:$A$5,Constants!B$2:B$5)) -> 0.093 | J25: =IF('Input Scenarios'!J22<>"", 'Input Scenarios'!J22,_xlfn.XLOOKUP($F25,Constants!$A$2:$A$5,Constants!C$2:C$5)) -> 0.8 | K25: =IF('Input Scenarios'!K22<>"", 'Input Scenarios'!K22,_xlfn.XLOOKUP($F25,Constants!$A$2:$A$5,Constants!D$2:D$5)) -> 0.23 | L25: =IF('Input Scenarios'!L22<>"", 'Input Scenarios'!L22,_xlfn.XLOOKUP($F25,Constants!$A$2:$A$5,Constants!E$2:E$5)) -> 0.47 | M25: ='Input Scenarios'!M22 -> 0.1 | N25: ='Input Scenarios'!N22 -> 0 | O25: ='Input Scenarios'!O22 -> 0 | P25: ='Input Scenarios'!P22 -> 0.9 | Q25: ='Input Scenarios'!Q22 -> 0.5 | R25: ='Input Scenarios'!R22 -> 0.25 | S25: ='Input Scenarios'!S22 -> 0.25 | T25: ='Input Scenarios'!T22 -> 0 | ... AE25: ='Input Scenarios'!AE22 -> 0 | AF25: =I25*(1-J25)*(1-AG25) -> 0.01581 | AG25: =IF(F25="", "",_xlfn.XLOOKUP(F25,Constants!$A$2:$A$5,Constants!F$2:F$5)) -> 0.15 | AH25: =IF(F25="", "",_xlfn.XLOOKUP(F25,Constants!$A$2:$A$5,Constants!G$2:G$5)) -> 0.36 | AI25: =_xlfn.XLOOKUP($A25, Constants!$F$8:$M$8,Constants!$F$9:$M$9) -> 0.015 | AJ25: =_xlfn.XLOOKUP($A25, Constants!$F$8:$M$8,Constants!$F$10:$M$10) -> 0.015 | AK25: =_xlfn.XLOOKUP($A25, Constants!$F$8:$M$8,Constants!$F$11:$M$11) -> 0.015 | AL25: =_xlfn.XLOOKUP($A25, Constants!$F$8:$M$8,Constants!$F$16:$M$16) -> 0.03 | AM25: =$AF25*$AH25*M25*AI25*Constants!$I$2 -> 5.7917722e-06 | AN25: =$AF25*$AH25*N25*AJ25*Constants!$I$2 -> 0 | AO25: =$AF25*$AH25*O25*AK25*Constants!$I$2 -> 0 | AP25: =$AF25*$AH25*P25*AL25*Constants!$I$2 -> 0.0001042519 | AQ25: =AM25*$G25*$H25 -> 1.072057 | AR25: =AN25*$G25*$H25 -> 0 | AS25: =AO25*$G25*$H25 -> 0 | AT25: =AP25*$G25*$H25 -> 19.297026 | AU25: =SUM(AQ25:AT25) -> 20.369084 | AV25: =_xlfn.XLOOKUP($A25, Constants!$F$8:$M$8,Constants!$F$12:$M$12) -> 0.02 | AW25: =_xlfn.XLOOKUP($A25, Constants!$F$8:$M$8,Constants!$F$13:$M$13) -> 0.01 | AX25: =_xlfn.XLOOKUP($A25, Constants!$F$8:$M$8,Constants!$F$15:$M$15) -> 0.1 | AY25: =_xlfn.XLOOKUP($A25, Constants!$F$8:$M$8,Constants!$F$14:$M$14) -> 0 | AZ25: =_xlfn.XLOOKUP($A25, Constants!$F$8:$M$8,Constants!$F$17:$M$17) -> 0 | BA25: =Constants!$E$9 -> 0.15 | BB25: =Constants!$E$10 -> 0 | BC25: =Constants!$E$11 -> 0.2 | BD25: =$AF25*M25*(1-BA25) -> 0.00134385 | BE25: =$AF25*N25*(1-BB25) -> 0 | BF25: =$AF25*O25*(1-BC25) -> 0 | BG25: =SUM(BD25:BF25) -> 0.00134385 | BH25: =(($BD25*Q25)+($BE25*V25)+($BF25*AA25))*AV25*$AH25*Constants!$I$2 -> 3.2820042e-06 | BI25: =(($BD25*R25)+($BE25*W25)+($BF25*AB25))*AW25*$AH25*Constants!$I$2 -> 8.2050106e-07 | BJ25: =(($BD25*S25)+($BE25*X25)+($BF25*AC25))*AX25*$AH25*Constants!$I$2 -> 8.2050106e-06 | BK25: =(($BD25*T25)+($BE25*Y25)+($BF25*AD25))*AY25*$AH25*Constants!$I$2 -> 0 | BL25: =(($BD25*U25)+($BE25*Z25)+($BF25*AE25))*AZ25*$AH25*Constants!$I$2 -> 0 | BM25: =$G25*$H25*BH25 -> 0.60749898 | BN25: =$G25*$H25*BI25 -> 0.15187475 | BO25: =$G25*$H25*BJ25 -> 1.5187475 | BP25: =$G25*$H25*BK25 -> 0 | BQ25: =$G25*$H25*BL25 -> 0 | BR25: =SUM(BM25:BQ25) -> 2.2781212 | BS25: =AU25+BR25 -> 22.647205
A26: ='Input Scenarios'!A23 -> NT | B26: ='Input Scenarios'!B23 -> 0 | C26: ='Input Scenarios'!C23 -> Non-irrigated crop (high rainfall) | D26: ='Input Scenarios'!D23 -> dry | E26: ='Input Scenarios'!E23 -> FALSE | F26: ='Input Scenarios'!F23 -> meatOther | G26: ='Input Scenarios'!G23 -> 1234 | H26: ='Input Scenarios'!H23 -> 150 | I26: =IF('Input Scenarios'!I23<>"", 'Input Scenarios'!I23,_xlfn.XLOOKUP($F26,Constants!$A$2:$A$5,Constants!B$2:B$5)) -> 0.093 | J26: =IF('Input Scenarios'!J23<>"", 'Input Scenarios'!J23,_xlfn.XLOOKUP($F26,Constants!$A$2:$A$5,Constants!C$2:C$5)) -> 0.8 | K26: =IF('Input Scenarios'!K23<>"", 'Input Scenarios'!K23,_xlfn.XLOOKUP($F26,Constants!$A$2:$A$5,Constants!D$2:D$5)) -> 0.23 | L26: =IF('Input Scenarios'!L23<>"", 'Input Scenarios'!L23,_xlfn.XLOOKUP($F26,Constants!$A$2:$A$5,Constants!E$2:E$5)) -> 0.47 | M26: ='Input Scenarios'!M23 -> 0.1 | N26: ='Input Scenarios'!N23 -> 0 | O26: ='Input Scenarios'!O23 -> 0 | P26: ='Input Scenarios'!P23 -> 0.9 | Q26: ='Input Scenarios'!Q23 -> 0.5 | R26: ='Input Scenarios'!R23 -> 0.25 | S26: ='Input Scenarios'!S23 -> 0.25 | T26: ='Input Scenarios'!T23 -> 0 | ... AE26: ='Input Scenarios'!AE23 -> 0 | AF26: =I26*(1-J26)*(1-AG26) -> 0.01581 | AG26: =IF(F26="", "",_xlfn.XLOOKUP(F26,Constants!$A$2:$A$5,Constants!F$2:F$5)) -> 0.15 | AH26: =IF(F26="", "",_xlfn.XLOOKUP(F26,Constants!$A$2:$A$5,Constants!G$2:G$5)) -> 0.36 | AI26: =_xlfn.XLOOKUP($A26, Constants!$F$8:$M$8,Constants!$F$9:$M$9) -> 0.015 | AJ26: =_xlfn.XLOOKUP($A26, Constants!$F$8:$M$8,Constants!$F$10:$M$10) -> 0.015 | AK26: =_xlfn.XLOOKUP($A26, Constants!$F$8:$M$8,Constants!$F$11:$M$11) -> 0.015 | AL26: =_xlfn.XLOOKUP($A26, Constants!$F$8:$M$8,Constants!$F$16:$M$16) -> 0.03 | AM26: =$AF26*$AH26*M26*AI26*Constants!$I$2 -> 5.7917722e-06 | AN26: =$AF26*$AH26*N26*AJ26*Constants!$I$2 -> 0 | AO26: =$AF26*$AH26*O26*AK26*Constants!$I$2 -> 0 | AP26: =$AF26*$AH26*P26*AL26*Constants!$I$2 -> 0.0001042519 | AQ26: =AM26*$G26*$H26 -> 1.072057 | AR26: =AN26*$G26*$H26 -> 0 | AS26: =AO26*$G26*$H26 -> 0 | AT26: =AP26*$G26*$H26 -> 19.297026 | AU26: =SUM(AQ26:AT26) -> 20.369084 | AV26: =_xlfn.XLOOKUP($A26, Constants!$F$8:$M$8,Constants!$F$12:$M$12) -> 0.02 | AW26: =_xlfn.XLOOKUP($A26, Constants!$F$8:$M$8,Constants!$F$13:$M$13) -> 0.01 | AX26: =_xlfn.XLOOKUP($A26, Constants!$F$8:$M$8,Constants!$F$15:$M$15) -> 0.1 | AY26: =_xlfn.XLOOKUP($A26, Constants!$F$8:$M$8,Constants!$F$14:$M$14) -> 0 | AZ26: =_xlfn.XLOOKUP($A26, Constants!$F$8:$M$8,Constants!$F$17:$M$17) -> 0 | BA26: =Constants!$E$9 -> 0.15 | BB26: =Constants!$E$10 -> 0 | BC26: =Constants!$E$11 -> 0.2 | BD26: =$AF26*M26*(1-BA26) -> 0.00134385 | BE26: =$AF26*N26*(1-BB26) -> 0 | BF26: =$AF26*O26*(1-BC26) -> 0 | BG26: =SUM(BD26:BF26) -> 0.00134385 | BH26: =(($BD26*Q26)+($BE26*V26)+($BF26*AA26))*AV26*$AH26*Constants!$I$2 -> 3.2820042e-06 | BI26: =(($BD26*R26)+($BE26*W26)+($BF26*AB26))*AW26*$AH26*Constants!$I$2 -> 8.2050106e-07 | BJ26: =(($BD26*S26)+($BE26*X26)+($BF26*AC26))*AX26*$AH26*Constants!$I$2 -> 8.2050106e-06 | BK26: =(($BD26*T26)+($BE26*Y26)+($BF26*AD26))*AY26*$AH26*Constants!$I$2 -> 0 | BL26: =(($BD26*U26)+($BE26*Z26)+($BF26*AE26))*AZ26*$AH26*Constants!$I$2 -> 0 | BM26: =$G26*$H26*BH26 -> 0.60749898 | BN26: =$G26*$H26*BI26 -> 0.15187475 | BO26: =$G26*$H26*BJ26 -> 1.5187475 | BP26: =$G26*$H26*BK26 -> 0 | BQ26: =$G26*$H26*BL26 -> 0 | BR26: =SUM(BM26:BQ26) -> 2.2781212 | BS26: =AU26+BR26 -> 22.647205
AF27: =IF(F27="", "",I27*(1-#REF!)*(1-AG27)) | AG27: =IF(F27="", "",_xlfn.XLOOKUP(F27,Constants!$A$2:$A$5,Constants!F$2:F$5)) | AH27: =IF(F27="", "",_xlfn.XLOOKUP(F27,Constants!$A$2:$A$5,Constants!G$2:G$5)) | AP27: =IF(ISBLANK(M27),"",$AF$26*$AH$26*N27*AI27*Constants!$I$2) | AU27: =IF(ISBLANK(G27), "", $G$26*AK27*$H$26) | AZ27: =IF(ISBLANK(M27), "", $G$26*AP27*$H$26) | BA27: =IF(OR(ISBLANK(M27), M27="pastureRangeAndPaddock"), "",_xlfn.XLOOKUP(M27,Constants!$B$9:$B$17,Constants!$E$9:$E$17)) | BF27: =IF(OR(ISBLANK(M27), M27="pastureRangeAndPaddock"), "",$AF$21*N27*(1-BA27)) | BG27: =IF(F27="", "",SUM(BF27:BF29)) | BT27: =IF(F27="", "", SUM(AZ27:AZ30,BQ27:BQ31)/1000)
AF28: =IF(F28="", "",I28*(1-#REF!)*(1-AG28)) | AG28: =IF(F28="", "",_xlfn.XLOOKUP(F28,Constants!$A$2:$A$5,Constants!F$2:F$5)) | AH28: =IF(F28="", "",_xlfn.XLOOKUP(F28,Constants!$A$2:$A$5,Constants!G$2:G$5)) | AP28: =IF(ISBLANK(M28),"",$AF$26*$AH$26*N28*AI28*Constants!$I$2) | AU28: =IF(ISBLANK(G28), "", $G$26*AK28*$H$26) | AZ28: =IF(ISBLANK(M28), "", $G$26*AP28*$H$26) | BA28: =IF(OR(ISBLANK(M28), M28="pastureRangeAndPaddock"), "",_xlfn.XLOOKUP(M28,Constants!$B$9:$B$17,Constants!$E$9:$E$17)) | BF28: =IF(OR(ISBLANK(M28), M28="pastureRangeAndPaddock"), "",$AF$21*N28*(1-BA28)) | BG28: =IF(F28="", "",SUM(BF28:BF30)) | BT28: =IF(F28="", "", SUM(AZ28:AZ31,BF28:BF32)/1000)
AF29: =IF(F29="", "",I29*(1-#REF!)*(1-AG29)) | AG29: =IF(F29="", "",_xlfn.XLOOKUP(F29,Constants!$A$2:$A$5,Constants!F$2:F$5)) | AH29: =IF(F29="", "",_xlfn.XLOOKUP(F29,Constants!$A$2:$A$5,Constants!G$2:G$5)) | AP29: =IF(ISBLANK(M29),"",$AF$26*$AH$26*N29*AI29*Constants!$I$2) | AU29: =IF(ISBLANK(G29), "", $G$26*AK29*$H$26) | AZ29: =IF(ISBLANK(M29), "", $G$26*AP29*$H$26) | BA29: =IF(OR(ISBLANK(M29), M29="pastureRangeAndPaddock"), "",_xlfn.XLOOKUP(M29,Constants!$B$9:$B$17,Constants!$E$9:$E$17)) | BF29: =IF(OR(ISBLANK(M29), M29="pastureRangeAndPaddock"), "",$AF$21*N29*(1-BA29)) | BG29: =IF(F29="", "",SUM(BF29:BF31)) | BT29: =IF(F29="", "", SUM(AL29:AL32,BF29:BF33)/1000)
