Workbook

Sheet Constants
A1: Table A.1.6.1: Swine – Intake and manure characteristics derived from PigBal (2020-2024)
A2: Class (j) | B2: Feed Intake (Ij) | C2: Volatile Solids (VSj) | D2: Nitrogen in Waste (NWj)
A3: boars | B3: 2.62 | C3: 0.4 | D3: 0.046
A4: sows | B4: 2.3 | C4: 0.46 | D4: 0.049
A5: gilts | B5: 2.5 | C5: 0.55 | D5: 0.046
A6: others | B6: 1.71 | C6: 0.39 | D6: =11.4/365 -> 0.031232877
G7: NOTE: There are no ACT values, the NSW values are being used for ACT
C8: Table A.1.6.2: Swine – Fraction of N volatilised by MMS | D8: Table A.1.6.3: Swine – Nitrous oxide EFs by MMS | E8: 4.5.2.3 | F8: Table A.1.6.4: Swine – MCFs (by State)
A9: MMS (m) | B9: m | C9: FracGASMmT | D9: EFm | E9: VSLm | F9: NSW | G9: ACT | H9: QLD | I9: NT | J9: SA | K9: TAS | L9: VIC | M9: WA
A10: anaerobicLagoon | B10: 1 | C10: 0.55 | D10: 0 | E10: 0 | F10: 0.75 | G10: =F10 -> 0.75 | H10: 0.78 | I10: =H10 -> 0.78 | J10: 0.75 | K10: 0.7 | L10: 0.74 | M10: 0.76
A11: solidStorage | B11: 4 | C11: 0.2 | D11: 0.005 | E11: 0 | F11: 0.02 | G11: =F11 -> 0.02 | H11: 0.02 | I11: =H11 -> 0.02 | J11: 0.02 | K11: 0.02 | L11: 0.02 | M11: 0.02
A12: outdoorAndFreeRange | B12: 5 | C12: 0.3 | D12: 0.02 | E12: 0 | F12: 0.01 | G12: =F12 -> 0.01 | H12: 0.03 | I12: =H12 -> 0.03 | J12: 0.01 | K12: 0.01 | L12: 0.01 | M12: 0.01
A13: digester | B13: 7 | C13: 0 | D13: 0 | E13: 0.75 | F13: 0.1 | G13: =F13 -> 0.1 | H13: 0.1 | I13: =H13 -> 0.1 | J13: 0.1 | K13: 0.1 | L13: 0.1 | M13: 0.1
A14: deepLitter | B14: 8 | C14: 0.125 | D14: 0.01 | E14: 0.05 | F14: 0.04 | G14: =F14 -> 0.04 | H14: 0.04 | I14: =H14 -> 0.04 | J14: 0.04 | K14: 0.04 | L14: 0.04 | M14: 0.04
A15: pitStorage | B15: 9 | C15: 0.25 | D15: 0.002 | E15: 0 | F15: 0.03 | G15: =F15 -> 0.03 | H15: 0.03 | I15: =H15 -> 0.03 | J15: 0.03 | K15: 0.03 | L15: 0.03 | M15: 0.03
A16: directApplication | B16: 13 | E16: 0 | F16: 0 | G16: =F16 -> 0 | H16: 0 | I16: =H16 -> 0 | J16: 0 | K16: 0 | L16: 0 | M16: 0
A18: Fixed Constants | D18: Production System | E18: EFN2O
A19: SSj | B19: 0.25 | D19: Irrigated pasture | E19: 0.0059
A20: SNj | B20: 0.25 | D20: Irrigated crop | E20: 0.007
A21: Bo | B21: 0.19 | D21: Non-irrigated pasture | E21: 0.0018
A22: p | B22: 0.6784 | D22: Non-irrigated crop (low rainfall) | E22: 0.0029
A23: CN2O | B23: =44/28 -> 1.5714286 | D23: Non-irrigated crop (high rainfall) | E23: 0.008
A24: EFLeach | B24: 0.011
A25: FracLEACHMS | B25: 0.02

Sheet Input Scenarios
A2: Method 1
A4: input | B4: input | C4: input | D4: input | E4: input | F4: input | G4: input | I4: input | J4: input | K4: input | L4: input | M4: input | N4: input | O4: input | P4: input | Q4: input | R4: input | S4: input
A8: State | B8: MAT | C8: Production system | D8: Leaching zone | E8: Swine class | F8: Number of poultry in each class j and subclass k | G8: Duration of stay for each class and subclass of poultry | H8: Feed Intake | I8: Volatile Solid production | J8: Nitrogen Waste production | K8: Uncovered anaerobic lagoons | L8: Solid Storage | M8: Outdoor | N8: Covered/Digester | O8: Deep Litter | P8: Pit Storage < 1 Month | Q8: Solids separated | R8: Solid separation rate | S8: Nitrogen separation rate
A10: i | B10: i | D10: (true or false) | E10: j | F10: Nj | G10: Dj | H10: Ij | I10: VSj | J10: NWj | K10: MMSjm=1T=1 | L10: MMSjm=4T=1 | M10: MMSjm=5T=1 | N10: MMSjm=7T=1 | O10: MMSjm=8T=1 | P10: MMSjm=9T=1 | Q10: true/false | R10: SSj | S10: SNj
A11: NSW | C11: Irrigated crop | D11: TRUE | E11: boars | F11: 111 | G11: 105 | K11: 1 | Q11: TRUE
A12: NSW | C12: Irrigated crop | D12: TRUE | E12: sows | F12: 222 | G12: 103 | K12: 1 | Q12: TRUE
A13: NSW | C13: Irrigated crop | D13: TRUE | E13: gilts | F13: 333 | G13: 200 | O13: 1 | Q13: FALSE
A14: NSW | C14: Irrigated crop | D14: TRUE | E14: others | F14: 444 | G14: 365 | O14: 1 | Q14: FALSE
A15: NT | C15: Irrigated pasture | D15: TRUE | E15: boars | F15: 105 | G15: 75 | K15: 0.2 | L15: 0.1 | M15: 0.2 | N15: 0.2 | O15: 0.2 | P15: 0.1 | Q15: TRUE
A16: NT | C16: Irrigated pasture | D16: TRUE | E16: sows | F16: 245 | G16: 290 | K16: 0.2 | L16: 0.1 | M16: 0.2 | N16: 0.2 | O16: 0.2 | P16: 0.1 | Q16: TRUE
A17: NT | C17: Irrigated pasture | D17: TRUE | E17: gilts | F17: 434 | G17: 280 | K17: 0.2 | L17: 0.1 | M17: 0.2 | N17: 0.2 | O17: 0.2 | P17: 0.1 | Q17: TRUE
A18: NT | C18: Irrigated pasture | D18: TRUE | E18: others | F18: 44 | G18: 290 | K18: 0.2 | L18: 0.1 | M18: 0.2 | N18: 0.2 | O18: 0.2 | P18: 0.1 | Q18: TRUE
A19: QLD | C19: Non-irrigated pasture | D19: TRUE | E19: boars | F19: 1000 | G19: 100 | Q19: FALSE
A20: QLD | C20: Non-irrigated pasture | D20: TRUE | E20: sows | F20: 233 | G20: 100 | Q20: FALSE
A21: QLD | C21: Non-irrigated pasture | D21: TRUE | E21: gilts | F21: 923 | G21: 100 | Q21: FALSE
A22: QLD | C22: Non-irrigated pasture | D22: TRUE | E22: others | F22: 122 | G22: 100 | Q22: FALSE
A23: WA | C23: Non-irrigated crop (low rainfall) | D23: FALSE | E23: boars | F23: 750 | G23: 200 | Q23: FALSE
A24: WA | C24: Non-irrigated crop (low rainfall) | D24: FALSE | E24: sows | F24: 600 | G24: 200 | Q24: FALSE
A25: WA | C25: Non-irrigated crop (low rainfall) | D25: FALSE | E25: gilts | F25: 100 | G25: 299 | Q25: TRUE
A26: WA | C26: Non-irrigated crop (low rainfall) | D26: FALSE | E26: others | F26: 999 | G26: 299 | Q26: TRUE

Sheet 4.5.1.1
A2: Method 1
A4: input | B4: input | C4: input | D4: input | E4: input | F4: input | G4: input | I4: input | K4: input | L4: input | M4: input | N4: input | O4: input | P4: input | Q4: input | R4: input
A8: State | B8: MAT | C8: Production system | D8: Leaching zone | E8: Swine class | F8: Number of poultry in each class j and subclass k | G8: Duration of stay for each class and subclass of poultry | H8: Feed Intake | I8: Volatile solid production | J8: Nitrogen waste production | K8: Uncovered anaerobic lagoons | L8: Outdoor | M8: Covered/Digester | N8: Deep Litter | O8: Pit Storage < 1 Month | P8: Solid Storage | Q8: Solids separated | R8: Solid separation rate
A10: i | B10: i | D10: (true or false) | E10: j | F10: Nj | G10: Dj | H10: Ij | I10: VSj | J10: NWj | K10: MMSjm=1T=1 | L10: MMSjm=5T=1 | M10: MMSjm=7T=1 | N10: MMSjm=8T=1 | O10: MMSjm=9T=1 | P10: MMSjm=4T=1 | Q10: true/false | R10: SSj | S10: SNj | T10: FVSjm=1T=1 | U10: FVSjm=5T=1 | V10: FVSjm=7T=1 | W10: FVSjm=8T=1 | X10: FVSjm=9T=1 | Y10: FVSjm=4T=1 | Z10: Bo | AA10: p | AB10: MCFim=1 | AC10: MCFim=5 | AD10: MCFim=7 | AE10: MCFim=8 | AF10: MCFim=9 | AG10: MCFim=4 | AH10: MCFim=13 | AI10: Mjm=1T=1 | AJ10: Mjm=5T=1 | AK10: Mjm=7T=1 | AL10: Mjm=8T=1 | AM10: Mjm=9T=1 | AN10: Mjm=4T=1 | AO10: ECH4jmT=1 | AP10: VSLm=1T=1 | AQ10: VSLm=5T=1 | AR10: VSLm=7T=1 | AS10: VSLm=8T=1 | AT10: VSLm=9T=1 | AU10: VSLm=4T=1 | AV10: VSTjm=1T=2 | AW10: VSTjm=5T=2 | AX10: VSTjm=7T=2 | AY10: VSTjm=8T=2 | AZ10: VSTjm=9T=2 | BA10: VSTjm=4T=2 | BB10: VSTjmT=2 | BC10: FVSjm=1T=2 | BD10: FVSjm=4T=2 | BE10: FVSjm=13T=2 | BF10: Mjm=1T=2 | BG10: Mjm=4T=2 | BH10: Mjm=13T=2 | BI10: ECH4jmT=2 | BJ10: ECH4j | BK10: ECH4
A11: ='Input Scenarios'!A11 -> NSW | B11: ='Input Scenarios'!B11 -> 0 | C11: ='Input Scenarios'!C11 -> Irrigated crop | D11: ='Input Scenarios'!D11 -> TRUE | E11: ='Input Scenarios'!E11 -> boars | F11: ='Input Scenarios'!F11 -> 111 | G11: ='Input Scenarios'!G11 -> 105 | H11: =IF('Input Scenarios'!H11<>"", 'Input Scenarios'!H11, _xlfn.XLOOKUP($E11,Constants!$A$3:$A$6, Constants!B$3:B$6)) -> 2.62 | I11: =IF('Input Scenarios'!I11<>"", 'Input Scenarios'!I11, _xlfn.XLOOKUP($E11,Constants!$A$3:$A$6, Constants!C$3:C$6)) -> 0.4 | J11: =IF('Input Scenarios'!J11<>"", 'Input Scenarios'!J11, _xlfn.XLOOKUP($E11,Constants!$A$3:$A$6, Constants!D$3:D$6)) -> 0.046 | K11: ='Input Scenarios'!K11 -> 1 | L11: ='Input Scenarios'!L11 -> 0 | M11: ='Input Scenarios'!M11 -> 0 | N11: ='Input Scenarios'!N11 -> 0 | O11: ='Input Scenarios'!O11 -> 0 | P11: ='Input Scenarios'!P11 -> 0 | Q11: ='Input Scenarios'!Q11 -> TRUE | R11: =IF('Input Scenarios'!$R11<>"", 'Input Scenarios'!$R11, IF($Q11, Constants!$B$19, 0)) -> 0.25 | S11: =IF('Input Scenarios'!$R11<>"", 'Input Scenarios'!$R11, IF($Q11, Constants!$B$20, 0)) -> 0.25 | T11: =K11*(1-$R11) -> 0.75 | U11: =L11 -> 0 | V11: =M11*(1-$R11) -> 0 | W11: =N11 -> 0 | X11: =O11*(1-$R11) -> 0 | Y11: =P11+(SUM(K11,M11,O11)*R11) -> 0.25 | Z11: =Constants!$B$21 -> 0.19 | AA11: =Constants!$B$22 -> 0.6784 | AB11: =_xlfn.XLOOKUP($A11,Constants!$F$9:$M$9,Constants!$F$10:$M$10) -> 0.75 | AC11: =_xlfn.XLOOKUP($A11,Constants!$F$9:$M$9,Constants!$F$12:$M$12) -> 0.01 | AD11: =_xlfn.XLOOKUP($A11,Constants!$F$9:$M$9,Constants!$F$13:$M$13) -> 0.1 | AE11: =_xlfn.XLOOKUP($A11,Constants!$F$9:$M$9,Constants!$F$14:$M$14) -> 0.04 | AF11: =_xlfn.XLOOKUP($A11,Constants!$F$9:$M$9,Constants!$F$15:$M$15) -> 0.03 | AG11: =_xlfn.XLOOKUP($A11,Constants!$F$9:$M$9,Constants!$F$11:$M$11) -> 0.02 | AH11: =_xlfn.XLOOKUP($A11,Constants!$F$9:$M$9,Constants!$F$16:$M$16) -> 0 | AI11: =$I11*T11*AB11*$Z11*$AA11 -> 0.0290016 | AJ11: =$I11*U11*AC11*$Z11*$AA11 -> 0 | AK11: =$I11*V11*AD11*$Z11*$AA11 -> 0 | AL11: =$I11*W11*AE11*$Z11*$AA11 -> 0 | AM11: =$I11*X11*AF11*$Z11*$AA11 -> 0 | AN11: =$I11*Y11*AG11*$Z11*$AA11 -> 0.000257792 | AO11: =(SUM(AI11:AN11)*F11*G11)/1000 -> 0.34101821 | AP11: =Constants!$E$10 -> 0 | AQ11: =Constants!$E$12 -> 0 | AR11: =Constants!$E$13 -> 0.75 | AS11: =Constants!$E$14 -> 0.05 | AT11: =Constants!$E$15 -> 0 | AU11: =Constants!$E$11 -> 0 | AV11: =(T11*(1-AP11)) -> 0.75 | AW11: =(U11*(1-AQ11)) -> 0 | AX11: =(V11*(1-AR11)) -> 0 | AY11: =(W11*(1-AS11)) -> 0 | AZ11: =(X11*(1-AT11)) -> 0 | BA11: =(Y11*(1-AU11)) -> 0.25 | BB11: =SUM(AV11:BA11)*I11 -> 0.4 | BC11: =AX11*$I11 -> 0 | BD11: =AY11*$I11 -> 0 | BE11: =SUM(AV11:AW11, AZ11:BA11)*$I11 -> 0.4 | BF11: =BC11*$Z11*AB11*$AA11 -> 0 | BG11: =BD11*$Z11*AG11*$AA11 -> 0 | BH11: =BE11*$Z11*AH11*$AA11 -> 0 | BI11: =(SUM(BF11:BH11)*F11*G11)/1000 -> 0 | BJ11: =SUM(AI11:AN11, BF11:BH11)*F11*G11/1000 -> 0.34101821 | BK11: =SUM(BJ11:BJ14) -> 1.496464
A12: ='Input Scenarios'!A12 -> NSW | B12: ='Input Scenarios'!B12 -> 0 | C12: ='Input Scenarios'!C12 -> Irrigated crop | D12: ='Input Scenarios'!D12 -> TRUE | E12: ='Input Scenarios'!E12 -> sows | F12: ='Input Scenarios'!F12 -> 222 | G12: ='Input Scenarios'!G12 -> 103 | H12: =IF('Input Scenarios'!H12<>"", 'Input Scenarios'!H12, _xlfn.XLOOKUP($E12,Constants!$A$3:$A$6, Constants!B$3:B$6)) -> 2.3 | I12: =IF('Input Scenarios'!I12<>"", 'Input Scenarios'!I12, _xlfn.XLOOKUP($E12,Constants!$A$3:$A$6, Constants!C$3:C$6)) -> 0.46 | J12: =IF('Input Scenarios'!J12<>"", 'Input Scenarios'!J12, _xlfn.XLOOKUP($E12,Constants!$A$3:$A$6, Constants!D$3:D$6)) -> 0.049 | K12: ='Input Scenarios'!K12 -> 1 | L12: ='Input Scenarios'!L12 -> 0 | M12: ='Input Scenarios'!M12 -> 0 | N12: ='Input Scenarios'!N12 -> 0 | O12: ='Input Scenarios'!O12 -> 0 | P12: ='Input Scenarios'!P12 -> 0 | Q12: ='Input Scenarios'!Q12 -> TRUE | R12: =IF('Input Scenarios'!$R12<>"", 'Input Scenarios'!$R12, IF($Q12, Constants!$B$19, 0)) -> 0.25 | S12: =IF('Input Scenarios'!$R12<>"", 'Input Scenarios'!$R12, IF($Q12, Constants!$B$20, 0)) -> 0.25 | T12: =K12*(1-$R12) -> 0.75 | U12: =L12 -> 0 | V12: =M12*(1-$R12) -> 0 | W12: =N12 -> 0 | X12: =O12*(1-$R12) -> 0 | Y12: =P12+(SUM(K12,M12,O12)*R12) -> 0.25 | Z12: =Constants!$B$21 -> 0.19 | AA12: =Constants!$B$22 -> 0.6784 | AB12: =_xlfn.XLOOKUP($A12,Constants!$F$9:$M$9,Constants!$F$10:$M$10) -> 0.75 | AC12: =_xlfn.XLOOKUP($A12,Constants!$F$9:$M$9,Constants!$F$12:$M$12) -> 0.01 | AD12: =_xlfn.XLOOKUP($A12,Constants!$F$9:$M$9,Constants!$F$13:$M$13) -> 0.1 | AE12: =_xlfn.XLOOKUP($A12,Constants!$F$9:$M$9,Constants!$F$14:$M$14) -> 0.04 | AF12: =_xlfn.XLOOKUP($A12,Constants!$F$9:$M$9,Constants!$F$15:$M$15) -> 0.03 | AG12: =_xlfn.XLOOKUP($A12,Constants!$F$9:$M$9,Constants!$F$11:$M$11) -> 0.02 | AH12: =_xlfn.XLOOKUP($A12,Constants!$F$9:$M$9,Constants!$F$16:$M$16) -> 0 | AI12: =$I12*T12*AB12*$Z12*$AA12 -> 0.03335184 | AJ12: =$I12*U12*AC12*$Z12*$AA12 -> 0 | AK12: =$I12*V12*AD12*$Z12*$AA12 -> 0 | AL12: =$I12*W12*AE12*$Z12*$AA12 -> 0 | AM12: =$I12*X12*AF12*$Z12*$AA12 -> 0 | AN12: =$I12*Y12*AG12*$Z12*$AA12 -> 0.0002964608 | AO12: =(SUM(AI12:AN12)*F12*G12)/1000 -> 0.76940205 | AP12: =Constants!$E$10 -> 0 | AQ12: =Constants!$E$12 -> 0 | AR12: =Constants!$E$13 -> 0.75 | AS12: =Constants!$E$14 -> 0.05 | AT12: =Constants!$E$15 -> 0 | AU12: =Constants!$E$11 -> 0 | AV12: =(T12*(1-AP12)) -> 0.75 | AW12: =(U12*(1-AQ12)) -> 0 | AX12: =(V12*(1-AR12)) -> 0 | AY12: =(W12*(1-AS12)) -> 0 | AZ12: =(X12*(1-AT12)) -> 0 | BA12: =(Y12*(1-AU12)) -> 0.25 | BB12: =SUM(AV12:BA12)*I12 -> 0.46 | BC12: =AX12*$I12 -> 0 | BD12: =AY12*$I12 -> 0 | BE12: =SUM(AV12:AW12, AZ12:BA12)*$I12 -> 0.46 | BF12: =BC12*$Z12*AB12*$AA12 -> 0 | BG12: =BD12*$Z12*AG12*$AA12 -> 0 | BH12: =BE12*$Z12*AH12*$AA12 -> 0 | BI12: =(SUM(BF12:BH12)*F12*G12)/1000 -> 0 | BJ12: =SUM(AI12:AN12, BF12:BH12)*F12*G12/1000 -> 0.76940205
A13: ='Input Scenarios'!A13 -> NSW | B13: ='Input Scenarios'!B13 -> 0 | C13: ='Input Scenarios'!C13 -> Irrigated crop | D13: ='Input Scenarios'!D13 -> TRUE | E13: ='Input Scenarios'!E13 -> gilts | F13: ='Input Scenarios'!F13 -> 333 | G13: ='Input Scenarios'!G13 -> 200 | H13: =IF('Input Scenarios'!H13<>"", 'Input Scenarios'!H13, _xlfn.XLOOKUP($E13,Constants!$A$3:$A$6, Constants!B$3:B$6)) -> 2.5 | I13: =IF('Input Scenarios'!I13<>"", 'Input Scenarios'!I13, _xlfn.XLOOKUP($E13,Constants!$A$3:$A$6, Constants!C$3:C$6)) -> 0.55 | J13: =IF('Input Scenarios'!J13<>"", 'Input Scenarios'!J13, _xlfn.XLOOKUP($E13,Constants!$A$3:$A$6, Constants!D$3:D$6)) -> 0.046 | K13: ='Input Scenarios'!K13 -> 0 | L13: ='Input Scenarios'!L13 -> 0 | M13: ='Input Scenarios'!M13 -> 0 | N13: ='Input Scenarios'!N13 -> 0 | O13: ='Input Scenarios'!O13 -> 1 | P13: ='Input Scenarios'!P13 -> 0 | Q13: ='Input Scenarios'!Q13 -> FALSE | R13: =IF('Input Scenarios'!$R13<>"", 'Input Scenarios'!$R13, IF($Q13, Constants!$B$19, 0)) -> 0 | S13: =IF('Input Scenarios'!$R13<>"", 'Input Scenarios'!$R13, IF($Q13, Constants!$B$20, 0)) -> 0 | T13: =K13*(1-$R13) -> 0 | U13: =L13 -> 0 | V13: =M13*(1-$R13) -> 0 | W13: =N13 -> 0 | X13: =O13*(1-$R13) -> 1 | Y13: =P13+(SUM(K13,M13,O13)*R13) -> 0 | Z13: =Constants!$B$21 -> 0.19 | AA13: =Constants!$B$22 -> 0.6784 | AB13: =_xlfn.XLOOKUP($A13,Constants!$F$9:$M$9,Constants!$F$10:$M$10) -> 0.75 | AC13: =_xlfn.XLOOKUP($A13,Constants!$F$9:$M$9,Constants!$F$12:$M$12) -> 0.01 | AD13: =_xlfn.XLOOKUP($A13,Constants!$F$9:$M$9,Constants!$F$13:$M$13) -> 0.1 | AE13: =_xlfn.XLOOKUP($A13,Constants!$F$9:$M$9,Constants!$F$14:$M$14) -> 0.04 | AF13: =_xlfn.XLOOKUP($A13,Constants!$F$9:$M$9,Constants!$F$15:$M$15) -> 0.03 | AG13: =_xlfn.XLOOKUP($A13,Constants!$F$9:$M$9,Constants!$F$11:$M$11) -> 0.02 | AH13: =_xlfn.XLOOKUP($A13,Constants!$F$9:$M$9,Constants!$F$16:$M$16) -> 0 | AI13: =$I13*T13*AB13*$Z13*$AA13 -> 0 | AJ13: =$I13*U13*AC13*$Z13*$AA13 -> 0 | AK13: =$I13*V13*AD13*$Z13*$AA13 -> 0 | AL13: =$I13*W13*AE13*$Z13*$AA13 -> 0 | AM13: =$I13*X13*AF13*$Z13*$AA13 -> 0.002126784 | AN13: =$I13*Y13*AG13*$Z13*$AA13 -> 0 | AO13: =(SUM(AI13:AN13)*F13*G13)/1000 -> 0.14164381 | AP13: =Constants!$E$10 -> 0 | AQ13: =Constants!$E$12 -> 0 | AR13: =Constants!$E$13 -> 0.75 | AS13: =Constants!$E$14 -> 0.05 | AT13: =Constants!$E$15 -> 0 | AU13: =Constants!$E$11 -> 0 | AV13: =(T13*(1-AP13)) -> 0 | AW13: =(U13*(1-AQ13)) -> 0 | AX13: =(V13*(1-AR13)) -> 0 | AY13: =(W13*(1-AS13)) -> 0 | AZ13: =(X13*(1-AT13)) -> 1 | BA13: =(Y13*(1-AU13)) -> 0 | BB13: =SUM(AV13:BA13)*I13 -> 0.55 | BC13: =AX13*$I13 -> 0 | BD13: =AY13*$I13 -> 0 | BE13: =SUM(AV13:AW13, AZ13:BA13)*$I13 -> 0.55 | BF13: =BC13*$Z13*AB13*$AA13 -> 0 | BG13: =BD13*$Z13*AG13*$AA13 -> 0 | BH13: =BE13*$Z13*AH13*$AA13 -> 0 | BI13: =(SUM(BF13:BH13)*F13*G13)/1000 -> 0 | BJ13: =SUM(AI13:AN13, BF13:BH13)*F13*G13/1000 -> 0.14164381
A14: ='Input Scenarios'!A14 -> NSW | B14: ='Input Scenarios'!B14 -> 0 | C14: ='Input Scenarios'!C14 -> Irrigated crop | D14: ='Input Scenarios'!D14 -> TRUE | E14: ='Input Scenarios'!E14 -> others | F14: ='Input Scenarios'!F14 -> 444 | G14: ='Input Scenarios'!G14 -> 365 | H14: =IF('Input Scenarios'!H14<>"", 'Input Scenarios'!H14, _xlfn.XLOOKUP($E14,Constants!$A$3:$A$6, Constants!B$3:B$6)) -> 1.71 | I14: =IF('Input Scenarios'!I14<>"", 'Input Scenarios'!I14, _xlfn.XLOOKUP($E14,Constants!$A$3:$A$6, Constants!C$3:C$6)) -> 0.39 | J14: =IF('Input Scenarios'!J14<>"", 'Input Scenarios'!J14, _xlfn.XLOOKUP($E14,Constants!$A$3:$A$6, Constants!D$3:D$6)) -> 0.031232877 | K14: ='Input Scenarios'!K14 -> 0 | L14: ='Input Scenarios'!L14 -> 0 | M14: ='Input Scenarios'!M14 -> 0 | N14: ='Input Scenarios'!N14 -> 0 | O14: ='Input Scenarios'!O14 -> 1 | P14: ='Input Scenarios'!P14 -> 0 | Q14: ='Input Scenarios'!Q14 -> FALSE | R14: =IF('Input Scenarios'!$R14<>"", 'Input Scenarios'!$R14, IF($Q14, Constants!$B$19, 0)) -> 0 | S14: =IF('Input Scenarios'!$R14<>"", 'Input Scenarios'!$R14, IF($Q14, Constants!$B$20, 0)) -> 0 | T14: =K14*(1-$R14) -> 0 | U14: =L14 -> 0 | V14: =M14*(1-$R14) -> 0 | W14: =N14 -> 0 | X14: =O14*(1-$R14) -> 1 | Y14: =P14+(SUM(K14,M14,O14)*R14) -> 0 | Z14: =Constants!$B$21 -> 0.19 | AA14: =Constants!$B$22 -> 0.6784 | AB14: =_xlfn.XLOOKUP($A14,Constants!$F$9:$M$9,Constants!$F$10:$M$10) -> 0.75 | AC14: =_xlfn.XLOOKUP($A14,Constants!$F$9:$M$9,Constants!$F$12:$M$12) -> 0.01 | AD14: =_xlfn.XLOOKUP($A14,Constants!$F$9:$M$9,Constants!$F$13:$M$13) -> 0.1 | AE14: =_xlfn.XLOOKUP($A14,Constants!$F$9:$M$9,Constants!$F$14:$M$14) -> 0.04 | AF14: =_xlfn.XLOOKUP($A14,Constants!$F$9:$M$9,Constants!$F$15:$M$15) -> 0.03 | AG14: =_xlfn.XLOOKUP($A14,Constants!$F$9:$M$9,Constants!$F$11:$M$11) -> 0.02 | AH14: =_xlfn.XLOOKUP($A14,Constants!$F$9:$M$9,Constants!$F$16:$M$16) -> 0 | AI14: =$I14*T14*AB14*$Z14*$AA14 -> 0 | AJ14: =$I14*U14*AC14*$Z14*$AA14 -> 0 | AK14: =$I14*V14*AD14*$Z14*$AA14 -> 0 | AL14: =$I14*W14*AE14*$Z14*$AA14 -> 0 | AM14: =$I14*X14*AF14*$Z14*$AA14 -> 0.0015080832 | AN14: =$I14*Y14*AG14*$Z14*$AA14 -> 0 | AO14: =(SUM(AI14:AN14)*F14*G14)/1000 -> 0.24439996 | AP14: =Constants!$E$10 -> 0 | AQ14: =Constants!$E$12 -> 0 | AR14: =Constants!$E$13 -> 0.75 | AS14: =Constants!$E$14 -> 0.05 | AT14: =Constants!$E$15 -> 0 | AU14: =Constants!$E$11 -> 0 | AV14: =(T14*(1-AP14)) -> 0 | AW14: =(U14*(1-AQ14)) -> 0 | AX14: =(V14*(1-AR14)) -> 0 | AY14: =(W14*(1-AS14)) -> 0 | AZ14: =(X14*(1-AT14)) -> 1 | BA14: =(Y14*(1-AU14)) -> 0 | BB14: =SUM(AV14:BA14)*I14 -> 0.39 | BC14: =AX14*$I14 -> 0 | BD14: =AY14*$I14 -> 0 | BE14: =SUM(AV14:AW14, AZ14:BA14)*$I14 -> 0.39 | BF14: =BC14*$Z14*AB14*$AA14 -> 0 | BG14: =BD14*$Z14*AG14*$AA14 -> 0 | BH14: =BE14*$Z14*AH14*$AA14 -> 0 | BI14: =(SUM(BF14:BH14)*F14*G14)/1000 -> 0 | BJ14: =SUM(AI14:AN14, BF14:BH14)*F14*G14/1000 -> 0.24439996
A15: ='Input Scenarios'!A15 -> NT | B15: ='Input Scenarios'!B15 -> 0 | C15: ='Input Scenarios'!C15 -> Irrigated pasture | D15: ='Input Scenarios'!D15 -> TRUE | E15: ='Input Scenarios'!E15 -> boars | F15: ='Input Scenarios'!F15 -> 105 | G15: ='Input Scenarios'!G15 -> 75 | H15: =IF('Input Scenarios'!H15<>"", 'Input Scenarios'!H15, _xlfn.XLOOKUP($E15,Constants!$A$3:$A$6, Constants!B$3:B$6)) -> 2.62 | I15: =IF('Input Scenarios'!I15<>"", 'Input Scenarios'!I15, _xlfn.XLOOKUP($E15,Constants!$A$3:$A$6, Constants!C$3:C$6)) -> 0.4 | J15: =IF('Input Scenarios'!J15<>"", 'Input Scenarios'!J15, _xlfn.XLOOKUP($E15,Constants!$A$3:$A$6, Constants!D$3:D$6)) -> 0.046 | K15: ='Input Scenarios'!K15 -> 0.2 | L15: ='Input Scenarios'!L15 -> 0.1 | M15: ='Input Scenarios'!M15 -> 0.2 | N15: ='Input Scenarios'!N15 -> 0.2 | O15: ='Input Scenarios'!O15 -> 0.2 | P15: ='Input Scenarios'!P15 -> 0.1 | Q15: ='Input Scenarios'!Q15 -> TRUE | R15: =IF('Input Scenarios'!$R15<>"", 'Input Scenarios'!$R15, IF($Q15, Constants!$B$19, 0)) -> 0.25 | S15: =IF('Input Scenarios'!$R15<>"", 'Input Scenarios'!$R15, IF($Q15, Constants!$B$20, 0)) -> 0.25 | T15: =K15*(1-$R15) -> 0.15 | U15: =L15 -> 0.1 | V15: =M15*(1-$R15) -> 0.15 | W15: =N15 -> 0.2 | X15: =O15*(1-$R15) -> 0.15 | Y15: =P15+(SUM(K15,M15,O15)*R15) -> 0.25 | Z15: =Constants!$B$21 -> 0.19 | AA15: =Constants!$B$22 -> 0.6784 | AB15: =_xlfn.XLOOKUP($A15,Constants!$F$9:$M$9,Constants!$F$10:$M$10) -> 0.78 | AC15: =_xlfn.XLOOKUP($A15,Constants!$F$9:$M$9,Constants!$F$12:$M$12) -> 0.03 | AD15: =_xlfn.XLOOKUP($A15,Constants!$F$9:$M$9,Constants!$F$13:$M$13) -> 0.1 | AE15: =_xlfn.XLOOKUP($A15,Constants!$F$9:$M$9,Constants!$F$14:$M$14) -> 0.04 | AF15: =_xlfn.XLOOKUP($A15,Constants!$F$9:$M$9,Constants!$F$15:$M$15) -> 0.03 | AG15: =_xlfn.XLOOKUP($A15,Constants!$F$9:$M$9,Constants!$F$11:$M$11) -> 0.02 | AH15: =_xlfn.XLOOKUP($A15,Constants!$F$9:$M$9,Constants!$F$16:$M$16) -> 0 | AI15: =$I15*T15*AB15*$Z15*$AA15 -> 0.0060323328 | AJ15: =$I15*U15*AC15*$Z15*$AA15 -> 0.0001546752 | AK15: =$I15*V15*AD15*$Z15*$AA15 -> 0.000773376 | AL15: =$I15*W15*AE15*$Z15*$AA15 -> 0.0004124672 | AM15: =$I15*X15*AF15*$Z15*$AA15 -> 0.0002320128 | AN15: =$I15*Y15*AG15*$Z15*$AA15 -> 0.000257792 | AO15: =(SUM(AI15:AN15)*F15*G15)/1000 -> 0.061918416 | AP15: =Constants!$E$10 -> 0 | AQ15: =Constants!$E$12 -> 0 | AR15: =Constants!$E$13 -> 0.75 | AS15: =Constants!$E$14 -> 0.05 | AT15: =Constants!$E$15 -> 0 | AU15: =Constants!$E$11 -> 0 | AV15: =(T15*(1-AP15)) -> 0.15 | AW15: =(U15*(1-AQ15)) -> 0.1 | AX15: =(V15*(1-AR15)) -> 0.0375 | AY15: =(W15*(1-AS15)) -> 0.19 | AZ15: =(X15*(1-AT15)) -> 0.15 | BA15: =(Y15*(1-AU15)) -> 0.25 | BB15: =SUM(AV15:BA15)*I15 -> 0.351 | BC15: =AX15*$I15 -> 0.015 | BD15: =AY15*$I15 -> 0.076 | BE15: =SUM(AV15:AW15, AZ15:BA15)*$I15 -> 0.26 | BF15: =BC15*$Z15*AB15*$AA15 -> 0.0015080832 | BG15: =BD15*$Z15*AG15*$AA15 -> 0.00019592192 | BH15: =BE15*$Z15*AH15*$AA15 -> 0 | BI15: =(SUM(BF15:BH15)*F15*G15)/1000 -> 0.01341904 | BJ15: =SUM(AI15:AN15, BF15:BH15)*F15*G15/1000 -> 0.075337456 | BK15: =SUM(BJ15:BJ18) -> 2.5745177
A16: ='Input Scenarios'!A16 -> NT | B16: ='Input Scenarios'!B16 -> 0 | C16: ='Input Scenarios'!C16 -> Irrigated pasture | D16: ='Input Scenarios'!D16 -> TRUE | E16: ='Input Scenarios'!E16 -> sows | F16: ='Input Scenarios'!F16 -> 245 | G16: ='Input Scenarios'!G16 -> 290 | H16: =IF('Input Scenarios'!H16<>"", 'Input Scenarios'!H16, _xlfn.XLOOKUP($E16,Constants!$A$3:$A$6, Constants!B$3:B$6)) -> 2.3 | I16: =IF('Input Scenarios'!I16<>"", 'Input Scenarios'!I16, _xlfn.XLOOKUP($E16,Constants!$A$3:$A$6, Constants!C$3:C$6)) -> 0.46 | J16: =IF('Input Scenarios'!J16<>"", 'Input Scenarios'!J16, _xlfn.XLOOKUP($E16,Constants!$A$3:$A$6, Constants!D$3:D$6)) -> 0.049 | K16: ='Input Scenarios'!K16 -> 0.2 | L16: ='Input Scenarios'!L16 -> 0.1 | M16: ='Input Scenarios'!M16 -> 0.2 | N16: ='Input Scenarios'!N16 -> 0.2 | O16: ='Input Scenarios'!O16 -> 0.2 | P16: ='Input Scenarios'!P16 -> 0.1 | Q16: ='Input Scenarios'!Q16 -> TRUE | R16: =IF('Input Scenarios'!$R16<>"", 'Input Scenarios'!$R16, IF($Q16, Constants!$B$19, 0)) -> 0.25 | S16: =IF('Input Scenarios'!$R16<>"", 'Input Scenarios'!$R16, IF($Q16, Constants!$B$20, 0)) -> 0.25 | T16: =K16*(1-$R16) -> 0.15 | U16: =L16 -> 0.1 | V16: =M16*(1-$R16) -> 0.15 | W16: =N16 -> 0.2 | X16: =O16*(1-$R16) -> 0.15 | Y16: =P16+(SUM(K16,M16,O16)*R16) -> 0.25 | Z16: =Constants!$B$21 -> 0.19 | AA16: =Constants!$B$22 -> 0.6784 | AB16: =_xlfn.XLOOKUP($A16,Constants!$F$9:$M$9,Constants!$F$10:$M$10) -> 0.78 | AC16: =_xlfn.XLOOKUP($A16,Constants!$F$9:$M$9,Constants!$F$12:$M$12) -> 0.03 | AD16: =_xlfn.XLOOKUP($A16,Constants!$F$9:$M$9,Constants!$F$13:$M$13) -> 0.1 | AE16: =_xlfn.XLOOKUP($A16,Constants!$F$9:$M$9,Constants!$F$14:$M$14) -> 0.04 | AF16: =_xlfn.XLOOKUP($A16,Constants!$F$9:$M$9,Constants!$F$15:$M$15) -> 0.03 | AG16: =_xlfn.XLOOKUP($A16,Constants!$F$9:$M$9,Constants!$F$11:$M$11) -> 0.02 | AH16: =_xlfn.XLOOKUP($A16,Constants!$F$9:$M$9,Constants!$F$16:$M$16) -> 0 | AI16: =$I16*T16*AB16*$Z16*$AA16 -> 0.0069371827 | AJ16: =$I16*U16*AC16*$Z16*$AA16 -> 0.00017787648 | AK16: =$I16*V16*AD16*$Z16*$AA16 -> 0.0008893824 | AL16: =$I16*W16*AE16*$Z16*$AA16 -> 0.00047433728 | AM16: =$I16*X16*AF16*$Z16*$AA16 -> 0.00026681472 | AN16: =$I16*Y16*AG16*$Z16*$AA16 -> 0.0002964608 | AO16: =(SUM(AI16:AN16)*F16*G16)/1000 -> 0.64243797 | AP16: =Constants!$E$10 -> 0 | AQ16: =Constants!$E$12 -> 0 | AR16: =Constants!$E$13 -> 0.75 | AS16: =Constants!$E$14 -> 0.05 | AT16: =Constants!$E$15 -> 0 | AU16: =Constants!$E$11 -> 0 | AV16: =(T16*(1-AP16)) -> 0.15 | AW16: =(U16*(1-AQ16)) -> 0.1 | AX16: =(V16*(1-AR16)) -> 0.0375 | AY16: =(W16*(1-AS16)) -> 0.19 | AZ16: =(X16*(1-AT16)) -> 0.15 | BA16: =(Y16*(1-AU16)) -> 0.25 | BB16: =SUM(AV16:BA16)*I16 -> 0.40365 | BC16: =AX16*$I16 -> 0.01725 | BD16: =AY16*$I16 -> 0.0874 | BE16: =SUM(AV16:AW16, AZ16:BA16)*$I16 -> 0.299 | BF16: =BC16*$Z16*AB16*$AA16 -> 0.0017342957 | BG16: =BD16*$Z16*AG16*$AA16 -> 0.00022531021 | BH16: =BE16*$Z16*AH16*$AA16 -> 0 | BI16: =(SUM(BF16:BH16)*F16*G16)/1000 -> 0.13923 | BJ16: =SUM(AI16:AN16, BF16:BH16)*F16*G16/1000 -> 0.78166796
A17: ='Input Scenarios'!A17 -> NT | B17: ='Input Scenarios'!B17 -> 0 | C17: ='Input Scenarios'!C17 -> Irrigated pasture | D17: ='Input Scenarios'!D17 -> TRUE | E17: ='Input Scenarios'!E17 -> gilts | F17: ='Input Scenarios'!F17 -> 434 | G17: ='Input Scenarios'!G17 -> 280 | H17: =IF('Input Scenarios'!H17<>"", 'Input Scenarios'!H17, _xlfn.XLOOKUP($E17,Constants!$A$3:$A$6, Constants!B$3:B$6)) -> 2.5 | I17: =IF('Input Scenarios'!I17<>"", 'Input Scenarios'!I17, _xlfn.XLOOKUP($E17,Constants!$A$3:$A$6, Constants!C$3:C$6)) -> 0.55 | J17: =IF('Input Scenarios'!J17<>"", 'Input Scenarios'!J17, _xlfn.XLOOKUP($E17,Constants!$A$3:$A$6, Constants!D$3:D$6)) -> 0.046 | K17: ='Input Scenarios'!K17 -> 0.2 | L17: ='Input Scenarios'!L17 -> 0.1 | M17: ='Input Scenarios'!M17 -> 0.2 | N17: ='Input Scenarios'!N17 -> 0.2 | O17: ='Input Scenarios'!O17 -> 0.2 | P17: ='Input Scenarios'!P17 -> 0.1 | Q17: ='Input Scenarios'!Q17 -> TRUE | R17: =IF('Input Scenarios'!$R17<>"", 'Input Scenarios'!$R17, IF($Q17, Constants!$B$19, 0)) -> 0.25 | S17: =IF('Input Scenarios'!$R17<>"", 'Input Scenarios'!$R17, IF($Q17, Constants!$B$20, 0)) -> 0.25 | T17: =K17*(1-$R17) -> 0.15 | U17: =L17 -> 0.1 | V17: =M17*(1-$R17) -> 0.15 | W17: =N17 -> 0.2 | X17: =O17*(1-$R17) -> 0.15 | Y17: =P17+(SUM(K17,M17,O17)*R17) -> 0.25 | Z17: =Constants!$B$21 -> 0.19 | AA17: =Constants!$B$22 -> 0.6784 | AB17: =_xlfn.XLOOKUP($A17,Constants!$F$9:$M$9,Constants!$F$10:$M$10) -> 0.78 | AC17: =_xlfn.XLOOKUP($A17,Constants!$F$9:$M$9,Constants!$F$12:$M$12) -> 0.03 | AD17: =_xlfn.XLOOKUP($A17,Constants!$F$9:$M$9,Constants!$F$13:$M$13) -> 0.1 | AE17: =_xlfn.XLOOKUP($A17,Constants!$F$9:$M$9,Constants!$F$14:$M$14) -> 0.04 | AF17: =_xlfn.XLOOKUP($A17,Constants!$F$9:$M$9,Constants!$F$15:$M$15) -> 0.03 | AG17: =_xlfn.XLOOKUP($A17,Constants!$F$9:$M$9,Constants!$F$11:$M$11) -> 0.02 | AH17: =_xlfn.XLOOKUP($A17,Constants!$F$9:$M$9,Constants!$F$16:$M$16) -> 0 | AI17: =$I17*T17*AB17*$Z17*$AA17 -> 0.0082944576 | AJ17: =$I17*U17*AC17*$Z17*$AA17 -> 0.0002126784 | AK17: =$I17*V17*AD17*$Z17*$AA17 -> 0.001063392 | AL17: =$I17*W17*AE17*$Z17*$AA17 -> 0.0005671424 | AM17: =$I17*X17*AF17*$Z17*$AA17 -> 0.0003190176 | AN17: =$I17*Y17*AG17*$Z17*$AA17 -> 0.000354464 | AO17: =(SUM(AI17:AN17)*F17*G17)/1000 -> 1.3137712 | AP17: =Constants!$E$10 -> 0 | AQ17: =Constants!$E$12 -> 0 | AR17: =Constants!$E$13 -> 0.75 | AS17: =Constants!$E$14 -> 0.05 | AT17: =Constants!$E$15 -> 0 | AU17: =Constants!$E$11 -> 0 | AV17: =(T17*(1-AP17)) -> 0.15 | AW17: =(U17*(1-AQ17)) -> 0.1 | AX17: =(V17*(1-AR17)) -> 0.0375 | AY17: =(W17*(1-AS17)) -> 0.19 | AZ17: =(X17*(1-AT17)) -> 0.15 | BA17: =(Y17*(1-AU17)) -> 0.25 | BB17: =SUM(AV17:BA17)*I17 -> 0.482625 | BC17: =AX17*$I17 -> 0.020625 | BD17: =AY17*$I17 -> 0.1045 | BE17: =SUM(AV17:AW17, AZ17:BA17)*$I17 -> 0.3575 | BF17: =BC17*$Z17*AB17*$AA17 -> 0.0020736144 | BG17: =BD17*$Z17*AG17*$AA17 -> 0.00026939264 | BH17: =BE17*$Z17*AH17*$AA17 -> 0 | BI17: =(SUM(BF17:BH17)*F17*G17)/1000 -> 0.28472222 | BJ17: =SUM(AI17:AN17, BF17:BH17)*F17*G17/1000 -> 1.5984934
A18: ='Input Scenarios'!A18 -> NT | B18: ='Input Scenarios'!B18 -> 0 | C18: ='Input Scenarios'!C18 -> Irrigated pasture | D18: ='Input Scenarios'!D18 -> TRUE | E18: ='Input Scenarios'!E18 -> others | F18: ='Input Scenarios'!F18 -> 44 | G18: ='Input Scenarios'!G18 -> 290 | H18: =IF('Input Scenarios'!H18<>"", 'Input Scenarios'!H18, _xlfn.XLOOKUP($E18,Constants!$A$3:$A$6, Constants!B$3:B$6)) -> 1.71 | I18: =IF('Input Scenarios'!I18<>"", 'Input Scenarios'!I18, _xlfn.XLOOKUP($E18,Constants!$A$3:$A$6, Constants!C$3:C$6)) -> 0.39 | J18: =IF('Input Scenarios'!J18<>"", 'Input Scenarios'!J18, _xlfn.XLOOKUP($E18,Constants!$A$3:$A$6, Constants!D$3:D$6)) -> 0.031232877 | K18: ='Input Scenarios'!K18 -> 0.2 | L18: ='Input Scenarios'!L18 -> 0.1 | M18: ='Input Scenarios'!M18 -> 0.2 | N18: ='Input Scenarios'!N18 -> 0.2 | O18: ='Input Scenarios'!O18 -> 0.2 | P18: ='Input Scenarios'!P18 -> 0.1 | Q18: ='Input Scenarios'!Q18 -> TRUE | R18: =IF('Input Scenarios'!$R18<>"", 'Input Scenarios'!$R18, IF($Q18, Constants!$B$19, 0)) -> 0.25 | S18: =IF('Input Scenarios'!$R18<>"", 'Input Scenarios'!$R18, IF($Q18, Constants!$B$20, 0)) -> 0.25 | T18: =K18*(1-$R18) -> 0.15 | U18: =L18 -> 0.1 | V18: =M18*(1-$R18) -> 0.15 | W18: =N18 -> 0.2 | X18: =O18*(1-$R18) -> 0.15 | Y18: =P18+(SUM(K18,M18,O18)*R18) -> 0.25 | Z18: =Constants!$B$21 -> 0.19 | AA18: =Constants!$B$22 -> 0.6784 | AB18: =_xlfn.XLOOKUP($A18,Constants!$F$9:$M$9,Constants!$F$10:$M$10) -> 0.78 | AC18: =_xlfn.XLOOKUP($A18,Constants!$F$9:$M$9,Constants!$F$12:$M$12) -> 0.03 | AD18: =_xlfn.XLOOKUP($A18,Constants!$F$9:$M$9,Constants!$F$13:$M$13) -> 0.1 | AE18: =_xlfn.XLOOKUP($A18,Constants!$F$9:$M$9,Constants!$F$14:$M$14) -> 0.04 | AF18: =_xlfn.XLOOKUP($A18,Constants!$F$9:$M$9,Constants!$F$15:$M$15) -> 0.03 | AG18: =_xlfn.XLOOKUP($A18,Constants!$F$9:$M$9,Constants!$F$11:$M$11) -> 0.02 | AH18: =_xlfn.XLOOKUP($A18,Constants!$F$9:$M$9,Constants!$F$16:$M$16) -> 0 | AI18: =$I18*T18*AB18*$Z18*$AA18 -> 0.0058815245 | AJ18: =$I18*U18*AC18*$Z18*$AA18 -> 0.00015080832 | AK18: =$I18*V18*AD18*$Z18*$AA18 -> 0.0007540416 | AL18: =$I18*W18*AE18*$Z18*$AA18 -> 0.00040215552 | AM18: =$I18*X18*AF18*$Z18*$AA18 -> 0.00022621248 | AN18: =$I18*Y18*AG18*$Z18*$AA18 -> 0.0002513472 | AO18: =(SUM(AI18:AN18)*F18*G18)/1000 -> 0.097819303 | AP18: =Constants!$E$10 -> 0 | AQ18: =Constants!$E$12 -> 0 | AR18: =Constants!$E$13 -> 0.75 | AS18: =Constants!$E$14 -> 0.05 | AT18: =Constants!$E$15 -> 0 | AU18: =Constants!$E$11 -> 0 | AV18: =(T18*(1-AP18)) -> 0.15 | AW18: =(U18*(1-AQ18)) -> 0.1 | AX18: =(V18*(1-AR18)) -> 0.0375 | AY18: =(W18*(1-AS18)) -> 0.19 | AZ18: =(X18*(1-AT18)) -> 0.15 | BA18: =(Y18*(1-AU18)) -> 0.25 | BB18: =SUM(AV18:BA18)*I18 -> 0.342225 | BC18: =AX18*$I18 -> 0.014625 | BD18: =AY18*$I18 -> 0.0741 | BE18: =SUM(AV18:AW18, AZ18:BA18)*$I18 -> 0.2535 | BF18: =BC18*$Z18*AB18*$AA18 -> 0.0014703811 | BG18: =BD18*$Z18*AG18*$AA18 -> 0.00019102387 | BH18: =BE18*$Z18*AH18*$AA18 -> 0 | BI18: =(SUM(BF18:BH18)*F18*G18)/1000 -> 0.021199528 | BJ18: =SUM(AI18:AN18, BF18:BH18)*F18*G18/1000 -> 0.11901883
A19: ='Input Scenarios'!A19 -> QLD | B19: ='Input Scenarios'!B19 -> 0 | C19: ='Input Scenarios'!C19 -> Non-irrigated pasture | D19: ='Input Scenarios'!D19 -> TRUE | E19: ='Input Scenarios'!E19 -> boars | F19: ='Input Scenarios'!F19 -> 1000 | G19: ='Input Scenarios'!G19 -> 100 | H19: =IF('Input Scenarios'!H19<>"", 'Input Scenarios'!H19, _xlfn.XLOOKUP($E19,Constants!$A$3:$A$6, Constants!B$3:B$6)) -> 2.62 | I19: =IF('Input Scenarios'!I19<>"", 'Input Scenarios'!I19, _xlfn.XLOOKUP($E19,Constants!$A$3:$A$6, Constants!C$3:C$6)) -> 0.4 | J19: =IF('Input Scenarios'!J19<>"", 'Input Scenarios'!J19, _xlfn.XLOOKUP($E19,Constants!$A$3:$A$6, Constants!D$3:D$6)) -> 0.046 | K19: ='Input Scenarios'!K19 -> 0 | L19: ='Input Scenarios'!L19 -> 0 | M19: ='Input Scenarios'!M19 -> 0 | N19: ='Input Scenarios'!N19 -> 0 | O19: ='Input Scenarios'!O19 -> 0 | P19: ='Input Scenarios'!P19 -> 0 | Q19: ='Input Scenarios'!Q19 -> FALSE | R19: =IF('Input Scenarios'!$R19<>"", 'Input Scenarios'!$R19, IF($Q19, Constants!$B$19, 0)) -> 0 | S19: =IF('Input Scenarios'!$R19<>"", 'Input Scenarios'!$R19, IF($Q19, Constants!$B$20, 0)) -> 0 | T19: =K19*(1-$R19) -> 0 | U19: =L19 -> 0 | V19: =M19*(1-$R19) -> 0 | W19: =N19 -> 0 | X19: =O19*(1-$R19) -> 0 | Y19: =P19+(SUM(K19,M19,O19)*R19) -> 0 | Z19: =Constants!$B$21 -> 0.19 | AA19: =Constants!$B$22 -> 0.6784 | AB19: =_xlfn.XLOOKUP($A19,Constants!$F$9:$M$9,Constants!$F$10:$M$10) -> 0.78 | AC19: =_xlfn.XLOOKUP($A19,Constants!$F$9:$M$9,Constants!$F$12:$M$12) -> 0.03 | AD19: =_xlfn.XLOOKUP($A19,Constants!$F$9:$M$9,Constants!$F$13:$M$13) -> 0.1 | AE19: =_xlfn.XLOOKUP($A19,Constants!$F$9:$M$9,Constants!$F$14:$M$14) -> 0.04 | AF19: =_xlfn.XLOOKUP($A19,Constants!$F$9:$M$9,Constants!$F$15:$M$15) -> 0.03 | AG19: =_xlfn.XLOOKUP($A19,Constants!$F$9:$M$9,Constants!$F$11:$M$11) -> 0.02 | AH19: =_xlfn.XLOOKUP($A19,Constants!$F$9:$M$9,Constants!$F$16:$M$16) -> 0 | AI19: =$I19*T19*AB19*$Z19*$AA19 -> 0 | AJ19: =$I19*U19*AC19*$Z19*$AA19 -> 0 | AK19: =$I19*V19*AD19*$Z19*$AA19 -> 0 | AL19: =$I19*W19*AE19*$Z19*$AA19 -> 0 | AM19: =$I19*X19*AF19*$Z19*$AA19 -> 0 | AN19: =$I19*Y19*AG19*$Z19*$AA19 -> 0 | AO19: =(SUM(AI19:AN19)*F19*G19)/1000 -> 0 | AP19: =Constants!$E$10 -> 0 | AQ19: =Constants!$E$12 -> 0 | AR19: =Constants!$E$13 -> 0.75 | AS19: =Constants!$E$14 -> 0.05 | AT19: =Constants!$E$15 -> 0 | AU19: =Constants!$E$11 -> 0 | AV19: =(T19*(1-AP19)) -> 0 | AW19: =(U19*(1-AQ19)) -> 0 | AX19: =(V19*(1-AR19)) -> 0 | AY19: =(W19*(1-AS19)) -> 0 | AZ19: =(X19*(1-AT19)) -> 0 | BA19: =(Y19*(1-AU19)) -> 0 | BB19: =SUM(AV19:BA19)*I19 -> 0 | BC19: =AX19*$I19 -> 0 | BD19: =AY19*$I19 -> 0 | BE19: =SUM(AV19:AW19, AZ19:BA19)*$I19 -> 0 | BF19: =BC19*$Z19*AB19*$AA19 -> 0 | BG19: =BD19*$Z19*AG19*$AA19 -> 0 | BH19: =BE19*$Z19*AH19*$AA19 -> 0 | BI19: =(SUM(BF19:BH19)*F19*G19)/1000 -> 0 | BJ19: =SUM(AI19:AN19, BF19:BH19)*F19*G19/1000 -> 0 | BK19: =SUM(BJ19:BJ22) -> 0
A20: ='Input Scenarios'!A20 -> QLD | B20: ='Input Scenarios'!B20 -> 0 | C20: ='Input Scenarios'!C20 -> Non-irrigated pasture | D20: ='Input Scenarios'!D20 -> TRUE | E20: ='Input Scenarios'!E20 -> sows | F20: ='Input Scenarios'!F20 -> 233 | G20: ='Input Scenarios'!G20 -> 100 | H20: =IF('Input Scenarios'!H20<>"", 'Input Scenarios'!H20, _xlfn.XLOOKUP($E20,Constants!$A$3:$A$6, Constants!B$3:B$6)) -> 2.3 | I20: =IF('Input Scenarios'!I20<>"", 'Input Scenarios'!I20, _xlfn.XLOOKUP($E20,Constants!$A$3:$A$6, Constants!C$3:C$6)) -> 0.46 | J20: =IF('Input Scenarios'!J20<>"", 'Input Scenarios'!J20, _xlfn.XLOOKUP($E20,Constants!$A$3:$A$6, Constants!D$3:D$6)) -> 0.049 | K20: ='Input Scenarios'!K20 -> 0 | L20: ='Input Scenarios'!L20 -> 0 | M20: ='Input Scenarios'!M20 -> 0 | N20: ='Input Scenarios'!N20 -> 0 | O20: ='Input Scenarios'!O20 -> 0 | P20: ='Input Scenarios'!P20 -> 0 | Q20: ='Input Scenarios'!Q20 -> FALSE | R20: =IF('Input Scenarios'!$R20<>"", 'Input Scenarios'!$R20, IF($Q20, Constants!$B$19, 0)) -> 0 | S20: =IF('Input Scenarios'!$R20<>"", 'Input Scenarios'!$R20, IF($Q20, Constants!$B$20, 0)) -> 0 | T20: =K20*(1-$R20) -> 0 | U20: =L20 -> 0 | V20: =M20*(1-$R20) -> 0 | W20: =N20 -> 0 | X20: =O20*(1-$R20) -> 0 | Y20: =P20+(SUM(K20,M20,O20)*R20) -> 0 | Z20: =Constants!$B$21 -> 0.19 | AA20: =Constants!$B$22 -> 0.6784 | AB20: =_xlfn.XLOOKUP($A20,Constants!$F$9:$M$9,Constants!$F$10:$M$10) -> 0.78 | AC20: =_xlfn.XLOOKUP($A20,Constants!$F$9:$M$9,Constants!$F$12:$M$12) -> 0.03 | AD20: =_xlfn.XLOOKUP($A20,Constants!$F$9:$M$9,Constants!$F$13:$M$13) -> 0.1 | AE20: =_xlfn.XLOOKUP($A20,Constants!$F$9:$M$9,Constants!$F$14:$M$14) -> 0.04 | AF20: =_xlfn.XLOOKUP($A20,Constants!$F$9:$M$9,Constants!$F$15:$M$15) -> 0.03 | AG20: =_xlfn.XLOOKUP($A20,Constants!$F$9:$M$9,Constants!$F$11:$M$11) -> 0.02 | AH20: =_xlfn.XLOOKUP($A20,Constants!$F$9:$M$9,Constants!$F$16:$M$16) -> 0 | AI20: =$I20*T20*AB20*$Z20*$AA20 -> 0 | AJ20: =$I20*U20*AC20*$Z20*$AA20 -> 0 | AK20: =$I20*V20*AD20*$Z20*$AA20 -> 0 | AL20: =$I20*W20*AE20*$Z20*$AA20 -> 0 | AM20: =$I20*X20*AF20*$Z20*$AA20 -> 0 | AN20: =$I20*Y20*AG20*$Z20*$AA20 -> 0 | AO20: =(SUM(AI20:AN20)*F20*G20)/1000 -> 0 | AP20: =Constants!$E$10 -> 0 | AQ20: =Constants!$E$12 -> 0 | AR20: =Constants!$E$13 -> 0.75 | AS20: =Constants!$E$14 -> 0.05 | AT20: =Constants!$E$15 -> 0 | AU20: =Constants!$E$11 -> 0 | AV20: =(T20*(1-AP20)) -> 0 | AW20: =(U20*(1-AQ20)) -> 0 | AX20: =(V20*(1-AR20)) -> 0 | AY20: =(W20*(1-AS20)) -> 0 | AZ20: =(X20*(1-AT20)) -> 0 | BA20: =(Y20*(1-AU20)) -> 0 | BB20: =SUM(AV20:BA20)*I20 -> 0 | BC20: =AX20*$I20 -> 0 | BD20: =AY20*$I20 -> 0 | BE20: =SUM(AV20:AW20, AZ20:BA20)*$I20 -> 0 | BF20: =BC20*$Z20*AB20*$AA20 -> 0 | BG20: =BD20*$Z20*AG20*$AA20 -> 0 | BH20: =BE20*$Z20*AH20*$AA20 -> 0 | BI20: =(SUM(BF20:BH20)*F20*G20)/1000 -> 0 | BJ20: =SUM(AI20:AN20, BF20:BH20)*F20*G20/1000 -> 0
A21: ='Input Scenarios'!A21 -> QLD | B21: ='Input Scenarios'!B21 -> 0 | C21: ='Input Scenarios'!C21 -> Non-irrigated pasture | D21: ='Input Scenarios'!D21 -> TRUE | E21: ='Input Scenarios'!E21 -> gilts | F21: ='Input Scenarios'!F21 -> 923 | G21: ='Input Scenarios'!G21 -> 100 | H21: =IF('Input Scenarios'!H21<>"", 'Input Scenarios'!H21, _xlfn.XLOOKUP($E21,Constants!$A$3:$A$6, Constants!B$3:B$6)) -> 2.5 | I21: =IF('Input Scenarios'!I21<>"", 'Input Scenarios'!I21, _xlfn.XLOOKUP($E21,Constants!$A$3:$A$6, Constants!C$3:C$6)) -> 0.55 | J21: =IF('Input Scenarios'!J21<>"", 'Input Scenarios'!J21, _xlfn.XLOOKUP($E21,Constants!$A$3:$A$6, Constants!D$3:D$6)) -> 0.046 | K21: ='Input Scenarios'!K21 -> 0 | L21: ='Input Scenarios'!L21 -> 0 | M21: ='Input Scenarios'!M21 -> 0 | N21: ='Input Scenarios'!N21 -> 0 | O21: ='Input Scenarios'!O21 -> 0 | P21: ='Input Scenarios'!P21 -> 0 | Q21: ='Input Scenarios'!Q21 -> FALSE | R21: =IF('Input Scenarios'!$R21<>"", 'Input Scenarios'!$R21, IF($Q21, Constants!$B$19, 0)) -> 0 | S21: =IF('Input Scenarios'!$R21<>"", 'Input Scenarios'!$R21, IF($Q21, Constants!$B$20, 0)) -> 0 | T21: =K21*(1-$R21) -> 0 | U21: =L21 -> 0 | V21: =M21*(1-$R21) -> 0 | W21: =N21 -> 0 | X21: =O21*(1-$R21) -> 0 | Y21: =P21+(SUM(K21,M21,O21)*R21) -> 0 | Z21: =Constants!$B$21 -> 0.19 | AA21: =Constants!$B$22 -> 0.6784 | AB21: =_xlfn.XLOOKUP($A21,Constants!$F$9:$M$9,Constants!$F$10:$M$10) -> 0.78 | AC21: =_xlfn.XLOOKUP($A21,Constants!$F$9:$M$9,Constants!$F$12:$M$12) -> 0.03 | AD21: =_xlfn.XLOOKUP($A21,Constants!$F$9:$M$9,Constants!$F$13:$M$13) -> 0.1 | AE21: =_xlfn.XLOOKUP($A21,Constants!$F$9:$M$9,Constants!$F$14:$M$14) -> 0.04 | AF21: =_xlfn.XLOOKUP($A21,Constants!$F$9:$M$9,Constants!$F$15:$M$15) -> 0.03 | AG21: =_xlfn.XLOOKUP($A21,Constants!$F$9:$M$9,Constants!$F$11:$M$11) -> 0.02 | AH21: =_xlfn.XLOOKUP($A21,Constants!$F$9:$M$9,Constants!$F$16:$M$16) -> 0 | AI21: =$I21*T21*AB21*$Z21*$AA21 -> 0 | AJ21: =$I21*U21*AC21*$Z21*$AA21 -> 0 | AK21: =$I21*V21*AD21*$Z21*$AA21 -> 0 | AL21: =$I21*W21*AE21*$Z21*$AA21 -> 0 | AM21: =$I21*X21*AF21*$Z21*$AA21 -> 0 | AN21: =$I21*Y21*AG21*$Z21*$AA21 -> 0 | AO21: =(SUM(AI21:AN21)*F21*G21)/1000 -> 0 | AP21: =Constants!$E$10 -> 0 | AQ21: =Constants!$E$12 -> 0 | AR21: =Constants!$E$13 -> 0.75 | AS21: =Constants!$E$14 -> 0.05 | AT21: =Constants!$E$15 -> 0 | AU21: =Constants!$E$11 -> 0 | AV21: =(T21*(1-AP21)) -> 0 | AW21: =(U21*(1-AQ21)) -> 0 | AX21: =(V21*(1-AR21)) -> 0 | AY21: =(W21*(1-AS21)) -> 0 | AZ21: =(X21*(1-AT21)) -> 0 | BA21: =(Y21*(1-AU21)) -> 0 | BB21: =SUM(AV21:BA21)*I21 -> 0 | BC21: =AX21*$I21 -> 0 | BD21: =AY21*$I21 -> 0 | BE21: =SUM(AV21:AW21, AZ21:BA21)*$I21 -> 0 | BF21: =BC21*$Z21*AB21*$AA21 -> 0 | BG21: =BD21*$Z21*AG21*$AA21 -> 0 | BH21: =BE21*$Z21*AH21*$AA21 -> 0 | BI21: =(SUM(BF21:BH21)*F21*G21)/1000 -> 0 | BJ21: =SUM(AI21:AN21, BF21:BH21)*F21*G21/1000 -> 0
A22: ='Input Scenarios'!A22 -> QLD | B22: ='Input Scenarios'!B22 -> 0 | C22: ='Input Scenarios'!C22 -> Non-irrigated pasture | D22: ='Input Scenarios'!D22 -> TRUE | E22: ='Input Scenarios'!E22 -> others | F22: ='Input Scenarios'!F22 -> 122 | G22: ='Input Scenarios'!G22 -> 100 | H22: =IF('Input Scenarios'!H22<>"", 'Input Scenarios'!H22, _xlfn.XLOOKUP($E22,Constants!$A$3:$A$6, Constants!B$3:B$6)) -> 1.71 | I22: =IF('Input Scenarios'!I22<>"", 'Input Scenarios'!I22, _xlfn.XLOOKUP($E22,Constants!$A$3:$A$6, Constants!C$3:C$6)) -> 0.39 | J22: =IF('Input Scenarios'!J22<>"", 'Input Scenarios'!J22, _xlfn.XLOOKUP($E22,Constants!$A$3:$A$6, Constants!D$3:D$6)) -> 0.031232877 | K22: ='Input Scenarios'!K22 -> 0 | L22: ='Input Scenarios'!L22 -> 0 | M22: ='Input Scenarios'!M22 -> 0 | N22: ='Input Scenarios'!N22 -> 0 | O22: ='Input Scenarios'!O22 -> 0 | P22: ='Input Scenarios'!P22 -> 0 | Q22: ='Input Scenarios'!Q22 -> FALSE | R22: =IF('Input Scenarios'!$R22<>"", 'Input Scenarios'!$R22, IF($Q22, Constants!$B$19, 0)) -> 0 | S22: =IF('Input Scenarios'!$R22<>"", 'Input Scenarios'!$R22, IF($Q22, Constants!$B$20, 0)) -> 0 | T22: =K22*(1-$R22) -> 0 | U22: =L22 -> 0 | V22: =M22*(1-$R22) -> 0 | W22: =N22 -> 0 | X22: =O22*(1-$R22) -> 0 | Y22: =P22+(SUM(K22,M22,O22)*R22) -> 0 | Z22: =Constants!$B$21 -> 0.19 | AA22: =Constants!$B$22 -> 0.6784 | AB22: =_xlfn.XLOOKUP($A22,Constants!$F$9:$M$9,Constants!$F$10:$M$10) -> 0.78 | AC22: =_xlfn.XLOOKUP($A22,Constants!$F$9:$M$9,Constants!$F$12:$M$12) -> 0.03 | AD22: =_xlfn.XLOOKUP($A22,Constants!$F$9:$M$9,Constants!$F$13:$M$13) -> 0.1 | AE22: =_xlfn.XLOOKUP($A22,Constants!$F$9:$M$9,Constants!$F$14:$M$14) -> 0.04 | AF22: =_xlfn.XLOOKUP($A22,Constants!$F$9:$M$9,Constants!$F$15:$M$15) -> 0.03 | AG22: =_xlfn.XLOOKUP($A22,Constants!$F$9:$M$9,Constants!$F$11:$M$11) -> 0.02 | AH22: =_xlfn.XLOOKUP($A22,Constants!$F$9:$M$9,Constants!$F$16:$M$16) -> 0 | AI22: =$I22*T22*AB22*$Z22*$AA22 -> 0 | AJ22: =$I22*U22*AC22*$Z22*$AA22 -> 0 | AK22: =$I22*V22*AD22*$Z22*$AA22 -> 0 | AL22: =$I22*W22*AE22*$Z22*$AA22 -> 0 | AM22: =$I22*X22*AF22*$Z22*$AA22 -> 0 | AN22: =$I22*Y22*AG22*$Z22*$AA22 -> 0 | AO22: =(SUM(AI22:AN22)*F22*G22)/1000 -> 0 | AP22: =Constants!$E$10 -> 0 | AQ22: =Constants!$E$12 -> 0 | AR22: =Constants!$E$13 -> 0.75 | AS22: =Constants!$E$14 -> 0.05 | AT22: =Constants!$E$15 -> 0 | AU22: =Constants!$E$11 -> 0 | AV22: =(T22*(1-AP22)) -> 0 | AW22: =(U22*(1-AQ22)) -> 0 | AX22: =(V22*(1-AR22)) -> 0 | AY22: =(W22*(1-AS22)) -> 0 | AZ22: =(X22*(1-AT22)) -> 0 | BA22: =(Y22*(1-AU22)) -> 0 | BB22: =SUM(AV22:BA22)*I22 -> 0 | BC22: =AX22*$I22 -> 0 | BD22: =AY22*$I22 -> 0 | BE22: =SUM(AV22:AW22, AZ22:BA22)*$I22 -> 0 | BF22: =BC22*$Z22*AB22*$AA22 -> 0 | BG22: =BD22*$Z22*AG22*$AA22 -> 0 | BH22: =BE22*$Z22*AH22*$AA22 -> 0 | BI22: =(SUM(BF22:BH22)*F22*G22)/1000 -> 0 | BJ22: =SUM(AI22:AN22, BF22:BH22)*F22*G22/1000 -> 0
A23: ='Input Scenarios'!A23 -> WA | B23: ='Input Scenarios'!B23 -> 0 | C23: ='Input Scenarios'!C23 -> Non-irrigated crop (low rainfall) | D23: ='Input Scenarios'!D23 -> FALSE | E23: ='Input Scenarios'!E23 -> boars | F23: ='Input Scenarios'!F23 -> 750 | G23: ='Input Scenarios'!G23 -> 200 | H23: =IF('Input Scenarios'!H23<>"", 'Input Scenarios'!H23, _xlfn.XLOOKUP($E23,Constants!$A$3:$A$6, Constants!B$3:B$6)) -> 2.62 | I23: =IF('Input Scenarios'!I23<>"", 'Input Scenarios'!I23, _xlfn.XLOOKUP($E23,Constants!$A$3:$A$6, Constants!C$3:C$6)) -> 0.4 | J23: =IF('Input Scenarios'!J23<>"", 'Input Scenarios'!J23, _xlfn.XLOOKUP($E23,Constants!$A$3:$A$6, Constants!D$3:D$6)) -> 0.046 | K23: ='Input Scenarios'!K23 -> 0 | L23: ='Input Scenarios'!L23 -> 0 | M23: ='Input Scenarios'!M23 -> 0 | N23: ='Input Scenarios'!N23 -> 0 | O23: ='Input Scenarios'!O23 -> 0 | P23: ='Input Scenarios'!P23 -> 0 | Q23: ='Input Scenarios'!Q23 -> FALSE | R23: =IF('Input Scenarios'!$R23<>"", 'Input Scenarios'!$R23, IF($Q23, Constants!$B$19, 0)) -> 0 | S23: =IF('Input Scenarios'!$R23<>"", 'Input Scenarios'!$R23, IF($Q23, Constants!$B$20, 0)) -> 0 | T23: =K23*(1-$R23) -> 0 | U23: =L23 -> 0 | V23: =M23*(1-$R23) -> 0 | W23: =N23 -> 0 | X23: =O23*(1-$R23) -> 0 | Y23: =P23+(SUM(K23,M23,O23)*R23) -> 0 | Z23: =Constants!$B$21 -> 0.19 | AA23: =Constants!$B$22 -> 0.6784 | AB23: =_xlfn.XLOOKUP($A23,Constants!$F$9:$M$9,Constants!$F$10:$M$10) -> 0.76 | AC23: =_xlfn.XLOOKUP($A23,Constants!$F$9:$M$9,Constants!$F$12:$M$12) -> 0.01 | AD23: =_xlfn.XLOOKUP($A23,Constants!$F$9:$M$9,Constants!$F$13:$M$13) -> 0.1 | AE23: =_xlfn.XLOOKUP($A23,Constants!$F$9:$M$9,Constants!$F$14:$M$14) -> 0.04 | AF23: =_xlfn.XLOOKUP($A23,Constants!$F$9:$M$9,Constants!$F$15:$M$15) -> 0.03 | AG23: =_xlfn.XLOOKUP($A23,Constants!$F$9:$M$9,Constants!$F$11:$M$11) -> 0.02 | AH23: =_xlfn.XLOOKUP($A23,Constants!$F$9:$M$9,Constants!$F$16:$M$16) -> 0 | AI23: =$I23*T23*AB23*$Z23*$AA23 -> 0 | AJ23: =$I23*U23*AC23*$Z23*$AA23 -> 0 | AK23: =$I23*V23*AD23*$Z23*$AA23 -> 0 | AL23: =$I23*W23*AE23*$Z23*$AA23 -> 0 | AM23: =$I23*X23*AF23*$Z23*$AA23 -> 0 | AN23: =$I23*Y23*AG23*$Z23*$AA23 -> 0 | AO23: =(SUM(AI23:AN23)*F23*G23)/1000 -> 0 | AP23: =Constants!$E$10 -> 0 | AQ23: =Constants!$E$12 -> 0 | AR23: =Constants!$E$13 -> 0.75 | AS23: =Constants!$E$14 -> 0.05 | AT23: =Constants!$E$15 -> 0 | AU23: =Constants!$E$11 -> 0 | AV23: =(T23*(1-AP23)) -> 0 | AW23: =(U23*(1-AQ23)) -> 0 | AX23: =(V23*(1-AR23)) -> 0 | AY23: =(W23*(1-AS23)) -> 0 | AZ23: =(X23*(1-AT23)) -> 0 | BA23: =(Y23*(1-AU23)) -> 0 | BB23: =SUM(AV23:BA23)*I23 -> 0 | BC23: =AX23*$I23 -> 0 | BD23: =AY23*$I23 -> 0 | BE23: =SUM(AV23:AW23, AZ23:BA23)*$I23 -> 0 | BF23: =BC23*$Z23*AB23*$AA23 -> 0 | BG23: =BD23*$Z23*AG23*$AA23 -> 0 | BH23: =BE23*$Z23*AH23*$AA23 -> 0 | BI23: =(SUM(BF23:BH23)*F23*G23)/1000 -> 0 | BJ23: =SUM(AI23:AN23, BF23:BH23)*F23*G23/1000 -> 0 | BK23: =SUM(BJ23:BJ26) -> 0
A24: ='Input Scenarios'!A24 -> WA | B24: ='Input Scenarios'!B24 -> 0 | C24: ='Input Scenarios'!C24 -> Non-irrigated crop (low rainfall) | D24: ='Input Scenarios'!D24 -> FALSE | E24: ='Input Scenarios'!E24 -> sows | F24: ='Input Scenarios'!F24 -> 600 | G24: ='Input Scenarios'!G24 -> 200 | H24: =IF('Input Scenarios'!H24<>"", 'Input Scenarios'!H24, _xlfn.XLOOKUP($E24,Constants!$A$3:$A$6, Constants!B$3:B$6)) -> 2.3 | I24: =IF('Input Scenarios'!I24<>"", 'Input Scenarios'!I24, _xlfn.XLOOKUP($E24,Constants!$A$3:$A$6, Constants!C$3:C$6)) -> 0.46 | J24: =IF('Input Scenarios'!J24<>"", 'Input Scenarios'!J24, _xlfn.XLOOKUP($E24,Constants!$A$3:$A$6, Constants!D$3:D$6)) -> 0.049 | K24: ='Input Scenarios'!K24 -> 0 | L24: ='Input Scenarios'!L24 -> 0 | M24: ='Input Scenarios'!M24 -> 0 | N24: ='Input Scenarios'!N24 -> 0 | O24: ='Input Scenarios'!O24 -> 0 | P24: ='Input Scenarios'!P24 -> 0 | Q24: ='Input Scenarios'!Q24 -> FALSE | R24: =IF('Input Scenarios'!$R24<>"", 'Input Scenarios'!$R24, IF($Q24, Constants!$B$19, 0)) -> 0 | S24: =IF('Input Scenarios'!$R24<>"", 'Input Scenarios'!$R24, IF($Q24, Constants!$B$20, 0)) -> 0 | T24: =K24*(1-$R24) -> 0 | U24: =L24 -> 0 | V24: =M24*(1-$R24) -> 0 | W24: =N24 -> 0 | X24: =O24*(1-$R24) -> 0 | Y24: =P24+(SUM(K24,M24,O24)*R24) -> 0 | Z24: =Constants!$B$21 -> 0.19 | AA24: =Constants!$B$22 -> 0.6784 | AB24: =_xlfn.XLOOKUP($A24,Constants!$F$9:$M$9,Constants!$F$10:$M$10) -> 0.76 | AC24: =_xlfn.XLOOKUP($A24,Constants!$F$9:$M$9,Constants!$F$12:$M$12) -> 0.01 | AD24: =_xlfn.XLOOKUP($A24,Constants!$F$9:$M$9,Constants!$F$13:$M$13) -> 0.1 | AE24: =_xlfn.XLOOKUP($A24,Constants!$F$9:$M$9,Constants!$F$14:$M$14) -> 0.04 | AF24: =_xlfn.XLOOKUP($A24,Constants!$F$9:$M$9,Constants!$F$15:$M$15) -> 0.03 | AG24: =_xlfn.XLOOKUP($A24,Constants!$F$9:$M$9,Constants!$F$11:$M$11) -> 0.02 | AH24: =_xlfn.XLOOKUP($A24,Constants!$F$9:$M$9,Constants!$F$16:$M$16) -> 0 | AI24: =$I24*T24*AB24*$Z24*$AA24 -> 0 | AJ24: =$I24*U24*AC24*$Z24*$AA24 -> 0 | AK24: =$I24*V24*AD24*$Z24*$AA24 -> 0 | AL24: =$I24*W24*AE24*$Z24*$AA24 -> 0 | AM24: =$I24*X24*AF24*$Z24*$AA24 -> 0 | AN24: =$I24*Y24*AG24*$Z24*$AA24 -> 0 | AO24: =(SUM(AI24:AN24)*F24*G24)/1000 -> 0 | AP24: =Constants!$E$10 -> 0 | AQ24: =Constants!$E$12 -> 0 | AR24: =Constants!$E$13 -> 0.75 | AS24: =Constants!$E$14 -> 0.05 | AT24: =Constants!$E$15 -> 0 | AU24: =Constants!$E$11 -> 0 | AV24: =(T24*(1-AP24)) -> 0 | AW24: =(U24*(1-AQ24)) -> 0 | AX24: =(V24*(1-AR24)) -> 0 | AY24: =(W24*(1-AS24)) -> 0 | AZ24: =(X24*(1-AT24)) -> 0 | BA24: =(Y24*(1-AU24)) -> 0 | BB24: =SUM(AV24:BA24)*I24 -> 0 | BC24: =AX24*$I24 -> 0 | BD24: =AY24*$I24 -> 0 | BE24: =SUM(AV24:AW24, AZ24:BA24)*$I24 -> 0 | BF24: =BC24*$Z24*AB24*$AA24 -> 0 | BG24: =BD24*$Z24*AG24*$AA24 -> 0 | BH24: =BE24*$Z24*AH24*$AA24 -> 0 | BI24: =(SUM(BF24:BH24)*F24*G24)/1000 -> 0 | BJ24: =SUM(AI24:AN24, BF24:BH24)*F24*G24/1000 -> 0
A25: ='Input Scenarios'!A25 -> WA | B25: ='Input Scenarios'!B25 -> 0 | C25: ='Input Scenarios'!C25 -> Non-irrigated crop (low rainfall) | D25: ='Input Scenarios'!D25 -> FALSE | E25: ='Input Scenarios'!E25 -> gilts | F25: ='Input Scenarios'!F25 -> 100 | G25: ='Input Scenarios'!G25 -> 299 | H25: =IF('Input Scenarios'!H25<>"", 'Input Scenarios'!H25, _xlfn.XLOOKUP($E25,Constants!$A$3:$A$6, Constants!B$3:B$6)) -> 2.5 | I25: =IF('Input Scenarios'!I25<>"", 'Input Scenarios'!I25, _xlfn.XLOOKUP($E25,Constants!$A$3:$A$6, Constants!C$3:C$6)) -> 0.55 | J25: =IF('Input Scenarios'!J25<>"", 'Input Scenarios'!J25, _xlfn.XLOOKUP($E25,Constants!$A$3:$A$6, Constants!D$3:D$6)) -> 0.046 | K25: ='Input Scenarios'!K25 -> 0 | L25: ='Input Scenarios'!L25 -> 0 | M25: ='Input Scenarios'!M25 -> 0 | N25: ='Input Scenarios'!N25 -> 0 | O25: ='Input Scenarios'!O25 -> 0 | P25: ='Input Scenarios'!P25 -> 0 | Q25: ='Input Scenarios'!Q25 -> TRUE | R25: =IF('Input Scenarios'!$R25<>"", 'Input Scenarios'!$R25, IF($Q25, Constants!$B$19, 0)) -> 0.25 | S25: =IF('Input Scenarios'!$R25<>"", 'Input Scenarios'!$R25, IF($Q25, Constants!$B$20, 0)) -> 0.25 | T25: =K25*(1-$R25) -> 0 | U25: =L25 -> 0 | V25: =M25*(1-$R25) -> 0 | W25: =N25 -> 0 | X25: =O25*(1-$R25) -> 0 | Y25: =P25+(SUM(K25,M25,O25)*R25) -> 0 | Z25: =Constants!$B$21 -> 0.19 | AA25: =Constants!$B$22 -> 0.6784 | AB25: =_xlfn.XLOOKUP($A25,Constants!$F$9:$M$9,Constants!$F$10:$M$10) -> 0.76 | AC25: =_xlfn.XLOOKUP($A25,Constants!$F$9:$M$9,Constants!$F$12:$M$12) -> 0.01 | AD25: =_xlfn.XLOOKUP($A25,Constants!$F$9:$M$9,Constants!$F$13:$M$13) -> 0.1 | AE25: =_xlfn.XLOOKUP($A25,Constants!$F$9:$M$9,Constants!$F$14:$M$14) -> 0.04 | AF25: =_xlfn.XLOOKUP($A25,Constants!$F$9:$M$9,Constants!$F$15:$M$15) -> 0.03 | AG25: =_xlfn.XLOOKUP($A25,Constants!$F$9:$M$9,Constants!$F$11:$M$11) -> 0.02 | AH25: =_xlfn.XLOOKUP($A25,Constants!$F$9:$M$9,Constants!$F$16:$M$16) -> 0 | AI25: =$I25*T25*AB25*$Z25*$AA25 -> 0 | AJ25: =$I25*U25*AC25*$Z25*$AA25 -> 0 | AK25: =$I25*V25*AD25*$Z25*$AA25 -> 0 | AL25: =$I25*W25*AE25*$Z25*$AA25 -> 0 | AM25: =$I25*X25*AF25*$Z25*$AA25 -> 0 | AN25: =$I25*Y25*AG25*$Z25*$AA25 -> 0 | AO25: =(SUM(AI25:AN25)*F25*G25)/1000 -> 0 | AP25: =Constants!$E$10 -> 0 | AQ25: =Constants!$E$12 -> 0 | AR25: =Constants!$E$13 -> 0.75 | AS25: =Constants!$E$14 -> 0.05 | AT25: =Constants!$E$15 -> 0 | AU25: =Constants!$E$11 -> 0 | AV25: =(T25*(1-AP25)) -> 0 | AW25: =(U25*(1-AQ25)) -> 0 | AX25: =(V25*(1-AR25)) -> 0 | AY25: =(W25*(1-AS25)) -> 0 | AZ25: =(X25*(1-AT25)) -> 0 | BA25: =(Y25*(1-AU25)) -> 0 | BB25: =SUM(AV25:BA25)*I25 -> 0 | BC25: =AX25*$I25 -> 0 | BD25: =AY25*$I25 -> 0 | BE25: =SUM(AV25:AW25, AZ25:BA25)*$I25 -> 0 | BF25: =BC25*$Z25*AB25*$AA25 -> 0 | BG25: =BD25*$Z25*AG25*$AA25 -> 0 | BH25: =BE25*$Z25*AH25*$AA25 -> 0 | BI25: =(SUM(BF25:BH25)*F25*G25)/1000 -> 0 | BJ25: =SUM(AI25:AN25, BF25:BH25)*F25*G25/1000 -> 0
A26: ='Input Scenarios'!A26 -> WA | B26: ='Input Scenarios'!B26 -> 0 | C26: ='Input Scenarios'!C26 -> Non-irrigated crop (low rainfall) | D26: ='Input Scenarios'!D26 -> FALSE | E26: ='Input Scenarios'!E26 -> others | F26: ='Input Scenarios'!F26 -> 999 | G26: ='Input Scenarios'!G26 -> 299 | H26: =IF('Input Scenarios'!H26<>"", 'Input Scenarios'!H26, _xlfn.XLOOKUP($E26,Constants!$A$3:$A$6, Constants!B$3:B$6)) -> 1.71 | I26: =IF('Input Scenarios'!I26<>"", 'Input Scenarios'!I26, _xlfn.XLOOKUP($E26,Constants!$A$3:$A$6, Constants!C$3:C$6)) -> 0.39 | J26: =IF('Input Scenarios'!J26<>"", 'Input Scenarios'!J26, _xlfn.XLOOKUP($E26,Constants!$A$3:$A$6, Constants!D$3:D$6)) -> 0.031232877 | K26: ='Input Scenarios'!K26 -> 0 | L26: ='Input Scenarios'!L26 -> 0 | M26: ='Input Scenarios'!M26 -> 0 | N26: ='Input Scenarios'!N26 -> 0 | O26: ='Input Scenarios'!O26 -> 0 | P26: ='Input Scenarios'!P26 -> 0 | Q26: ='Input Scenarios'!Q26 -> TRUE | R26: =IF('Input Scenarios'!$R26<>"", 'Input Scenarios'!$R26, IF($Q26, Constants!$B$19, 0)) -> 0.25 | S26: =IF('Input Scenarios'!$R26<>"", 'Input Scenarios'!$R26, IF($Q26, Constants!$B$20, 0)) -> 0.25 | T26: =K26*(1-$R26) -> 0 | U26: =L26 -> 0 | V26: =M26*(1-$R26) -> 0 | W26: =N26 -> 0 | X26: =O26*(1-$R26) -> 0 | Y26: =P26+(SUM(K26,M26,O26)*R26) -> 0 | Z26: =Constants!$B$21 -> 0.19 | AA26: =Constants!$B$22 -> 0.6784 | AB26: =_xlfn.XLOOKUP($A26,Constants!$F$9:$M$9,Constants!$F$10:$M$10) -> 0.76 | AC26: =_xlfn.XLOOKUP($A26,Constants!$F$9:$M$9,Constants!$F$12:$M$12) -> 0.01 | AD26: =_xlfn.XLOOKUP($A26,Constants!$F$9:$M$9,Constants!$F$13:$M$13) -> 0.1 | AE26: =_xlfn.XLOOKUP($A26,Constants!$F$9:$M$9,Constants!$F$14:$M$14) -> 0.04 | AF26: =_xlfn.XLOOKUP($A26,Constants!$F$9:$M$9,Constants!$F$15:$M$15) -> 0.03 | AG26: =_xlfn.XLOOKUP($A26,Constants!$F$9:$M$9,Constants!$F$11:$M$11) -> 0.02 | AH26: =_xlfn.XLOOKUP($A26,Constants!$F$9:$M$9,Constants!$F$16:$M$16) -> 0 | AI26: =$I26*T26*AB26*$Z26*$AA26 -> 0 | AJ26: =$I26*U26*AC26*$Z26*$AA26 -> 0 | AK26: =$I26*V26*AD26*$Z26*$AA26 -> 0 | AL26: =$I26*W26*AE26*$Z26*$AA26 -> 0 | AM26: =$I26*X26*AF26*$Z26*$AA26 -> 0 | AN26: =$I26*Y26*AG26*$Z26*$AA26 -> 0 | AO26: =(SUM(AI26:AN26)*F26*G26)/1000 -> 0 | AP26: =Constants!$E$10 -> 0 | AQ26: =Constants!$E$12 -> 0 | AR26: =Constants!$E$13 -> 0.75 | AS26: =Constants!$E$14 -> 0.05 | AT26: =Constants!$E$15 -> 0 | AU26: =Constants!$E$11 -> 0 | AV26: =(T26*(1-AP26)) -> 0 | AW26: =(U26*(1-AQ26)) -> 0 | AX26: =(V26*(1-AR26)) -> 0 | AY26: =(W26*(1-AS26)) -> 0 | AZ26: =(X26*(1-AT26)) -> 0 | BA26: =(Y26*(1-AU26)) -> 0 | BB26: =SUM(AV26:BA26)*I26 -> 0 | BC26: =AX26*$I26 -> 0 | BD26: =AY26*$I26 -> 0 | BE26: =SUM(AV26:AW26, AZ26:BA26)*$I26 -> 0 | BF26: =BC26*$Z26*AB26*$AA26 -> 0 | BG26: =BD26*$Z26*AG26*$AA26 -> 0 | BH26: =BE26*$Z26*AH26*$AA26 -> 0 | BI26: =(SUM(BF26:BH26)*F26*G26)/1000 -> 0 | BJ26: =SUM(AI26:AN26, BF26:BH26)*F26*G26/1000 -> 0

Sheet 4.5.1.3
A2: Method 1
A4: input | B4: input | C4: input | D4: input | E4: input | F4: input | G4: input | I4: input | K4: input | L4: input | M4: input | N4: input | O4: input | P4: input | Q4: input | R4: input
A8: State | B8: MAT | C8: Production system | D8: Leaching zone | E8: Swine class | F8: Number of poultry in each class j and subclass k | G8: Duration of stay for each class and subclass of poultry | H8: Feed Intake | I8: Volatile solid production | J8: Nitrogen waste production | K8: Uncovered anaerobic lagoons | L8: Outdoor | M8: Covered/Digester | N8: Deep Litter | O8: Pit Storage < 1 Month | P8: Solid Storage | Q8: Solids separated | R8: Solid separation rate
BD9: Stage 1 | BJ9: Stage 2
A10: i | B10: i | D10: (true or false) | E10: j | F10: Nj | G10: Dj | H10: Ij | I10: VSj | J10: NWj | K10: MMSjm=1T=1 | L10: MMSjm=5T=1 | M10: MMSjm=7T=1 | N10: MMSjm=8T=1 | O10: MMSjm=9T=1 | P10: MMSjm=4T=1 | Q10: true/false | R10: SSj | S10: SNj | T10: AEj | U10: FNjm=1T=1 | V10: FNjm=5T=1 | W10: FNjm=7T=1 | X10: FNjm=8T=1 | Y10: FNjm=9T=1 | Z10: FNjm=4T=1 | AA10: MNjm=1T=1 | AB10: MNjm=5T=1 | AC10: MNjm=7T=1 | AD10: MNjm=8T=1 | AE10: MNjm=9T=1 | AF10: MNjm=4T=1 | AG10: FracGASMm=1T=1 | AH10: FracGASMm=5T=1 | AI10: FracGASMm=7T=1 | AJ10: FracGASMm=8T=1 | AK10: FracGASMm=9T=1 | AL10: FracGASMm=4T=1 | AM10: EFm=1 | AN10: EFm=5 | AO10: EFm=7 | AP10: EFm=8 | AQ10: EFm=9 | AR10: EFm=4 | AS10: NTjm=1T=2 | AT10: NTjm=5T=2 | AU10: NTjm=7T=2 | AV10: NTjm=8T=2 | AW10: NTjm=9T=2 | AX10: NTjm=4T=2 | AY10: NTjmT=2 | AZ10: MNjm=1T=2 | BA10: MNjm=4T=2 | BB10: MNjm=13T=2 | BC10: CN2O | BD10: EN2O,dir (m=1, T=1) | BE10: EN2O,dir (m=1, T=5) | BF10: EN2O,dir (m=1, T=7) | BG10: EN2O,dir (m=1, T=8) | BH10: EN2O,dir (m=1, T=9) | BI10: EN2O,dir (m=1, T=4) | BJ10: EN2O,dir (m=1, T=2) | BK10: EN2O,dir (m=1, T=4) | BL10: EN2O,dir
A11: ='Input Scenarios'!A11 -> NSW | B11: ='Input Scenarios'!B11 -> 0 | C11: ='Input Scenarios'!C11 -> Irrigated crop | D11: ='Input Scenarios'!D11 -> TRUE | E11: ='Input Scenarios'!E11 -> boars | F11: ='Input Scenarios'!F11 -> 111 | G11: ='Input Scenarios'!G11 -> 105 | H11: =IF('Input Scenarios'!H11<>"", 'Input Scenarios'!H11, _xlfn.XLOOKUP($E11,Constants!$A$3:$A$6, Constants!B$3:B$6)) -> 2.62 | I11: =IF('Input Scenarios'!I11<>"", 'Input Scenarios'!I11, _xlfn.XLOOKUP($E11,Constants!$A$3:$A$6, Constants!C$3:C$6)) -> 0.4 | J11: =IF('Input Scenarios'!J11<>"", 'Input Scenarios'!J11, _xlfn.XLOOKUP($E11,Constants!$A$3:$A$6, Constants!D$3:D$6)) -> 0.046 | K11: ='Input Scenarios'!K11 -> 1 | L11: ='Input Scenarios'!L11 -> 0 | M11: ='Input Scenarios'!M11 -> 0 | N11: ='Input Scenarios'!N11 -> 0 | O11: ='Input Scenarios'!O11 -> 0 | P11: ='Input Scenarios'!P11 -> 0 | Q11: ='Input Scenarios'!Q11 -> TRUE | R11: =IF('Input Scenarios'!$R11<>"", 'Input Scenarios'!$R11, IF($Q11, Constants!$B$19, 0)) -> 0.25 | S11: =IF('Input Scenarios'!$R11<>"", 'Input Scenarios'!$R11, IF($Q11, Constants!$B$20, 0)) -> 0.25 | T11: =F11*G11*J11 -> 536.13 | U11: =K11*(1-$S11) -> 0.75 | V11: =L11 -> 0 | W11: =M11*(1-$S11) -> 0 | X11: =N11 -> 0 | Y11: =O11*(1-$S11) -> 0 | Z11: =P11+(SUM(K11, M11, O11)*S11) -> 0.25 | AA11: =$T11*U11 -> 402.0975 | AB11: =$T11*V11 -> 0 | AC11: =$T11*W11 -> 0 | AD11: =$T11*X11 -> 0 | AE11: =$T11*Y11 -> 0 | AF11: =$T11*Z11 -> 134.0325 | AG11: =Constants!$C$10 -> 0.55 | AH11: =Constants!$C$12 -> 0.3 | AI11: =Constants!$C$13 -> 0 | AJ11: =Constants!$C$14 -> 0.125 | AK11: =Constants!$C$15 -> 0.25 | AL11: =Constants!$C$11 -> 0.2 | AM11: =Constants!$D$10 -> 0 | AN11: =Constants!$D$12 -> 0.02 | AO11: =Constants!$D$13 -> 0 | AP11: =Constants!$D$14 -> 0.01 | AQ11: =Constants!$D$15 -> 0.002 | AR11: =Constants!$D$11 -> 0.005 | AS11: =AA11*(1-AG11-AM11) -> 180.94387 | AT11: =AB11*(1-AH11-AN11) -> 0 | AU11: =AC11*(1-AI11-AO11) -> 0 | AV11: =AD11*(1-AJ11-AP11) -> 0 | AW11: =AE11*(1-AK11-AQ11) -> 0 | AX11: =AF11*(1-AL11-AR11) -> 106.55584 | AY11: =SUM(AS11:AX11) -> 287.49971 | AZ11: =AU11 -> 0 | BA11: =AV11 -> 0 | BB11: =SUM(AS11:AT11,AW11:AX11) -> 287.49971 | BC11: =Constants!$B$23 -> 1.5714286 | BD11: =(AA11*AM11*$BC11) -> 0 | BE11: =(AB11*AN11*$BC11) -> 0 | BF11: =(AC11*AO11*$BC11) -> 0 | BG11: =(AD11*AP11*$BC11) -> 0 | BH11: =(AE11*AQ11*$BC11) -> 0 | BI11: =(AF11*AR11*$BC11) -> 1.0531125 | BJ11: =(AZ11*AM11*$BC11) -> 0 | BK11: =(BA11*AR11*$BC11) -> 0 | BL11: =SUM(BD11:BK14)/1000 -> 0.028790308
