Workbook

Sheet Input Scenarios
A1: Method 1 Inputs
A3: input | C3: input
A5: State | B5: MAT | C5: Production system | D5: Number of cattle | E5: Avg. length of star | F5: Allocations to MMS in treatment stage 2 | J5: Dry matter intake | K5: Nitrogen Retention Rate | L5: Dry matter digestibility | M5: Crude protein
F6: solid storage | G6: composting | H6: directApplication
A7: i | B7: i | D7: Nj | E7: Dj | F7: MMSjm=4T=2 | G7: MMSjm=7T=2 | H7: MMSjm=13T=2 | I7: PF | J7: Ij | K7: NRj | L7: DMDj | M7: CPj
A8: NSW | C8: Non-irrigated pasture | D8: 200 | E8: 79 | F8: 0.4 | G8: 0.4 | H8: 0.2 | I8: 0.5
A9: QLD | C9: Irrigated pasture | D9: 200 | E9: 80 | F9: 0.4 | G9: 0.4 | H9: 0.2 | I9: 0.5
A10: SA | C10: Irrigated crop | D10: 200 | E10: 81 | F10: 0.4 | G10: 0.4 | H10: 0.2 | I10: 0.5
A11: VIC | C11: Non-irrigated crop (low rainfall) | D11: 200 | E11: 200 | F11: 0.4 | G11: 0.4 | H11: 0.2 | I11: 0.5
A12: WA | C12: Non-irrigated crop (high rainfall) | D12: 200 | E12: 201 | F12: 0.4 | G12: 0.4 | H12: 0.2 | I12: 0.5
A14: Method 2 inputs
A16: input | C16: input
A18: State | B18: MAT | C18: Production system | D18: Number of cattle | E18: Avg. length of star | F18: Allocations to MMS in treatment stage 2 | J18: Dry matter intake | K18: Nitrogen Retention Rate | L18: Dry matter digestibility | M18: Crude protein
F19: solid storage | G19: composting | H19: directApplication
A20: i | B20: i | D20: Nj | E20: Dj | F20: MMSjm=4T=2 | G20: MMSjm=7T=2 | H20: MMSjm=13T=2 | I20: PF | J20: Ij | K20: NRj | L20: DMDj | M20: CPj
A21: NSW | B21: 14 | C21: Non-irrigated pasture | D21: 200 | E21: 79 | F21: 0.4 | G21: 0.4 | H21: 0.2 | I21: 0.5
A22: QLD | B22: 27 | C22: Irrigated pasture | D22: 200 | E22: 80 | F22: 0.4 | G22: 0.4 | H22: 0.2 | I22: 0.5
A23: SA | B23: 22 | C23: Irrigated crop | D23: 200 | E23: 81 | F23: 0.4 | G23: 0.4 | H23: 0.2 | I23: 0.5
A24: VIC | B24: 16 | C24: Non-irrigated crop (low rainfall) | D24: 200 | E24: 200 | F24: 0.4 | G24: 0.4 | H24: 0.2 | I24: 0.5
A25: WA | B25: 28 or above | C25: Non-irrigated crop (high rainfall) | D25: 200 | E25: 201 | F25: 0.4 | G25: 0.4 | H25: 0.2 | I25: 0.5

Sheet Constants
A1: Feedlot Type | B1: Ij | C1: NRj | D1: DMDj | E1: CPj
A2: Domestic | B2: 10.4 | C2: 0.204 | D2: 0.81 | E2: 0.14
A3: Mid-fed | B3: 10.8 | C3: 0.127 | D3: 0.81 | E3: 0.12
A4: Long-fed | B4: 8.2 | C4: 0.07 | D4: 0.81 | E4: 0.12
E6: MCFim by state
A7: MMS | B7: m | C7: EFm | D7: FracGASMm | E7: NSW | F7: QLD | G7: VIC | H7: SA | I7: WA
A8: drylot | B8: 5 | C8: 0.0054 | D8: 0.6 | E8: 0.01 | F8: 0.03 | G8: 0.01 | H8: 0.01 | I8: 0.01
A9: solidStorage | B9: 4 | C9: 0.005 | D9: 0.25 | E9: 0.02 | F9: 0.02 | G9: 0.02 | H9: 0.02 | I9: 0.02
A10: composting | B10: 7 | C10: 0.01 | D10: 0.4 | E10: 0.01 | F10: 0.01 | G10: 0.01 | H10: 0.01 | I10: 0.01
A11: directApplication | B11: 13 | C11: 0 | D11: 0 | E11: 0 | F11: 0 | G11: 0 | H11: 0 | I11: 0
A12: anaerobicLagoon | B12: 1 | C12: 0 | D12: 0.35 | E12: 0.75 | F12: 0.77 | G12: 0.75 | H12: 0.75 | I12: 0.77
E14: MCFim BY MAT
A15: Production system | B15: EFN2O | E15: MAT | F15: drylot | G15: solidStorage | H15: composting | I15: directApplication | J15: anaerobicLagoon
A16: Non-irrigated pasture | B16: 0.0018 | E16: 10 or below | G16: 0.02 | H16: 0.005 | I16: 0 | J16: 0.66
A17: Irrigated pasture | B17: 0.0059 | E17: 11 | G17: 0.02 | H17: 0.005 | I17: 0 | J17: 0.68
A18: Irrigated crop | B18: 0.007 | E18: 12 | G18: 0.02 | H18: 0.005 | I18: 0 | J18: 0.7
A19: Non-irrigated crop (low rainfall) | B19: 0.0029 | E19: 13 | G19: 0.02 | H19: 0.005 | I19: 0 | J19: 0.71
A20: Non-irrigated crop (high rainfall) | B20: 0.008 | E20: 14 | G20: 0.02 | H20: 0.005 | I20: 0 | J20: 0.73
E21: 15 | G21: 0.02 | H21: 0.01 | I21: 0 | J21: 0.74
A22: Climate Zone | B22: EFPRP | E22: 16 | G22: 0.02 | H22: 0.01 | I22: 0 | J22: 0.75
A23: wet | B23: 0.006 | E23: 17 | G23: 0.02 | H23: 0.01 | I23: 0 | J23: 0.76
A24: dry | B24: 0.002 | E24: 18 | G24: 0.02 | H24: 0.01 | I24: 0 | J24: 0.77
E25: 19 | G25: 0.02 | H25: 0.01 | I25: 0 | J25: 0.78
A26: Fixed Constants | E26: 20 | G26: 0.02 | H26: 0.01 | I26: 0 | J26: 0.78
A27: A | B27: 0.16 | E27: 21 | G27: 0.02 | H27: 0.01 | I27: 0 | J27: 0.78
A28: VSL | B28: 0.5 | E28: 22 | G28: 0.02 | H28: 0.01 | I28: 0 | J28: 0.78
A29: MMSm=1T=3 | B29: 0.02 | E29: 23 | G29: 0.02 | H29: 0.01 | I29: 0 | J29: 0.79
A30: Bo | B30: 0.19 | E30: 24 | G30: 0.02 | H30: 0.01 | I30: 0 | J30: 0.79
A31: 𝜌 | B31: 0.6784 | E31: 25 | G31: 0.02 | H31: 0.01 | I31: 0 | J31: 0.79
A32: Crude protein to nitrogen | B32: 6.25 | E32: 26 | G32: 0.02 | H32: 0.015 | I32: 0 | J32: 0.79
A33: CN2O | B33: =44/28 -> 1.5714286 | E33: 27 | G33: 0.02 | H33: 0.015 | I33: 0 | J33: 0.8
E34: 28 or above | G34: 0.02 | H34: 0.015 | I34: 0 | J34: 0.8

Sheet 4.1.1.1
A3: input | C3: input
A5: State | B5: MAT | C5: Production system | D5: Number of cattle | E5: Avg. length of star | F5: Allocations to MMS in treatment stage 2 | J5: Dry matter intake | K5: Nitrogen Retention Rate | L5: Dry matter digestibility | M5: Crude protein
F6: solid storage | G6: composting | H6: directApplication
A7: i | B7: i | D7: Nj | E7: Dj | F7: MMSjm=4T=2 | G7: MMSjm=7T=2 | H7: MMSjm=13T=2 | I7: PF | J7: Ij | K7: NRj | L7: DMDj | M7: CPj | N7: A | O7: VSj | P7: Bo | Q7: 𝜌 | R7: MCFim=5 | S7: Mjm=5T=1 | T7: VSL | U7: MCFim=4 | V7: MCFim=7 | W7: MCFim=13 | X7: Mjm=4T=2 | Y7: Mjm=7T=2 | Z7: Mjm=13T=2 | AA7: MMSm=1T=3 | AB7: MCFim=1 | AC7: Mjm=1T=3 | AD7: Mjm | AE7: ECH4
A8: ='Input Scenarios'!A8 -> NSW | B8: =IF('Input Scenarios'!B8<>"", 'Input Scenarios'!B8, "") | C8: ='Input Scenarios'!C8 -> Non-irrigated pasture | D8: ='Input Scenarios'!D8 -> 200 | E8: ='Input Scenarios'!E8 -> 79 | F8: ='Input Scenarios'!F8 -> 0.4 | G8: ='Input Scenarios'!G8 -> 0.4 | H8: ='Input Scenarios'!H8 -> 0.2 | I8: ='Input Scenarios'!I8 -> 0.5 | J8: =IF('Input Scenarios'!J8<>"", 'Input Scenarios'!J8, IF($E8<=80, Constants!B$2, IF($E8<=200, Constants!B$3, Constants!B$4))) -> 10.4 | K8: =IF('Input Scenarios'!K8<>"", 'Input Scenarios'!K8, IF($E8<=80, Constants!C$2, IF($E8<=200, Constants!C$3, Constants!C$4))) -> 0.204 | L8: =IF('Input Scenarios'!L8<>"", 'Input Scenarios'!L8, IF($E8<=80, Constants!D$2, IF($E8<=200, Constants!D$3, Constants!D$4))) -> 0.81 | M8: =IF('Input Scenarios'!M8<>"", 'Input Scenarios'!M8, IF($E8<=80, Constants!E$2, IF($E8<=200, Constants!E$3, Constants!E$4))) -> 0.14 | N8: =Constants!$B$27 -> 0.16 | O8: =J8*(1-L8)*(1-N8) -> 1.65984 | P8: =Constants!$B$30 -> 0.19 | Q8: =Constants!$B$31 -> 0.6784 | R8: =_xlfn.XLOOKUP(A8, Constants!$E$7:$I$7, Constants!$E$8:$I$8) -> 0.01 | S8: =O8*P8*Q8*R8 -> 0.0021394674 | T8: =Constants!$B$28 -> 0.5 | U8: =_xlfn.XLOOKUP($A8, Constants!$E$7:$I$7, Constants!$E$9:$I$9) -> 0.02 | V8: =_xlfn.XLOOKUP($A8, Constants!$E$7:$I$7, Constants!$E$10:$I$10) -> 0.01 | W8: =_xlfn.XLOOKUP($A8, Constants!$E$7:$I$7, Constants!$E$11:$I$11) -> 0 | X8: =(1-$T8)*$O8*$P8*$Q8*F8*U8 -> 0.00085578695 | Y8: =(1-$T8)*$O8*$P8*$Q8*G8*V8 -> 0.00042789347 | Z8: =(1-$T8)*$O8*$P8*$Q8*H8*W8 -> 0 | AA8: =Constants!$B$29 -> 0.02 | AB8: =_xlfn.XLOOKUP($A8, Constants!$E$7:$I$7, Constants!$E$12:$I$12) -> 0.75 | AC8: =O8*AA8*AB8*P8*Q8 -> 0.003209201 | AD8: =S8+SUM(X8:Z8)+AC8 -> 0.0066323488 | AE8: =D8*E8*AD8/1000 -> 0.10479111
A9: ='Input Scenarios'!A9 -> QLD | B9: =IF('Input Scenarios'!B9<>"", 'Input Scenarios'!B9, "") | C9: ='Input Scenarios'!C9 -> Irrigated pasture | D9: ='Input Scenarios'!D9 -> 200 | E9: ='Input Scenarios'!E9 -> 80 | F9: ='Input Scenarios'!F9 -> 0.4 | G9: ='Input Scenarios'!G9 -> 0.4 | H9: ='Input Scenarios'!H9 -> 0.2 | I9: ='Input Scenarios'!I9 -> 0.5 | J9: =IF('Input Scenarios'!J9<>"", 'Input Scenarios'!J9, IF($E9<=80, Constants!B$2, IF($E9<=200, Constants!B$3, Constants!B$4))) -> 10.4 | K9: =IF('Input Scenarios'!K9<>"", 'Input Scenarios'!K9, IF($E9<=80, Constants!C$2, IF($E9<=200, Constants!C$3, Constants!C$4))) -> 0.204 | L9: =IF('Input Scenarios'!L9<>"", 'Input Scenarios'!L9, IF($E9<=80, Constants!D$2, IF($E9<=200, Constants!D$3, Constants!D$4))) -> 0.81 | M9: =IF('Input Scenarios'!M9<>"", 'Input Scenarios'!M9, IF($E9<=80, Constants!E$2, IF($E9<=200, Constants!E$3, Constants!E$4))) -> 0.14 | N9: =Constants!$B$27 -> 0.16 | O9: =J9*(1-L9)*(1-N9) -> 1.65984 | P9: =Constants!$B$30 -> 0.19 | Q9: =Constants!$B$31 -> 0.6784 | R9: =_xlfn.XLOOKUP(A9, Constants!$E$7:$I$7, Constants!$E$8:$I$8) -> 0.03 | S9: =O9*P9*Q9*R9 -> 0.0064184021 | T9: =Constants!$B$28 -> 0.5 | U9: =_xlfn.XLOOKUP($A9, Constants!$E$7:$I$7, Constants!$E$9:$I$9) -> 0.02 | V9: =_xlfn.XLOOKUP($A9, Constants!$E$7:$I$7, Constants!$E$10:$I$10) -> 0.01 | W9: =_xlfn.XLOOKUP($A9, Constants!$E$7:$I$7, Constants!$E$11:$I$11) -> 0 | X9: =(1-$T9)*$O9*$P9*$Q9*F9*U9 -> 0.00085578695 | Y9: =(1-$T9)*$O9*$P9*$Q9*G9*V9 -> 0.00042789347 | Z9: =(1-$T9)*$O9*$P9*$Q9*H9*W9 -> 0 | AA9: =Constants!$B$29 -> 0.02 | AB9: =_xlfn.XLOOKUP($A9, Constants!$E$7:$I$7, Constants!$E$12:$I$12) -> 0.77 | AC9: =O9*AA9*AB9*P9*Q9 -> 0.0032947797 | AD9: =S9+SUM(X9:Z9)+AC9 -> 0.010996862 | AE9: =D9*E9*AD9/1000 -> 0.1759498
A10: ='Input Scenarios'!A10 -> SA | B10: =IF('Input Scenarios'!B10<>"", 'Input Scenarios'!B10, "") | C10: ='Input Scenarios'!C10 -> Irrigated crop | D10: ='Input Scenarios'!D10 -> 200 | E10: ='Input Scenarios'!E10 -> 81 | F10: ='Input Scenarios'!F10 -> 0.4 | G10: ='Input Scenarios'!G10 -> 0.4 | H10: ='Input Scenarios'!H10 -> 0.2 | I10: ='Input Scenarios'!I10 -> 0.5 | J10: =IF('Input Scenarios'!J10<>"", 'Input Scenarios'!J10, IF($E10<=80, Constants!B$2, IF($E10<=200, Constants!B$3, Constants!B$4))) -> 10.8 | K10: =IF('Input Scenarios'!K10<>"", 'Input Scenarios'!K10, IF($E10<=80, Constants!C$2, IF($E10<=200, Constants!C$3, Constants!C$4))) -> 0.127 | L10: =IF('Input Scenarios'!L10<>"", 'Input Scenarios'!L10, IF($E10<=80, Constants!D$2, IF($E10<=200, Constants!D$3, Constants!D$4))) -> 0.81 | M10: =IF('Input Scenarios'!M10<>"", 'Input Scenarios'!M10, IF($E10<=80, Constants!E$2, IF($E10<=200, Constants!E$3, Constants!E$4))) -> 0.12 | N10: =Constants!$B$27 -> 0.16 | O10: =J10*(1-L10)*(1-N10) -> 1.72368 | P10: =Constants!$B$30 -> 0.19 | Q10: =Constants!$B$31 -> 0.6784 | R10: =_xlfn.XLOOKUP(A10, Constants!$E$7:$I$7, Constants!$E$8:$I$8) -> 0.01 | S10: =O10*P10*Q10*R10 -> 0.0022217546 | T10: =Constants!$B$28 -> 0.5 | U10: =_xlfn.XLOOKUP($A10, Constants!$E$7:$I$7, Constants!$E$9:$I$9) -> 0.02 | V10: =_xlfn.XLOOKUP($A10, Constants!$E$7:$I$7, Constants!$E$10:$I$10) -> 0.01 | W10: =_xlfn.XLOOKUP($A10, Constants!$E$7:$I$7, Constants!$E$11:$I$11) -> 0 | X10: =(1-$T10)*$O10*$P10*$Q10*F10*U10 -> 0.00088870183 | Y10: =(1-$T10)*$O10*$P10*$Q10*G10*V10 -> 0.00044435091 | Z10: =(1-$T10)*$O10*$P10*$Q10*H10*W10 -> 0 | AA10: =Constants!$B$29 -> 0.02 | AB10: =_xlfn.XLOOKUP($A10, Constants!$E$7:$I$7, Constants!$E$12:$I$12) -> 0.75 | AC10: =O10*AA10*AB10*P10*Q10 -> 0.0033326319 | AD10: =S10+SUM(X10:Z10)+AC10 -> 0.0068874392 | AE10: =D10*E10*AD10/1000 -> 0.11157651
A11: ='Input Scenarios'!A11 -> VIC | B11: =IF('Input Scenarios'!B11<>"", 'Input Scenarios'!B11, "") | C11: ='Input Scenarios'!C11 -> Non-irrigated crop (low rainfall) | D11: ='Input Scenarios'!D11 -> 200 | E11: ='Input Scenarios'!E11 -> 200 | F11: ='Input Scenarios'!F11 -> 0.4 | G11: ='Input Scenarios'!G11 -> 0.4 | H11: ='Input Scenarios'!H11 -> 0.2 | I11: ='Input Scenarios'!I11 -> 0.5 | J11: =IF('Input Scenarios'!J11<>"", 'Input Scenarios'!J11, IF($E11<=80, Constants!B$2, IF($E11<=200, Constants!B$3, Constants!B$4))) -> 10.8 | K11: =IF('Input Scenarios'!K11<>"", 'Input Scenarios'!K11, IF($E11<=80, Constants!C$2, IF($E11<=200, Constants!C$3, Constants!C$4))) -> 0.127 | L11: =IF('Input Scenarios'!L11<>"", 'Input Scenarios'!L11, IF($E11<=80, Constants!D$2, IF($E11<=200, Constants!D$3, Constants!D$4))) -> 0.81 | M11: =IF('Input Scenarios'!M11<>"", 'Input Scenarios'!M11, IF($E11<=80, Constants!E$2, IF($E11<=200, Constants!E$3, Constants!E$4))) -> 0.12 | N11: =Constants!$B$27 -> 0.16 | O11: =J11*(1-L11)*(1-N11) -> 1.72368 | P11: =Constants!$B$30 -> 0.19 | Q11: =Constants!$B$31 -> 0.6784 | R11: =_xlfn.XLOOKUP(A11, Constants!$E$7:$I$7, Constants!$E$8:$I$8) -> 0.01 | S11: =O11*P11*Q11*R11 -> 0.0022217546 | T11: =Constants!$B$28 -> 0.5 | U11: =_xlfn.XLOOKUP($A11, Constants!$E$7:$I$7, Constants!$E$9:$I$9) -> 0.02 | V11: =_xlfn.XLOOKUP($A11, Constants!$E$7:$I$7, Constants!$E$10:$I$10) -> 0.01 | W11: =_xlfn.XLOOKUP($A11, Constants!$E$7:$I$7, Constants!$E$11:$I$11) -> 0 | X11: =(1-$T11)*$O11*$P11*$Q11*F11*U11 -> 0.00088870183 | Y11: =(1-$T11)*$O11*$P11*$Q11*G11*V11 -> 0.00044435091 | Z11: =(1-$T11)*$O11*$P11*$Q11*H11*W11 -> 0 | AA11: =Constants!$B$29 -> 0.02 | AB11: =_xlfn.XLOOKUP($A11, Constants!$E$7:$I$7, Constants!$E$12:$I$12) -> 0.75 | AC11: =O11*AA11*AB11*P11*Q11 -> 0.0033326319 | AD11: =S11+SUM(X11:Z11)+AC11 -> 0.0068874392 | AE11: =D11*E11*AD11/1000 -> 0.27549757
A12: ='Input Scenarios'!A12 -> WA | B12: =IF('Input Scenarios'!B12<>"", 'Input Scenarios'!B12, "") | C12: ='Input Scenarios'!C12 -> Non-irrigated crop (high rainfall) | D12: ='Input Scenarios'!D12 -> 200 | E12: ='Input Scenarios'!E12 -> 201 | F12: ='Input Scenarios'!F12 -> 0.4 | G12: ='Input Scenarios'!G12 -> 0.4 | H12: ='Input Scenarios'!H12 -> 0.2 | I12: ='Input Scenarios'!I12 -> 0.5 | J12: =IF('Input Scenarios'!J12<>"", 'Input Scenarios'!J12, IF($E12<=80, Constants!B$2, IF($E12<=200, Constants!B$3, Constants!B$4))) -> 8.2 | K12: =IF('Input Scenarios'!K12<>"", 'Input Scenarios'!K12, IF($E12<=80, Constants!C$2, IF($E12<=200, Constants!C$3, Constants!C$4))) -> 0.07 | L12: =IF('Input Scenarios'!L12<>"", 'Input Scenarios'!L12, IF($E12<=80, Constants!D$2, IF($E12<=200, Constants!D$3, Constants!D$4))) -> 0.81 | M12: =IF('Input Scenarios'!M12<>"", 'Input Scenarios'!M12, IF($E12<=80, Constants!E$2, IF($E12<=200, Constants!E$3, Constants!E$4))) -> 0.12 | N12: =Constants!$B$27 -> 0.16 | O12: =J12*(1-L12)*(1-N12) -> 1.30872 | P12: =Constants!$B$30 -> 0.19 | Q12: =Constants!$B$31 -> 0.6784 | R12: =_xlfn.XLOOKUP(A12, Constants!$E$7:$I$7, Constants!$E$8:$I$8) -> 0.01 | S12: =O12*P12*Q12*R12 -> 0.0016868877 | T12: =Constants!$B$28 -> 0.5 | U12: =_xlfn.XLOOKUP($A12, Constants!$E$7:$I$7, Constants!$E$9:$I$9) -> 0.02 | V12: =_xlfn.XLOOKUP($A12, Constants!$E$7:$I$7, Constants!$E$10:$I$10) -> 0.01 | W12: =_xlfn.XLOOKUP($A12, Constants!$E$7:$I$7, Constants!$E$11:$I$11) -> 0 | X12: =(1-$T12)*$O12*$P12*$Q12*F12*U12 -> 0.00067475509 | Y12: =(1-$T12)*$O12*$P12*$Q12*G12*V12 -> 0.00033737755 | Z12: =(1-$T12)*$O12*$P12*$Q12*H12*W12 -> 0 | AA12: =Constants!$B$29 -> 0.02 | AB12: =_xlfn.XLOOKUP($A12, Constants!$E$7:$I$7, Constants!$E$12:$I$12) -> 0.77 | AC12: =O12*AA12*AB12*P12*Q12 -> 0.0025978071 | AD12: =S12+SUM(X12:Z12)+AC12 -> 0.0052968275 | AE12: =D12*E12*AD12/1000 -> 0.21293246

Sheet 4.1.1.2
A3: input | C3: input
A5: State | B5: MAT | C5: Production system | D5: Number of cattle | E5: Avg. length of star | F5: Allocations to MMS in treatment stage 2 | J5: Dry matter intake | K5: Nitrogen Retention Rate | L5: Dry matter digestibility | M5: Crude protein
F6: solid storage | G6: composting | H6: directApplication
A7: i | B7: i | D7: Nj | E7: Dj | F7: MMSjm=4T=2 | G7: MMSjm=7T=2 | H7: MMSjm=13T=2 | I7: PF | J7: Ij | K7: NRj | L7: DMDj | M7: CPj | N7: A | O7: VSj | P7: Bo | Q7: 𝜌 | R7: MCFim=5 | S7: Mjm=5T=1 | T7: VSL | U7: MCFim=4 | V7: MCFim=7 | W7: MCFim=13 | X7: Mjm=4T=2 | Y7: Mjm=7T=2 | Z7: Mjm=13T=2 | AA7: MMSm=1T=3 | AB7: MCFim=1 | AC7: Mjm=1T=3 | AD7: Mjm | AE7: ECH4
A8: ='Input Scenarios'!A21 -> NSW | B8: =IF('Input Scenarios'!B21<>"", 'Input Scenarios'!B21, "") -> 14 | C8: ='Input Scenarios'!C21 -> Non-irrigated pasture | D8: ='Input Scenarios'!D21 -> 200 | E8: ='Input Scenarios'!E21 -> 79 | F8: ='Input Scenarios'!F21 -> 0.4 | G8: ='Input Scenarios'!G21 -> 0.4 | H8: ='Input Scenarios'!H21 -> 0.2 | I8: ='Input Scenarios'!I21 -> 0.5 | J8: =IF('Input Scenarios'!J21<>"", 'Input Scenarios'!J21, IF($E8<=80, Constants!B$2, IF($E8<=200, Constants!B$3, Constants!B$4))) -> 10.4 | K8: =IF('Input Scenarios'!K21<>"", 'Input Scenarios'!K21, IF($E8<=80, Constants!C$2, IF($E8<=200, Constants!C$3, Constants!C$4))) -> 0.204 | L8: =IF('Input Scenarios'!L21<>"", 'Input Scenarios'!L21, IF($E8<=80, Constants!D$2, IF($E8<=200, Constants!D$3, Constants!D$4))) -> 0.81 | M8: =IF('Input Scenarios'!M21<>"", 'Input Scenarios'!M21, IF($E8<=80, Constants!E$2, IF($E8<=200, Constants!E$3, Constants!E$4))) -> 0.14 | N8: =Constants!$B$27 -> 0.16 | O8: =J8*(1-L8)*(1-N8) -> 1.65984 | P8: =Constants!$B$30 -> 0.19 | Q8: =Constants!$B$31 -> 0.6784 | R8: =_xlfn.XLOOKUP(A8, Constants!$E$7:$I$7, Constants!$E$8:$I$8) -> 0.01 | S8: =O8*P8*Q8*R8 -> 0.0021394674 | T8: =Constants!$B$28 -> 0.5 | U8: =_xlfn.XLOOKUP($B8, Constants!$E$16:$E$34,Constants!G$16:G$34) -> 0.02 | V8: =_xlfn.XLOOKUP($B8, Constants!$E$16:$E$34,Constants!H$16:H$34) -> 0.005 | W8: =_xlfn.XLOOKUP($B8, Constants!$E$16:$E$34,Constants!I$16:I$34) -> 0 | X8: =(1-$T8)*$O8*$P8*$Q8*F8*U8 -> 0.00085578695 | Y8: =(1-$T8)*$O8*$P8*$Q8*G8*V8 -> 0.00021394674 | Z8: =(1-$T8)*$O8*$P8*$Q8*H8*W8 -> 0 | AA8: =Constants!$B$29 -> 0.02 | AB8: =_xlfn.XLOOKUP($B8, Constants!$E$16:$E$34,Constants!J$16:J$34) -> 0.73 | AC8: =O8*AA8*AB8*P8*Q8 -> 0.0031236224 | AD8: =S8+SUM(X8:Z8)+AC8 -> 0.0063328234 | AE8: =D8*E8*AD8/1000 -> 0.10005861
A9: ='Input Scenarios'!A22 -> QLD | B9: =IF('Input Scenarios'!B22<>"", 'Input Scenarios'!B22, "") -> 27 | C9: ='Input Scenarios'!C22 -> Irrigated pasture | D9: ='Input Scenarios'!D22 -> 200 | E9: ='Input Scenarios'!E22 -> 80 | F9: ='Input Scenarios'!F22 -> 0.4 | G9: ='Input Scenarios'!G22 -> 0.4 | H9: ='Input Scenarios'!H22 -> 0.2 | I9: ='Input Scenarios'!I22 -> 0.5 | J9: =IF('Input Scenarios'!J22<>"", 'Input Scenarios'!J22, IF($E9<=80, Constants!B$2, IF($E9<=200, Constants!B$3, Constants!B$4))) -> 10.4 | K9: =IF('Input Scenarios'!K22<>"", 'Input Scenarios'!K22, IF($E9<=80, Constants!C$2, IF($E9<=200, Constants!C$3, Constants!C$4))) -> 0.204 | L9: =IF('Input Scenarios'!L22<>"", 'Input Scenarios'!L22, IF($E9<=80, Constants!D$2, IF($E9<=200, Constants!D$3, Constants!D$4))) -> 0.81 | M9: =IF('Input Scenarios'!M22<>"", 'Input Scenarios'!M22, IF($E9<=80, Constants!E$2, IF($E9<=200, Constants!E$3, Constants!E$4))) -> 0.14 | N9: =Constants!$B$27 -> 0.16 | O9: =J9*(1-L9)*(1-N9) -> 1.65984 | P9: =Constants!$B$30 -> 0.19 | Q9: =Constants!$B$31 -> 0.6784 | R9: =_xlfn.XLOOKUP(A9, Constants!$E$7:$I$7, Constants!$E$8:$I$8) -> 0.03 | S9: =O9*P9*Q9*R9 -> 0.0064184021 | T9: =Constants!$B$28 -> 0.5 | U9: =_xlfn.XLOOKUP($B9, Constants!$E$16:$E$34,Constants!G$16:G$34) -> 0.02 | V9: =_xlfn.XLOOKUP($B9, Constants!$E$16:$E$34,Constants!H$16:H$34) -> 0.015 | W9: =_xlfn.XLOOKUP($B9, Constants!$E$16:$E$34,Constants!I$16:I$34) -> 0 | X9: =(1-$T9)*$O9*$P9*$Q9*F9*U9 -> 0.00085578695 | Y9: =(1-$T9)*$O9*$P9*$Q9*G9*V9 -> 0.00064184021 | Z9: =(1-$T9)*$O9*$P9*$Q9*H9*W9 -> 0 | AA9: =Constants!$B$29 -> 0.02 | AB9: =_xlfn.XLOOKUP($B9, Constants!$E$16:$E$34,Constants!J$16:J$34) -> 0.8 | AC9: =O9*AA9*AB9*P9*Q9 -> 0.0034231478 | AD9: =S9+SUM(X9:Z9)+AC9 -> 0.011339177 | AE9: =D9*E9*AD9/1000 -> 0.18142683
A10: ='Input Scenarios'!A23 -> SA | B10: =IF('Input Scenarios'!B23<>"", 'Input Scenarios'!B23, "") -> 22 | C10: ='Input Scenarios'!C23 -> Irrigated crop | D10: ='Input Scenarios'!D23 -> 200 | E10: ='Input Scenarios'!E23 -> 81 | F10: ='Input Scenarios'!F23 -> 0.4 | G10: ='Input Scenarios'!G23 -> 0.4 | H10: ='Input Scenarios'!H23 -> 0.2 | I10: ='Input Scenarios'!I23 -> 0.5 | J10: =IF('Input Scenarios'!J23<>"", 'Input Scenarios'!J23, IF($E10<=80, Constants!B$2, IF($E10<=200, Constants!B$3, Constants!B$4))) -> 10.8 | K10: =IF('Input Scenarios'!K23<>"", 'Input Scenarios'!K23, IF($E10<=80, Constants!C$2, IF($E10<=200, Constants!C$3, Constants!C$4))) -> 0.127 | L10: =IF('Input Scenarios'!L23<>"", 'Input Scenarios'!L23, IF($E10<=80, Constants!D$2, IF($E10<=200, Constants!D$3, Constants!D$4))) -> 0.81 | M10: =IF('Input Scenarios'!M23<>"", 'Input Scenarios'!M23, IF($E10<=80, Constants!E$2, IF($E10<=200, Constants!E$3, Constants!E$4))) -> 0.12 | N10: =Constants!$B$27 -> 0.16 | O10: =J10*(1-L10)*(1-N10) -> 1.72368 | P10: =Constants!$B$30 -> 0.19 | Q10: =Constants!$B$31 -> 0.6784 | R10: =_xlfn.XLOOKUP(A10, Constants!$E$7:$I$7, Constants!$E$8:$I$8) -> 0.01 | S10: =O10*P10*Q10*R10 -> 0.0022217546 | T10: =Constants!$B$28 -> 0.5 | U10: =_xlfn.XLOOKUP($B10, Constants!$E$16:$E$34,Constants!G$16:G$34) -> 0.02 | V10: =_xlfn.XLOOKUP($B10, Constants!$E$16:$E$34,Constants!H$16:H$34) -> 0.01 | W10: =_xlfn.XLOOKUP($B10, Constants!$E$16:$E$34,Constants!I$16:I$34) -> 0 | X10: =(1-$T10)*$O10*$P10*$Q10*F10*U10 -> 0.00088870183 | Y10: =(1-$T10)*$O10*$P10*$Q10*G10*V10 -> 0.00044435091 | Z10: =(1-$T10)*$O10*$P10*$Q10*H10*W10 -> 0 | AA10: =Constants!$B$29 -> 0.02 | AB10: =_xlfn.XLOOKUP($B10, Constants!$E$16:$E$34,Constants!J$16:J$34) -> 0.78 | AC10: =O10*AA10*AB10*P10*Q10 -> 0.0034659371 | AD10: =S10+SUM(X10:Z10)+AC10 -> 0.0070207445 | AE10: =D10*E10*AD10/1000 -> 0.11373606
A11: ='Input Scenarios'!A24 -> VIC | B11: =IF('Input Scenarios'!B24<>"", 'Input Scenarios'!B24, "") -> 16 | C11: ='Input Scenarios'!C24 -> Non-irrigated crop (low rainfall) | D11: ='Input Scenarios'!D24 -> 200 | E11: ='Input Scenarios'!E24 -> 200 | F11: ='Input Scenarios'!F24 -> 0.4 | G11: ='Input Scenarios'!G24 -> 0.4 | H11: ='Input Scenarios'!H24 -> 0.2 | I11: ='Input Scenarios'!I24 -> 0.5 | J11: =IF('Input Scenarios'!J24<>"", 'Input Scenarios'!J24, IF($E11<=80, Constants!B$2, IF($E11<=200, Constants!B$3, Constants!B$4))) -> 10.8 | K11: =IF('Input Scenarios'!K24<>"", 'Input Scenarios'!K24, IF($E11<=80, Constants!C$2, IF($E11<=200, Constants!C$3, Constants!C$4))) -> 0.127 | L11: =IF('Input Scenarios'!L24<>"", 'Input Scenarios'!L24, IF($E11<=80, Constants!D$2, IF($E11<=200, Constants!D$3, Constants!D$4))) -> 0.81 | M11: =IF('Input Scenarios'!M24<>"", 'Input Scenarios'!M24, IF($E11<=80, Constants!E$2, IF($E11<=200, Constants!E$3, Constants!E$4))) -> 0.12 | N11: =Constants!$B$27 -> 0.16 | O11: =J11*(1-L11)*(1-N11) -> 1.72368 | P11: =Constants!$B$30 -> 0.19 | Q11: =Constants!$B$31 -> 0.6784 | R11: =_xlfn.XLOOKUP(A11, Constants!$E$7:$I$7, Constants!$E$8:$I$8) -> 0.01 | S11: =O11*P11*Q11*R11 -> 0.0022217546 | T11: =Constants!$B$28 -> 0.5 | U11: =_xlfn.XLOOKUP($B11, Constants!$E$16:$E$34,Constants!G$16:G$34) -> 0.02 | V11: =_xlfn.XLOOKUP($B11, Constants!$E$16:$E$34,Constants!H$16:H$34) -> 0.01 | W11: =_xlfn.XLOOKUP($B11, Constants!$E$16:$E$34,Constants!I$16:I$34) -> 0 | X11: =(1-$T11)*$O11*$P11*$Q11*F11*U11 -> 0.00088870183 | Y11: =(1-$T11)*$O11*$P11*$Q11*G11*V11 -> 0.00044435091 | Z11: =(1-$T11)*$O11*$P11*$Q11*H11*W11 -> 0 | AA11: =Constants!$B$29 -> 0.02 | AB11: =_xlfn.XLOOKUP($B11, Constants!$E$16:$E$34,Constants!J$16:J$34) -> 0.75 | AC11: =O11*AA11*AB11*P11*Q11 -> 0.0033326319 | AD11: =S11+SUM(X11:Z11)+AC11 -> 0.0068874392 | AE11: =D11*E11*AD11/1000 -> 0.27549757
A12: ='Input Scenarios'!A25 -> WA | B12: =IF('Input Scenarios'!B25<>"", 'Input Scenarios'!B25, "") -> 28 or above | C12: ='Input Scenarios'!C25 -> Non-irrigated crop (high rainfall) | D12: ='Input Scenarios'!D25 -> 200 | E12: ='Input Scenarios'!E25 -> 201 | F12: ='Input Scenarios'!F25 -> 0.4 | G12: ='Input Scenarios'!G25 -> 0.4 | H12: ='Input Scenarios'!H25 -> 0.2 | I12: ='Input Scenarios'!I25 -> 0.5 | J12: =IF('Input Scenarios'!J25<>"", 'Input Scenarios'!J25, IF($E12<=80, Constants!B$2, IF($E12<=200, Constants!B$3, Constants!B$4))) -> 8.2 | K12: =IF('Input Scenarios'!K25<>"", 'Input Scenarios'!K25, IF($E12<=80, Constants!C$2, IF($E12<=200, Constants!C$3, Constants!C$4))) -> 0.07 | L12: =IF('Input Scenarios'!L25<>"", 'Input Scenarios'!L25, IF($E12<=80, Constants!D$2, IF($E12<=200, Constants!D$3, Constants!D$4))) -> 0.81 | M12: =IF('Input Scenarios'!M25<>"", 'Input Scenarios'!M25, IF($E12<=80, Constants!E$2, IF($E12<=200, Constants!E$3, Constants!E$4))) -> 0.12 | N12: =Constants!$B$27 -> 0.16 | O12: =J12*(1-L12)*(1-N12) -> 1.30872 | P12: =Constants!$B$30 -> 0.19 | Q12: =Constants!$B$31 -> 0.6784 | R12: =_xlfn.XLOOKUP(A12, Constants!$E$7:$I$7, Constants!$E$8:$I$8) -> 0.01 | S12: =O12*P12*Q12*R12 -> 0.0016868877 | T12: =Constants!$B$28 -> 0.5 | U12: =_xlfn.XLOOKUP($B12, Constants!$E$16:$E$34,Constants!G$16:G$34) -> 0.02 | V12: =_xlfn.XLOOKUP($B12, Constants!$E$16:$E$34,Constants!H$16:H$34) -> 0.015 | W12: =_xlfn.XLOOKUP($B12, Constants!$E$16:$E$34,Constants!I$16:I$34) -> 0 | X12: =(1-$T12)*$O12*$P12*$Q12*F12*U12 -> 0.00067475509 | Y12: =(1-$T12)*$O12*$P12*$Q12*G12*V12 -> 0.00050606632 | Z12: =(1-$T12)*$O12*$P12*$Q12*H12*W12 -> 0 | AA12: =Constants!$B$29 -> 0.02 | AB12: =_xlfn.XLOOKUP($B12, Constants!$E$16:$E$34,Constants!J$16:J$34) -> 0.8 | AC12: =O12*AA12*AB12*P12*Q12 -> 0.0026990204 | AD12: =S12+SUM(X12:Z12)+AC12 -> 0.0055667295 | AE12: =D12*E12*AD12/1000 -> 0.22378253

Sheet 4.1.1.3
A3: input | C3: input
A5: State | B5: MAT | C5: Production system | D5: Number of cattle | E5: Avg. length of star | F5: Allocations to MMS in treatment stage 2 | J5: Dry matter intake | K5: Nitrogen Retention Rate | L5: Dry matter digestibility | M5: Crude protein
F6: solid storage | G6: composting | H6: directApplication | Q6: (Also MNjm=5T=1)
A7: i | B7: i | D7: Nj | E7: Dj | F7: MMSjm=4T=2 | G7: MMSjm=7T=2 | H7: MMSjm=13T=2 | I7: PF | J7: Ij | K7: NRj | L7: DMDj | M7: CPj | O7: NIj | P7: NEj | Q7: AEj | R7: MMSm=1T=3 | S7: FracGASMm=5 | T7: NTjmT=2 | U7: MNjm=5T=1 | V7: MNjm=4T=2 | W7: MNjm=7T=2 | X7: MNjm=13T=2 | Y7: MNjm=1T=3 | Z7: EFm=5 | AA7: EFm=4 | AB7: EFm=7 | AC7: EFm=13 | AD7: EFm=1 | AE7: CN2O | AF7: EN2O,dir (m=5) | AG7: EN2O,dir (m=4) | AH7: EN2O,dir (m=7) | AI7: EN2O,dir (m=13) | AJ7: EN2O,dir (m=1) | AK7: EN2O,dir
A8: ='Input Scenarios'!A8 -> NSW | B8: =IF('Input Scenarios'!B8<>"", 'Input Scenarios'!B8, "") | C8: ='Input Scenarios'!C8 -> Non-irrigated pasture | D8: ='Input Scenarios'!D8 -> 200 | E8: ='Input Scenarios'!E8 -> 79 | F8: ='Input Scenarios'!F8 -> 0.4 | G8: ='Input Scenarios'!G8 -> 0.4 | H8: ='Input Scenarios'!H8 -> 0.2 | I8: ='Input Scenarios'!I8 -> 0.5 | J8: =IF('Input Scenarios'!J8<>"", 'Input Scenarios'!J8, IF($E8<=80, Constants!B$2, IF($E8<=200, Constants!B$3, Constants!B$4))) -> 10.4 | K8: =IF('Input Scenarios'!K8<>"", 'Input Scenarios'!K8, IF($E8<=80, Constants!C$2, IF($E8<=200, Constants!C$3, Constants!C$4))) -> 0.204 | L8: =IF('Input Scenarios'!L8<>"", 'Input Scenarios'!L8, IF($E8<=80, Constants!D$2, IF($E8<=200, Constants!D$3, Constants!D$4))) -> 0.81 | M8: =IF('Input Scenarios'!M8<>"", 'Input Scenarios'!M8, IF($E8<=80, Constants!E$2, IF($E8<=200, Constants!E$3, Constants!E$4))) -> 0.14 | N8: =Constants!$B$32 -> 6.25 | O8: =J8*M8/N8 -> 0.23296 | P8: =O8*(1-K8) -> 0.18543616 | Q8: =D8*E8*P8 -> 2929.8913 | R8: =Constants!$B$29 -> 0.02 | S8: =Constants!$D$8 -> 0.6 | T8: =(Q8*(1-S8-Z8))-(Q8*R8) -> 1097.5373 | U8: =Q8 -> 2929.8913 | V8: =$T8*F8 -> 439.01492 | W8: =$T8*G8 -> 439.01492 | X8: =$T8*H8 -> 219.50746 | Y8: =Q8*R8 -> 58.597827 | Z8: =Constants!$C$8 -> 0.0054 | AA8: =Constants!$C$9 -> 0.005 | AB8: =Constants!$C$10 -> 0.01 | AC8: =Constants!$C$11 -> 0 | AD8: =Constants!$C$12 -> 0 | AE8: =Constants!$B$33 -> 1.5714286 | AF8: =U8*Z8*$AE8 -> 24.862221 | AG8: =V8*AA8*$AE8 -> 3.4494029 | AH8: =W8*AB8*$AE8 -> 6.8988058 | AI8: =X8*AC8*$AE8 -> 0 | AJ8: =Y8*AD8*$AE8 -> 0 | AK8: =SUM(AF8:AJ8)/1000 -> 0.035210429
A9: ='Input Scenarios'!A9 -> QLD | B9: =IF('Input Scenarios'!B9<>"", 'Input Scenarios'!B9, "") | C9: ='Input Scenarios'!C9 -> Irrigated pasture | D9: ='Input Scenarios'!D9 -> 200 | E9: ='Input Scenarios'!E9 -> 80 | F9: ='Input Scenarios'!F9 -> 0.4 | G9: ='Input Scenarios'!G9 -> 0.4 | H9: ='Input Scenarios'!H9 -> 0.2 | I9: ='Input Scenarios'!I9 -> 0.5 | J9: =IF('Input Scenarios'!J9<>"", 'Input Scenarios'!J9, IF($E9<=80, Constants!B$2, IF($E9<=200, Constants!B$3, Constants!B$4))) -> 10.4 | K9: =IF('Input Scenarios'!K9<>"", 'Input Scenarios'!K9, IF($E9<=80, Constants!C$2, IF($E9<=200, Constants!C$3, Constants!C$4))) -> 0.204 | L9: =IF('Input Scenarios'!L9<>"", 'Input Scenarios'!L9, IF($E9<=80, Constants!D$2, IF($E9<=200, Constants!D$3, Constants!D$4))) -> 0.81 | M9: =IF('Input Scenarios'!M9<>"", 'Input Scenarios'!M9, IF($E9<=80, Constants!E$2, IF($E9<=200, Constants!E$3, Constants!E$4))) -> 0.14 | N9: =Constants!$B$32 -> 6.25 | O9: =J9*M9/N9 -> 0.23296 | P9: =O9*(1-K9) -> 0.18543616 | Q9: =D9*E9*P9 -> 2966.9786 | R9: =Constants!$B$29 -> 0.02 | S9: =Constants!$D$8 -> 0.6 | T9: =(Q9*(1-S9-Z9))-(Q9*R9) -> 1111.4302 | U9: =Q9 -> 2966.9786 | V9: =$T9*F9 -> 444.57207 | W9: =$T9*G9 -> 444.57207 | X9: =$T9*H9 -> 222.28603 | Y9: =Q9*R9 -> 59.339571 | Z9: =Constants!$C$8 -> 0.0054 | AA9: =Constants!$C$9 -> 0.005 | AB9: =Constants!$C$10 -> 0.01 | AC9: =Constants!$C$11 -> 0 | AD9: =Constants!$C$12 -> 0 | AE9: =Constants!$B$33 -> 1.5714286 | AF9: =U9*Z9*$AE9 -> 25.176932 | AG9: =V9*AA9*$AE9 -> 3.4930662 | AH9: =W9*AB9*$AE9 -> 6.9861325 | AI9: =X9*AC9*$AE9 -> 0 | AJ9: =Y9*AD9*$AE9 -> 0 | AK9: =SUM(AF9:AJ9)/1000 -> 0.035656131
A10: ='Input Scenarios'!A10 -> SA | B10: =IF('Input Scenarios'!B10<>"", 'Input Scenarios'!B10, "") | C10: ='Input Scenarios'!C10 -> Irrigated crop | D10: ='Input Scenarios'!D10 -> 200 | E10: ='Input Scenarios'!E10 -> 81 | F10: ='Input Scenarios'!F10 -> 0.4 | G10: ='Input Scenarios'!G10 -> 0.4 | H10: ='Input Scenarios'!H10 -> 0.2 | I10: ='Input Scenarios'!I10 -> 0.5 | J10: =IF('Input Scenarios'!J10<>"", 'Input Scenarios'!J10, IF($E10<=80, Constants!B$2, IF($E10<=200, Constants!B$3, Constants!B$4))) -> 10.8 | K10: =IF('Input Scenarios'!K10<>"", 'Input Scenarios'!K10, IF($E10<=80, Constants!C$2, IF($E10<=200, Constants!C$3, Constants!C$4))) -> 0.127 | L10: =IF('Input Scenarios'!L10<>"", 'Input Scenarios'!L10, IF($E10<=80, Constants!D$2, IF($E10<=200, Constants!D$3, Constants!D$4))) -> 0.81 | M10: =IF('Input Scenarios'!M10<>"", 'Input Scenarios'!M10, IF($E10<=80, Constants!E$2, IF($E10<=200, Constants!E$3, Constants!E$4))) -> 0.12 | N10: =Constants!$B$32 -> 6.25 | O10: =J10*M10/N10 -> 0.20736 | P10: =O10*(1-K10) -> 0.18102528 | Q10: =D10*E10*P10 -> 2932.6095 | R10: =Constants!$B$29 -> 0.02 | S10: =Constants!$D$8 -> 0.6 | T10: =(Q10*(1-S10-Z10))-(Q10*R10) -> 1098.5555 | U10: =Q10 -> 2932.6095 | V10: =$T10*F10 -> 439.42221 | W10: =$T10*G10 -> 439.42221 | X10: =$T10*H10 -> 219.71111 | Y10: =Q10*R10 -> 58.652191 | Z10: =Constants!$C$8 -> 0.0054 | AA10: =Constants!$C$9 -> 0.005 | AB10: =Constants!$C$10 -> 0.01 | AC10: =Constants!$C$11 -> 0 | AD10: =Constants!$C$12 -> 0 | AE10: =Constants!$B$33 -> 1.5714286 | AF10: =U10*Z10*$AE10 -> 24.885287 | AG10: =V10*AA10*$AE10 -> 3.4526031 | AH10: =W10*AB10*$AE10 -> 6.9052062 | AI10: =X10*AC10*$AE10 -> 0 | AJ10: =Y10*AD10*$AE10 -> 0 | AK10: =SUM(AF10:AJ10)/1000 -> 0.035243096
A11: ='Input Scenarios'!A11 -> VIC | B11: =IF('Input Scenarios'!B11<>"", 'Input Scenarios'!B11, "") | C11: ='Input Scenarios'!C11 -> Non-irrigated crop (low rainfall) | D11: ='Input Scenarios'!D11 -> 200 | E11: ='Input Scenarios'!E11 -> 200 | F11: ='Input Scenarios'!F11 -> 0.4 | G11: ='Input Scenarios'!G11 -> 0.4 | H11: ='Input Scenarios'!H11 -> 0.2 | I11: ='Input Scenarios'!I11 -> 0.5 | J11: =IF('Input Scenarios'!J11<>"", 'Input Scenarios'!J11, IF($E11<=80, Constants!B$2, IF($E11<=200, Constants!B$3, Constants!B$4))) -> 10.8 | K11: =IF('Input Scenarios'!K11<>"", 'Input Scenarios'!K11, IF($E11<=80, Constants!C$2, IF($E11<=200, Constants!C$3, Constants!C$4))) -> 0.127 | L11: =IF('Input Scenarios'!L11<>"", 'Input Scenarios'!L11, IF($E11<=80, Constants!D$2, IF($E11<=200, Constants!D$3, Constants!D$4))) -> 0.81 | M11: =IF('Input Scenarios'!M11<>"", 'Input Scenarios'!M11, IF($E11<=80, Constants!E$2, IF($E11<=200, Constants!E$3, Constants!E$4))) -> 0.12 | N11: =Constants!$B$32 -> 6.25 | O11: =J11*M11/N11 -> 0.20736 | P11: =O11*(1-K11) -> 0.18102528 | Q11: =D11*E11*P11 -> 7241.0112 | R11: =Constants!$B$29 -> 0.02 | S11: =Constants!$D$8 -> 0.6 | T11: =(Q11*(1-S11-Z11))-(Q11*R11) -> 2712.4828 | U11: =Q11 -> 7241.0112 | V11: =$T11*F11 -> 1084.9931 | W11: =$T11*G11 -> 1084.9931 | X11: =$T11*H11 -> 542.49656 | Y11: =Q11*R11 -> 144.82022 | Z11: =Constants!$C$8 -> 0.0054 | AA11: =Constants!$C$9 -> 0.005 | AB11: =Constants!$C$10 -> 0.01 | AC11: =Constants!$C$11 -> 0 | AD11: =Constants!$C$12 -> 0 | AE11: =Constants!$B$33 -> 1.5714286 | AF11: =U11*Z11*$AE11 -> 61.445152 | AG11: =V11*AA11*$AE11 -> 8.5249459 | AH11: =W11*AB11*$AE11 -> 17.049892 | AI11: =X11*AC11*$AE11 -> 0 | AJ11: =Y11*AD11*$AE11 -> 0 | AK11: =SUM(AF11:AJ11)/1000 -> 0.08701999
A12: ='Input Scenarios'!A12 -> WA | B12: =IF('Input Scenarios'!B12<>"", 'Input Scenarios'!B12, "") | C12: ='Input Scenarios'!C12 -> Non-irrigated crop (high rainfall) | D12: ='Input Scenarios'!D12 -> 200 | E12: ='Input Scenarios'!E12 -> 201 | F12: ='Input Scenarios'!F12 -> 0.4 | G12: ='Input Scenarios'!G12 -> 0.4 | H12: ='Input Scenarios'!H12 -> 0.2 | I12: ='Input Scenarios'!I12 -> 0.5 | J12: =IF('Input Scenarios'!J12<>"", 'Input Scenarios'!J12, IF($E12<=80, Constants!B$2, IF($E12<=200, Constants!B$3, Constants!B$4))) -> 8.2 | K12: =IF('Input Scenarios'!K12<>"", 'Input Scenarios'!K12, IF($E12<=80, Constants!C$2, IF($E12<=200, Constants!C$3, Constants!C$4))) -> 0.07 | L12: =IF('Input Scenarios'!L12<>"", 'Input Scenarios'!L12, IF($E12<=80, Constants!D$2, IF($E12<=200, Constants!D$3, Constants!D$4))) -> 0.81 | M12: =IF('Input Scenarios'!M12<>"", 'Input Scenarios'!M12, IF($E12<=80, Constants!E$2, IF($E12<=200, Constants!E$3, Constants!E$4))) -> 0.12 | N12: =Constants!$B$32 -> 6.25 | O12: =J12*M12/N12 -> 0.15744 | P12: =O12*(1-K12) -> 0.1464192 | Q12: =D12*E12*P12 -> 5886.0518 | R12: =Constants!$B$29 -> 0.02 | S12: =Constants!$D$8 -> 0.6 | T12: =(Q12*(1-S12-Z12))-(Q12*R12) -> 2204.915 | U12: =Q12 -> 5886.0518 | V12: =$T12*F12 -> 881.96601 | W12: =$T12*G12 -> 881.96601 | X12: =$T12*H12 -> 440.983 | Y12: =Q12*R12 -> 117.72104 | Z12: =Constants!$C$8 -> 0.0054 | AA12: =Constants!$C$9 -> 0.005 | AB12: =Constants!$C$10 -> 0.01 | AC12: =Constants!$C$11 -> 0 | AD12: =Constants!$C$12 -> 0 | AE12: =Constants!$B$33 -> 1.5714286 | AF12: =U12*Z12*$AE12 -> 49.947354 | AG12: =V12*AA12*$AE12 -> 6.9297329 | AH12: =W12*AB12*$AE12 -> 13.859466 | AI12: =X12*AC12*$AE12 -> 0 | AJ12: =Y12*AD12*$AE12 -> 0 | AK12: =SUM(AF12:AJ12)/1000 -> 0.070736553

Sheet 4.1.1.4
A3: input | C3: input
A5: State | B5: MAT | C5: Production system | D5: Number of cattle | E5: Avg. length of star | F5: Allocations to MMS in treatment stage 2 | J5: Dry matter intake | K5: Nitrogen Retention Rate | L5: Dry matter digestibility | M5: Crude protein
F6: solid storage | G6: composting | H6: directApplication | Q6: (Also MNjm=5T=1)
A7: i | B7: i | D7: Nj | E7: Dj | F7: MMSjm=4T=2 | G7: MMSjm=7T=2 | H7: MMSjm=13T=2 | I7: PF | J7: Ij | K7: NRj | L7: DMDj | M7: CPj | O7: NIj | P7: NEj | Q7: AEj | R7: MMSm=1T=3 | S7: FracGASMm=5 | T7: NTjmT=2 | U7: MNjm=5T=1 | V7: MNjm=4T=2 | W7: MNjm=7T=2 | X7: MNjm=13T=2 | Y7: MNjm=1T=3 | Z7: EFm=5 | AA7: EFm=4 | AB7: EFm=7 | AC7: EFm=13 | AD7: EFm=1 | AE7: CN2O | AF7: EN2O,dir (m=5) | AG7: EN2O,dir (m=4) | AH7: EN2O,dir (m=7) | AI7: EN2O,dir (m=13) | AJ7: EN2O,dir (m=1) | AK7: EN2O,dir
A8: ='Input Scenarios'!A21 -> NSW | B8: =IF('Input Scenarios'!B21<>"", 'Input Scenarios'!B21, "") -> 14 | C8: ='Input Scenarios'!C21 -> Non-irrigated pasture | D8: ='Input Scenarios'!D21 -> 200 | E8: ='Input Scenarios'!E21 -> 79 | F8: ='Input Scenarios'!F21 -> 0.4 | G8: ='Input Scenarios'!G21 -> 0.4 | H8: ='Input Scenarios'!H21 -> 0.2 | I8: ='Input Scenarios'!I21 -> 0.5 | J8: =IF('Input Scenarios'!J21<>"", 'Input Scenarios'!J21, IF($E8<=80, Constants!B$2, IF($E8<=200, Constants!B$3, Constants!B$4))) -> 10.4 | K8: =IF('Input Scenarios'!K21<>"", 'Input Scenarios'!K21, IF($E8<=80, Constants!C$2, IF($E8<=200, Constants!C$3, Constants!C$4))) -> 0.204 | L8: =IF('Input Scenarios'!L21<>"", 'Input Scenarios'!L21, IF($E8<=80, Constants!D$2, IF($E8<=200, Constants!D$3, Constants!D$4))) -> 0.81 | M8: =IF('Input Scenarios'!M21<>"", 'Input Scenarios'!M21, IF($E8<=80, Constants!E$2, IF($E8<=200, Constants!E$3, Constants!E$4))) -> 0.14 | N8: =Constants!$B$32 -> 6.25 | O8: =J8*M8/N8 -> 0.23296 | P8: =O8*(1-K8) -> 0.18543616 | Q8: =D8*E8*P8 -> 2929.8913 | R8: =Constants!$B$29 -> 0.02 | S8: =Constants!$D$8 -> 0.6 | T8: =(Q8*(1-S8-Z8))-(Q8*R8) -> 1097.5373 | U8: =Q8 -> 2929.8913 | V8: =$T8*F8 -> 439.01492 | W8: =$T8*G8 -> 439.01492 | X8: =$T8*H8 -> 219.50746 | Y8: =Q8*R8 -> 58.597827 | Z8: =Constants!$C$8 -> 0.0054 | AA8: =Constants!$C$9 -> 0.005 | AB8: =Constants!$C$10 -> 0.01 | AC8: =Constants!$C$11 -> 0 | AD8: =Constants!$C$12 -> 0 | AE8: =Constants!$B$33 -> 1.5714286 | AF8: =U8*Z8*$AE8 -> 24.862221 | AG8: =V8*AA8*$AE8 -> 3.4494029 | AH8: =W8*AB8*$AE8 -> 6.8988058 | AI8: =X8*AC8*$AE8 -> 0 | AJ8: =Y8*AD8*$AE8 -> 0 | AK8: =SUM(AF8:AJ8)/1000 -> 0.035210429
A9: ='Input Scenarios'!A22 -> QLD | B9: =IF('Input Scenarios'!B22<>"", 'Input Scenarios'!B22, "") -> 27 | C9: ='Input Scenarios'!C22 -> Irrigated pasture | D9: ='Input Scenarios'!D22 -> 200 | E9: ='Input Scenarios'!E22 -> 80 | F9: ='Input Scenarios'!F22 -> 0.4 | G9: ='Input Scenarios'!G22 -> 0.4 | H9: ='Input Scenarios'!H22 -> 0.2 | I9: ='Input Scenarios'!I22 -> 0.5 | J9: =IF('Input Scenarios'!J22<>"", 'Input Scenarios'!J22, IF($E9<=80, Constants!B$2, IF($E9<=200, Constants!B$3, Constants!B$4))) -> 10.4 | K9: =IF('Input Scenarios'!K22<>"", 'Input Scenarios'!K22, IF($E9<=80, Constants!C$2, IF($E9<=200, Constants!C$3, Constants!C$4))) -> 0.204 | L9: =IF('Input Scenarios'!L22<>"", 'Input Scenarios'!L22, IF($E9<=80, Constants!D$2, IF($E9<=200, Constants!D$3, Constants!D$4))) -> 0.81 | M9: =IF('Input Scenarios'!M22<>"", 'Input Scenarios'!M22, IF($E9<=80, Constants!E$2, IF($E9<=200, Constants!E$3, Constants!E$4))) -> 0.14 | N9: =Constants!$B$32 -> 6.25 | O9: =J9*M9/N9 -> 0.23296 | P9: =O9*(1-K9) -> 0.18543616 | Q9: =D9*E9*P9 -> 2966.9786 | R9: =Constants!$B$29 -> 0.02 | S9: =Constants!$D$8 -> 0.6 | T9: =(Q9*(1-S9-Z9))-(Q9*R9) -> 1111.4302 | U9: =Q9 -> 2966.9786 | V9: =$T9*F9 -> 444.57207 | W9: =$T9*G9 -> 444.57207 | X9: =$T9*H9 -> 222.28603 | Y9: =Q9*R9 -> 59.339571 | Z9: =Constants!$C$8 -> 0.0054 | AA9: =Constants!$C$9 -> 0.005 | AB9: =Constants!$C$10 -> 0.01 | AC9: =Constants!$C$11 -> 0 | AD9: =Constants!$C$12 -> 0 | AE9: =Constants!$B$33 -> 1.5714286 | AF9: =U9*Z9*$AE9 -> 25.176932 | AG9: =V9*AA9*$AE9 -> 3.4930662 | AH9: =W9*AB9*$AE9 -> 6.9861325 | AI9: =X9*AC9*$AE9 -> 0 | AJ9: =Y9*AD9*$AE9 -> 0 | AK9: =SUM(AF9:AJ9)/1000 -> 0.035656131
A10: ='Input Scenarios'!A23 -> SA | B10: =IF('Input Scenarios'!B23<>"", 'Input Scenarios'!B23, "") -> 22 | C10: ='Input Scenarios'!C23 -> Irrigated crop | D10: ='Input Scenarios'!D23 -> 200 | E10: ='Input Scenarios'!E23 -> 81 | F10: ='Input Scenarios'!F23 -> 0.4 | G10: ='Input Scenarios'!G23 -> 0.4 | H10: ='Input Scenarios'!H23 -> 0.2 | I10: ='Input Scenarios'!I23 -> 0.5 | J10: =IF('Input Scenarios'!J23<>"", 'Input Scenarios'!J23, IF($E10<=80, Constants!B$2, IF($E10<=200, Constants!B$3, Constants!B$4))) -> 10.8 | K10: =IF('Input Scenarios'!K23<>"", 'Input Scenarios'!K23, IF($E10<=80, Constants!C$2, IF($E10<=200, Constants!C$3, Constants!C$4))) -> 0.127 | L10: =IF('Input Scenarios'!L23<>"", 'Input Scenarios'!L23, IF($E10<=80, Constants!D$2, IF($E10<=200, Constants!D$3, Constants!D$4))) -> 0.81 | M10: =IF('Input Scenarios'!M23<>"", 'Input Scenarios'!M23, IF($E10<=80, Constants!E$2, IF($E10<=200, Constants!E$3, Constants!E$4))) -> 0.12 | N10: =Constants!$B$32 -> 6.25 | O10: =J10*M10/N10 -> 0.20736 | P10: =O10*(1-K10) -> 0.18102528 | Q10: =D10*E10*P10 -> 2932.6095 | R10: =Constants!$B$29 -> 0.02 | S10: =Constants!$D$8 -> 0.6 | T10: =(Q10*(1-S10-Z10))-(Q10*R10) -> 1098.5555 | U10: =Q10 -> 2932.6095 | V10: =$T10*F10 -> 439.42221 | W10: =$T10*G10 -> 439.42221 | X10: =$T10*H10 -> 219.71111 | Y10: =Q10*R10 -> 58.652191 | Z10: =Constants!$C$8 -> 0.0054 | AA10: =Constants!$C$9 -> 0.005 | AB10: =Constants!$C$10 -> 0.01 | AC10: =Constants!$C$11 -> 0 | AD10: =Constants!$C$12 -> 0 | AE10: =Constants!$B$33 -> 1.5714286 | AF10: =U10*Z10*$AE10 -> 24.885287 | AG10: =V10*AA10*$AE10 -> 3.4526031 | AH10: =W10*AB10*$AE10 -> 6.9052062 | AI10: =X10*AC10*$AE10 -> 0 | AJ10: =Y10*AD10*$AE10 -> 0 | AK10: =SUM(AF10:AJ10)/1000 -> 0.035243096
A11: ='Input Scenarios'!A24 -> VIC | B11: =IF('Input Scenarios'!B24<>"", 'Input Scenarios'!B24, "") -> 16 | C11: ='Input Scenarios'!C24 -> Non-irrigated crop (low rainfall) | D11: ='Input Scenarios'!D24 -> 200 | E11: ='Input Scenarios'!E24 -> 200 | F11: ='Input Scenarios'!F24 -> 0.4 | G11: ='Input Scenarios'!G24 -> 0.4 | H11: ='Input Scenarios'!H24 -> 0.2 | I11: ='Input Scenarios'!I24 -> 0.5 | J11: =IF('Input Scenarios'!J24<>"", 'Input Scenarios'!J24, IF($E11<=80, Constants!B$2, IF($E11<=200, Constants!B$3, Constants!B$4))) -> 10.8 | K11: =IF('Input Scenarios'!K24<>"", 'Input Scenarios'!K24, IF($E11<=80, Constants!C$2, IF($E11<=200, Constants!C$3, Constants!C$4))) -> 0.127 | L11: =IF('Input Scenarios'!L24<>"", 'Input Scenarios'!L24, IF($E11<=80, Constants!D$2, IF($E11<=200, Constants!D$3, Constants!D$4))) -> 0.81 | M11: =IF('Input Scenarios'!M24<>"", 'Input Scenarios'!M24, IF($E11<=80, Constants!E$2, IF($E11<=200, Constants!E$3, Constants!E$4))) -> 0.12 | N11: =Constants!$B$32 -> 6.25 | O11: =J11*M11/N11 -> 0.20736 | P11: =O11*(1-K11) -> 0.18102528 | Q11: =D11*E11*P11 -> 7241.0112 | R11: =Constants!$B$29 -> 0.02 | S11: =Constants!$D$8 -> 0.6 | T11: =(Q11*(1-S11-Z11))-(Q11*R11) -> 2712.4828 | U11: =Q11 -> 7241.0112 | V11: =$T11*F11 -> 1084.9931 | W11: =$T11*G11 -> 1084.9931 | X11: =$T11*H11 -> 542.49656 | Y11: =Q11*R11 -> 144.82022 | Z11: =Constants!$C$8 -> 0.0054 | AA11: =Constants!$C$9 -> 0.005 | AB11: =Constants!$C$10 -> 0.01 | AC11: =Constants!$C$11 -> 0 | AD11: =Constants!$C$12 -> 0 | AE11: =Constants!$B$33 -> 1.5714286 | AF11: =U11*Z11*$AE11 -> 61.445152 | AG11: =V11*AA11*$AE11 -> 8.5249459 | AH11: =W11*AB11*$AE11 -> 17.049892 | AI11: =X11*AC11*$AE11 -> 0 | AJ11: =Y11*AD11*$AE11 -> 0 | AK11: =SUM(AF11:AJ11)/1000 -> 0.08701999
A12: ='Input Scenarios'!A25 -> WA | B12: =IF('Input Scenarios'!B25<>"", 'Input Scenarios'!B25, "") -> 28 or above | C12: ='Input Scenarios'!C25 -> Non-irrigated crop (high rainfall) | D12: ='Input Scenarios'!D25 -> 200 | E12: ='Input Scenarios'!E25 -> 201 | F12: ='Input Scenarios'!F25 -> 0.4 | G12: ='Input Scenarios'!G25 -> 0.4 | H12: ='Input Scenarios'!H25 -> 0.2 | I12: ='Input Scenarios'!I25 -> 0.5 | J12: =IF('Input Scenarios'!J25<>"", 'Input Scenarios'!J25, IF($E12<=80, Constants!B$2, IF($E12<=200, Constants!B$3, Constants!B$4))) -> 8.2 | K12: =IF('Input Scenarios'!K25<>"", 'Input Scenarios'!K25, IF($E12<=80, Constants!C$2, IF($E12<=200, Constants!C$3, Constants!C$4))) -> 0.07 | L12: =IF('Input Scenarios'!L25<>"", 'Input Scenarios'!L25, IF($E12<=80, Constants!D$2, IF($E12<=200, Constants!D$3, Constants!D$4))) -> 0.81 | M12: =IF('Input Scenarios'!M25<>"", 'Input Scenarios'!M25, IF($E12<=80, Constants!E$2, IF($E12<=200, Constants!E$3, Constants!E$4))) -> 0.12 | N12: =Constants!$B$32 -> 6.25 | O12: =J12*M12/N12 -> 0.15744 | P12: =O12*(1-K12) -> 0.1464192 | Q12: =D12*E12*P12 -> 5886.0518 | R12: =Constants!$B$29 -> 0.02 | S12: =Constants!$D$8 -> 0.6 | T12: =(Q12*(1-S12-Z12))-(Q12*R12) -> 2204.915 | U12: =Q12 -> 5886.0518 | V12: =$T12*F12 -> 881.96601 | W12: =$T12*G12 -> 881.96601 | X12: =$T12*H12 -> 440.983 | Y12: =Q12*R12 -> 117.72104 | Z12: =Constants!$C$8 -> 0.0054 | AA12: =Constants!$C$9 -> 0.005 | AB12: =Constants!$C$10 -> 0.01 | AC12: =Constants!$C$11 -> 0 | AD12: =Constants!$C$12 -> 0 | AE12: =Constants!$B$33 -> 1.5714286 | AF12: =U12*Z12*$AE12 -> 49.947354 | AG12: =V12*AA12*$AE12 -> 6.9297329 | AH12: =W12*AB12*$AE12 -> 13.859466 | AI12: =X12*AC12*$AE12 -> 0 | AJ12: =Y12*AD12*$AE12 -> 0 | AK12: =SUM(AF12:AJ12)/1000 -> 0.070736553

Sheet 4.1.1.5
A3: input | C3: input
A5: State | B5: MAT | C5: Production system | D5: Number of cattle | E5: Avg. length of star | F5: Allocations to MMS in treatment stage 2 | J5: Dry matter intake | K5: Nitrogen Retention Rate | L5: Dry matter digestibility | M5: Crude protein
F6: solid storage | G6: composting | H6: directApplication | Q6: (Also MNjm=5T=1)
A7: i | B7: i | D7: Nj | E7: Dj | F7: MMSjm=4T=2 | G7: MMSjm=7T=2 | H7: MMSjm=13T=2 | I7: PF | J7: Ij | K7: NRj | L7: DMDj | M7: CPj | O7: NIj | P7: NEj | Q7: AEj | R7: MMSm=1T=3 | S7: EFm=5 | T7: NTjmT=2 | U7: MNjm=5T=1 | V7: MNjm=4T=2 | W7: MNjm=7T=2 | X7: MNjm=13T=2 | Y7: MNjm=1T=3 | Z7: FracGASMm=5 | AA7: FracGASMm=4 | AB7: FracGASMm=7 | AC7: FracGASMm=13 | AD7: FracGASMm=1 | AE7: MMSATMOS (m=5) | AF7: MMSATMOS (m=4) | AG7: MMSATMOS (m=7) | AH7: MMSATMOS (m=13) | AI7: MMSATMOS (m=1) | AJ7: MMSATMOS | AK7: EFN2O | AL7: CN2O | AM7: EN2O,ad
A8: ='Input Scenarios'!A8 -> NSW | B8: =IF('Input Scenarios'!B8<>"", 'Input Scenarios'!B8, "") | C8: ='Input Scenarios'!C8 -> Non-irrigated pasture | D8: ='Input Scenarios'!D8 -> 200 | E8: ='Input Scenarios'!E8 -> 79 | F8: ='Input Scenarios'!F8 -> 0.4 | G8: ='Input Scenarios'!G8 -> 0.4 | H8: ='Input Scenarios'!H8 -> 0.2 | I8: ='Input Scenarios'!I8 -> 0.5 | J8: =IF('Input Scenarios'!J8<>"", 'Input Scenarios'!J8, IF($E8<=80, Constants!B$2, IF($E8<=200, Constants!B$3, Constants!B$4))) -> 10.4 | K8: =IF('Input Scenarios'!K8<>"", 'Input Scenarios'!K8, IF($E8<=80, Constants!C$2, IF($E8<=200, Constants!C$3, Constants!C$4))) -> 0.204 | L8: =IF('Input Scenarios'!L8<>"", 'Input Scenarios'!L8, IF($E8<=80, Constants!D$2, IF($E8<=200, Constants!D$3, Constants!D$4))) -> 0.81 | M8: =IF('Input Scenarios'!M8<>"", 'Input Scenarios'!M8, IF($E8<=80, Constants!E$2, IF($E8<=200, Constants!E$3, Constants!E$4))) -> 0.14 | N8: =Constants!$B$32 -> 6.25 | O8: =J8*M8/N8 -> 0.23296 | P8: =O8*(1-K8) -> 0.18543616 | Q8: =D8*E8*P8 -> 2929.8913 | R8: =Constants!$B$29 -> 0.02 | S8: =Constants!$C$8 -> 0.0054 | T8: =(Q8*(1-Z8-S8))-(Q8*R8) -> 1097.5373 | U8: =Q8 -> 2929.8913 | V8: =$T8*F8 -> 439.01492 | W8: =$T8*G8 -> 439.01492 | X8: =$T8*H8 -> 219.50746 | Y8: =Q8*R8 -> 58.597827 | Z8: =Constants!$D$8 -> 0.6 | AA8: =Constants!$D$9 -> 0.25 | AB8: =Constants!$D$10 -> 0.4 | AC8: =Constants!$D$11 -> 0 | AD8: =Constants!$D$12 -> 0.35 | AE8: =U8*Z8 -> 1757.9348 | AF8: =V8*AA8 -> 109.75373 | AG8: =W8*AB8 -> 175.60597 | AH8: =X8*AC8 -> 0 | AI8: =Y8*AD8 -> 20.509239 | AJ8: =SUM(AE8:AI8) -> 2063.8037 | AK8: =_xlfn.XLOOKUP(C8,Constants!$A$16:$A$20,Constants!$B$16:$B$20) -> 0.0018 | AL8: =Constants!$B$33 -> 1.5714286 | AM8: =AJ8*AK8*AL8/1000 -> 0.0058376163
A9: ='Input Scenarios'!A9 -> QLD | B9: =IF('Input Scenarios'!B9<>"", 'Input Scenarios'!B9, "") | C9: ='Input Scenarios'!C9 -> Irrigated pasture | D9: ='Input Scenarios'!D9 -> 200 | E9: ='Input Scenarios'!E9 -> 80 | F9: ='Input Scenarios'!F9 -> 0.4 | G9: ='Input Scenarios'!G9 -> 0.4 | H9: ='Input Scenarios'!H9 -> 0.2 | I9: ='Input Scenarios'!I9 -> 0.5 | J9: =IF('Input Scenarios'!J9<>"", 'Input Scenarios'!J9, IF($E9<=80, Constants!B$2, IF($E9<=200, Constants!B$3, Constants!B$4))) -> 10.4 | K9: =IF('Input Scenarios'!K9<>"", 'Input Scenarios'!K9, IF($E9<=80, Constants!C$2, IF($E9<=200, Constants!C$3, Constants!C$4))) -> 0.204 | L9: =IF('Input Scenarios'!L9<>"", 'Input Scenarios'!L9, IF($E9<=80, Constants!D$2, IF($E9<=200, Constants!D$3, Constants!D$4))) -> 0.81 | M9: =IF('Input Scenarios'!M9<>"", 'Input Scenarios'!M9, IF($E9<=80, Constants!E$2, IF($E9<=200, Constants!E$3, Constants!E$4))) -> 0.14 | N9: =Constants!$B$32 -> 6.25 | O9: =J9*M9/N9 -> 0.23296 | P9: =O9*(1-K9) -> 0.18543616 | Q9: =D9*E9*P9 -> 2966.9786 | R9: =Constants!$B$29 -> 0.02 | S9: =Constants!$C$8 -> 0.0054 | T9: =(Q9*(1-Z9-S9))-(Q9*R9) -> 1111.4302 | U9: =Q9 -> 2966.9786 | V9: =$T9*F9 -> 444.57207 | W9: =$T9*G9 -> 444.57207 | X9: =$T9*H9 -> 222.28603 | Y9: =Q9*R9 -> 59.339571 | Z9: =Constants!$D$8 -> 0.6 | AA9: =Constants!$D$9 -> 0.25 | AB9: =Constants!$D$10 -> 0.4 | AC9: =Constants!$D$11 -> 0 | AD9: =Constants!$D$12 -> 0.35 | AE9: =U9*Z9 -> 1780.1871 | AF9: =V9*AA9 -> 111.14302 | AG9: =W9*AB9 -> 177.82883 | AH9: =X9*AC9 -> 0 | AI9: =Y9*AD9 -> 20.76885 | AJ9: =SUM(AE9:AI9) -> 2089.9278 | AK9: =_xlfn.XLOOKUP(C9,Constants!$A$16:$A$20,Constants!$B$16:$B$20) -> 0.0059 | AL9: =Constants!$B$33 -> 1.5714286 | AM9: =AJ9*AK9*AL9/1000 -> 0.019376617
A10: ='Input Scenarios'!A10 -> SA | B10: =IF('Input Scenarios'!B10<>"", 'Input Scenarios'!B10, "") | C10: ='Input Scenarios'!C10 -> Irrigated crop | D10: ='Input Scenarios'!D10 -> 200 | E10: ='Input Scenarios'!E10 -> 81 | F10: ='Input Scenarios'!F10 -> 0.4 | G10: ='Input Scenarios'!G10 -> 0.4 | H10: ='Input Scenarios'!H10 -> 0.2 | I10: ='Input Scenarios'!I10 -> 0.5 | J10: =IF('Input Scenarios'!J10<>"", 'Input Scenarios'!J10, IF($E10<=80, Constants!B$2, IF($E10<=200, Constants!B$3, Constants!B$4))) -> 10.8 | K10: =IF('Input Scenarios'!K10<>"", 'Input Scenarios'!K10, IF($E10<=80, Constants!C$2, IF($E10<=200, Constants!C$3, Constants!C$4))) -> 0.127 | L10: =IF('Input Scenarios'!L10<>"", 'Input Scenarios'!L10, IF($E10<=80, Constants!D$2, IF($E10<=200, Constants!D$3, Constants!D$4))) -> 0.81 | M10: =IF('Input Scenarios'!M10<>"", 'Input Scenarios'!M10, IF($E10<=80, Constants!E$2, IF($E10<=200, Constants!E$3, Constants!E$4))) -> 0.12 | N10: =Constants!$B$32 -> 6.25 | O10: =J10*M10/N10 -> 0.20736 | P10: =O10*(1-K10) -> 0.18102528 | Q10: =D10*E10*P10 -> 2932.6095 | R10: =Constants!$B$29 -> 0.02 | S10: =Constants!$C$8 -> 0.0054 | T10: =(Q10*(1-Z10-S10))-(Q10*R10) -> 1098.5555 | U10: =Q10 -> 2932.6095 | V10: =$T10*F10 -> 439.42221 | W10: =$T10*G10 -> 439.42221 | X10: =$T10*H10 -> 219.71111 | Y10: =Q10*R10 -> 58.652191 | Z10: =Constants!$D$8 -> 0.6 | AA10: =Constants!$D$9 -> 0.25 | AB10: =Constants!$D$10 -> 0.4 | AC10: =Constants!$D$11 -> 0 | AD10: =Constants!$D$12 -> 0.35 | AE10: =U10*Z10 -> 1759.5657 | AF10: =V10*AA10 -> 109.85555 | AG10: =W10*AB10 -> 175.76889 | AH10: =X10*AC10 -> 0 | AI10: =Y10*AD10 -> 20.528267 | AJ10: =SUM(AE10:AI10) -> 2065.7184 | AK10: =_xlfn.XLOOKUP(C10,Constants!$A$16:$A$20,Constants!$B$16:$B$20) -> 0.007 | AL10: =Constants!$B$33 -> 1.5714286 | AM10: =AJ10*AK10*AL10/1000 -> 0.022722903
A11: ='Input Scenarios'!A11 -> VIC | B11: =IF('Input Scenarios'!B11<>"", 'Input Scenarios'!B11, "") | C11: ='Input Scenarios'!C11 -> Non-irrigated crop (low rainfall) | D11: ='Input Scenarios'!D11 -> 200 | E11: ='Input Scenarios'!E11 -> 200 | F11: ='Input Scenarios'!F11 -> 0.4 | G11: ='Input Scenarios'!G11 -> 0.4 | H11: ='Input Scenarios'!H11 -> 0.2 | I11: ='Input Scenarios'!I11 -> 0.5 | J11: =IF('Input Scenarios'!J11<>"", 'Input Scenarios'!J11, IF($E11<=80, Constants!B$2, IF($E11<=200, Constants!B$3, Constants!B$4))) -> 10.8 | K11: =IF('Input Scenarios'!K11<>"", 'Input Scenarios'!K11, IF($E11<=80, Constants!C$2, IF($E11<=200, Constants!C$3, Constants!C$4))) -> 0.127 | L11: =IF('Input Scenarios'!L11<>"", 'Input Scenarios'!L11, IF($E11<=80, Constants!D$2, IF($E11<=200, Constants!D$3, Constants!D$4))) -> 0.81 | M11: =IF('Input Scenarios'!M11<>"", 'Input Scenarios'!M11, IF($E11<=80, Constants!E$2, IF($E11<=200, Constants!E$3, Constants!E$4))) -> 0.12 | N11: =Constants!$B$32 -> 6.25 | O11: =J11*M11/N11 -> 0.20736 | P11: =O11*(1-K11) -> 0.18102528 | Q11: =D11*E11*P11 -> 7241.0112 | R11: =Constants!$B$29 -> 0.02 | S11: =Constants!$C$8 -> 0.0054 | T11: =(Q11*(1-Z11-S11))-(Q11*R11) -> 2712.4828 | U11: =Q11 -> 7241.0112 | V11: =$T11*F11 -> 1084.9931 | W11: =$T11*G11 -> 1084.9931 | X11: =$T11*H11 -> 542.49656 | Y11: =Q11*R11 -> 144.82022 | Z11: =Constants!$D$8 -> 0.6 | AA11: =Constants!$D$9 -> 0.25 | AB11: =Constants!$D$10 -> 0.4 | AC11: =Constants!$D$11 -> 0 | AD11: =Constants!$D$12 -> 0.35 | AE11: =U11*Z11 -> 4344.6067 | AF11: =V11*AA11 -> 271.24828 | AG11: =W11*AB11 -> 433.99725 | AH11: =X11*AC11 -> 0 | AI11: =Y11*AD11 -> 50.687078 | AJ11: =SUM(AE11:AI11) -> 5100.5393 | AK11: =_xlfn.XLOOKUP(C11,Constants!$A$16:$A$20,Constants!$B$16:$B$20) -> 0.0029 | AL11: =Constants!$B$33 -> 1.5714286 | AM11: =AJ11*AK11*AL11/1000 -> 0.023243886
A12: ='Input Scenarios'!A12 -> WA | B12: =IF('Input Scenarios'!B12<>"", 'Input Scenarios'!B12, "") | C12: ='Input Scenarios'!C12 -> Non-irrigated crop (high rainfall) | D12: ='Input Scenarios'!D12 -> 200 | E12: ='Input Scenarios'!E12 -> 201 | F12: ='Input Scenarios'!F12 -> 0.4 | G12: ='Input Scenarios'!G12 -> 0.4 | H12: ='Input Scenarios'!H12 -> 0.2 | I12: ='Input Scenarios'!I12 -> 0.5 | J12: =IF('Input Scenarios'!J12<>"", 'Input Scenarios'!J12, IF($E12<=80, Constants!B$2, IF($E12<=200, Constants!B$3, Constants!B$4))) -> 8.2 | K12: =IF('Input Scenarios'!K12<>"", 'Input Scenarios'!K12, IF($E12<=80, Constants!C$2, IF($E12<=200, Constants!C$3, Constants!C$4))) -> 0.07 | L12: =IF('Input Scenarios'!L12<>"", 'Input Scenarios'!L12, IF($E12<=80, Constants!D$2, IF($E12<=200, Constants!D$3, Constants!D$4))) -> 0.81 | M12: =IF('Input Scenarios'!M12<>"", 'Input Scenarios'!M12, IF($E12<=80, Constants!E$2, IF($E12<=200, Constants!E$3, Constants!E$4))) -> 0.12 | N12: =Constants!$B$32 -> 6.25 | O12: =J12*M12/N12 -> 0.15744 | P12: =O12*(1-K12) -> 0.1464192 | Q12: =D12*E12*P12 -> 5886.0518 | R12: =Constants!$B$29 -> 0.02 | S12: =Constants!$C$8 -> 0.0054 | T12: =(Q12*(1-Z12-S12))-(Q12*R12) -> 2204.915 | U12: =Q12 -> 5886.0518 | V12: =$T12*F12 -> 881.96601 | W12: =$T12*G12 -> 881.96601 | X12: =$T12*H12 -> 440.983 | Y12: =Q12*R12 -> 117.72104 | Z12: =Constants!$D$8 -> 0.6 | AA12: =Constants!$D$9 -> 0.25 | AB12: =Constants!$D$10 -> 0.4 | AC12: =Constants!$D$11 -> 0 | AD12: =Constants!$D$12 -> 0.35 | AE12: =U12*Z12 -> 3531.6311 | AF12: =V12*AA12 -> 220.4915 | AG12: =W12*AB12 -> 352.7864 | AH12: =X12*AC12 -> 0 | AI12: =Y12*AD12 -> 41.202363 | AJ12: =SUM(AE12:AI12) -> 4146.1114 | AK12: =_xlfn.XLOOKUP(C12,Constants!$A$16:$A$20,Constants!$B$16:$B$20) -> 0.008 | AL12: =Constants!$B$33 -> 1.5714286 | AM12: =AJ12*AK12*AL12/1000 -> 0.052122543

Sheet 4.1.1.6
A3: input | C3: input
A5: State | B5: MAT | C5: Production system | D5: Number of cattle | E5: Avg. length of star | F5: Allocations to MMS in treatment stage 2 | J5: Dry matter intake | K5: Nitrogen Retention Rate | L5: Dry matter digestibility | M5: Crude protein
F6: solid storage | G6: composting | H6: directApplication | Q6: (Also MNjm=5T=1)
A7: i | B7: i | D7: Nj | E7: Dj | F7: MMSjm=4T=2 | G7: MMSjm=7T=2 | H7: MMSjm=13T=2 | I7: PF | J7: Ij | K7: NRj | L7: DMDj | M7: CPj | O7: NIj | P7: NEj | Q7: AEj | R7: MMSm=1T=3 | S7: EFm=5 | T7: NTjmT=2 | U7: MNjm=5T=1 | V7: MNjm=4T=2 | W7: MNjm=7T=2 | X7: MNjm=13T=2 | Y7: MNjm=1T=3 | Z7: FracGASMm=5 | AA7: FracGASMm=4 | AB7: FracGASMm=7 | AC7: FracGASMm=13 | AD7: FracGASMm=1 | AE7: MMSATMOS (m=5) | AF7: MMSATMOS (m=4) | AG7: MMSATMOS (m=7) | AH7: MMSATMOS (m=13) | AI7: MMSATMOS (m=1) | AJ7: MMSATMOS | AK7: EFN2O | AL7: CN2O | AM7: EN2O,ad
A8: ='Input Scenarios'!A21 -> NSW | B8: =IF('Input Scenarios'!B21<>"", 'Input Scenarios'!B21, "") -> 14 | C8: ='Input Scenarios'!C21 -> Non-irrigated pasture | D8: ='Input Scenarios'!D21 -> 200 | E8: ='Input Scenarios'!E21 -> 79 | F8: ='Input Scenarios'!F21 -> 0.4 | G8: ='Input Scenarios'!G21 -> 0.4 | H8: ='Input Scenarios'!H21 -> 0.2 | I8: ='Input Scenarios'!I21 -> 0.5 | J8: =IF('Input Scenarios'!J21<>"", 'Input Scenarios'!J21, IF($E8<=80, Constants!B$2, IF($E8<=200, Constants!B$3, Constants!B$4))) -> 10.4 | K8: =IF('Input Scenarios'!K21<>"", 'Input Scenarios'!K21, IF($E8<=80, Constants!C$2, IF($E8<=200, Constants!C$3, Constants!C$4))) -> 0.204 | L8: =IF('Input Scenarios'!L21<>"", 'Input Scenarios'!L21, IF($E8<=80, Constants!D$2, IF($E8<=200, Constants!D$3, Constants!D$4))) -> 0.81 | M8: =IF('Input Scenarios'!M21<>"", 'Input Scenarios'!M21, IF($E8<=80, Constants!E$2, IF($E8<=200, Constants!E$3, Constants!E$4))) -> 0.14 | N8: =Constants!$B$32 -> 6.25 | O8: =J8*M8/N8 -> 0.23296 | P8: =O8*(1-K8) -> 0.18543616 | Q8: =D8*E8*P8 -> 2929.8913 | R8: =Constants!$B$29 -> 0.02 | S8: =Constants!$C$8 -> 0.0054 | T8: =(Q8*(1-Z8-S8))-(Q8*R8) -> 1097.5373 | U8: =Q8 -> 2929.8913 | V8: =$T8*F8 -> 439.01492 | W8: =$T8*G8 -> 439.01492 | X8: =$T8*H8 -> 219.50746 | Y8: =Q8*R8 -> 58.597827 | Z8: =Constants!$D$8 -> 0.6 | AA8: =Constants!$D$9 -> 0.25 | AB8: =Constants!$D$10 -> 0.4 | AC8: =Constants!$D$11 -> 0 | AD8: =Constants!$D$12 -> 0.35 | AE8: =U8*Z8 -> 1757.9348 | AF8: =V8*AA8 -> 109.75373 | AG8: =W8*AB8 -> 175.60597 | AH8: =X8*AC8 -> 0 | AI8: =Y8*AD8 -> 20.509239 | AJ8: =SUM(AE8:AI8) -> 2063.8037 | AK8: =_xlfn.XLOOKUP(C8,Constants!$A$16:$A$20,Constants!$B$16:$B$20) -> 0.0018 | AL8: =Constants!$B$33 -> 1.5714286 | AM8: =AJ8*AK8*AL8/1000 -> 0.0058376163
A9: ='Input Scenarios'!A22 -> QLD | B9: =IF('Input Scenarios'!B22<>"", 'Input Scenarios'!B22, "") -> 27 | C9: ='Input Scenarios'!C22 -> Irrigated pasture | D9: ='Input Scenarios'!D22 -> 200 | E9: ='Input Scenarios'!E22 -> 80 | F9: ='Input Scenarios'!F22 -> 0.4 | G9: ='Input Scenarios'!G22 -> 0.4 | H9: ='Input Scenarios'!H22 -> 0.2 | I9: ='Input Scenarios'!I22 -> 0.5 | J9: =IF('Input Scenarios'!J22<>"", 'Input Scenarios'!J22, IF($E9<=80, Constants!B$2, IF($E9<=200, Constants!B$3, Constants!B$4))) -> 10.4 | K9: =IF('Input Scenarios'!K22<>"", 'Input Scenarios'!K22, IF($E9<=80, Constants!C$2, IF($E9<=200, Constants!C$3, Constants!C$4))) -> 0.204 | L9: =IF('Input Scenarios'!L22<>"", 'Input Scenarios'!L22, IF($E9<=80, Constants!D$2, IF($E9<=200, Constants!D$3, Constants!D$4))) -> 0.81 | M9: =IF('Input Scenarios'!M22<>"", 'Input Scenarios'!M22, IF($E9<=80, Constants!E$2, IF($E9<=200, Constants!E$3, Constants!E$4))) -> 0.14 | N9: =Constants!$B$32 -> 6.25 | O9: =J9*M9/N9 -> 0.23296 | P9: =O9*(1-K9) -> 0.18543616 | Q9: =D9*E9*P9 -> 2966.9786 | R9: =Constants!$B$29 -> 0.02 | S9: =Constants!$C$8 -> 0.0054 | T9: =(Q9*(1-Z9-S9))-(Q9*R9) -> 1111.4302 | U9: =Q9 -> 2966.9786 | V9: =$T9*F9 -> 444.57207 | W9: =$T9*G9 -> 444.57207 | X9: =$T9*H9 -> 222.28603 | Y9: =Q9*R9 -> 59.339571 | Z9: =Constants!$D$8 -> 0.6 | AA9: =Constants!$D$9 -> 0.25 | AB9: =Constants!$D$10 -> 0.4 | AC9: =Constants!$D$11 -> 0 | AD9: =Constants!$D$12 -> 0.35 | AE9: =U9*Z9 -> 1780.1871 | AF9: =V9*AA9 -> 111.14302 | AG9: =W9*AB9 -> 177.82883 | AH9: =X9*AC9 -> 0 | AI9: =Y9*AD9 -> 20.76885 | AJ9: =SUM(AE9:AI9) -> 2089.9278 | AK9: =_xlfn.XLOOKUP(C9,Constants!$A$16:$A$20,Constants!$B$16:$B$20) -> 0.0059 | AL9: =Constants!$B$33 -> 1.5714286 | AM9: =AJ9*AK9*AL9/1000 -> 0.019376617
A10: ='Input Scenarios'!A23 -> SA | B10: =IF('Input Scenarios'!B23<>"", 'Input Scenarios'!B23, "") -> 22 | C10: ='Input Scenarios'!C23 -> Irrigated crop | D10: ='Input Scenarios'!D23 -> 200 | E10: ='Input Scenarios'!E23 -> 81 | F10: ='Input Scenarios'!F23 -> 0.4 | G10: ='Input Scenarios'!G23 -> 0.4 | H10: ='Input Scenarios'!H23 -> 0.2 | I10: ='Input Scenarios'!I23 -> 0.5 | J10: =IF('Input Scenarios'!J23<>"", 'Input Scenarios'!J23, IF($E10<=80, Constants!B$2, IF($E10<=200, Constants!B$3, Constants!B$4))) -> 10.8 | K10: =IF('Input Scenarios'!K23<>"", 'Input Scenarios'!K23, IF($E10<=80, Constants!C$2, IF($E10<=200, Constants!C$3, Constants!C$4))) -> 0.127 | L10: =IF('Input Scenarios'!L23<>"", 'Input Scenarios'!L23, IF($E10<=80, Constants!D$2, IF($E10<=200, Constants!D$3, Constants!D$4))) -> 0.81 | M10: =IF('Input Scenarios'!M23<>"", 'Input Scenarios'!M23, IF($E10<=80, Constants!E$2, IF($E10<=200, Constants!E$3, Constants!E$4))) -> 0.12 | N10: =Constants!$B$32 -> 6.25 | O10: =J10*M10/N10 -> 0.20736 | P10: =O10*(1-K10) -> 0.18102528 | Q10: =D10*E10*P10 -> 2932.6095 | R10: =Constants!$B$29 -> 0.02 | S10: =Constants!$C$8 -> 0.0054 | T10: =(Q10*(1-Z10-S10))-(Q10*R10) -> 1098.5555 | U10: =Q10 -> 2932.6095 | V10: =$T10*F10 -> 439.42221 | W10: =$T10*G10 -> 439.42221 | X10: =$T10*H10 -> 219.71111 | Y10: =Q10*R10 -> 58.652191 | Z10: =Constants!$D$8 -> 0.6 | AA10: =Constants!$D$9 -> 0.25 | AB10: =Constants!$D$10 -> 0.4 | AC10: =Constants!$D$11 -> 0 | AD10: =Constants!$D$12 -> 0.35 | AE10: =U10*Z10 -> 1759.5657 | AF10: =V10*AA10 -> 109.85555 | AG10: =W10*AB10 -> 175.76889 | AH10: =X10*AC10 -> 0 | AI10: =Y10*AD10 -> 20.528267 | AJ10: =SUM(AE10:AI10) -> 2065.7184 | AK10: =_xlfn.XLOOKUP(C10,Constants!$A$16:$A$20,Constants!$B$16:$B$20) -> 0.007 | AL10: =Constants!$B$33 -> 1.5714286 | AM10: =AJ10*AK10*AL10/1000 -> 0.022722903
