Workbook

Sheet Constants
A1: Breed | B1: milkingCows | C1: heifersGt1 | D1: heifersLt1Weaned | E1: bullsGt1 | F1: bullsLt1Weaned | G1: heifersLt1PreWeaned | H1: bullsLt1PreWeaned | J1: Pre-weaned calves | K1: MPWmanure | L1: VSj | M1: NPWj | O1: Metabolic rate increase | P1: MRj
A2: Medium Friesian | B2: 550 | C2: 380 | D2: 155 | E2: 600 | F2: 225 | G2: 155 | H2: 225 | J2: heifersLt1PreWeaned | K2: 0.0176 | L2: 0.2685 | M2: 0.0137 | O2: milkingCows | P2: 1.1
A3: Large Friesian | B3: 600 | C3: 415 | D3: 170 | E3: 600 | F3: 225 | G3: 170 | H3: 225 | J3: bullsLt1PreWeaned | K3: 0.0204 | L3: 0.3003 | M3: 0.0092 | O3: others | P3: 1
A4: Holstein-Friesian | B4: 650 | C4: 450 | D4: 185 | E4: 600 | F4: 225 | G4: 185 | H4: 225
A5: Friesian crossbred | B5: 500 | C5: 350 | D5: 145 | E5: 600 | F5: 225 | G5: 145 | H5: 225 | J5: Class | K5: Dj | M5: Feeding system | N5: Pasture | O5: Milking Shed | P5: Feedpad
A6: Jersey | B6: 400 | C6: 275 | D6: 115 | E6: 600 | F6: 225 | G6: 115 | H6: 225 | J6: milkingCows | K6: 365 | M6: Grazed only | N6: 0.89 | O6: 0.11 | P6: 0
A7: Jersey crossbred | B7: 450 | C7: 315 | D7: 130 | E7: 600 | F7: 225 | G7: 130 | H7: 225 | J7: bullsGt1 | K7: 365 | M7: Limited feedpad | N7: 0.79 | O7: 0.11 | P7: 0.1
A8: Ayrshire | B8: 540 | C8: 375 | D8: 150 | E8: 600 | F8: 225 | G8: 150 | H8: 225 | J8: heifersGt1 | K8: 365 | M8: Limited grazing | N8: 0.534 | O8: 0.11 | P8: 0.356
A9: Guernsey | B9: 480 | C9: 335 | D9: 140 | E9: 600 | F9: 225 | G9: 140 | H9: 225 | J9: heifersLt1Weaned | K9: 281 | M9: Zero grazing | N9: 0 | O9: 0.11 | P9: 0.89
A10: Brown Swiss | B10: 600 | C10: 415 | D10: 170 | E10: 600 | F10: 225 | G10: 170 | H10: 225 | J10: bullsLt1Weaned | K10: 281
A11: Illawarra/Aussie Red | B11: 550 | C11: 375 | D11: 150 | E11: 600 | F11: 225 | G11: 150 | H11: 225 | J11: heifersLt1PreWeaned | K11: 84
J12: bullsLt1PreWeaned | K12: 84
A13: Class | B13: milkingCows | C13: heifersGt1 | D13: heifersLt1Weaned | E13: bullsGt1 | F13: bullsLt1Weaned
A14: Reference Weight | B14: 590 | C14: 590 | D14: 590 | E14: 770 | F14: 770
A15: LWG | B15: 0.016 | C15: 0.6 | D15: 0.57 | E15: 0.1 | F15: 0.8
E17: MCFim by state
A18: MMS | B18: m | C18: EFm | D18: FracGASMm | E18: NSW | F18: ACT | G18: QLD | H18: NT | I18: VIC | J18: SA | K18: WA | L18: TAS
A19: anaerobicLagoon | B19: 1 | C19: 0 | D19: 0.35 | E19: 0.76 | F19: 0.72 | G19: 0.78 | H19: 0.8 | I19: 0.73 | J19: 0.74 | K19: 0.76 | L19: 0.69
A20: sumpDispersal | B20: 3a | C20: 0 | D20: 0.07 | E20: 0.005 | F20: 0.005 | G20: 0.005 | H20: 0.01 | I20: 0.005 | J20: 0.005 | K20: 0.005 | L20: 0.001
A21: drainToPaddock | B21: 3b | C21: 0 | D21: 0.2 | E21: 0.18 | F21: 0.15 | G21: 0.24 | H21: 0.5 | I21: 0.17 | J21: 0.17 | K21: 0.18 | L21: 0.13
A22: solidStorage | B22: 4 | C22: 0.005 | D22: 0.3 | E22: 0.02 | F22: 0.02 | G22: 0.02 | H22: 0.02 | I22: 0.02 | J22: 0.02 | K22: 0.02 | L22: 0.02
A23: pastureRangeAndPaddock | B23: 14 | C23: 0 | D23: 0 | E23: 0.01 | F23: 0.01 | G23: 0.01 | H23: 0.02 | I23: 0.01 | J23: 0.01 | K23: 0.01 | L23: 0.01
E25: MCFim BY MAT
A26: Production system | B26: EFN2O | E26: MAT | F26: anaerobicLagoon | G26: sumpDispersal | H26: drainToPaddock | I26: solidStorage | K26: Dairy pasture range and paddock is state based - 0.03 (QLD, NT) or 0.01 (Other States) – source NIR
A27: Non-irrigated pasture | B27: 0.0018 | E27: 10 or below | F27: 0.66 | G27: 0.001 | H27: 0.1 | I27: 0.02
A28: Irrigated pasture | B28: 0.0059 | E28: 11 | F28: 0.68 | G28: 0.001 | H28: 0.11 | I28: 0.02
A29: Irrigated crop | B29: 0.007 | E29: 12 | F29: 0.7 | G29: 0.001 | H29: 0.13 | I29: 0.02
A30: Non-irrigated crop (low rainfall) | B30: 0.0029 | E30: 13 | F30: 0.71 | G30: 0.001 | H30: 0.14 | I30: 0.02
A31: Non-irrigated crop (high rainfall) | B31: 0.008 | E31: 14 | F31: 0.73 | G31: 0.001 | H31: 0.15 | I31: 0.02
E32: 15 | F32: 0.74 | G32: 0.005 | H32: 0.17 | I32: 0.02
A33: Climate Zone | B33: EFPRP | E33: 16 | F33: 0.75 | G33: 0.005 | H33: 0.18 | I33: 0.02
A34: wet | B34: 0.006 | E34: 17 | F34: 0.76 | G34: 0.005 | H34: 0.2 | I34: 0.02
A35: dry | B35: 0.002 | E35: 18 | F35: 0.77 | G35: 0.005 | H35: 0.22 | I35: 0.02
E36: 19 | F36: 0.78 | G36: 0.005 | H36: 0.24 | I36: 0.02
A37: Fixed Constants | E37: 20 | F37: 0.78 | G37: 0.005 | H37: 0.26 | I37: 0.02
A38: SS | B38: 0.2 | E38: 21 | F38: 0.78 | G38: 0.005 | H38: 0.29 | I38: 0.02
A39: FC | B39: 4 | E39: 22 | F39: 0.78 | G39: 0.005 | H39: 0.31 | I39: 0.02
A40: PC | B40: 3.3 | E40: 23 | F40: 0.79 | G40: 0.005 | H40: 0.34 | I40: 0.02
A41: NE | B41: 3.054 | E41: 24 | F41: 0.79 | G41: 0.005 | H41: 0.37 | I41: 0.02
A42: GEC | B42: 18.4 | E42: 25 | F42: 0.79 | G42: 0.005 | H42: 0.41 | I42: 0.02
...

Sheet Input Scenarios
A1: Method 1 Inputs
A3: input | C3: input | D3: input | E3: input | Y3: input
A5: State | B5: MAT | C5: Production system | D5: Climate Zone | E5: Leaching zone | F5: Feed system | G5: Time spent in locations | J5: Allocations to MMS from milk shed | N5: Allocations to MMS from feedpad | R5: Solids separated | S5: Solid separation rate | Y5: Dairy class
W6: L/head/day
A7: i | B7: i | D7: (wet or dry) | E7: (true or false) | G7: pasture | H7: milk shed | I7: feedpad | J7: anaerobic lagoon | K7: sump and dispersal | L7: drains to paddock | M7: solid storage | N7: anaerobic lagoon | O7: sump and dispersal | P7: drains to paddock | Q7: solid storage | R7: true or false | S7: SSm | T7: MPj (kg) | U7: FC | V7: PC | W7: MPj (L) | X7: breed | Y7: j | Z7: Nj | AA7: Dj | AB7: Wj | AC7: LWGj | AD7: DMDj | AE7: CPj
A8: NSW | C8: Non-irrigated pasture | D8: wet | E8: FALSE | F8: Limited grazing | J8: 0.25 | K8: 0.25 | L8: 0.25 | M8: 0.25 | N8: 0.25 | O8: 0.25 | P8: 0.25 | Q8: 0.25 | R8: TRUE | W8: 15 | X8: Medium Friesian | Y8: milkingCows | Z8: 200
A9: NSW | C9: Non-irrigated pasture | D9: wet | E9: FALSE | F9: Limited grazing | J9: 0.25 | K9: 0.25 | L9: 0.25 | M9: 0.25 | N9: 0.25 | O9: 0.25 | P9: 0.25 | Q9: 0.25 | R9: TRUE | X9: Medium Friesian | Y9: heifersGt1 | Z9: 200
A10: NSW | C10: Non-irrigated pasture | D10: wet | E10: FALSE | F10: Limited grazing | J10: 0.25 | K10: 0.25 | L10: 0.25 | M10: 0.25 | N10: 0.25 | O10: 0.25 | P10: 0.25 | Q10: 0.25 | R10: TRUE | X10: Medium Friesian | Y10: heifersLt1PreWeaned | Z10: 200
A11: NSW | C11: Non-irrigated pasture | D11: wet | E11: FALSE | F11: Limited grazing | J11: 0.25 | K11: 0.25 | L11: 0.25 | M11: 0.25 | N11: 0.25 | O11: 0.25 | P11: 0.25 | Q11: 0.25 | R11: TRUE | X11: Medium Friesian | Y11: heifersLt1Weaned | Z11: 200
A12: NSW | C12: Non-irrigated pasture | D12: wet | E12: FALSE | F12: Limited grazing | J12: 0.25 | K12: 0.25 | L12: 0.25 | M12: 0.25 | N12: 0.25 | O12: 0.25 | P12: 0.25 | Q12: 0.25 | R12: TRUE | X12: Medium Friesian | Y12: bullsGt1 | Z12: 200
A13: NSW | C13: Non-irrigated pasture | D13: wet | E13: FALSE | F13: Limited grazing | J13: 0.25 | K13: 0.25 | L13: 0.25 | M13: 0.25 | N13: 0.25 | O13: 0.25 | P13: 0.25 | Q13: 0.25 | R13: TRUE | X13: Medium Friesian | Y13: bullsLt1PreWeaned | Z13: 200
A14: NSW | C14: Non-irrigated pasture | D14: wet | E14: FALSE | F14: Limited grazing | J14: 0.25 | K14: 0.25 | L14: 0.25 | M14: 0.25 | N14: 0.25 | O14: 0.25 | P14: 0.25 | Q14: 0.25 | R14: TRUE | X14: Medium Friesian | Y14: bullsLt1Weaned | Z14: 200
A15: QLD | C15: Non-irrigated crop (high rainfall) | D15: wet | E15: TRUE | F15: Limited feedpad | L15: 1 | N15: 1 | R15: TRUE | T15: 3 | X15: Large Friesian | Y15: milkingCows | Z15: 200
A16: QLD | C16: Non-irrigated crop (high rainfall) | D16: wet | E16: TRUE | F16: Limited feedpad | L16: 1 | N16: 1 | R16: TRUE | X16: Large Friesian | Y16: heifersGt1 | Z16: 200
A17: QLD | C17: Non-irrigated crop (high rainfall) | D17: wet | E17: TRUE | F17: Limited feedpad | L17: 1 | N17: 1 | R17: TRUE | X17: Large Friesian | Y17: heifersLt1PreWeaned | Z17: 200
A18: QLD | C18: Non-irrigated crop (high rainfall) | D18: wet | E18: TRUE | F18: Limited feedpad | L18: 1 | N18: 1 | R18: TRUE | X18: Large Friesian | Y18: heifersLt1Weaned | Z18: 200
A19: QLD | C19: Non-irrigated crop (high rainfall) | D19: wet | E19: TRUE | F19: Limited feedpad | L19: 1 | N19: 1 | R19: TRUE | X19: Large Friesian | Y19: bullsGt1 | Z19: 200
A20: QLD | C20: Non-irrigated crop (high rainfall) | D20: wet | E20: TRUE | F20: Limited feedpad | L20: 1 | N20: 1 | R20: TRUE | X20: Large Friesian | Y20: bullsLt1PreWeaned | Z20: 200
A21: QLD | C21: Non-irrigated crop (high rainfall) | D21: wet | E21: TRUE | F21: Limited feedpad | L21: 1 | N21: 1 | R21: TRUE | X21: Large Friesian | Y21: bullsLt1Weaned | Z21: 200
A22: NT | C22: Irrigated pasture | D22: dry | E22: FALSE | F22: Zero grazing | J22: 0 | K22: 0.5 | L22: 0.5 | M22: 0 | N22: 0.5 | O22: 0 | P22: 0 | Q22: 0.5 | R22: FALSE | T22: 2.8 | X22: Holstein-Friesian | Y22: milkingCows | Z22: 200
A23: NT | C23: Irrigated pasture | D23: dry | E23: FALSE | F23: Zero grazing | J23: 0 | K23: 0.5 | L23: 0.5 | M23: 0 | N23: 0.5 | O23: 0 | P23: 0 | Q23: 0.5 | R23: FALSE | X23: Holstein-Friesian | Y23: heifersGt1 | Z23: 200
A24: NT | C24: Irrigated pasture | D24: dry | E24: FALSE | F24: Zero grazing | J24: 0 | K24: 0.5 | L24: 0.5 | M24: 0 | N24: 0.5 | O24: 0 | P24: 0 | Q24: 0.5 | R24: FALSE | X24: Holstein-Friesian | Y24: heifersLt1PreWeaned | Z24: 200
A25: NT | C25: Irrigated pasture | D25: dry | E25: FALSE | F25: Zero grazing | J25: 0 | K25: 0.5 | L25: 0.5 | M25: 0 | N25: 0.5 | O25: 0 | P25: 0 | Q25: 0.5 | R25: FALSE | X25: Holstein-Friesian | Y25: heifersLt1Weaned | Z25: 200
A26: NT | C26: Irrigated pasture | D26: dry | E26: FALSE | F26: Zero grazing | J26: 0 | K26: 0.5 | L26: 0.5 | M26: 0 | N26: 0.5 | O26: 0 | P26: 0 | Q26: 0.5 | R26: FALSE | X26: Holstein-Friesian | Y26: bullsGt1 | Z26: 200
A27: NT | C27: Irrigated pasture | D27: dry | E27: FALSE | F27: Zero grazing | J27: 0 | K27: 0.5 | L27: 0.5 | M27: 0 | N27: 0.5 | O27: 0 | P27: 0 | Q27: 0.5 | R27: FALSE | X27: Holstein-Friesian | Y27: bullsLt1PreWeaned | Z27: 200
A28: NT | C28: Irrigated pasture | D28: dry | E28: FALSE | F28: Zero grazing | J28: 0 | K28: 0.5 | L28: 0.5 | M28: 0 | N28: 0.5 | O28: 0 | P28: 0 | Q28: 0.5 | R28: FALSE | X28: Holstein-Friesian | Y28: bullsLt1Weaned | Z28: 200
A29: TAS | C29: Irrigated crop | D29: dry | E29: TRUE | F29: Grazed only | J29: 0.1 | K29: 0.2 | L29: 0.3 | M29: 0.4 | N29: 0.4 | O29: 0.3 | P29: 0.2 | Q29: 0.1 | R29: FALSE | W29: 20 | X29: Friesian crossbred | Y29: milkingCows | Z29: 200
A30: TAS | C30: Irrigated crop | D30: dry | E30: TRUE | F30: Grazed only | J30: 0.1 | K30: 0.2 | L30: 0.3 | M30: 0.4 | N30: 0.4 | O30: 0.3 | P30: 0.2 | Q30: 0.1 | R30: FALSE | X30: Friesian crossbred | Y30: heifersGt1 | Z30: 200
A31: TAS | C31: Irrigated crop | D31: dry | E31: TRUE | F31: Grazed only | J31: 0.1 | K31: 0.2 | L31: 0.3 | M31: 0.4 | N31: 0.4 | O31: 0.3 | P31: 0.2 | Q31: 0.1 | R31: FALSE | X31: Friesian crossbred | Y31: heifersLt1PreWeaned | Z31: 200
A32: TAS | C32: Irrigated crop | D32: dry | E32: TRUE | F32: Grazed only | J32: 0.1 | K32: 0.2 | L32: 0.3 | M32: 0.4 | N32: 0.4 | O32: 0.3 | P32: 0.2 | Q32: 0.1 | R32: FALSE | X32: Friesian crossbred | Y32: heifersLt1Weaned | Z32: 200
A33: TAS | C33: Irrigated crop | D33: dry | E33: TRUE | F33: Grazed only | J33: 0.1 | K33: 0.2 | L33: 0.3 | M33: 0.4 | N33: 0.4 | O33: 0.3 | P33: 0.2 | Q33: 0.1 | R33: FALSE | X33: Friesian crossbred | Y33: bullsGt1 | Z33: 200
A34: TAS | C34: Irrigated crop | D34: dry | E34: TRUE | F34: Grazed only | J34: 0.1 | K34: 0.2 | L34: 0.3 | M34: 0.4 | N34: 0.4 | O34: 0.3 | P34: 0.2 | Q34: 0.1 | R34: FALSE | X34: Friesian crossbred | Y34: bullsLt1PreWeaned | Z34: 200
A35: TAS | C35: Irrigated crop | D35: dry | E35: TRUE | F35: Grazed only | J35: 0.1 | K35: 0.2 | L35: 0.3 | M35: 0.4 | N35: 0.4 | O35: 0.3 | P35: 0.2 | Q35: 0.1 | R35: FALSE | X35: Friesian crossbred | Y35: bullsLt1Weaned | Z35: 200
A36: VIC | C36: Non-irrigated pasture | D36: wet | E36: FALSE | F36: Limited grazing | J36: 0.25 | K36: 0.25 | L36: 0.25 | M36: 0.25 | N36: 0.25 | O36: 0.25 | P36: 0.25 | Q36: 0.25 | R36: TRUE | W36: 30 | X36: Jersey | Y36: milkingCows | Z36: 200
A37: VIC | C37: Non-irrigated pasture | D37: wet | E37: FALSE | F37: Limited grazing | J37: 0.25 | K37: 0.25 | L37: 0.25 | M37: 0.25 | N37: 0.25 | O37: 0.25 | P37: 0.25 | Q37: 0.25 | R37: TRUE | X37: Jersey | Y37: heifersGt1 | Z37: 200
A38: VIC | C38: Non-irrigated pasture | D38: wet | E38: FALSE | F38: Limited grazing | J38: 0.25 | K38: 0.25 | L38: 0.25 | M38: 0.25 | N38: 0.25 | O38: 0.25 | P38: 0.25 | Q38: 0.25 | R38: TRUE | X38: Jersey | Y38: heifersLt1PreWeaned | Z38: 200
A39: VIC | C39: Non-irrigated pasture | D39: wet | E39: FALSE | F39: Limited grazing | J39: 0.25 | K39: 0.25 | L39: 0.25 | M39: 0.25 | N39: 0.25 | O39: 0.25 | P39: 0.25 | Q39: 0.25 | R39: TRUE | X39: Jersey | Y39: heifersLt1Weaned | Z39: 200
A40: VIC | C40: Non-irrigated pasture | D40: wet | E40: FALSE | F40: Limited grazing | J40: 0.25 | K40: 0.25 | L40: 0.25 | M40: 0.25 | N40: 0.25 | O40: 0.25 | P40: 0.25 | Q40: 0.25 | R40: TRUE | X40: Jersey | Y40: bullsGt1 | Z40: 200
A41: VIC | C41: Non-irrigated pasture | D41: wet | E41: FALSE | F41: Limited grazing | J41: 0.25 | K41: 0.25 | L41: 0.25 | M41: 0.25 | N41: 0.25 | O41: 0.25 | P41: 0.25 | Q41: 0.25 | R41: TRUE | X41: Jersey | Y41: bullsLt1PreWeaned | Z41: 200
A42: VIC | C42: Non-irrigated pasture | D42: wet | E42: FALSE | F42: Limited grazing | J42: 0.25 | K42: 0.25 | L42: 0.25 | M42: 0.25 | N42: 0.25 | O42: 0.25 | P42: 0.25 | Q42: 0.25 | R42: TRUE | X42: Jersey | Y42: bullsLt1Weaned | Z42: 200
...

Sheet 4.3.1.1
A1: Method 1
A3: input | C3: input | D3: input | E3: input | Y3: input
A5: State | B5: MAT | C5: Production system | D5: Climate Zone | E5: Leaching zone | F5: Feed system | G5: Time spent in locations | J5: Allocations to MMS from milk shed | N5: Allocations to MMS from feedpad | R5: Solids separated | S5: Solid separation rate | T5: Milk solids | U5: fat content | V5: protein content | Y5: Dairy class | AF5: MMS allocations (resolved) | AL5: Milk density
U6: fraction | V6: fraction | W6: L/head/day | AK6: L/head/day | BN6: kg CH4 | BO6: t CH4
A7: i | B7: i | D7: (wet or dry) | E7: (true or false) | G7: pasture | H7: milk shed | I7: feedpad | J7: anaerobic lagoon | K7: sump and dispersal | L7: drains to paddock | M7: solid storage | N7: anaerobic lagoon | O7: sump and dispersal | P7: drains to paddock | Q7: solid storage | R7: true or false | S7: SSm | T7: MSj (kg) | U7: FC | V7: PC | W7: MPj (L) | Y7: j | Z7: Nj | AA7: Dj | AB7: Wj | AC7: LWGj | AD7: DMDj | AE7: CPj | AF7: MMSm=1 | AG7: MMSm=3a | AH7: MMSm=3b | AI7: MMSm=4 | AJ7: MMSm=14 | AK7: MPj (Normalised) | AM7: NE | AN7: GEC | AO7: k | AP7: qmj | AQ7: MIj | AR7: MRj | AS7: Ij | AT7: A | AU7: VSj | AV7: FVSm=1 | AW7: FVSm=3a | AX7: FVSm=3b | AY7: FVSm=4 | AZ7: FVSm=14 | BA7: MCFim=1 | BB7: MCFim=3a | BC7: MCFim=3b | BD7: MCFim=4 | BE7: MCFim=14 | BF7: Bo | BG7: p | BH7: Mjm=1 | BI7: Mjm=3a | BJ7: Mjm=3b | BK7: Mjm=4 | BL7: Mjm=14 | BM7: MPWmanure | BN7: ECH4 (j) | BO7: ECH4
A8: ='Input Scenarios'!A8 -> NSW | B8: ='Input Scenarios'!B8 -> 0 | C8: ='Input Scenarios'!C8 -> Non-irrigated pasture | D8: ='Input Scenarios'!D8 -> wet | E8: ='Input Scenarios'!E8 -> FALSE | F8: ='Input Scenarios'!F8 -> Limited grazing | G8: =IF('Input Scenarios'!G8<>"", 'Input Scenarios'!G8, _xlfn.XLOOKUP($F8, Constants!$M$6:$M$9,Constants!N$6:N$9)) -> 0.534 | H8: =IF('Input Scenarios'!H8<>"", 'Input Scenarios'!H8, _xlfn.XLOOKUP($F8, Constants!$M$6:$M$9,Constants!O$6:O$9)) -> 0.11 | I8: =IF('Input Scenarios'!I8<>"", 'Input Scenarios'!I8, _xlfn.XLOOKUP($F8, Constants!$M$6:$M$9,Constants!P$6:P$9)) -> 0.356 | J8: ='Input Scenarios'!J8 -> 0.25 | K8: ='Input Scenarios'!K8 -> 0.25 | L8: ='Input Scenarios'!L8 -> 0.25 | M8: ='Input Scenarios'!M8 -> 0.25 | N8: ='Input Scenarios'!N8 -> 0.25 | O8: ='Input Scenarios'!O8 -> 0.25 | P8: ='Input Scenarios'!P8 -> 0.25 | Q8: ='Input Scenarios'!Q8 -> 0.25 | R8: ='Input Scenarios'!R8 -> TRUE | S8: =IF('Input Scenarios'!S8<>"", 'Input Scenarios'!S8, IF(R8, Constants!$B$38, 0)) -> 0.2 | T8: =IF('Input Scenarios'!T8<>"", 'Input Scenarios'!T8, "") | U8: =IF('Input Scenarios'!U8<>"", 'Input Scenarios'!U8, IF(W8<>"", "", Constants!$B$39)) | V8: =IF('Input Scenarios'!V8<>"", 'Input Scenarios'!V8, IF(W8<>"", "", Constants!$B$40)) | W8: =IF('Input Scenarios'!W8<>"", 'Input Scenarios'!W8, "") -> 15 | X8: ='Input Scenarios'!X8 -> Medium Friesian | Y8: ='Input Scenarios'!Y8 -> milkingCows | Z8: ='Input Scenarios'!Z8 -> 200 | AA8: =IF('Input Scenarios'!AA8<>"", 'Input Scenarios'!AA8, _xlfn.XLOOKUP(Y8,Constants!$J$6:$J$12,Constants!$K$6:$K$12)) -> 365 | AB8: =IF('Input Scenarios'!AB8<>"", 'Input Scenarios'!AB8, INDEX(Constants!$B$2:$H$11, MATCH(X8, Constants!$A$2:$A$11, 0), MATCH(Y8,Constants!$B$1:$H$1, 0))) -> 550 | AC8: =IF('Input Scenarios'!AC8<>"", 'Input Scenarios'!AC8, _xlfn.XLOOKUP(Y8, Constants!$B$13:$H$13, Constants!$B$15:$H$15, "")) -> 0.016 | AD8: =IF('Input Scenarios'!AD8<>"", 'Input Scenarios'!AD8, Constants!$B$45) -> 0.75 | AE8: =IF('Input Scenarios'!AE8<>"", 'Input Scenarios'!AE8, Constants!$B$46) -> 0.2 | AF8: =IF($Y8="milkingCows",($H8*J8)+($I8*N8), 0) -> 0.1165 | AG8: =IF($Y8="milkingCows",($H8*K8)+($I8*O8), 0) -> 0.1165 | AH8: =IF($Y8="milkingCows",($H8*L8)+($I8*P8), 0) -> 0.1165 | AI8: =IF($Y8="milkingCows",($H8*M8)+($I8*Q8), 0) -> 0.1165 | AJ8: =IF($Y8="milkingCows",G8, 1) -> 0.534 | AK8: =IF(Y8="milkingCows", IF(W8<>"", W8, T8/((U8+V8)*0.01)), 0) -> 15 | AL8: =Constants!$B$44 -> 1.03 | AM8: =Constants!$B$41 -> 3.054 | AN8: =Constants!$B$42 -> 18.4 | AO8: =Constants!$B$43 -> 0.6 | AP8: =0.795*(AD8)-0.0014 -> 0.59485 | AQ8: =(AK8*AL8*AM8)/(AN8*AO8*AP8) -> 7.1849041 | AR8: =IF(Y8="milkingCows", Constants!$P$2, Constants!$P$3) -> 1.1 | AS8: =IFERROR(((((1.185 + (0.00454*AB8) - (0.0000026*(AB8^2)) + (0.315*AC8))^2)*AR8)+AQ8), "") -> 16.43935 | AT8: =Constants!$B$47 -> 0.08 | AU8: =IFERROR((AS8*(1-AD8)+(0.04*AS8))*(1-AT8), "") -> 4.3860185 | AV8: =AF8*(1-S8) -> 0.0932 | AW8: =AG8 -> 0.1165 | AX8: =AH8 -> 0.1165 | AY8: =AI8+(AF8*S8) -> 0.1398 | AZ8: =AJ8 -> 0.534 | BA8: =_xlfn.XLOOKUP($A8, Constants!$E$18:$L$18,Constants!$E$19:$L$19) -> 0.76 | BB8: =_xlfn.XLOOKUP($A8, Constants!$E$18:$L$18,Constants!$E$20:$L$20) -> 0.005 | BC8: =_xlfn.XLOOKUP($A8, Constants!$E$18:$L$18,Constants!$E$21:$L$21) -> 0.18 | BD8: =_xlfn.XLOOKUP($A8, Constants!$E$18:$L$18,Constants!$E$22:$L$22) -> 0.02 | BE8: =_xlfn.XLOOKUP($A8, Constants!$E$18:$L$18,Constants!$E$23:$L$23) -> 0.01 | BF8: =Constants!$B$48 -> 0.24 | BG8: =Constants!$B$49 -> 0.6784 | BH8: =IF(ISNUMBER(FIND("PreWeaned",$Y8)), "", $AU8*AV8*BA8*$BF8*$BG8) -> 0.050582122 | BI8: =IF(ISNUMBER(FIND("PreWeaned",$Y8)), "", $AU8*AW8*BB8*$BF8*$BG8) -> 0.0004159714 | BJ8: =IF(ISNUMBER(FIND("PreWeaned",$Y8)), "", $AU8*AX8*BC8*$BF8*$BG8) -> 0.01497497 | BK8: =IF(ISNUMBER(FIND("PreWeaned",$Y8)), "", $AU8*AY8*BD8*$BF8*$BG8) -> 0.0019966627 | BL8: =IF(ISNUMBER(FIND("PreWeaned",$Y8)), "", $AU8*AZ8*BE8*$BF8*$BG8) -> 0.0038133687 | BM8: =IF(ISNUMBER(FIND("PreWeaned",Y8)),_xlfn.XLOOKUP(Y8,Constants!$J$2:$J$3,Constants!$K$2:$K$3), "") | BN8: =Z8*AA8*SUM(BH8:BM8) -> 5240.1659 | BO8: =SUM(BN8:BN14)/1000 -> 6.6304737
A9: ='Input Scenarios'!A9 -> NSW | B9: ='Input Scenarios'!B9 -> 0 | C9: ='Input Scenarios'!C9 -> Non-irrigated pasture | D9: ='Input Scenarios'!D9 -> wet | E9: ='Input Scenarios'!E9 -> FALSE | F9: ='Input Scenarios'!F9 -> Limited grazing | G9: =IF('Input Scenarios'!G9<>"", 'Input Scenarios'!G9, _xlfn.XLOOKUP($F9, Constants!$M$6:$M$9,Constants!N$6:N$9)) -> 0.534 | H9: =IF('Input Scenarios'!H9<>"", 'Input Scenarios'!H9, _xlfn.XLOOKUP($F9, Constants!$M$6:$M$9,Constants!O$6:O$9)) -> 0.11 | I9: =IF('Input Scenarios'!I9<>"", 'Input Scenarios'!I9, _xlfn.XLOOKUP($F9, Constants!$M$6:$M$9,Constants!P$6:P$9)) -> 0.356 | J9: ='Input Scenarios'!J9 -> 0.25 | K9: ='Input Scenarios'!K9 -> 0.25 | L9: ='Input Scenarios'!L9 -> 0.25 | M9: ='Input Scenarios'!M9 -> 0.25 | N9: ='Input Scenarios'!N9 -> 0.25 | O9: ='Input Scenarios'!O9 -> 0.25 | P9: ='Input Scenarios'!P9 -> 0.25 | Q9: ='Input Scenarios'!Q9 -> 0.25 | R9: ='Input Scenarios'!R9 -> TRUE | S9: =IF('Input Scenarios'!S9<>"", 'Input Scenarios'!S9, IF(R9, Constants!$B$38, 0)) -> 0.2 | T9: =IF('Input Scenarios'!T9<>"", 'Input Scenarios'!T9, "") | U9: =IF('Input Scenarios'!U9<>"", 'Input Scenarios'!U9, IF(W9<>"", "", Constants!$B$39)) -> 4 | V9: =IF('Input Scenarios'!V9<>"", 'Input Scenarios'!V9, IF(W9<>"", "", Constants!$B$40)) -> 3.3 | W9: =IF('Input Scenarios'!W9<>"", 'Input Scenarios'!W9, "") | X9: ='Input Scenarios'!X9 -> Medium Friesian | Y9: ='Input Scenarios'!Y9 -> heifersGt1 | Z9: ='Input Scenarios'!Z9 -> 200 | AA9: =IF('Input Scenarios'!AA9<>"", 'Input Scenarios'!AA9, _xlfn.XLOOKUP(Y9,Constants!$J$6:$J$12,Constants!$K$6:$K$12)) -> 365 | AB9: =IF('Input Scenarios'!AB9<>"", 'Input Scenarios'!AB9, INDEX(Constants!$B$2:$H$11, MATCH(X9, Constants!$A$2:$A$11, 0), MATCH(Y9,Constants!$B$1:$H$1, 0))) -> 380 | AC9: =IF('Input Scenarios'!AC9<>"", 'Input Scenarios'!AC9, _xlfn.XLOOKUP(Y9, Constants!$B$13:$H$13, Constants!$B$15:$H$15, "")) -> 0.6 | AD9: =IF('Input Scenarios'!AD9<>"", 'Input Scenarios'!AD9, Constants!$B$45) -> 0.75 | AE9: =IF('Input Scenarios'!AE9<>"", 'Input Scenarios'!AE9, Constants!$B$46) -> 0.2 | AF9: =IF($Y9="milkingCows",($H9*J9)+($I9*N9), 0) -> 0 | AG9: =IF($Y9="milkingCows",($H9*K9)+($I9*O9), 0) -> 0 | AH9: =IF($Y9="milkingCows",($H9*L9)+($I9*P9), 0) -> 0 | AI9: =IF($Y9="milkingCows",($H9*M9)+($I9*Q9), 0) -> 0 | AJ9: =IF($Y9="milkingCows",G9, 1) -> 1 | AK9: =IF(Y9="milkingCows", IF(W9<>"", W9, T9/((U9+V9)*0.01)), 0) -> 0 | AL9: =Constants!$B$44 -> 1.03 | AM9: =Constants!$B$41 -> 3.054 | AN9: =Constants!$B$42 -> 18.4 | AO9: =Constants!$B$43 -> 0.6 | AP9: =0.795*(AD9)-0.0014 -> 0.59485 | AQ9: =(AK9*AL9*AM9)/(AN9*AO9*AP9) -> 0 | AR9: =IF(Y9="milkingCows", Constants!$P$2, Constants!$P$3) -> 1 | AS9: =IFERROR(((((1.185 + (0.00454*AB9) - (0.0000026*(AB9^2)) + (0.315*AC9))^2)*AR9)+AQ9), "") -> 7.4188685 | AT9: =Constants!$B$47 -> 0.08 | AU9: =IFERROR((AS9*(1-AD9)+(0.04*AS9))*(1-AT9), "") -> 1.9793541 | AV9: =AF9*(1-S9) -> 0 | AW9: =AG9 -> 0 | AX9: =AH9 -> 0 | AY9: =AI9+(AF9*S9) -> 0 | AZ9: =AJ9 -> 1 | BA9: =_xlfn.XLOOKUP($A9, Constants!$E$18:$L$18,Constants!$E$19:$L$19) -> 0.76 | BB9: =_xlfn.XLOOKUP($A9, Constants!$E$18:$L$18,Constants!$E$20:$L$20) -> 0.005 | BC9: =_xlfn.XLOOKUP($A9, Constants!$E$18:$L$18,Constants!$E$21:$L$21) -> 0.18 | BD9: =_xlfn.XLOOKUP($A9, Constants!$E$18:$L$18,Constants!$E$22:$L$22) -> 0.02 | BE9: =_xlfn.XLOOKUP($A9, Constants!$E$18:$L$18,Constants!$E$23:$L$23) -> 0.01 | BF9: =Constants!$B$48 -> 0.24 | BG9: =Constants!$B$49 -> 0.6784 | BH9: =IF(ISNUMBER(FIND("PreWeaned",$Y9)), "", $AU9*AV9*BA9*$BF9*$BG9) -> 0 | BI9: =IF(ISNUMBER(FIND("PreWeaned",$Y9)), "", $AU9*AW9*BB9*$BF9*$BG9) -> 0 | BJ9: =IF(ISNUMBER(FIND("PreWeaned",$Y9)), "", $AU9*AX9*BC9*$BF9*$BG9) -> 0 | BK9: =IF(ISNUMBER(FIND("PreWeaned",$Y9)), "", $AU9*AY9*BD9*$BF9*$BG9) -> 0 | BL9: =IF(ISNUMBER(FIND("PreWeaned",$Y9)), "", $AU9*AZ9*BE9*$BF9*$BG9) -> 0.0032227052 | BM9: =IF(ISNUMBER(FIND("PreWeaned",Y9)),_xlfn.XLOOKUP(Y9,Constants!$J$2:$J$3,Constants!$K$2:$K$3), "") | BN9: =Z9*AA9*SUM(BH9:BM9) -> 235.25748
A10: ='Input Scenarios'!A10 -> NSW | B10: ='Input Scenarios'!B10 -> 0 | C10: ='Input Scenarios'!C10 -> Non-irrigated pasture | D10: ='Input Scenarios'!D10 -> wet | E10: ='Input Scenarios'!E10 -> FALSE | F10: ='Input Scenarios'!F10 -> Limited grazing | G10: =IF('Input Scenarios'!G10<>"", 'Input Scenarios'!G10, _xlfn.XLOOKUP($F10, Constants!$M$6:$M$9,Constants!N$6:N$9)) -> 0.534 | H10: =IF('Input Scenarios'!H10<>"", 'Input Scenarios'!H10, _xlfn.XLOOKUP($F10, Constants!$M$6:$M$9,Constants!O$6:O$9)) -> 0.11 | I10: =IF('Input Scenarios'!I10<>"", 'Input Scenarios'!I10, _xlfn.XLOOKUP($F10, Constants!$M$6:$M$9,Constants!P$6:P$9)) -> 0.356 | J10: ='Input Scenarios'!J10 -> 0.25 | K10: ='Input Scenarios'!K10 -> 0.25 | L10: ='Input Scenarios'!L10 -> 0.25 | M10: ='Input Scenarios'!M10 -> 0.25 | N10: ='Input Scenarios'!N10 -> 0.25 | O10: ='Input Scenarios'!O10 -> 0.25 | P10: ='Input Scenarios'!P10 -> 0.25 | Q10: ='Input Scenarios'!Q10 -> 0.25 | R10: ='Input Scenarios'!R10 -> TRUE | S10: =IF('Input Scenarios'!S10<>"", 'Input Scenarios'!S10, IF(R10, Constants!$B$38, 0)) -> 0.2 | T10: =IF('Input Scenarios'!T10<>"", 'Input Scenarios'!T10, "") | U10: =IF('Input Scenarios'!U10<>"", 'Input Scenarios'!U10, IF(W10<>"", "", Constants!$B$39)) -> 4 | V10: =IF('Input Scenarios'!V10<>"", 'Input Scenarios'!V10, IF(W10<>"", "", Constants!$B$40)) -> 3.3 | W10: =IF('Input Scenarios'!W10<>"", 'Input Scenarios'!W10, "") | X10: ='Input Scenarios'!X10 -> Medium Friesian | Y10: ='Input Scenarios'!Y10 -> heifersLt1PreWeaned | Z10: ='Input Scenarios'!Z10 -> 200 | AA10: =IF('Input Scenarios'!AA10<>"", 'Input Scenarios'!AA10, _xlfn.XLOOKUP(Y10,Constants!$J$6:$J$12,Constants!$K$6:$K$12)) -> 84 | AB10: =IF('Input Scenarios'!AB10<>"", 'Input Scenarios'!AB10, INDEX(Constants!$B$2:$H$11, MATCH(X10, Constants!$A$2:$A$11, 0), MATCH(Y10,Constants!$B$1:$H$1, 0))) -> 155 | AC10: =IF('Input Scenarios'!AC10<>"", 'Input Scenarios'!AC10, _xlfn.XLOOKUP(Y10, Constants!$B$13:$H$13, Constants!$B$15:$H$15, "")) | AD10: =IF('Input Scenarios'!AD10<>"", 'Input Scenarios'!AD10, Constants!$B$45) -> 0.75 | AE10: =IF('Input Scenarios'!AE10<>"", 'Input Scenarios'!AE10, Constants!$B$46) -> 0.2 | AF10: =IF($Y10="milkingCows",($H10*J10)+($I10*N10), 0) -> 0 | AG10: =IF($Y10="milkingCows",($H10*K10)+($I10*O10), 0) -> 0 | AH10: =IF($Y10="milkingCows",($H10*L10)+($I10*P10), 0) -> 0 | AI10: =IF($Y10="milkingCows",($H10*M10)+($I10*Q10), 0) -> 0 | AJ10: =IF($Y10="milkingCows",G10, 1) -> 1 | AK10: =IF(Y10="milkingCows", IF(W10<>"", W10, T10/((U10+V10)*0.01)), 0) -> 0 | AL10: =Constants!$B$44 -> 1.03 | AM10: =Constants!$B$41 -> 3.054 | AN10: =Constants!$B$42 -> 18.4 | AO10: =Constants!$B$43 -> 0.6 | AP10: =0.795*(AD10)-0.0014 -> 0.59485 | AQ10: =(AK10*AL10*AM10)/(AN10*AO10*AP10) -> 0 | AR10: =IF(Y10="milkingCows", Constants!$P$2, Constants!$P$3) -> 1 | AS10: =IFERROR(((((1.185 + (0.00454*AB10) - (0.0000026*(AB10^2)) + (0.315*AC10))^2)*AR10)+AQ10), "") | AT10: =Constants!$B$47 -> 0.08 | AU10: =IFERROR((AS10*(1-AD10)+(0.04*AS10))*(1-AT10), "") | AV10: =AF10*(1-S10) -> 0 | AW10: =AG10 -> 0 | AX10: =AH10 -> 0 | AY10: =AI10+(AF10*S10) -> 0 | AZ10: =AJ10 -> 1 | BA10: =_xlfn.XLOOKUP($A10, Constants!$E$18:$L$18,Constants!$E$19:$L$19) -> 0.76 | BB10: =_xlfn.XLOOKUP($A10, Constants!$E$18:$L$18,Constants!$E$20:$L$20) -> 0.005 | BC10: =_xlfn.XLOOKUP($A10, Constants!$E$18:$L$18,Constants!$E$21:$L$21) -> 0.18 | BD10: =_xlfn.XLOOKUP($A10, Constants!$E$18:$L$18,Constants!$E$22:$L$22) -> 0.02 | BE10: =_xlfn.XLOOKUP($A10, Constants!$E$18:$L$18,Constants!$E$23:$L$23) -> 0.01 | BF10: =Constants!$B$48 -> 0.24 | BG10: =Constants!$B$49 -> 0.6784 | BH10: =IF(ISNUMBER(FIND("PreWeaned",$Y10)), "", $AU10*AV10*BA10*$BF10*$BG10) | BI10: =IF(ISNUMBER(FIND("PreWeaned",$Y10)), "", $AU10*AW10*BB10*$BF10*$BG10) | BJ10: =IF(ISNUMBER(FIND("PreWeaned",$Y10)), "", $AU10*AX10*BC10*$BF10*$BG10) | BK10: =IF(ISNUMBER(FIND("PreWeaned",$Y10)), "", $AU10*AY10*BD10*$BF10*$BG10) | BL10: =IF(ISNUMBER(FIND("PreWeaned",$Y10)), "", $AU10*AZ10*BE10*$BF10*$BG10) | BM10: =IF(ISNUMBER(FIND("PreWeaned",Y10)),_xlfn.XLOOKUP(Y10,Constants!$J$2:$J$3,Constants!$K$2:$K$3), "") -> 0.0176 | BN10: =Z10*AA10*SUM(BH10:BM10) -> 295.68
A11: ='Input Scenarios'!A11 -> NSW | B11: ='Input Scenarios'!B11 -> 0 | C11: ='Input Scenarios'!C11 -> Non-irrigated pasture | D11: ='Input Scenarios'!D11 -> wet | E11: ='Input Scenarios'!E11 -> FALSE | F11: ='Input Scenarios'!F11 -> Limited grazing | G11: =IF('Input Scenarios'!G11<>"", 'Input Scenarios'!G11, _xlfn.XLOOKUP($F11, Constants!$M$6:$M$9,Constants!N$6:N$9)) -> 0.534 | H11: =IF('Input Scenarios'!H11<>"", 'Input Scenarios'!H11, _xlfn.XLOOKUP($F11, Constants!$M$6:$M$9,Constants!O$6:O$9)) -> 0.11 | I11: =IF('Input Scenarios'!I11<>"", 'Input Scenarios'!I11, _xlfn.XLOOKUP($F11, Constants!$M$6:$M$9,Constants!P$6:P$9)) -> 0.356 | J11: ='Input Scenarios'!J11 -> 0.25 | K11: ='Input Scenarios'!K11 -> 0.25 | L11: ='Input Scenarios'!L11 -> 0.25 | M11: ='Input Scenarios'!M11 -> 0.25 | N11: ='Input Scenarios'!N11 -> 0.25 | O11: ='Input Scenarios'!O11 -> 0.25 | P11: ='Input Scenarios'!P11 -> 0.25 | Q11: ='Input Scenarios'!Q11 -> 0.25 | R11: ='Input Scenarios'!R11 -> TRUE | S11: =IF('Input Scenarios'!S11<>"", 'Input Scenarios'!S11, IF(R11, Constants!$B$38, 0)) -> 0.2 | T11: =IF('Input Scenarios'!T11<>"", 'Input Scenarios'!T11, "") | U11: =IF('Input Scenarios'!U11<>"", 'Input Scenarios'!U11, IF(W11<>"", "", Constants!$B$39)) -> 4 | V11: =IF('Input Scenarios'!V11<>"", 'Input Scenarios'!V11, IF(W11<>"", "", Constants!$B$40)) -> 3.3 | W11: =IF('Input Scenarios'!W11<>"", 'Input Scenarios'!W11, "") | X11: ='Input Scenarios'!X11 -> Medium Friesian | Y11: ='Input Scenarios'!Y11 -> heifersLt1Weaned | Z11: ='Input Scenarios'!Z11 -> 200 | AA11: =IF('Input Scenarios'!AA11<>"", 'Input Scenarios'!AA11, _xlfn.XLOOKUP(Y11,Constants!$J$6:$J$12,Constants!$K$6:$K$12)) -> 281 | AB11: =IF('Input Scenarios'!AB11<>"", 'Input Scenarios'!AB11, INDEX(Constants!$B$2:$H$11, MATCH(X11, Constants!$A$2:$A$11, 0), MATCH(Y11,Constants!$B$1:$H$1, 0))) -> 155 | AC11: =IF('Input Scenarios'!AC11<>"", 'Input Scenarios'!AC11, _xlfn.XLOOKUP(Y11, Constants!$B$13:$H$13, Constants!$B$15:$H$15, "")) -> 0.57 | AD11: =IF('Input Scenarios'!AD11<>"", 'Input Scenarios'!AD11, Constants!$B$45) -> 0.75 | AE11: =IF('Input Scenarios'!AE11<>"", 'Input Scenarios'!AE11, Constants!$B$46) -> 0.2 | AF11: =IF($Y11="milkingCows",($H11*J11)+($I11*N11), 0) -> 0 | AG11: =IF($Y11="milkingCows",($H11*K11)+($I11*O11), 0) -> 0 | AH11: =IF($Y11="milkingCows",($H11*L11)+($I11*P11), 0) -> 0 | AI11: =IF($Y11="milkingCows",($H11*M11)+($I11*Q11), 0) -> 0 | AJ11: =IF($Y11="milkingCows",G11, 1) -> 1 | AK11: =IF(Y11="milkingCows", IF(W11<>"", W11, T11/((U11+V11)*0.01)), 0) -> 0 | AL11: =Constants!$B$44 -> 1.03 | AM11: =Constants!$B$41 -> 3.054 | AN11: =Constants!$B$42 -> 18.4 | AO11: =Constants!$B$43 -> 0.6 | AP11: =0.795*(AD11)-0.0014 -> 0.59485 | AQ11: =(AK11*AL11*AM11)/(AN11*AO11*AP11) -> 0 | AR11: =IF(Y11="milkingCows", Constants!$P$2, Constants!$P$3) -> 1 | AS11: =IFERROR(((((1.185 + (0.00454*AB11) - (0.0000026*(AB11^2)) + (0.315*AC11))^2)*AR11)+AQ11), "") -> 4.0231735 | AT11: =Constants!$B$47 -> 0.08 | AU11: =IFERROR((AS11*(1-AD11)+(0.04*AS11))*(1-AT11), "") -> 1.0733827 | AV11: =AF11*(1-S11) -> 0 | AW11: =AG11 -> 0 | AX11: =AH11 -> 0 | AY11: =AI11+(AF11*S11) -> 0 | AZ11: =AJ11 -> 1 | BA11: =_xlfn.XLOOKUP($A11, Constants!$E$18:$L$18,Constants!$E$19:$L$19) -> 0.76 | BB11: =_xlfn.XLOOKUP($A11, Constants!$E$18:$L$18,Constants!$E$20:$L$20) -> 0.005 | BC11: =_xlfn.XLOOKUP($A11, Constants!$E$18:$L$18,Constants!$E$21:$L$21) -> 0.18 | BD11: =_xlfn.XLOOKUP($A11, Constants!$E$18:$L$18,Constants!$E$22:$L$22) -> 0.02 | BE11: =_xlfn.XLOOKUP($A11, Constants!$E$18:$L$18,Constants!$E$23:$L$23) -> 0.01 | BF11: =Constants!$B$48 -> 0.24 | BG11: =Constants!$B$49 -> 0.6784 | BH11: =IF(ISNUMBER(FIND("PreWeaned",$Y11)), "", $AU11*AV11*BA11*$BF11*$BG11) -> 0 | BI11: =IF(ISNUMBER(FIND("PreWeaned",$Y11)), "", $AU11*AW11*BB11*$BF11*$BG11) -> 0 | BJ11: =IF(ISNUMBER(FIND("PreWeaned",$Y11)), "", $AU11*AX11*BC11*$BF11*$BG11) -> 0 | BK11: =IF(ISNUMBER(FIND("PreWeaned",$Y11)), "", $AU11*AY11*BD11*$BF11*$BG11) -> 0 | BL11: =IF(ISNUMBER(FIND("PreWeaned",$Y11)), "", $AU11*AZ11*BE11*$BF11*$BG11) -> 0.0017476387 | BM11: =IF(ISNUMBER(FIND("PreWeaned",Y11)),_xlfn.XLOOKUP(Y11,Constants!$J$2:$J$3,Constants!$K$2:$K$3), "") | BN11: =Z11*AA11*SUM(BH11:BM11) -> 98.217298
A12: ='Input Scenarios'!A12 -> NSW | B12: ='Input Scenarios'!B12 -> 0 | C12: ='Input Scenarios'!C12 -> Non-irrigated pasture | D12: ='Input Scenarios'!D12 -> wet | E12: ='Input Scenarios'!E12 -> FALSE | F12: ='Input Scenarios'!F12 -> Limited grazing | G12: =IF('Input Scenarios'!G12<>"", 'Input Scenarios'!G12, _xlfn.XLOOKUP($F12, Constants!$M$6:$M$9,Constants!N$6:N$9)) -> 0.534 | H12: =IF('Input Scenarios'!H12<>"", 'Input Scenarios'!H12, _xlfn.XLOOKUP($F12, Constants!$M$6:$M$9,Constants!O$6:O$9)) -> 0.11 | I12: =IF('Input Scenarios'!I12<>"", 'Input Scenarios'!I12, _xlfn.XLOOKUP($F12, Constants!$M$6:$M$9,Constants!P$6:P$9)) -> 0.356 | J12: ='Input Scenarios'!J12 -> 0.25 | K12: ='Input Scenarios'!K12 -> 0.25 | L12: ='Input Scenarios'!L12 -> 0.25 | M12: ='Input Scenarios'!M12 -> 0.25 | N12: ='Input Scenarios'!N12 -> 0.25 | O12: ='Input Scenarios'!O12 -> 0.25 | P12: ='Input Scenarios'!P12 -> 0.25 | Q12: ='Input Scenarios'!Q12 -> 0.25 | R12: ='Input Scenarios'!R12 -> TRUE | S12: =IF('Input Scenarios'!S12<>"", 'Input Scenarios'!S12, IF(R12, Constants!$B$38, 0)) -> 0.2 | T12: =IF('Input Scenarios'!T12<>"", 'Input Scenarios'!T12, "") | U12: =IF('Input Scenarios'!U12<>"", 'Input Scenarios'!U12, IF(W12<>"", "", Constants!$B$39)) -> 4 | V12: =IF('Input Scenarios'!V12<>"", 'Input Scenarios'!V12, IF(W12<>"", "", Constants!$B$40)) -> 3.3 | W12: =IF('Input Scenarios'!W12<>"", 'Input Scenarios'!W12, "") | X12: ='Input Scenarios'!X12 -> Medium Friesian | Y12: ='Input Scenarios'!Y12 -> bullsGt1 | Z12: ='Input Scenarios'!Z12 -> 200 | AA12: =IF('Input Scenarios'!AA12<>"", 'Input Scenarios'!AA12, _xlfn.XLOOKUP(Y12,Constants!$J$6:$J$12,Constants!$K$6:$K$12)) -> 365 | AB12: =IF('Input Scenarios'!AB12<>"", 'Input Scenarios'!AB12, INDEX(Constants!$B$2:$H$11, MATCH(X12, Constants!$A$2:$A$11, 0), MATCH(Y12,Constants!$B$1:$H$1, 0))) -> 600 | AC12: =IF('Input Scenarios'!AC12<>"", 'Input Scenarios'!AC12, _xlfn.XLOOKUP(Y12, Constants!$B$13:$H$13, Constants!$B$15:$H$15, "")) -> 0.1 | AD12: =IF('Input Scenarios'!AD12<>"", 'Input Scenarios'!AD12, Constants!$B$45) -> 0.75 | AE12: =IF('Input Scenarios'!AE12<>"", 'Input Scenarios'!AE12, Constants!$B$46) -> 0.2 | AF12: =IF($Y12="milkingCows",($H12*J12)+($I12*N12), 0) -> 0 | AG12: =IF($Y12="milkingCows",($H12*K12)+($I12*O12), 0) -> 0 | AH12: =IF($Y12="milkingCows",($H12*L12)+($I12*P12), 0) -> 0 | AI12: =IF($Y12="milkingCows",($H12*M12)+($I12*Q12), 0) -> 0 | AJ12: =IF($Y12="milkingCows",G12, 1) -> 1 | AK12: =IF(Y12="milkingCows", IF(W12<>"", W12, T12/((U12+V12)*0.01)), 0) -> 0 | AL12: =Constants!$B$44 -> 1.03 | AM12: =Constants!$B$41 -> 3.054 | AN12: =Constants!$B$42 -> 18.4 | AO12: =Constants!$B$43 -> 0.6 | AP12: =0.795*(AD12)-0.0014 -> 0.59485 | AQ12: =(AK12*AL12*AM12)/(AN12*AO12*AP12) -> 0 | AR12: =IF(Y12="milkingCows", Constants!$P$2, Constants!$P$3) -> 1 | AS12: =IFERROR(((((1.185 + (0.00454*AB12) - (0.0000026*(AB12^2)) + (0.315*AC12))^2)*AR12)+AQ12), "") -> 9.0270202 | AT12: =Constants!$B$47 -> 0.08 | AU12: =IFERROR((AS12*(1-AD12)+(0.04*AS12))*(1-AT12), "") -> 2.408409 | AV12: =AF12*(1-S12) -> 0 | AW12: =AG12 -> 0 | AX12: =AH12 -> 0 | AY12: =AI12+(AF12*S12) -> 0 | AZ12: =AJ12 -> 1 | BA12: =_xlfn.XLOOKUP($A12, Constants!$E$18:$L$18,Constants!$E$19:$L$19) -> 0.76 | BB12: =_xlfn.XLOOKUP($A12, Constants!$E$18:$L$18,Constants!$E$20:$L$20) -> 0.005 | BC12: =_xlfn.XLOOKUP($A12, Constants!$E$18:$L$18,Constants!$E$21:$L$21) -> 0.18 | BD12: =_xlfn.XLOOKUP($A12, Constants!$E$18:$L$18,Constants!$E$22:$L$22) -> 0.02 | BE12: =_xlfn.XLOOKUP($A12, Constants!$E$18:$L$18,Constants!$E$23:$L$23) -> 0.01 | BF12: =Constants!$B$48 -> 0.24 | BG12: =Constants!$B$49 -> 0.6784 | BH12: =IF(ISNUMBER(FIND("PreWeaned",$Y12)), "", $AU12*AV12*BA12*$BF12*$BG12) -> 0 | BI12: =IF(ISNUMBER(FIND("PreWeaned",$Y12)), "", $AU12*AW12*BB12*$BF12*$BG12) -> 0 | BJ12: =IF(ISNUMBER(FIND("PreWeaned",$Y12)), "", $AU12*AX12*BC12*$BF12*$BG12) -> 0 | BK12: =IF(ISNUMBER(FIND("PreWeaned",$Y12)), "", $AU12*AY12*BD12*$BF12*$BG12) -> 0 | BL12: =IF(ISNUMBER(FIND("PreWeaned",$Y12)), "", $AU12*AZ12*BE12*$BF12*$BG12) -> 0.0039212752 | BM12: =IF(ISNUMBER(FIND("PreWeaned",Y12)),_xlfn.XLOOKUP(Y12,Constants!$J$2:$J$3,Constants!$K$2:$K$3), "") | BN12: =Z12*AA12*SUM(BH12:BM12) -> 286.25309
A13: ='Input Scenarios'!A13 -> NSW | B13: ='Input Scenarios'!B13 -> 0 | C13: ='Input Scenarios'!C13 -> Non-irrigated pasture | D13: ='Input Scenarios'!D13 -> wet | E13: ='Input Scenarios'!E13 -> FALSE | F13: ='Input Scenarios'!F13 -> Limited grazing | G13: =IF('Input Scenarios'!G13<>"", 'Input Scenarios'!G13, _xlfn.XLOOKUP($F13, Constants!$M$6:$M$9,Constants!N$6:N$9)) -> 0.534 | H13: =IF('Input Scenarios'!H13<>"", 'Input Scenarios'!H13, _xlfn.XLOOKUP($F13, Constants!$M$6:$M$9,Constants!O$6:O$9)) -> 0.11 | I13: =IF('Input Scenarios'!I13<>"", 'Input Scenarios'!I13, _xlfn.XLOOKUP($F13, Constants!$M$6:$M$9,Constants!P$6:P$9)) -> 0.356 | J13: ='Input Scenarios'!J13 -> 0.25 | K13: ='Input Scenarios'!K13 -> 0.25 | L13: ='Input Scenarios'!L13 -> 0.25 | M13: ='Input Scenarios'!M13 -> 0.25 | N13: ='Input Scenarios'!N13 -> 0.25 | O13: ='Input Scenarios'!O13 -> 0.25 | P13: ='Input Scenarios'!P13 -> 0.25 | Q13: ='Input Scenarios'!Q13 -> 0.25 | R13: ='Input Scenarios'!R13 -> TRUE | S13: =IF('Input Scenarios'!S13<>"", 'Input Scenarios'!S13, IF(R13, Constants!$B$38, 0)) -> 0.2 | T13: =IF('Input Scenarios'!T13<>"", 'Input Scenarios'!T13, "") | U13: =IF('Input Scenarios'!U13<>"", 'Input Scenarios'!U13, IF(W13<>"", "", Constants!$B$39)) -> 4 | V13: =IF('Input Scenarios'!V13<>"", 'Input Scenarios'!V13, IF(W13<>"", "", Constants!$B$40)) -> 3.3 | W13: =IF('Input Scenarios'!W13<>"", 'Input Scenarios'!W13, "") | X13: ='Input Scenarios'!X13 -> Medium Friesian | Y13: ='Input Scenarios'!Y13 -> bullsLt1PreWeaned | Z13: ='Input Scenarios'!Z13 -> 200 | AA13: =IF('Input Scenarios'!AA13<>"", 'Input Scenarios'!AA13, _xlfn.XLOOKUP(Y13,Constants!$J$6:$J$12,Constants!$K$6:$K$12)) -> 84 | AB13: =IF('Input Scenarios'!AB13<>"", 'Input Scenarios'!AB13, INDEX(Constants!$B$2:$H$11, MATCH(X13, Constants!$A$2:$A$11, 0), MATCH(Y13,Constants!$B$1:$H$1, 0))) -> 225 | AC13: =IF('Input Scenarios'!AC13<>"", 'Input Scenarios'!AC13, _xlfn.XLOOKUP(Y13, Constants!$B$13:$H$13, Constants!$B$15:$H$15, "")) | AD13: =IF('Input Scenarios'!AD13<>"", 'Input Scenarios'!AD13, Constants!$B$45) -> 0.75 | AE13: =IF('Input Scenarios'!AE13<>"", 'Input Scenarios'!AE13, Constants!$B$46) -> 0.2 | AF13: =IF($Y13="milkingCows",($H13*J13)+($I13*N13), 0) -> 0 | AG13: =IF($Y13="milkingCows",($H13*K13)+($I13*O13), 0) -> 0 | AH13: =IF($Y13="milkingCows",($H13*L13)+($I13*P13), 0) -> 0 | AI13: =IF($Y13="milkingCows",($H13*M13)+($I13*Q13), 0) -> 0 | AJ13: =IF($Y13="milkingCows",G13, 1) -> 1 | AK13: =IF(Y13="milkingCows", IF(W13<>"", W13, T13/((U13+V13)*0.01)), 0) -> 0 | AL13: =Constants!$B$44 -> 1.03 | AM13: =Constants!$B$41 -> 3.054 | AN13: =Constants!$B$42 -> 18.4 | AO13: =Constants!$B$43 -> 0.6 | AP13: =0.795*(AD13)-0.0014 -> 0.59485 | AQ13: =(AK13*AL13*AM13)/(AN13*AO13*AP13) -> 0 | AR13: =IF(Y13="milkingCows", Constants!$P$2, Constants!$P$3) -> 1 | AS13: =IFERROR(((((1.185 + (0.00454*AB13) - (0.0000026*(AB13^2)) + (0.315*AC13))^2)*AR13)+AQ13), "") | AT13: =Constants!$B$47 -> 0.08 | AU13: =IFERROR((AS13*(1-AD13)+(0.04*AS13))*(1-AT13), "") | AV13: =AF13*(1-S13) -> 0 | AW13: =AG13 -> 0 | AX13: =AH13 -> 0 | AY13: =AI13+(AF13*S13) -> 0 | AZ13: =AJ13 -> 1 | BA13: =_xlfn.XLOOKUP($A13, Constants!$E$18:$L$18,Constants!$E$19:$L$19) -> 0.76 | BB13: =_xlfn.XLOOKUP($A13, Constants!$E$18:$L$18,Constants!$E$20:$L$20) -> 0.005 | BC13: =_xlfn.XLOOKUP($A13, Constants!$E$18:$L$18,Constants!$E$21:$L$21) -> 0.18 | BD13: =_xlfn.XLOOKUP($A13, Constants!$E$18:$L$18,Constants!$E$22:$L$22) -> 0.02 | BE13: =_xlfn.XLOOKUP($A13, Constants!$E$18:$L$18,Constants!$E$23:$L$23) -> 0.01 | BF13: =Constants!$B$48 -> 0.24 | BG13: =Constants!$B$49 -> 0.6784 | BH13: =IF(ISNUMBER(FIND("PreWeaned",$Y13)), "", $AU13*AV13*BA13*$BF13*$BG13) | BI13: =IF(ISNUMBER(FIND("PreWeaned",$Y13)), "", $AU13*AW13*BB13*$BF13*$BG13) | BJ13: =IF(ISNUMBER(FIND("PreWeaned",$Y13)), "", $AU13*AX13*BC13*$BF13*$BG13) | BK13: =IF(ISNUMBER(FIND("PreWeaned",$Y13)), "", $AU13*AY13*BD13*$BF13*$BG13) | BL13: =IF(ISNUMBER(FIND("PreWeaned",$Y13)), "", $AU13*AZ13*BE13*$BF13*$BG13) | BM13: =IF(ISNUMBER(FIND("PreWeaned",Y13)),_xlfn.XLOOKUP(Y13,Constants!$J$2:$J$3,Constants!$K$2:$K$3), "") -> 0.0204 | BN13: =Z13*AA13*SUM(BH13:BM13) -> 342.72
A14: ='Input Scenarios'!A14 -> NSW | B14: ='Input Scenarios'!B14 -> 0 | C14: ='Input Scenarios'!C14 -> Non-irrigated pasture | D14: ='Input Scenarios'!D14 -> wet | E14: ='Input Scenarios'!E14 -> FALSE | F14: ='Input Scenarios'!F14 -> Limited grazing | G14: =IF('Input Scenarios'!G14<>"", 'Input Scenarios'!G14, _xlfn.XLOOKUP($F14, Constants!$M$6:$M$9,Constants!N$6:N$9)) -> 0.534 | H14: =IF('Input Scenarios'!H14<>"", 'Input Scenarios'!H14, _xlfn.XLOOKUP($F14, Constants!$M$6:$M$9,Constants!O$6:O$9)) -> 0.11 | I14: =IF('Input Scenarios'!I14<>"", 'Input Scenarios'!I14, _xlfn.XLOOKUP($F14, Constants!$M$6:$M$9,Constants!P$6:P$9)) -> 0.356 | J14: ='Input Scenarios'!J14 -> 0.25 | K14: ='Input Scenarios'!K14 -> 0.25 | L14: ='Input Scenarios'!L14 -> 0.25 | M14: ='Input Scenarios'!M14 -> 0.25 | N14: ='Input Scenarios'!N14 -> 0.25 | O14: ='Input Scenarios'!O14 -> 0.25 | P14: ='Input Scenarios'!P14 -> 0.25 | Q14: ='Input Scenarios'!Q14 -> 0.25 | R14: ='Input Scenarios'!R14 -> TRUE | S14: =IF('Input Scenarios'!S14<>"", 'Input Scenarios'!S14, IF(R14, Constants!$B$38, 0)) -> 0.2 | T14: =IF('Input Scenarios'!T14<>"", 'Input Scenarios'!T14, "") | U14: =IF('Input Scenarios'!U14<>"", 'Input Scenarios'!U14, IF(W14<>"", "", Constants!$B$39)) -> 4 | V14: =IF('Input Scenarios'!V14<>"", 'Input Scenarios'!V14, IF(W14<>"", "", Constants!$B$40)) -> 3.3 | W14: =IF('Input Scenarios'!W14<>"", 'Input Scenarios'!W14, "") | X14: ='Input Scenarios'!X14 -> Medium Friesian | Y14: ='Input Scenarios'!Y14 -> bullsLt1Weaned | Z14: ='Input Scenarios'!Z14 -> 200 | AA14: =IF('Input Scenarios'!AA14<>"", 'Input Scenarios'!AA14, _xlfn.XLOOKUP(Y14,Constants!$J$6:$J$12,Constants!$K$6:$K$12)) -> 281 | AB14: =IF('Input Scenarios'!AB14<>"", 'Input Scenarios'!AB14, INDEX(Constants!$B$2:$H$11, MATCH(X14, Constants!$A$2:$A$11, 0), MATCH(Y14,Constants!$B$1:$H$1, 0))) -> 225 | AC14: =IF('Input Scenarios'!AC14<>"", 'Input Scenarios'!AC14, _xlfn.XLOOKUP(Y14, Constants!$B$13:$H$13, Constants!$B$15:$H$15, "")) -> 0.8 | AD14: =IF('Input Scenarios'!AD14<>"", 'Input Scenarios'!AD14, Constants!$B$45) -> 0.75 | AE14: =IF('Input Scenarios'!AE14<>"", 'Input Scenarios'!AE14, Constants!$B$46) -> 0.2 | AF14: =IF($Y14="milkingCows",($H14*J14)+($I14*N14), 0) -> 0 | AG14: =IF($Y14="milkingCows",($H14*K14)+($I14*O14), 0) -> 0 | AH14: =IF($Y14="milkingCows",($H14*L14)+($I14*P14), 0) -> 0 | AI14: =IF($Y14="milkingCows",($H14*M14)+($I14*Q14), 0) -> 0 | AJ14: =IF($Y14="milkingCows",G14, 1) -> 1 | AK14: =IF(Y14="milkingCows", IF(W14<>"", W14, T14/((U14+V14)*0.01)), 0) -> 0 | AL14: =Constants!$B$44 -> 1.03 | AM14: =Constants!$B$41 -> 3.054 | AN14: =Constants!$B$42 -> 18.4 | AO14: =Constants!$B$43 -> 0.6 | AP14: =0.795*(AD14)-0.0014 -> 0.59485 | AQ14: =(AK14*AL14*AM14)/(AN14*AO14*AP14) -> 0 | AR14: =IF(Y14="milkingCows", Constants!$P$2, Constants!$P$3) -> 1 | AS14: =IFERROR(((((1.185 + (0.00454*AB14) - (0.0000026*(AB14^2)) + (0.315*AC14))^2)*AR14)+AQ14), "") -> 5.4143473 | AT14: =Constants!$B$47 -> 0.08 | AU14: =IFERROR((AS14*(1-AD14)+(0.04*AS14))*(1-AT14), "") -> 1.4445479 | AV14: =AF14*(1-S14) -> 0 | AW14: =AG14 -> 0 | AX14: =AH14 -> 0 | AY14: =AI14+(AF14*S14) -> 0 | AZ14: =AJ14 -> 1 | BA14: =_xlfn.XLOOKUP($A14, Constants!$E$18:$L$18,Constants!$E$19:$L$19) -> 0.76 | BB14: =_xlfn.XLOOKUP($A14, Constants!$E$18:$L$18,Constants!$E$20:$L$20) -> 0.005 | BC14: =_xlfn.XLOOKUP($A14, Constants!$E$18:$L$18,Constants!$E$21:$L$21) -> 0.18 | BD14: =_xlfn.XLOOKUP($A14, Constants!$E$18:$L$18,Constants!$E$22:$L$22) -> 0.02 | BE14: =_xlfn.XLOOKUP($A14, Constants!$E$18:$L$18,Constants!$E$23:$L$23) -> 0.01 | BF14: =Constants!$B$48 -> 0.24 | BG14: =Constants!$B$49 -> 0.6784 | BH14: =IF(ISNUMBER(FIND("PreWeaned",$Y14)), "", $AU14*AV14*BA14*$BF14*$BG14) -> 0 | BI14: =IF(ISNUMBER(FIND("PreWeaned",$Y14)), "", $AU14*AW14*BB14*$BF14*$BG14) -> 0 | BJ14: =IF(ISNUMBER(FIND("PreWeaned",$Y14)), "", $AU14*AX14*BC14*$BF14*$BG14) -> 0 | BK14: =IF(ISNUMBER(FIND("PreWeaned",$Y14)), "", $AU14*AY14*BD14*$BF14*$BG14) -> 0 | BL14: =IF(ISNUMBER(FIND("PreWeaned",$Y14)), "", $AU14*AZ14*BE14*$BF14*$BG14) -> 0.002351955 | BM14: =IF(ISNUMBER(FIND("PreWeaned",Y14)),_xlfn.XLOOKUP(Y14,Constants!$J$2:$J$3,Constants!$K$2:$K$3), "") | BN14: =Z14*AA14*SUM(BH14:BM14) -> 132.17987
A15: ='Input Scenarios'!A15 -> QLD | B15: ='Input Scenarios'!B15 -> 0 | C15: ='Input Scenarios'!C15 -> Non-irrigated crop (high rainfall) | D15: ='Input Scenarios'!D15 -> wet | E15: ='Input Scenarios'!E15 -> TRUE | F15: ='Input Scenarios'!F15 -> Limited feedpad | G15: =IF('Input Scenarios'!G15<>"", 'Input Scenarios'!G15, _xlfn.XLOOKUP($F15, Constants!$M$6:$M$9,Constants!N$6:N$9)) -> 0.79 | H15: =IF('Input Scenarios'!H15<>"", 'Input Scenarios'!H15, _xlfn.XLOOKUP($F15, Constants!$M$6:$M$9,Constants!O$6:O$9)) -> 0.11 | I15: =IF('Input Scenarios'!I15<>"", 'Input Scenarios'!I15, _xlfn.XLOOKUP($F15, Constants!$M$6:$M$9,Constants!P$6:P$9)) -> 0.1 | J15: ='Input Scenarios'!J15 -> 0 | K15: ='Input Scenarios'!K15 -> 0 | L15: ='Input Scenarios'!L15 -> 1 | M15: ='Input Scenarios'!M15 -> 0 | N15: ='Input Scenarios'!N15 -> 1 | O15: ='Input Scenarios'!O15 -> 0 | P15: ='Input Scenarios'!P15 -> 0 | Q15: ='Input Scenarios'!Q15 -> 0 | R15: ='Input Scenarios'!R15 -> TRUE | S15: =IF('Input Scenarios'!S15<>"", 'Input Scenarios'!S15, IF(R15, Constants!$B$38, 0)) -> 0.2 | T15: =IF('Input Scenarios'!T15<>"", 'Input Scenarios'!T15, "") -> 3 | U15: =IF('Input Scenarios'!U15<>"", 'Input Scenarios'!U15, IF(W15<>"", "", Constants!$B$39)) -> 4 | V15: =IF('Input Scenarios'!V15<>"", 'Input Scenarios'!V15, IF(W15<>"", "", Constants!$B$40)) -> 3.3 | W15: =IF('Input Scenarios'!W15<>"", 'Input Scenarios'!W15, "") | X15: ='Input Scenarios'!X15 -> Large Friesian | Y15: ='Input Scenarios'!Y15 -> milkingCows | Z15: ='Input Scenarios'!Z15 -> 200 | AA15: =IF('Input Scenarios'!AA15<>"", 'Input Scenarios'!AA15, _xlfn.XLOOKUP(Y15,Constants!$J$6:$J$12,Constants!$K$6:$K$12)) -> 365 | AB15: =IF('Input Scenarios'!AB15<>"", 'Input Scenarios'!AB15, INDEX(Constants!$B$2:$H$11, MATCH(X15, Constants!$A$2:$A$11, 0), MATCH(Y15,Constants!$B$1:$H$1, 0))) -> 600 | AC15: =IF('Input Scenarios'!AC15<>"", 'Input Scenarios'!AC15, _xlfn.XLOOKUP(Y15, Constants!$B$13:$H$13, Constants!$B$15:$H$15, "")) -> 0.016 | AD15: =IF('Input Scenarios'!AD15<>"", 'Input Scenarios'!AD15, Constants!$B$45) -> 0.75 | AE15: =IF('Input Scenarios'!AE15<>"", 'Input Scenarios'!AE15, Constants!$B$46) -> 0.2 | AF15: =IF($Y15="milkingCows",($H15*J15)+($I15*N15), 0) -> 0.1 | AG15: =IF($Y15="milkingCows",($H15*K15)+($I15*O15), 0) -> 0 | AH15: =IF($Y15="milkingCows",($H15*L15)+($I15*P15), 0) -> 0.11 | AI15: =IF($Y15="milkingCows",($H15*M15)+($I15*Q15), 0) -> 0 | AJ15: =IF($Y15="milkingCows",G15, 1) -> 0.79 | AK15: =IF(Y15="milkingCows", IF(W15<>"", W15, T15/((U15+V15)*0.01)), 0) -> 41.09589 | AL15: =Constants!$B$44 -> 1.03 | AM15: =Constants!$B$41 -> 3.054 | AN15: =Constants!$B$42 -> 18.4 | AO15: =Constants!$B$43 -> 0.6 | AP15: =0.795*(AD15)-0.0014 -> 0.59485 | AQ15: =(AK15*AL15*AM15)/(AN15*AO15*AP15) -> 19.684669 | AR15: =IF(Y15="milkingCows", Constants!$P$2, Constants!$P$3) -> 1.1 | AS15: =IFERROR(((((1.185 + (0.00454*AB15) - (0.0000026*(AB15^2)) + (0.315*AC15))^2)*AR15)+AQ15), "") -> 29.440263 | AT15: =Constants!$B$47 -> 0.08 | AU15: =IFERROR((AS15*(1-AD15)+(0.04*AS15))*(1-AT15), "") -> 7.8546622 | AV15: =AF15*(1-S15) -> 0.08 | AW15: =AG15 -> 0 | AX15: =AH15 -> 0.11 | AY15: =AI15+(AF15*S15) -> 0.02 | AZ15: =AJ15 -> 0.79 | BA15: =_xlfn.XLOOKUP($A15, Constants!$E$18:$L$18,Constants!$E$19:$L$19) -> 0.78 | BB15: =_xlfn.XLOOKUP($A15, Constants!$E$18:$L$18,Constants!$E$20:$L$20) -> 0.005 | BC15: =_xlfn.XLOOKUP($A15, Constants!$E$18:$L$18,Constants!$E$21:$L$21) -> 0.24 | BD15: =_xlfn.XLOOKUP($A15, Constants!$E$18:$L$18,Constants!$E$22:$L$22) -> 0.02 | BE15: =_xlfn.XLOOKUP($A15, Constants!$E$18:$L$18,Constants!$E$23:$L$23) -> 0.01 | BF15: =Constants!$B$48 -> 0.24 | BG15: =Constants!$B$49 -> 0.6784 | BH15: =IF(ISNUMBER(FIND("PreWeaned",$Y15)), "", $AU15*AV15*BA15*$BF15*$BG15) -> 0.079801157 | BI15: =IF(ISNUMBER(FIND("PreWeaned",$Y15)), "", $AU15*AW15*BB15*$BF15*$BG15) -> 0 | BJ15: =IF(ISNUMBER(FIND("PreWeaned",$Y15)), "", $AU15*AX15*BC15*$BF15*$BG15) -> 0.033762028 | BK15: =IF(ISNUMBER(FIND("PreWeaned",$Y15)), "", $AU15*AY15*BD15*$BF15*$BG15) -> 0.00051154588 | BL15: =IF(ISNUMBER(FIND("PreWeaned",$Y15)), "", $AU15*AZ15*BE15*$BF15*$BG15) -> 0.010103031 | BM15: =IF(ISNUMBER(FIND("PreWeaned",Y15)),_xlfn.XLOOKUP(Y15,Constants!$J$2:$J$3,Constants!$K$2:$K$3), "") | BN15: =Z15*AA15*SUM(BH15:BM15) -> 9064.9766 | BO15: =SUM(BN15:BN21)/1000 -> 10.475977
A16: ='Input Scenarios'!A16 -> QLD | B16: ='Input Scenarios'!B16 -> 0 | C16: ='Input Scenarios'!C16 -> Non-irrigated crop (high rainfall) | D16: ='Input Scenarios'!D16 -> wet | E16: ='Input Scenarios'!E16 -> TRUE | F16: ='Input Scenarios'!F16 -> Limited feedpad | G16: =IF('Input Scenarios'!G16<>"", 'Input Scenarios'!G16, _xlfn.XLOOKUP($F16, Constants!$M$6:$M$9,Constants!N$6:N$9)) -> 0.79 | H16: =IF('Input Scenarios'!H16<>"", 'Input Scenarios'!H16, _xlfn.XLOOKUP($F16, Constants!$M$6:$M$9,Constants!O$6:O$9)) -> 0.11 | I16: =IF('Input Scenarios'!I16<>"", 'Input Scenarios'!I16, _xlfn.XLOOKUP($F16, Constants!$M$6:$M$9,Constants!P$6:P$9)) -> 0.1 | J16: ='Input Scenarios'!J16 -> 0 | K16: ='Input Scenarios'!K16 -> 0 | L16: ='Input Scenarios'!L16 -> 1 | M16: ='Input Scenarios'!M16 -> 0 | N16: ='Input Scenarios'!N16 -> 1 | O16: ='Input Scenarios'!O16 -> 0 | P16: ='Input Scenarios'!P16 -> 0 | Q16: ='Input Scenarios'!Q16 -> 0 | R16: ='Input Scenarios'!R16 -> TRUE | S16: =IF('Input Scenarios'!S16<>"", 'Input Scenarios'!S16, IF(R16, Constants!$B$38, 0)) -> 0.2 | T16: =IF('Input Scenarios'!T16<>"", 'Input Scenarios'!T16, "") | U16: =IF('Input Scenarios'!U16<>"", 'Input Scenarios'!U16, IF(W16<>"", "", Constants!$B$39)) -> 4 | V16: =IF('Input Scenarios'!V16<>"", 'Input Scenarios'!V16, IF(W16<>"", "", Constants!$B$40)) -> 3.3 | W16: =IF('Input Scenarios'!W16<>"", 'Input Scenarios'!W16, "") | X16: ='Input Scenarios'!X16 -> Large Friesian | Y16: ='Input Scenarios'!Y16 -> heifersGt1 | Z16: ='Input Scenarios'!Z16 -> 200 | AA16: =IF('Input Scenarios'!AA16<>"", 'Input Scenarios'!AA16, _xlfn.XLOOKUP(Y16,Constants!$J$6:$J$12,Constants!$K$6:$K$12)) -> 365 | AB16: =IF('Input Scenarios'!AB16<>"", 'Input Scenarios'!AB16, INDEX(Constants!$B$2:$H$11, MATCH(X16, Constants!$A$2:$A$11, 0), MATCH(Y16,Constants!$B$1:$H$1, 0))) -> 415 | AC16: =IF('Input Scenarios'!AC16<>"", 'Input Scenarios'!AC16, _xlfn.XLOOKUP(Y16, Constants!$B$13:$H$13, Constants!$B$15:$H$15, "")) -> 0.6 | AD16: =IF('Input Scenarios'!AD16<>"", 'Input Scenarios'!AD16, Constants!$B$45) -> 0.75 | AE16: =IF('Input Scenarios'!AE16<>"", 'Input Scenarios'!AE16, Constants!$B$46) -> 0.2 | AF16: =IF($Y16="milkingCows",($H16*J16)+($I16*N16), 0) -> 0 | AG16: =IF($Y16="milkingCows",($H16*K16)+($I16*O16), 0) -> 0 | AH16: =IF($Y16="milkingCows",($H16*L16)+($I16*P16), 0) -> 0 | AI16: =IF($Y16="milkingCows",($H16*M16)+($I16*Q16), 0) -> 0 | AJ16: =IF($Y16="milkingCows",G16, 1) -> 1 | AK16: =IF(Y16="milkingCows", IF(W16<>"", W16, T16/((U16+V16)*0.01)), 0) -> 0 | AL16: =Constants!$B$44 -> 1.03 | AM16: =Constants!$B$41 -> 3.054 | AN16: =Constants!$B$42 -> 18.4 | AO16: =Constants!$B$43 -> 0.6 | AP16: =0.795*(AD16)-0.0014 -> 0.59485 | AQ16: =(AK16*AL16*AM16)/(AN16*AO16*AP16) -> 0 | AR16: =IF(Y16="milkingCows", Constants!$P$2, Constants!$P$3) -> 1 | AS16: =IFERROR(((((1.185 + (0.00454*AB16) - (0.0000026*(AB16^2)) + (0.315*AC16))^2)*AR16)+AQ16), "") -> 7.8978704 | AT16: =Constants!$B$47 -> 0.08 | AU16: =IFERROR((AS16*(1-AD16)+(0.04*AS16))*(1-AT16), "") -> 2.1071518 | AV16: =AF16*(1-S16) -> 0 | AW16: =AG16 -> 0 | AX16: =AH16 -> 0 | AY16: =AI16+(AF16*S16) -> 0 | AZ16: =AJ16 -> 1 | BA16: =_xlfn.XLOOKUP($A16, Constants!$E$18:$L$18,Constants!$E$19:$L$19) -> 0.78 | BB16: =_xlfn.XLOOKUP($A16, Constants!$E$18:$L$18,Constants!$E$20:$L$20) -> 0.005 | BC16: =_xlfn.XLOOKUP($A16, Constants!$E$18:$L$18,Constants!$E$21:$L$21) -> 0.24 | BD16: =_xlfn.XLOOKUP($A16, Constants!$E$18:$L$18,Constants!$E$22:$L$22) -> 0.02 | BE16: =_xlfn.XLOOKUP($A16, Constants!$E$18:$L$18,Constants!$E$23:$L$23) -> 0.01 | BF16: =Constants!$B$48 -> 0.24 | BG16: =Constants!$B$49 -> 0.6784 | BH16: =IF(ISNUMBER(FIND("PreWeaned",$Y16)), "", $AU16*AV16*BA16*$BF16*$BG16) -> 0 | BI16: =IF(ISNUMBER(FIND("PreWeaned",$Y16)), "", $AU16*AW16*BB16*$BF16*$BG16) -> 0 | BJ16: =IF(ISNUMBER(FIND("PreWeaned",$Y16)), "", $AU16*AX16*BC16*$BF16*$BG16) -> 0 | BK16: =IF(ISNUMBER(FIND("PreWeaned",$Y16)), "", $AU16*AY16*BD16*$BF16*$BG16) -> 0 | BL16: =IF(ISNUMBER(FIND("PreWeaned",$Y16)), "", $AU16*AZ16*BE16*$BF16*$BG16) -> 0.0034307803 | BM16: =IF(ISNUMBER(FIND("PreWeaned",Y16)),_xlfn.XLOOKUP(Y16,Constants!$J$2:$J$3,Constants!$K$2:$K$3), "") | BN16: =Z16*AA16*SUM(BH16:BM16) -> 250.44696
A17: ='Input Scenarios'!A17 -> QLD | B17: ='Input Scenarios'!B17 -> 0 | C17: ='Input Scenarios'!C17 -> Non-irrigated crop (high rainfall) | D17: ='Input Scenarios'!D17 -> wet | E17: ='Input Scenarios'!E17 -> TRUE | F17: ='Input Scenarios'!F17 -> Limited feedpad | G17: =IF('Input Scenarios'!G17<>"", 'Input Scenarios'!G17, _xlfn.XLOOKUP($F17, Constants!$M$6:$M$9,Constants!N$6:N$9)) -> 0.79 | H17: =IF('Input Scenarios'!H17<>"", 'Input Scenarios'!H17, _xlfn.XLOOKUP($F17, Constants!$M$6:$M$9,Constants!O$6:O$9)) -> 0.11 | I17: =IF('Input Scenarios'!I17<>"", 'Input Scenarios'!I17, _xlfn.XLOOKUP($F17, Constants!$M$6:$M$9,Constants!P$6:P$9)) -> 0.1 | J17: ='Input Scenarios'!J17 -> 0 | K17: ='Input Scenarios'!K17 -> 0 | L17: ='Input Scenarios'!L17 -> 1 | M17: ='Input Scenarios'!M17 -> 0 | N17: ='Input Scenarios'!N17 -> 1 | O17: ='Input Scenarios'!O17 -> 0 | P17: ='Input Scenarios'!P17 -> 0 | Q17: ='Input Scenarios'!Q17 -> 0 | R17: ='Input Scenarios'!R17 -> TRUE | S17: =IF('Input Scenarios'!S17<>"", 'Input Scenarios'!S17, IF(R17, Constants!$B$38, 0)) -> 0.2 | T17: =IF('Input Scenarios'!T17<>"", 'Input Scenarios'!T17, "") | U17: =IF('Input Scenarios'!U17<>"", 'Input Scenarios'!U17, IF(W17<>"", "", Constants!$B$39)) -> 4 | V17: =IF('Input Scenarios'!V17<>"", 'Input Scenarios'!V17, IF(W17<>"", "", Constants!$B$40)) -> 3.3 | W17: =IF('Input Scenarios'!W17<>"", 'Input Scenarios'!W17, "") | X17: ='Input Scenarios'!X17 -> Large Friesian | Y17: ='Input Scenarios'!Y17 -> heifersLt1PreWeaned | Z17: ='Input Scenarios'!Z17 -> 200 | AA17: =IF('Input Scenarios'!AA17<>"", 'Input Scenarios'!AA17, _xlfn.XLOOKUP(Y17,Constants!$J$6:$J$12,Constants!$K$6:$K$12)) -> 84 | AB17: =IF('Input Scenarios'!AB17<>"", 'Input Scenarios'!AB17, INDEX(Constants!$B$2:$H$11, MATCH(X17, Constants!$A$2:$A$11, 0), MATCH(Y17,Constants!$B$1:$H$1, 0))) -> 170 | AC17: =IF('Input Scenarios'!AC17<>"", 'Input Scenarios'!AC17, _xlfn.XLOOKUP(Y17, Constants!$B$13:$H$13, Constants!$B$15:$H$15, "")) | AD17: =IF('Input Scenarios'!AD17<>"", 'Input Scenarios'!AD17, Constants!$B$45) -> 0.75 | AE17: =IF('Input Scenarios'!AE17<>"", 'Input Scenarios'!AE17, Constants!$B$46) -> 0.2 | AF17: =IF($Y17="milkingCows",($H17*J17)+($I17*N17), 0) -> 0 | AG17: =IF($Y17="milkingCows",($H17*K17)+($I17*O17), 0) -> 0 | AH17: =IF($Y17="milkingCows",($H17*L17)+($I17*P17), 0) -> 0 | AI17: =IF($Y17="milkingCows",($H17*M17)+($I17*Q17), 0) -> 0 | AJ17: =IF($Y17="milkingCows",G17, 1) -> 1 | AK17: =IF(Y17="milkingCows", IF(W17<>"", W17, T17/((U17+V17)*0.01)), 0) -> 0 | AL17: =Constants!$B$44 -> 1.03 | AM17: =Constants!$B$41 -> 3.054 | AN17: =Constants!$B$42 -> 18.4 | AO17: =Constants!$B$43 -> 0.6 | AP17: =0.795*(AD17)-0.0014 -> 0.59485 | AQ17: =(AK17*AL17*AM17)/(AN17*AO17*AP17) -> 0 | AR17: =IF(Y17="milkingCows", Constants!$P$2, Constants!$P$3) -> 1 | AS17: =IFERROR(((((1.185 + (0.00454*AB17) - (0.0000026*(AB17^2)) + (0.315*AC17))^2)*AR17)+AQ17), "") | AT17: =Constants!$B$47 -> 0.08 | AU17: =IFERROR((AS17*(1-AD17)+(0.04*AS17))*(1-AT17), "") | AV17: =AF17*(1-S17) -> 0 | AW17: =AG17 -> 0 | AX17: =AH17 -> 0 | AY17: =AI17+(AF17*S17) -> 0 | AZ17: =AJ17 -> 1 | BA17: =_xlfn.XLOOKUP($A17, Constants!$E$18:$L$18,Constants!$E$19:$L$19) -> 0.78 | BB17: =_xlfn.XLOOKUP($A17, Constants!$E$18:$L$18,Constants!$E$20:$L$20) -> 0.005 | BC17: =_xlfn.XLOOKUP($A17, Constants!$E$18:$L$18,Constants!$E$21:$L$21) -> 0.24 | BD17: =_xlfn.XLOOKUP($A17, Constants!$E$18:$L$18,Constants!$E$22:$L$22) -> 0.02 | BE17: =_xlfn.XLOOKUP($A17, Constants!$E$18:$L$18,Constants!$E$23:$L$23) -> 0.01 | BF17: =Constants!$B$48 -> 0.24 | BG17: =Constants!$B$49 -> 0.6784 | BH17: =IF(ISNUMBER(FIND("PreWeaned",$Y17)), "", $AU17*AV17*BA17*$BF17*$BG17) | BI17: =IF(ISNUMBER(FIND("PreWeaned",$Y17)), "", $AU17*AW17*BB17*$BF17*$BG17) | BJ17: =IF(ISNUMBER(FIND("PreWeaned",$Y17)), "", $AU17*AX17*BC17*$BF17*$BG17) | BK17: =IF(ISNUMBER(FIND("PreWeaned",$Y17)), "", $AU17*AY17*BD17*$BF17*$BG17) | BL17: =IF(ISNUMBER(FIND("PreWeaned",$Y17)), "", $AU17*AZ17*BE17*$BF17*$BG17) | BM17: =IF(ISNUMBER(FIND("PreWeaned",Y17)),_xlfn.XLOOKUP(Y17,Constants!$J$2:$J$3,Constants!$K$2:$K$3), "") -> 0.0176 | BN17: =Z17*AA17*SUM(BH17:BM17) -> 295.68
