Workbook

Sheet Constants
A1: Table A.1.6.1: Swine – Intake and manure characteristics derived from PigBal (2020-2024)
A2: Class (j) | B2: Feed Intake (Ij) | C2: Volatile Solids (VSj) | D2: Nitrogen in Waste (NWj)
A3: boars | B3: 2.3 | C3: 0.4 | D3: 0.046
A4: sows | B4: 2.62 | C4: 0.46 | D4: 0.049
A5: gilts | B5: 2.5 | C5: 0.55 | D5: 0.046
A6: others | B6: 1.71 | C6: 0.39 | D6: 0.031
G7: NOTE: There are no ACT values, the NSW values are being used for ACT
C8: Table A.1.6.2: Swine – Fraction of N volatilised by MMS | D8: Table A.1.6.3: Swine – Nitrous oxide EFs by MMS | E8: 4.5.2.3 | F8: Table A.1.6.4: Swine – MCFs (by State)
A9: MMS (m) | B9: m | C9: FracGASMmT | D9: EFm | E9: VSLm | F9: NSW | G9: ACT | H9: QLD | I9: NT | J9: SA | K9: TAS | L9: VIC | M9: WA
A10: anaerobicLagoon | B10: 1 | C10: 0.55 | D10: 0 | E10: 0 | F10: 0.75 | G10: =F10 -> 0.75 | H10: 0.78 | I10: =H10 -> 0.78 | J10: 0.75 | K10: 0.7 | L10: 0.74 | M10: 0.76
A11: solidStorage | B11: 4 | C11: 0.2 | D11: 0.005 | E11: 0 | F11: 0.02 | G11: =F11 -> 0.02 | H11: 0.02 | I11: =H11 -> 0.02 | J11: 0.02 | K11: 0.02 | L11: 0.02 | M11: 0.02
A12: outdoorAndFreeRange | B12: 5 | C12: 0.3 | D12: 0.02 | E12: 0 | F12: 0.01 | G12: =F12 -> 0.01 | H12: 0.03 | I12: =H12 -> 0.03 | J12: 0.01 | K12: 0.01 | L12: 0.01 | M12: 0.01
A13: digester | B13: 7 | C13: 0 | D13: 0 | E13: 0.75 | F13: 0.1 | G13: =F13 -> 0.1 | H13: 0.1 | I13: =H13 -> 0.1 | J13: 0.1 | K13: 0.1 | L13: 0.1 | M13: 0.1
A14: deepLitter | B14: 8 | C14: 0.125 | D14: 0.01 | E14: 0.05 | F14: 0.04 | G14: =F14 -> 0.04 | H14: 0.04 | I14: =H14 -> 0.04 | J14: 0.04 | K14: 0.04 | L14: 0.04 | M14: 0.04
A15: pitStorage | B15: 9 | C15: 0.25 | D15: 0.002 | E15: 0 | F15: 0.03 | G15: =F15 -> 0.03 | H15: 0.03 | I15: =H15 -> 0.03 | J15: 0.03 | K15: 0.03 | L15: 0.03 | M15: 0.03
A16: directApplication | B16: 13 | E16: 0 | F16: 0 | G16: =F16 -> 0 | H16: 0 | I16: =H16 -> 0 | J16: 0 | K16: 0 | L16: 0 | M16: 0
A18: Fixed Constants | D18: Production System | E18: EFN2O | G18: MCFim BY MAT | H18: m=1 | I18: m=4 | J18: m=7 | K18: m=8 | L18: m=9 | M18: m=13
A19: SSj | B19: 0.25 | D19: Irrigated pasture | E19: 0.0059 | G19: MAT | H19: anaerobicLagoon | I19: solidStorage | J19: digester | K19: deepLitter | L19: pitStorage | M19: directApplication
A20: SNj | B20: 0.25 | D20: Irrigated crop | E20: 0.007 | G20: 10 or below | H20: 0.66 | I20: 0.02 | J20: 0.1 | K20: 0.04 | L20: 0.03 | M20: 0
A21: B0 | B21: 0.45 | D21: Non-irrigated pasture | E21: 0.0018 | G21: 11 | H21: 0.68 | I21: 0.02 | J21: 0.1 | K21: 0.04 | L21: 0.03 | M21: 0
A22: p | B22: 0.6784 | D22: Non-irrigated crop (low rainfall) | E22: 0.0029 | G22: 12 | H22: 0.7 | I22: 0.02 | J22: 0.1 | K22: 0.04 | L22: 0.03 | M22: 0
A23: CN2O | B23: =[1]!common_cn2o -> 1.57 | D23: Non-irrigated crop (high rainfall) | E23: 0.008 | G23: 13 | H23: 0.71 | I23: 0.02 | J23: 0.1 | K23: 0.04 | L23: 0.03 | M23: 0
A24: EFLeach | B24: 0.011 | G24: 14 | H24: 0.73 | I24: 0.02 | J24: 0.1 | K24: 0.04 | L24: 0.03 | M24: 0
A25: FracLEACHMS | B25: 0.02 | G25: 15 | H25: 0.74 | I25: 0.02 | J25: 0.1 | K25: 0.04 | L25: 0.03 | M25: 0
G26: 16 | H26: 0.75 | I26: 0.02 | J26: 0.1 | K26: 0.04 | L26: 0.03 | M26: 0
G27: 17 | H27: 0.76 | I27: 0.02 | J27: 0.1 | K27: 0.04 | L27: 0.03 | M27: 0
G28: 18 | H28: 0.77 | I28: 0.02 | J28: 0.1 | K28: 0.04 | L28: 0.03 | M28: 0
G29: 19 | H29: 0.77 | I29: 0.02 | J29: 0.1 | K29: 0.04 | L29: 0.03 | M29: 0
G30: 20 | H30: 0.78 | I30: 0.02 | J30: 0.1 | K30: 0.04 | L30: 0.03 | M30: 0
G31: 21 | H31: 0.78 | I31: 0.02 | J31: 0.1 | K31: 0.04 | L31: 0.03 | M31: 0
G32: 22 | H32: 0.78 | I32: 0.02 | J32: 0.1 | K32: 0.04 | L32: 0.03 | M32: 0
G33: 23 | H33: 0.79 | I33: 0.02 | J33: 0.1 | K33: 0.04 | L33: 0.03 | M33: 0
G34: 24 | H34: 0.79 | I34: 0.02 | J34: 0.1 | K34: 0.04 | L34: 0.03 | M34: 0
G35: 25 | H35: 0.79 | I35: 0.02 | J35: 0.1 | K35: 0.04 | L35: 0.03 | M35: 0
G36: 26 | H36: 0.79 | I36: 0.02 | J36: 0.1 | K36: 0.04 | L36: 0.03 | M36: 0
G37: 27 | H37: 0.8 | I37: 0.02 | J37: 0.1 | K37: 0.04 | L37: 0.03 | M37: 0
G38: 28 or above | H38: 0.8 | I38: 0.02 | J38: 0.1 | K38: 0.04 | L38: 0.03 | M38: 0

Sheet 4.5
A2: Method 1
A4: input | B4: input | C4: input | D4: input | E4: input | F4: input | G4: input | I4: input | J4: input | K4: input | L4: input | M4: input | N4: input | O4: input | P4: input | Q4: input | R4: input | S4: input | T4: input | U4: input | V4: input | W4: input | X4: input | Y4: input | BH4: expression | BI4: expression | BJ4: expression | BK4: expression | BL4: expression | BM4: expression | BN4: constant | BO4: constant | BP4: constant | BQ4: constant | BR4: constant | BS4: constant | BT4: constant | BU4: constant | BV4: constant | BW4: expression | BX4: expression | BY4: expression | BZ4: expression | CA4: expression | CB4: expression | CC4: expression | CD4: constant | CE4: constant | CF4: constant | CG4: constant | CH4: constant | CI4: expression | CJ4: expression | CK4: expression | CL4: expression | CM4: expression | CN4: expression | CO4: expression | CP4: expression | CS4: expression | CT4: expression | CU4: expression | CX4: expression | CY4: expression | CZ4: expression | DA4: expression | DB4: expression | DC4: expression | DD4: expression | DE4: expression | DF4: expression | DG4: expression | DH4: expression | DI4: expression | DJ4: expression | DK4: expression | DL4: expression | DM4: expression | DN4: expression | DO4: constant | DP4: constant | DQ4: constant | DR4: constant | DS4: constant | DT4: constant | DU4: constant | DV4: constant | DW4: constant | DX4: constant | DY4: constant | DZ4: constant | EA4: constant | EB4: expression | EC4: expression | ED4: expression | EE4: expression | EF4: expression | EG4: expression | EH4: expression | EI4: expression | EJ4: expression | EK4: expression | EL4: expression | EM4: expression | EN4: expression | EO4: expression | EP4: expression | EQ4: expression | ER4: expression | ES4: expression | ET4: expression | EU4: expression | EV4: expression | EW4: expression | EX4: expression
BH6: NOTE: The unconfirmed implication is that this expression only applies for m=1,7,9 | DC6: 𝐹𝑁𝑗𝑚 𝑇=1 = 𝑀𝑀𝑆𝑗𝑚 𝑇=1 × (1 − 𝑆𝑁𝑚) | DD6: 𝐹𝑁 𝑗𝑚=4 𝑇=1 = 𝑀𝑀𝑆 𝑗𝑚=4 𝑇=1 + (𝑀𝑀𝑆𝑗𝑚=1,7,9 𝑇=1 × 𝑆𝑁𝑚)
BH7: 𝐹𝑉𝑆𝑗𝑚 𝑇=1 = 𝑀𝑀𝑆𝑗𝑚 𝑇=1 × (1 − 𝑆𝑆𝑚) | BI7: 𝐹𝑉𝑆𝑗𝑚=4 𝑇=1 = 𝑀𝑀𝑆𝑗𝑚=4 𝑇=1 + (𝑀𝑀𝑆𝑗𝑚=1,7,9 𝑇=1 × 𝑆𝑆𝑚) | BW7: 𝑀𝑗𝑚 𝑇=1 = 𝑉𝑆𝑗 × 𝐹𝑉𝑆𝑗𝑚 𝑇=1 × 𝑀𝐶𝐹𝑖𝑚 × 𝐵𝑂 × 𝜌 | DA7: 𝐸𝐶𝐻4 = ∑ ∑ ∑ (𝐷𝑗𝑚𝑇 × 𝑀𝑗𝑚𝑇 × 𝑁𝑗𝑚𝑇) × 10−3 | DB7: 𝐴𝐸𝑗 = 𝑁𝑗 × 𝑁𝑊𝑗 × 𝐷 | DI7: 𝑀𝑁 𝑗𝑚 𝑇=1 = 𝐴𝐸 𝑗 × 𝐹𝑁 𝑗𝑚 𝑇=1
A8: State | B8: MAT | C8: Production system | D8: Leaching zone | E8: Swine class | F8: Number of poultry in each class j and subclass k | G8: Duration of stay for each class and subclass of poultry | H8: Feed Intake | I8: Volatile Solid production | J8: Nitrogen Waste production | K8: ` | L8: Solid Storage | M8: Outdoor | N8: Covered/Digester | O8: Deep Litter | P8: Pit Storage < 1 Month | Q8: Solids separated | R8: Solid separation rate | S8: Nitrogen separation rate | T8: Solids separated | U8: Solid separation rate | V8: Nitrogen separation rate | W8: Solids separated | X8: Solid separation rate | Y8: Nitrogen separation rate | Z8: Uncovered anaerobic lagoons | AA8: Solid Storage | AB8: Covered/Digester | AC8: Pit Storage < 1 Month | AD8: Direct Application | AE8: Uncovered anaerobic lagoons | AF8: Solid Storage | AG8: Covered/Digester | AH8: Pit Storage < 1 Month | AI8: Direct Application | AJ8: Uncovered anaerobic lagoons | AK8: Solid Storage | AL8: Covered/Digester | AM8: Pit Storage < 1 Month | AN8: Direct Application | AO8: Uncovered anaerobic lagoons | AP8: Solid Storage | AQ8: Covered/Digester | AR8: Pit Storage < 1 Month | AS8: Direct Application | AT8: Uncovered anaerobic lagoons | AU8: Solid Storage | AV8: Covered/Digester | AW8: Pit Storage < 1 Month | AX8: Direct Application | AY8: Feed Intake | AZ8: Volatile Solid production | BA8: Nitrogen Waste production | DB8: Annual nitrogen excretion | DC8: Fraction of nitrogen per system (stage 1) | DI8: Mass of nitrogen per system (stage 1) | EH8: Nitrogen leaving | EM8: Mass of nitrogen per system (stage 2)
Q9: m=1 | T9: m=7 | W9: m=9 | Z9: Allocations from anaerobic lagoons (m=1) | AE9: Allocations from solid storage (m=4) | AJ9: Allocations from covered lagoons/digesters (m=7) | AO9: Allocations from deep litter (m=8) | AT9: Allocations from pit storage (m=9) | DC9: Uncovered anaerobic lagoons | DD9: Solid Storage | DE9: Outdoor | DF9: Covered/Digester | DG9: Deep Litter | DH9: Pit Storage < 1 Month | DI9: Uncovered anaerobic lagoons | DJ9: Solid Storage | DK9: Outdoor | DL9: Covered/Digester | DM9: Deep Litter | DN9: Pit Storage < 1 Month | DO9: Uncovered anaerobic lagoons | DP9: Solid Storage | DQ9: Outdoor | DR9: Covered/Digester | DS9: Deep Litter | DT9: Pit Storage < 1 Month | DU9: Uncovered anaerobic lagoons | DV9: Solid Storage | DW9: Outdoor | DX9: Covered/Digester | DY9: Deep Litter | DZ9: Pit Storage < 1 Month | EB9: Stage 1 | EH9: Uncovered anaerobic lagoons | EI9: Solid Storage | EJ9: Covered/Digester | EK9: Deep Litter | EL9: Pit Storage < 1 Month | ER9: Stage 2 | EY9: Stage 1 | FE9: Stage 2 | FJ9: Total
A10: i | B10: i | D10: (true or false) | E10: j | F10: Nj | G10: Dj | H10: Ij | I10: VSj | J10: NWj | K10: MMSjm=1T=1 | L10: MMSjm=4T=1 | M10: MMSjm=5T=1 | N10: MMSjm=7T=1 | O10: MMSjm=8T=1 | P10: MMSjm=9T=1 | Q10: true/false | R10: SSm=1 | S10: SNm=1 | T10: true/false | U10: SSm=7 | V10: SNm=7 | W10: true/false | X10: SSm=9 | Y10: SNm=9 | AA10: MMSjm=4T=2 | AB10: MMSjm=7T=2 | AC10: MMSjm=9T=2 | AD10: MMSjm=13T=2 | AE10: MMSjm=1T=2 | AG10: MMSjm=7T=2 | AH10: MMSjm=9T=2 | AI10: MMSjm=13T=2 | AJ10: MMSjm=1T=2 | AK10: MMSjm=4T=2 | AM10: MMSjm=9T=2 | AN10: MMSjm=13T=2 | AO10: MMSjm=1T=2 | AP10: MMSjm=4T=2 | AQ10: MMSjm=7T=2 | AR10: MMSjm=9T=2 | AS10: MMSjm=13T=2 | AT10: MMSjm=1T=2 | AU10: MMSjm=4T=2 | AV10: MMSjm=7T=2 | AX10: MMSjm=13T=2 | AY10: Ij | AZ10: VSj | BA10: NWj | BB10: SSm=1 | BC10: SSm=7 | BD10: SSm=9 | BE10: SNm=1 | BF10: SNm=7 | BG10: SNm=9 | BH10: FVSjm=1T=1 | BI10: FVSjm=4T=1 | BJ10: FVSjm=5T=1 | BK10: FVSjm=7T=1 | BL10: FVSjm=8T=1 | BM10: FVSjm=9T=1 | BN10: Bo | BO10: p | BP10: MCFim=1 | BQ10: MCFim=4 | BR10: MCFim=5 | BS10: MCFim=7 | BT10: MCFim=8 | BU10: MCFim=9 | BV10: MCFim=13 | BW10: Mjm=1T=1 | BX10: Mjm=4T=1 | BY10: Mjm=5T=1 | BZ10: Mjm=7T=1 | CA10: Mjm=8T=1 | CB10: Mjm=9T=1 | CC10: ECH4jmT=1 | CD10: VSLm=1T=1 | CE10: VSLm=4T=1 | CF10: VSLm=7T=1 | CG10: VSLm=8T=1 | CH10: VSLm=9T=1 | CI10: VSTjm=1T=2 | CJ10: VSTjm=4T=2 | CK10: VSTjm=7T=2 | CL10: VSTjm=8T=2 | CM10: VSTjm=9T=2 | CN10: VSTjmT=2 | CO10: FVSjm=1T=2 | CP10: FVSjm=4T=2 | CQ10: FVSjm=7T=2 | CR10: FVSjm=9T=2 | CS10: FVSjm=13T=2 | CT10: Mjm=1T=2 | CU10: Mjm=4T=2 | CV10: Mjm=7T=2 | CW10: Mjm=9T=2 | CX10: Mjm=13T=2 | CY10: ECH4jmT=2 | CZ10: ECH4j | DA10: ECH4 | DB10: AEj | DC10: FNjm=1T=1 | DD10: FNjm=4T=1 | DE10: FNjm=5T=1 | DF10: FNjm=7T=1 | DG10: FNjm=8T=1 | DH10: FNjm=9T=1 | DI10: MNjm=1T=1 | DJ10: MNjm=4T=1 | DK10: MNjm=5T=1 | DL10: MNjm=7T=1 | DM10: MNjm=8T=1 | DN10: MNjm=9T=1 | DO10: FracGASMm=1T=1 | DP10: FracGASMm=4T=1 | DQ10: FracGASMm=5T=1 | DR10: FracGASMm=7T=1 | DS10: FracGASMm=8T=1 | DT10: FracGASMm=9T=1 | DU10: EFm=1 | DV10: EFm=4 | DW10: EFm=5 | DX10: EFm=7 | DY10: EFm=8 | DZ10: EFm=9 | EA10: CN2O | EB10: EN2O,dir (T=1, m=1) | EC10: EN2O,dir (T=1, m=4) | ED10: EN2O,dir (T=1, m=5) | EE10: EN2O,dir (T=1, m=7) | EF10: EN2O,dir (T=1, m=8) | EG10: EN2O,dir (T=1, m=9) | EH10: NTjm=1T=2 | EI10: NTjm=4T=2 | EJ10: NTjm=7T=2 | EK10: NTjm=8T=2 | EL10: NTjm=9T=2 | EM10: MNjm=1T=2 | EN10: MNjm=4T=2 | EO10: MNjm=7T=2 | EP10: MNjm=9T=2 | EQ10: MNjm=13T=2 | ER10: EN2O,dir (T=2, m=1) | ES10: EN2O,dir (T=2, m=4) | ET10: EN2O,dir (T=2, m=7) | EU10: EN2O,dir (T=2, m=9) | EV10: EN2O,dir (T=2, m=13) | EW10: EN2O,dir (j) | EX10: EN2O,dir | EY10: MMSATMOS (m=1, T=1) | EZ10: MMSATMOS (m=4, T=1) | FA10: MMSATMOS (m=5, T=1) | FB10: MMSATMOS (m=7, T=1) | FC10: MMSATMOS (m=8, T=1) | FD10: MMSATMOS (m=9, T=1) | FE10: MMSATMOS (m=1, T=2) | FF10: MMSATMOS (m=4, T=2) | FG10: MMSATMOS (m=7, T=2) | FH10: MMSATMOS (m=9, T=2) | FI10: MMSATMOS (m=13, T=2) | FJ10: MMSATMOS (j) | FK10: EFN2O | FL10: EN2O,ad (j) | FM10: EN2O,ad | FN10: EFLeach | FO10: FracWET | FP10: FracLEACHMS | FQ10: MNLeachjm=5 | FR10: EN2O,leach (j) | FS10: EN2O,leach
A11: NSW | C11: Irrigated crop | D11: TRUE | E11: boars | F11: 111 | G11: 105 | K11: 1 | Q11: TRUE | T11: TRUE | W11: TRUE | AB11: 0.5 | AD11: 0.5 | AH11: 0.5 | AI11: 0.5 | AY11: =IF(H11<>"", H11, _xlfn.XLOOKUP($E11,Constants!$A$3:$A$6, Constants!B$3:B$6)) -> 2.3 | AZ11: =IF(I11<>"", I11, _xlfn.XLOOKUP($E11,Constants!$A$3:$A$6, Constants!C$3:C$6)) -> 0.4 | BA11: =IF(J11<>"", J11, _xlfn.XLOOKUP($E11,Constants!$A$3:$A$6, Constants!D$3:D$6)) -> 0.046 | BB11: =IF(R11<>"", R11, IF(Q11, Constants!$B$19, 0)) -> 0.25 | BC11: =IF(U11<>"", U11, IF(T11, Constants!$B$19, 0)) -> 0.25 | BD11: =IF(X11<>"", X11, IF(W11, Constants!$B$19, 0)) -> 0.25 | BE11: =IF(S11<>"", S11, IF(Q11, Constants!$B$20, 0)) -> 0.25 | BF11: =IF(V11<>"", V11, IF(T11, Constants!$B$20, 0)) -> 0.25 | BG11: =IF(Y11<>"", Y11, IF(W11, Constants!$B$20, 0)) -> 0.25 | BH11: =K11*(1-BB11) -> 0.75 | BI11: =L11+(K11*BB11)+(N11*BC11)+(P11*BD11) -> 0.25 | BJ11: =M11 -> 0 | BK11: =N11*(1-BC11) -> 0 | BL11: =O11 -> 0 | BM11: =P11*(1-BD11) -> 0 | BN11: =Constants!$B$21 -> 0.45 | BO11: =Constants!$B$22 -> 0.6784 | BP11: =_xlfn.XLOOKUP($A11,Constants!$F$9:$M$9,Constants!$F$10:$M$10) -> 0.75 | BQ11: =_xlfn.XLOOKUP($A11,Constants!$F$9:$M$9,Constants!$F$11:$M$11) -> 0.02 | BR11: =_xlfn.XLOOKUP($A11,Constants!$F$9:$M$9,Constants!$F$12:$M$12) -> 0.01 | BS11: =_xlfn.XLOOKUP($A11,Constants!$F$9:$M$9,Constants!$F$13:$M$13) -> 0.1 | BT11: =_xlfn.XLOOKUP($A11,Constants!$F$9:$M$9,Constants!$F$14:$M$14) -> 0.04 | BU11: =_xlfn.XLOOKUP($A11,Constants!$F$9:$M$9,Constants!$F$15:$M$15) -> 0.03 | BV11: =_xlfn.XLOOKUP($A11,Constants!$F$9:$M$9,Constants!$F$16:$M$16) -> 0 | BW11: =$AZ11*BH11*BP11*$BN11*$BO11 -> 0.068688 | BX11: =$AZ11*BI11*BQ11*$BN11*$BO11 -> 0.00061056 | BY11: =$AZ11*BJ11*BR11*$BN11*$BO11 -> 0 | BZ11: =$AZ11*BK11*BS11*$BN11*$BO11 -> 0 | CA11: =$AZ11*BL11*BT11*$BN11*$BO11 -> 0 | CB11: =$AZ11*BM11*BU11*$BN11*$BO11 -> 0 | CC11: =(SUM(BW11:CB11)*F11*G11)/1000 -> 0.80767472 | CD11: =Constants!$E$10 -> 0 | CE11: =Constants!$E$11 -> 0 | CF11: =Constants!$E$13 -> 0.75 | CG11: =Constants!$E$14 -> 0.05 | CH11: =Constants!$E$15 -> 0 | CI11: =(BH11*(1-CD11)) -> 0.75 | CJ11: =(BI11*(1-CE11)) -> 0.25 | CK11: =(BK11*(1-CF11)) -> 0 | CL11: =(BL11*(1-CG11)) -> 0 | CM11: =(BM11*(1-CH11)) -> 0 | CN11: =SUM(CI11:CM11)*I11 -> 0 | CO11: =$CI11*Z11+$CJ11*AE11+$CK11*AJ11+$CL11*AO11+$CM11*AT11 -> 0 | CP11: =$CI11*AA11+$CJ11*AF11+$CK11*AK11+$CL11*AP11+$CM11*AU11 -> 0 | CQ11: =$CI11*AB11+$CJ11*AG11+$CK11*AL11+$CL11*AQ11+$CM11*AV11 -> 0.375 | CR11: =$CI11*AC11+$CJ11*AH11+$CK11*AM11+$CL11*AR11+$CM11*AW11 -> 0.125 | CS11: =$CI11*AD11+$CJ11*AI11+$CK11*AN11+$CL11*AS11+$CM11*AX11 -> 0.5 | CT11: =CO11*$BN11*BP11*$BO11*$AZ11 -> 0 | CU11: =CP11*$BN11*BQ11*$BO11*$AZ11 -> 0 | CV11: =CQ11*$BN11*BS11*$BO11*$AZ11 -> 0.0045792 | CW11: =CR11*$BN11*BU11*$BO11*$AZ11 -> 0.00045792 | CX11: =CS11*$BN11*BV11*$BO11*$AZ11 -> 0 | CY11: =(SUM(CT11:CX11)*F11*G11)/1000 -> 0.058707634 | CZ11: =CC11+CY11 -> 0.86638235 | DA11: =SUM(CZ11:CZ14) -> 4.6192572 | DB11: =F11*G11*BA11 -> 536.13 | DC11: =K11*(1-BE11) -> 0.75 | DD11: =L11+(K11*BE11)+(N11*BF11)+(P11*BG11) -> 0.25 | DE11: =M11 -> 0 | DF11: =N11*(1-BF11) -> 0 | DG11: =O11 -> 0 | DH11: =P11*(1-BG11) -> 0 | DI11: =$DB11*DC11 -> 402.0975 | DJ11: =$DB11*DD11 -> 134.0325 | DK11: =$DB11*DE11 -> 0 | DL11: =$DB11*DF11 -> 0 | DM11: =$DB11*DG11 -> 0 | DN11: =$DB11*DH11 -> 0 | DO11: =Constants!$C$10 -> 0.55 | DP11: =Constants!$C$11 -> 0.2 | DQ11: =Constants!$C$12 -> 0.3 | DR11: =Constants!$C$13 -> 0 | DS11: =Constants!$C$14 -> 0.125 | DT11: =Constants!$C$15 -> 0.25 | DU11: =Constants!$D$10 -> 0 | DV11: =Constants!$D$11 -> 0.005 | DW11: =Constants!$D$12 -> 0.02 | DX11: =Constants!$D$13 -> 0 | DY11: =Constants!$D$14 -> 0.01 | DZ11: =Constants!$D$15 -> 0.002 | EA11: =Constants!$B$23 -> 1.57 | EB11: =DI11*DU11*$EA11 -> 0 | EC11: =DJ11*DV11*$EA11 -> 1.0521551 | ED11: =DK11*DW11*$EA11 -> 0 | EE11: =DL11*DX11*$EA11 -> 0 | EF11: =DM11*DY11*$EA11 -> 0 | EG11: =DN11*DZ11*$EA11 -> 0 | EH11: =DI11*(1-DO11-DU11) -> 180.94387 | EI11: =DJ11*(1-DP11-DV11) -> 106.55584 | EJ11: =DL11*(1-DR11-DX11) -> 0 | EK11: =DM11*(1-DS11-DY11) -> 0 | EL11: =DN11*(1-DT11-DZ11) -> 0 | EM11: =$EH11*Z11+$EI11*AE11+$EJ11*AJ11+$EK11*AO11+$EL11*AT11 -> 0 | EN11: =$EH11*AA11+$EI11*AF11+$EJ11*AK11+$EK11*AP11+$EL11*AU11 -> 0 | EO11: =$EH11*AB11+$EI11*AG11+$EJ11*AL11+$EK11*AQ11+$EL11*AV11 -> 90.471937 | EP11: =$EH11*AC11+$EI11*AH11+$EJ11*AM11+$EK11*AR11+$EL11*AW11 -> 53.277919 | EQ11: =$EH11*AD11+$EI11*AI11+$EJ11*AN11+$EK11*AS11+$EL11*AX11 -> 143.74986 | ER11: =EM11*DU11*$EA11 -> 0 | ES11: =EN11*DV11*$EA11 -> 0 | ET11: =EO11*DX11*$EA11 -> 0 | EU11: =EP11*DZ11*$EA11 -> 0.16729266 | EV11: =EQ11*0*$EA11 -> 0 | EW11: =SUM(EB11:EG11,ER11:EV11)/1000 -> 0.0012194478 | EX11: =SUM(EW11:EW14) -> 0.18565691 | EY11: =DI11*DO11 -> 221.15363 | EZ11: =DJ11*DP11 -> 26.8065 | FA11: =DK11*DQ11 -> 0 | FB11: =DL11*DR11 -> 0 | FC11: =DM11*DS11 -> 0 | FD11: =DN11*DT11 -> 0 | FE11: =EM11*DO11 -> 0 | FF11: =EN11*DP11 -> 0 | FG11: =EO11*DR11 -> 0 | FH11: =EP11*DT11 -> 13.31948 | FI11: =EQ11*0 -> 0 | FJ11: =SUM(EY11:FI11) -> 261.2796 | FK11: =_xlfn.XLOOKUP(C11, Constants!$D$19:$D$23, Constants!$E$19:$E$23) -> 0.007 | FL11: =(EA11*FJ11*FK11)/1000 -> 0.0028714629 | FM11: =SUM(FL11:FL14) -> 0.035358997 | FN11: =Constants!$B$24 -> 0.011 | FO11: =IF(D11, 1, 0) -> 1 | FP11: =Constants!$B$25 -> 0.02 | FQ11: =DK11*FO11*FP11 -> 0 | FR11: =FQ11*FN11*EA11 -> 0 | FS11: =SUM(FR11:FR14)/1000 -> 0
A12: NSW | C12: Irrigated crop | D12: TRUE | E12: sows | F12: 222 | G12: 103 | K12: 1 | Q12: TRUE | T12: TRUE | W12: TRUE | AB12: 0.5 | AD12: 0.5 | AH12: 0.5 | AI12: 0.5 | AY12: =IF(H12<>"", H12, _xlfn.XLOOKUP($E12,Constants!$A$3:$A$6, Constants!B$3:B$6)) -> 2.62 | AZ12: =IF(I12<>"", I12, _xlfn.XLOOKUP($E12,Constants!$A$3:$A$6, Constants!C$3:C$6)) -> 0.46 | BA12: =IF(J12<>"", J12, _xlfn.XLOOKUP($E12,Constants!$A$3:$A$6, Constants!D$3:D$6)) -> 0.049 | BB12: =IF(R12<>"", R12, IF(Q12, Constants!$B$19, 0)) -> 0.25 | BC12: =IF(U12<>"", U12, IF(T12, Constants!$B$19, 0)) -> 0.25 | BD12: =IF(X12<>"", X12, IF(W12, Constants!$B$19, 0)) -> 0.25 | BE12: =IF(S12<>"", S12, IF(Q12, Constants!$B$20, 0)) -> 0.25 | BF12: =IF(V12<>"", V12, IF(T12, Constants!$B$20, 0)) -> 0.25 | BG12: =IF(Y12<>"", Y12, IF(W12, Constants!$B$20, 0)) -> 0.25 | BH12: =K12*(1-BB12) -> 0.75 | BI12: =L12+(K12*BB12)+(N12*BC12)+(P12*BD12) -> 0.25 | BJ12: =M12 -> 0 | BK12: =N12*(1-BC12) -> 0 | BL12: =O12 -> 0 | BM12: =P12*(1-BD12) -> 0 | BN12: =Constants!$B$21 -> 0.45 | BO12: =Constants!$B$22 -> 0.6784 | BP12: =_xlfn.XLOOKUP($A12,Constants!$F$9:$M$9,Constants!$F$10:$M$10) -> 0.75 | BQ12: =_xlfn.XLOOKUP($A12,Constants!$F$9:$M$9,Constants!$F$11:$M$11) -> 0.02 | BR12: =_xlfn.XLOOKUP($A12,Constants!$F$9:$M$9,Constants!$F$12:$M$12) -> 0.01 | BS12: =_xlfn.XLOOKUP($A12,Constants!$F$9:$M$9,Constants!$F$13:$M$13) -> 0.1 | BT12: =_xlfn.XLOOKUP($A12,Constants!$F$9:$M$9,Constants!$F$14:$M$14) -> 0.04 | BU12: =_xlfn.XLOOKUP($A12,Constants!$F$9:$M$9,Constants!$F$15:$M$15) -> 0.03 | BV12: =_xlfn.XLOOKUP($A12,Constants!$F$9:$M$9,Constants!$F$16:$M$16) -> 0 | BW12: =$AZ12*BH12*BP12*$BN12*$BO12 -> 0.0789912 | BX12: =$AZ12*BI12*BQ12*$BN12*$BO12 -> 0.000702144 | BY12: =$AZ12*BJ12*BR12*$BN12*$BO12 -> 0 | BZ12: =$AZ12*BK12*BS12*$BN12*$BO12 -> 0 | CA12: =$AZ12*BL12*BT12*$BN12*$BO12 -> 0 | CB12: =$AZ12*BM12*BU12*$BN12*$BO12 -> 0 | CC12: =(SUM(BW12:CB12)*F12*G12)/1000 -> 1.822268 | CD12: =Constants!$E$10 -> 0 | CE12: =Constants!$E$11 -> 0 | CF12: =Constants!$E$13 -> 0.75 | CG12: =Constants!$E$14 -> 0.05 | CH12: =Constants!$E$15 -> 0 | CI12: =(BH12*(1-CD12)) -> 0.75 | CJ12: =(BI12*(1-CE12)) -> 0.25 | CK12: =(BK12*(1-CF12)) -> 0 | CL12: =(BL12*(1-CG12)) -> 0 | CM12: =(BM12*(1-CH12)) -> 0 | CN12: =SUM(CI12:CM12)*I12 -> 0 | CO12: =$CI12*Z12+$CJ12*AE12+$CK12*AJ12+$CL12*AO12+$CM12*AT12 -> 0 | CP12: =$CI12*AA12+$CJ12*AF12+$CK12*AK12+$CL12*AP12+$CM12*AU12 -> 0 | CQ12: =$CI12*AB12+$CJ12*AG12+$CK12*AL12+$CL12*AQ12+$CM12*AV12 -> 0.375 | CR12: =$CI12*AC12+$CJ12*AH12+$CK12*AM12+$CL12*AR12+$CM12*AW12 -> 0.125 | CS12: =$CI12*AD12+$CJ12*AI12+$CK12*AN12+$CL12*AS12+$CM12*AX12 -> 0.5 | CT12: =CO12*$BN12*BP12*$BO12*$AZ12 -> 0 | CU12: =CP12*$BN12*BQ12*$BO12*$AZ12 -> 0 | CV12: =CQ12*$BN12*BS12*$BO12*$AZ12 -> 0.00526608 | CW12: =CR12*$BN12*BU12*$BO12*$AZ12 -> 0.000526608 | CX12: =CS12*$BN12*BV12*$BO12*$AZ12 -> 0 | CY12: =(SUM(CT12:CX12)*F12*G12)/1000 -> 0.1324556 | CZ12: =CC12+CY12 -> 1.9547236 | DB12: =F12*G12*BA12 -> 1120.434 | DC12: =K12*(1-BE12) -> 0.75 | DD12: =L12+(K12*BE12)+(N12*BF12)+(P12*BG12) -> 0.25 | DE12: =M12 -> 0 | DF12: =N12*(1-BF12) -> 0 | DG12: =O12 -> 0 | DH12: =P12*(1-BG12) -> 0 | DI12: =$DB12*DC12 -> 840.3255 | DJ12: =$DB12*DD12 -> 280.1085 | DK12: =$DB12*DE12 -> 0 | DL12: =$DB12*DF12 -> 0 | DM12: =$DB12*DG12 -> 0 | DN12: =$DB12*DH12 -> 0 | DO12: =Constants!$C$10 -> 0.55 | DP12: =Constants!$C$11 -> 0.2 | DQ12: =Constants!$C$12 -> 0.3 | DR12: =Constants!$C$13 -> 0 | DS12: =Constants!$C$14 -> 0.125 | DT12: =Constants!$C$15 -> 0.25 | DU12: =Constants!$D$10 -> 0 | DV12: =Constants!$D$11 -> 0.005 | DW12: =Constants!$D$12 -> 0.02 | DX12: =Constants!$D$13 -> 0 | DY12: =Constants!$D$14 -> 0.01 | DZ12: =Constants!$D$15 -> 0.002 | EA12: =Constants!$B$23 -> 1.57 | EB12: =DI12*DU12*$EA12 -> 0 | EC12: =DJ12*DV12*$EA12 -> 2.1988517 | ED12: =DK12*DW12*$EA12 -> 0 | EE12: =DL12*DX12*$EA12 -> 0 | EF12: =DM12*DY12*$EA12 -> 0 | EG12: =DN12*DZ12*$EA12 -> 0 | EH12: =DI12*(1-DO12-DU12) -> 378.14647 | EI12: =DJ12*(1-DP12-DV12) -> 222.68626 | EJ12: =DL12*(1-DR12-DX12) -> 0 | EK12: =DM12*(1-DS12-DY12) -> 0 | EL12: =DN12*(1-DT12-DZ12) -> 0 | EM12: =$EH12*Z12+$EI12*AE12+$EJ12*AJ12+$EK12*AO12+$EL12*AT12 -> 0 | EN12: =$EH12*AA12+$EI12*AF12+$EJ12*AK12+$EK12*AP12+$EL12*AU12 -> 0 | EO12: =$EH12*AB12+$EI12*AG12+$EJ12*AL12+$EK12*AQ12+$EL12*AV12 -> 189.07324 | EP12: =$EH12*AC12+$EI12*AH12+$EJ12*AM12+$EK12*AR12+$EL12*AW12 -> 111.34313 | EQ12: =$EH12*AD12+$EI12*AI12+$EJ12*AN12+$EK12*AS12+$EL12*AX12 -> 300.41637 | ER12: =EM12*DU12*$EA12 -> 0 | ES12: =EN12*DV12*$EA12 -> 0 | ET12: =EO12*DX12*$EA12 -> 0 | EU12: =EP12*DZ12*$EA12 -> 0.34961742 | EV12: =EQ12*0*$EA12 -> 0 | EW12: =SUM(EB12:EG12,ER12:EV12)/1000 -> 0.0025484691 | EY12: =DI12*DO12 -> 462.17902 | EZ12: =DJ12*DP12 -> 56.0217 | FA12: =DK12*DQ12 -> 0 | FB12: =DL12*DR12 -> 0 | FC12: =DM12*DS12 -> 0 | FD12: =DN12*DT12 -> 0 | FE12: =EM12*DO12 -> 0 | FF12: =EN12*DP12 -> 0 | FG12: =EO12*DR12 -> 0 | FH12: =EP12*DT12 -> 27.835782 | FI12: =EQ12*0 -> 0 | FJ12: =SUM(EY12:FI12) -> 546.03651 | FK12: =_xlfn.XLOOKUP(C12, Constants!$D$19:$D$23, Constants!$E$19:$E$23) -> 0.007 | FL12: =(EA12*FJ12*FK12)/1000 -> 0.0060009412 | FN12: =Constants!$B$24 -> 0.011 | FO12: =IF(D12, 1, 0) -> 1 | FP12: =Constants!$B$25 -> 0.02 | FQ12: =DK12*FO12*FP12 -> 0 | FR12: =FQ12*FN12*EA12 -> 0
A13: NSW | C13: Irrigated crop | D13: TRUE | E13: gilts | F13: 333 | G13: 200 | O13: 1 | Q13: FALSE | T13: FALSE | W13: FALSE | AP13: 1 | AY13: =IF(H13<>"", H13, _xlfn.XLOOKUP($E13,Constants!$A$3:$A$6, Constants!B$3:B$6)) -> 2.5 | AZ13: =IF(I13<>"", I13, _xlfn.XLOOKUP($E13,Constants!$A$3:$A$6, Constants!C$3:C$6)) -> 0.55 | BA13: =IF(J13<>"", J13, _xlfn.XLOOKUP($E13,Constants!$A$3:$A$6, Constants!D$3:D$6)) -> 0.046 | BB13: =IF(R13<>"", R13, IF(Q13, Constants!$B$19, 0)) -> 0 | BC13: =IF(U13<>"", U13, IF(T13, Constants!$B$19, 0)) -> 0 | BD13: =IF(X13<>"", X13, IF(W13, Constants!$B$19, 0)) -> 0 | BE13: =IF(S13<>"", S13, IF(Q13, Constants!$B$20, 0)) -> 0 | BF13: =IF(V13<>"", V13, IF(T13, Constants!$B$20, 0)) -> 0 | BG13: =IF(Y13<>"", Y13, IF(W13, Constants!$B$20, 0)) -> 0 | BH13: =K13*(1-BB13) -> 0 | BI13: =L13+(K13*BB13)+(N13*BC13)+(P13*BD13) -> 0 | BJ13: =M13 -> 0 | BK13: =N13*(1-BC13) -> 0 | BL13: =O13 -> 1 | BM13: =P13*(1-BD13) -> 0 | BN13: =Constants!$B$21 -> 0.45 | BO13: =Constants!$B$22 -> 0.6784 | BP13: =_xlfn.XLOOKUP($A13,Constants!$F$9:$M$9,Constants!$F$10:$M$10) -> 0.75 | BQ13: =_xlfn.XLOOKUP($A13,Constants!$F$9:$M$9,Constants!$F$11:$M$11) -> 0.02 | BR13: =_xlfn.XLOOKUP($A13,Constants!$F$9:$M$9,Constants!$F$12:$M$12) -> 0.01 | BS13: =_xlfn.XLOOKUP($A13,Constants!$F$9:$M$9,Constants!$F$13:$M$13) -> 0.1 | BT13: =_xlfn.XLOOKUP($A13,Constants!$F$9:$M$9,Constants!$F$14:$M$14) -> 0.04 | BU13: =_xlfn.XLOOKUP($A13,Constants!$F$9:$M$9,Constants!$F$15:$M$15) -> 0.03 | BV13: =_xlfn.XLOOKUP($A13,Constants!$F$9:$M$9,Constants!$F$16:$M$16) -> 0 | BW13: =$AZ13*BH13*BP13*$BN13*$BO13 -> 0 | BX13: =$AZ13*BI13*BQ13*$BN13*$BO13 -> 0 | BY13: =$AZ13*BJ13*BR13*$BN13*$BO13 -> 0 | BZ13: =$AZ13*BK13*BS13*$BN13*$BO13 -> 0 | CA13: =$AZ13*BL13*BT13*$BN13*$BO13 -> 0.00671616 | CB13: =$AZ13*BM13*BU13*$BN13*$BO13 -> 0 | CC13: =(SUM(BW13:CB13)*F13*G13)/1000 -> 0.44729626 | CD13: =Constants!$E$10 -> 0 | CE13: =Constants!$E$11 -> 0 | CF13: =Constants!$E$13 -> 0.75 | CG13: =Constants!$E$14 -> 0.05 | CH13: =Constants!$E$15 -> 0 | CI13: =(BH13*(1-CD13)) -> 0 | CJ13: =(BI13*(1-CE13)) -> 0 | CK13: =(BK13*(1-CF13)) -> 0 | CL13: =(BL13*(1-CG13)) -> 0.95 | CM13: =(BM13*(1-CH13)) -> 0 | CN13: =SUM(CI13:CM13)*I13 -> 0 | CO13: =$CI13*Z13+$CJ13*AE13+$CK13*AJ13+$CL13*AO13+$CM13*AT13 -> 0 | CP13: =$CI13*AA13+$CJ13*AF13+$CK13*AK13+$CL13*AP13+$CM13*AU13 -> 0.95 | CQ13: =$CI13*AB13+$CJ13*AG13+$CK13*AL13+$CL13*AQ13+$CM13*AV13 -> 0 | CR13: =$CI13*AC13+$CJ13*AH13+$CK13*AM13+$CL13*AR13+$CM13*AW13 -> 0 | CS13: =$CI13*AD13+$CJ13*AI13+$CK13*AN13+$CL13*AS13+$CM13*AX13 -> 0 | CT13: =CO13*$BN13*BP13*$BO13*$AZ13 -> 0 | CU13: =CP13*$BN13*BQ13*$BO13*$AZ13 -> 0.003190176 | CV13: =CQ13*$BN13*BS13*$BO13*$AZ13 -> 0 | CW13: =CR13*$BN13*BU13*$BO13*$AZ13 -> 0 | CX13: =CS13*$BN13*BV13*$BO13*$AZ13 -> 0 | CY13: =(SUM(CT13:CX13)*F13*G13)/1000 -> 0.21246572 | CZ13: =CC13+CY13 -> 0.65976198 | DB13: =F13*G13*BA13 -> 3063.6 | DC13: =K13*(1-BE13) -> 0 | DD13: =L13+(K13*BE13)+(N13*BF13)+(P13*BG13) -> 0 | DE13: =M13 -> 0 | DF13: =N13*(1-BF13) -> 0 | DG13: =O13 -> 1 | DH13: =P13*(1-BG13) -> 0 | DI13: =$DB13*DC13 -> 0 | DJ13: =$DB13*DD13 -> 0 | DK13: =$DB13*DE13 -> 0 | DL13: =$DB13*DF13 -> 0 | DM13: =$DB13*DG13 -> 3063.6 | DN13: =$DB13*DH13 -> 0 | DO13: =Constants!$C$10 -> 0.55 | DP13: =Constants!$C$11 -> 0.2 | DQ13: =Constants!$C$12 -> 0.3 | DR13: =Constants!$C$13 -> 0 | DS13: =Constants!$C$14 -> 0.125 | DT13: =Constants!$C$15 -> 0.25 | DU13: =Constants!$D$10 -> 0 | DV13: =Constants!$D$11 -> 0.005 | DW13: =Constants!$D$12 -> 0.02 | DX13: =Constants!$D$13 -> 0 | DY13: =Constants!$D$14 -> 0.01 | DZ13: =Constants!$D$15 -> 0.002 | EA13: =Constants!$B$23 -> 1.57 | EB13: =DI13*DU13*$EA13 -> 0 | EC13: =DJ13*DV13*$EA13 -> 0 | ED13: =DK13*DW13*$EA13 -> 0 | EE13: =DL13*DX13*$EA13 -> 0 | EF13: =DM13*DY13*$EA13 -> 48.09852 | EG13: =DN13*DZ13*$EA13 -> 0 | EH13: =DI13*(1-DO13-DU13) -> 0 | EI13: =DJ13*(1-DP13-DV13) -> 0 | EJ13: =DL13*(1-DR13-DX13) -> 0 | EK13: =DM13*(1-DS13-DY13) -> 2650.014 | EL13: =DN13*(1-DT13-DZ13) -> 0 | EM13: =$EH13*Z13+$EI13*AE13+$EJ13*AJ13+$EK13*AO13+$EL13*AT13 -> 0 | EN13: =$EH13*AA13+$EI13*AF13+$EJ13*AK13+$EK13*AP13+$EL13*AU13 -> 2650.014 | EO13: =$EH13*AB13+$EI13*AG13+$EJ13*AL13+$EK13*AQ13+$EL13*AV13 -> 0 | EP13: =$EH13*AC13+$EI13*AH13+$EJ13*AM13+$EK13*AR13+$EL13*AW13 -> 0 | EQ13: =$EH13*AD13+$EI13*AI13+$EJ13*AN13+$EK13*AS13+$EL13*AX13 -> 0 | ER13: =EM13*DU13*$EA13 -> 0 | ES13: =EN13*DV13*$EA13 -> 20.80261 | ET13: =EO13*DX13*$EA13 -> 0 | EU13: =EP13*DZ13*$EA13 -> 0 | EV13: =EQ13*0*$EA13 -> 0 | EW13: =SUM(EB13:EG13,ER13:EV13)/1000 -> 0.06890113 | EY13: =DI13*DO13 -> 0 | EZ13: =DJ13*DP13 -> 0 | FA13: =DK13*DQ13 -> 0 | FB13: =DL13*DR13 -> 0 | FC13: =DM13*DS13 -> 382.95 | FD13: =DN13*DT13 -> 0 | FE13: =EM13*DO13 -> 0 | FF13: =EN13*DP13 -> 530.0028 | FG13: =EO13*DR13 -> 0 | FH13: =EP13*DT13 -> 0 | FI13: =EQ13*0 -> 0 | FJ13: =SUM(EY13:FI13) -> 912.9528 | FK13: =_xlfn.XLOOKUP(C13, Constants!$D$19:$D$23, Constants!$E$19:$E$23) -> 0.007 | FL13: =(EA13*FJ13*FK13)/1000 -> 0.010033351 | FN13: =Constants!$B$24 -> 0.011 | FO13: =IF(D13, 1, 0) -> 1 | FP13: =Constants!$B$25 -> 0.02 | FQ13: =DK13*FO13*FP13 -> 0 | FR13: =FQ13*FN13*EA13 -> 0
A14: NSW | C14: Irrigated crop | D14: TRUE | E14: others | F14: 444 | G14: 365 | O14: 1 | Q14: FALSE | T14: FALSE | W14: FALSE | AP14: 1 | AY14: =IF(H14<>"", H14, _xlfn.XLOOKUP($E14,Constants!$A$3:$A$6, Constants!B$3:B$6)) -> 1.71 | AZ14: =IF(I14<>"", I14, _xlfn.XLOOKUP($E14,Constants!$A$3:$A$6, Constants!C$3:C$6)) -> 0.39 | BA14: =IF(J14<>"", J14, _xlfn.XLOOKUP($E14,Constants!$A$3:$A$6, Constants!D$3:D$6)) -> 0.031 | BB14: =IF(R14<>"", R14, IF(Q14, Constants!$B$19, 0)) -> 0 | BC14: =IF(U14<>"", U14, IF(T14, Constants!$B$19, 0)) -> 0 | BD14: =IF(X14<>"", X14, IF(W14, Constants!$B$19, 0)) -> 0 | BE14: =IF(S14<>"", S14, IF(Q14, Constants!$B$20, 0)) -> 0 | BF14: =IF(V14<>"", V14, IF(T14, Constants!$B$20, 0)) -> 0 | BG14: =IF(Y14<>"", Y14, IF(W14, Constants!$B$20, 0)) -> 0 | BH14: =K14*(1-BB14) -> 0 | BI14: =L14+(K14*BB14)+(N14*BC14)+(P14*BD14) -> 0 | BJ14: =M14 -> 0 | BK14: =N14*(1-BC14) -> 0 | BL14: =O14 -> 1 | BM14: =P14*(1-BD14) -> 0 | BN14: =Constants!$B$21 -> 0.45 | BO14: =Constants!$B$22 -> 0.6784 | BP14: =_xlfn.XLOOKUP($A14,Constants!$F$9:$M$9,Constants!$F$10:$M$10) -> 0.75 | BQ14: =_xlfn.XLOOKUP($A14,Constants!$F$9:$M$9,Constants!$F$11:$M$11) -> 0.02 | BR14: =_xlfn.XLOOKUP($A14,Constants!$F$9:$M$9,Constants!$F$12:$M$12) -> 0.01 | BS14: =_xlfn.XLOOKUP($A14,Constants!$F$9:$M$9,Constants!$F$13:$M$13) -> 0.1 | BT14: =_xlfn.XLOOKUP($A14,Constants!$F$9:$M$9,Constants!$F$14:$M$14) -> 0.04 | BU14: =_xlfn.XLOOKUP($A14,Constants!$F$9:$M$9,Constants!$F$15:$M$15) -> 0.03 | BV14: =_xlfn.XLOOKUP($A14,Constants!$F$9:$M$9,Constants!$F$16:$M$16) -> 0 | BW14: =$AZ14*BH14*BP14*$BN14*$BO14 -> 0 | BX14: =$AZ14*BI14*BQ14*$BN14*$BO14 -> 0 | BY14: =$AZ14*BJ14*BR14*$BN14*$BO14 -> 0 | BZ14: =$AZ14*BK14*BS14*$BN14*$BO14 -> 0 | CA14: =$AZ14*BL14*BT14*$BN14*$BO14 -> 0.004762368 | CB14: =$AZ14*BM14*BU14*$BN14*$BO14 -> 0 | CC14: =(SUM(BW14:CB14)*F14*G14)/1000 -> 0.77178936 | CD14: =Constants!$E$10 -> 0 | CE14: =Constants!$E$11 -> 0 | CF14: =Constants!$E$13 -> 0.75 | CG14: =Constants!$E$14 -> 0.05 | CH14: =Constants!$E$15 -> 0 | CI14: =(BH14*(1-CD14)) -> 0 | CJ14: =(BI14*(1-CE14)) -> 0 | CK14: =(BK14*(1-CF14)) -> 0 | CL14: =(BL14*(1-CG14)) -> 0.95 | CM14: =(BM14*(1-CH14)) -> 0 | CN14: =SUM(CI14:CM14)*I14 -> 0 | CO14: =$CI14*Z14+$CJ14*AE14+$CK14*AJ14+$CL14*AO14+$CM14*AT14 -> 0 | CP14: =$CI14*AA14+$CJ14*AF14+$CK14*AK14+$CL14*AP14+$CM14*AU14 -> 0.95 | CQ14: =$CI14*AB14+$CJ14*AG14+$CK14*AL14+$CL14*AQ14+$CM14*AV14 -> 0 | CR14: =$CI14*AC14+$CJ14*AH14+$CK14*AM14+$CL14*AR14+$CM14*AW14 -> 0 | CS14: =$CI14*AD14+$CJ14*AI14+$CK14*AN14+$CL14*AS14+$CM14*AX14 -> 0 | CT14: =CO14*$BN14*BP14*$BO14*$AZ14 -> 0 | CU14: =CP14*$BN14*BQ14*$BO14*$AZ14 -> 0.0022621248 | CV14: =CQ14*$BN14*BS14*$BO14*$AZ14 -> 0 | CW14: =CR14*$BN14*BU14*$BO14*$AZ14 -> 0 | CX14: =CS14*$BN14*BV14*$BO14*$AZ14 -> 0 | CY14: =(SUM(CT14:CX14)*F14*G14)/1000 -> 0.36659995 | CZ14: =CC14+CY14 -> 1.1383893 | DB14: =F14*G14*BA14 -> 5023.86 | DC14: =K14*(1-BE14) -> 0 | DD14: =L14+(K14*BE14)+(N14*BF14)+(P14*BG14) -> 0 | DE14: =M14 -> 0 | DF14: =N14*(1-BF14) -> 0 | DG14: =O14 -> 1 | DH14: =P14*(1-BG14) -> 0 | DI14: =$DB14*DC14 -> 0 | DJ14: =$DB14*DD14 -> 0 | DK14: =$DB14*DE14 -> 0 | DL14: =$DB14*DF14 -> 0 | DM14: =$DB14*DG14 -> 5023.86 | DN14: =$DB14*DH14 -> 0 | DO14: =Constants!$C$10 -> 0.55 | DP14: =Constants!$C$11 -> 0.2 | DQ14: =Constants!$C$12 -> 0.3 | DR14: =Constants!$C$13 -> 0 | DS14: =Constants!$C$14 -> 0.125 | DT14: =Constants!$C$15 -> 0.25 | DU14: =Constants!$D$10 -> 0 | DV14: =Constants!$D$11 -> 0.005 | DW14: =Constants!$D$12 -> 0.02 | DX14: =Constants!$D$13 -> 0 | DY14: =Constants!$D$14 -> 0.01 | DZ14: =Constants!$D$15 -> 0.002 | EA14: =Constants!$B$23 -> 1.57 | EB14: =DI14*DU14*$EA14 -> 0 | EC14: =DJ14*DV14*$EA14 -> 0 | ED14: =DK14*DW14*$EA14 -> 0 | EE14: =DL14*DX14*$EA14 -> 0 | EF14: =DM14*DY14*$EA14 -> 78.874602 | EG14: =DN14*DZ14*$EA14 -> 0 | EH14: =DI14*(1-DO14-DU14) -> 0 | EI14: =DJ14*(1-DP14-DV14) -> 0 | EJ14: =DL14*(1-DR14-DX14) -> 0 | EK14: =DM14*(1-DS14-DY14) -> 4345.6389 | EL14: =DN14*(1-DT14-DZ14) -> 0 | EM14: =$EH14*Z14+$EI14*AE14+$EJ14*AJ14+$EK14*AO14+$EL14*AT14 -> 0 | EN14: =$EH14*AA14+$EI14*AF14+$EJ14*AK14+$EK14*AP14+$EL14*AU14 -> 4345.6389 | EO14: =$EH14*AB14+$EI14*AG14+$EJ14*AL14+$EK14*AQ14+$EL14*AV14 -> 0 | EP14: =$EH14*AC14+$EI14*AH14+$EJ14*AM14+$EK14*AR14+$EL14*AW14 -> 0 | EQ14: =$EH14*AD14+$EI14*AI14+$EJ14*AN14+$EK14*AS14+$EL14*AX14 -> 0 | ER14: =EM14*DU14*$EA14 -> 0 | ES14: =EN14*DV14*$EA14 -> 34.113265 | ET14: =EO14*DX14*$EA14 -> 0 | EU14: =EP14*DZ14*$EA14 -> 0 | EV14: =EQ14*0*$EA14 -> 0 | EW14: =SUM(EB14:EG14,ER14:EV14)/1000 -> 0.11298787 | EY14: =DI14*DO14 -> 0 | EZ14: =DJ14*DP14 -> 0 | FA14: =DK14*DQ14 -> 0 | FB14: =DL14*DR14 -> 0 | FC14: =DM14*DS14 -> 627.9825 | FD14: =DN14*DT14 -> 0 | FE14: =EM14*DO14 -> 0 | FF14: =EN14*DP14 -> 869.12778 | FG14: =EO14*DR14 -> 0 | FH14: =EP14*DT14 -> 0 | FI14: =EQ14*0 -> 0 | FJ14: =SUM(EY14:FI14) -> 1497.1103 | FK14: =_xlfn.XLOOKUP(C14, Constants!$D$19:$D$23, Constants!$E$19:$E$23) -> 0.007 | FL14: =(EA14*FJ14*FK14)/1000 -> 0.016453242 | FN14: =Constants!$B$24 -> 0.011 | FO14: =IF(D14, 1, 0) -> 1 | FP14: =Constants!$B$25 -> 0.02 | FQ14: =DK14*FO14*FP14 -> 0 | FR14: =FQ14*FN14*EA14 -> 0
A15: NT | C15: Irrigated pasture | D15: TRUE | E15: boars | F15: 105 | G15: 75 | K15: 0.2 | L15: 0.1 | M15: 0.2 | N15: 0.2 | O15: 0.2 | P15: 0.1 | Q15: TRUE | T15: TRUE | W15: TRUE | AA15: 0.25 | AB15: 0.25 | AC15: 0.25 | AD15: 0.25 | AE15: 0.25 | AG15: 0.25 | AH15: 0.25 | AI15: 0.25 | AJ15: 0.25 | AK15: 0.25 | AM15: 0.25 | AN15: 0.25 | AO15: 0.2 | AP15: 0.2 | AQ15: 0.2 | AR15: 0.2 | AS15: 0.2 | AT15: 0.25 | AU15: 0.25 | AV15: 0.25 | AX15: 0.25 | AY15: =IF(H15<>"", H15, _xlfn.XLOOKUP($E15,Constants!$A$3:$A$6, Constants!B$3:B$6)) -> 2.3 | AZ15: =IF(I15<>"", I15, _xlfn.XLOOKUP($E15,Constants!$A$3:$A$6, Constants!C$3:C$6)) -> 0.4 | BA15: =IF(J15<>"", J15, _xlfn.XLOOKUP($E15,Constants!$A$3:$A$6, Constants!D$3:D$6)) -> 0.046 | BB15: =IF(R15<>"", R15, IF(Q15, Constants!$B$19, 0)) -> 0.25 | BC15: =IF(U15<>"", U15, IF(T15, Constants!$B$19, 0)) -> 0.25 | BD15: =IF(X15<>"", X15, IF(W15, Constants!$B$19, 0)) -> 0.25 | BE15: =IF(S15<>"", S15, IF(Q15, Constants!$B$20, 0)) -> 0.25 | BF15: =IF(V15<>"", V15, IF(T15, Constants!$B$20, 0)) -> 0.25 | BG15: =IF(Y15<>"", Y15, IF(W15, Constants!$B$20, 0)) -> 0.25 | BH15: =K15*(1-BB15) -> 0.15 | BI15: =L15+(K15*BB15)+(N15*BC15)+(P15*BD15) -> 0.225 | BJ15: =M15 -> 0.2 | BK15: =N15*(1-BC15) -> 0.15 | BL15: =O15 -> 0.2 | BM15: =P15*(1-BD15) -> 0.075 | BN15: =Constants!$B$21 -> 0.45 | BO15: =Constants!$B$22 -> 0.6784 | BP15: =_xlfn.XLOOKUP($A15,Constants!$F$9:$M$9,Constants!$F$10:$M$10) -> 0.78 | BQ15: =_xlfn.XLOOKUP($A15,Constants!$F$9:$M$9,Constants!$F$11:$M$11) -> 0.02 | BR15: =_xlfn.XLOOKUP($A15,Constants!$F$9:$M$9,Constants!$F$12:$M$12) -> 0.03 | BS15: =_xlfn.XLOOKUP($A15,Constants!$F$9:$M$9,Constants!$F$13:$M$13) -> 0.1 | BT15: =_xlfn.XLOOKUP($A15,Constants!$F$9:$M$9,Constants!$F$14:$M$14) -> 0.04 | BU15: =_xlfn.XLOOKUP($A15,Constants!$F$9:$M$9,Constants!$F$15:$M$15) -> 0.03 | BV15: =_xlfn.XLOOKUP($A15,Constants!$F$9:$M$9,Constants!$F$16:$M$16) -> 0 | BW15: =$AZ15*BH15*BP15*$BN15*$BO15 -> 0.014287104 | BX15: =$AZ15*BI15*BQ15*$BN15*$BO15 -> 0.000549504 | BY15: =$AZ15*BJ15*BR15*$BN15*$BO15 -> 0.000732672 | BZ15: =$AZ15*BK15*BS15*$BN15*$BO15 -> 0.00183168 | CA15: =$AZ15*BL15*BT15*$BN15*$BO15 -> 0.000976896 | CB15: =$AZ15*BM15*BU15*$BN15*$BO15 -> 0.000274752 | CC15: =(SUM(BW15:CB15)*F15*G15)/1000 -> 0.14688929 | CD15: =Constants!$E$10 -> 0 | CE15: =Constants!$E$11 -> 0 | CF15: =Constants!$E$13 -> 0.75 | CG15: =Constants!$E$14 -> 0.05 | CH15: =Constants!$E$15 -> 0 | CI15: =(BH15*(1-CD15)) -> 0.15 | CJ15: =(BI15*(1-CE15)) -> 0.225 | CK15: =(BK15*(1-CF15)) -> 0.0375 | CL15: =(BL15*(1-CG15)) -> 0.19 | CM15: =(BM15*(1-CH15)) -> 0.075 | CN15: =SUM(CI15:CM15)*I15 -> 0 | CO15: =$CI15*Z15+$CJ15*AE15+$CK15*AJ15+$CL15*AO15+$CM15*AT15 -> 0.122375 | CP15: =$CI15*AA15+$CJ15*AF15+$CK15*AK15+$CL15*AP15+$CM15*AU15 -> 0.103625 | CQ15: =$CI15*AB15+$CJ15*AG15+$CK15*AL15+$CL15*AQ15+$CM15*AV15 -> 0.1505 | CR15: =$CI15*AC15+$CJ15*AH15+$CK15*AM15+$CL15*AR15+$CM15*AW15 -> 0.141125 | CS15: =$CI15*AD15+$CJ15*AI15+$CK15*AN15+$CL15*AS15+$CM15*AX15 -> 0.159875 | CT15: =CO15*$BN15*BP15*$BO15*$AZ15 -> 0.011655896 | CU15: =CP15*$BN15*BQ15*$BO15*$AZ15 -> 0.00025307712 | CV15: =CQ15*$BN15*BS15*$BO15*$AZ15 -> 0.0018377856 | CW15: =CR15*$BN15*BU15*$BO15*$AZ15 -> 0.00051699168 | CX15: =CS15*$BN15*BV15*$BO15*$AZ15 -> 0 | CY15: =(SUM(CT15:CX15)*F15*G15)/1000 -> 0.11232703 | CZ15: =CC15+CY15 -> 0.25921632 | DA15: =SUM(CZ15:CZ18) -> 8.8582363 | DB15: =F15*G15*BA15 -> 362.25 | DC15: =K15*(1-BE15) -> 0.15 | DD15: =L15+(K15*BE15)+(N15*BF15)+(P15*BG15) -> 0.225 | DE15: =M15 -> 0.2 | DF15: =N15*(1-BF15) -> 0.15 | DG15: =O15 -> 0.2 | DH15: =P15*(1-BG15) -> 0.075 | DI15: =$DB15*DC15 -> 54.3375 | DJ15: =$DB15*DD15 -> 81.50625 | DK15: =$DB15*DE15 -> 72.45 | DL15: =$DB15*DF15 -> 54.3375 | DM15: =$DB15*DG15 -> 72.45 | DN15: =$DB15*DH15 -> 27.16875 | DO15: =Constants!$C$10 -> 0.55 | DP15: =Constants!$C$11 -> 0.2 | DQ15: =Constants!$C$12 -> 0.3 | DR15: =Constants!$C$13 -> 0 | DS15: =Constants!$C$14 -> 0.125 | DT15: =Constants!$C$15 -> 0.25 | DU15: =Constants!$D$10 -> 0 | DV15: =Constants!$D$11 -> 0.005 | DW15: =Constants!$D$12 -> 0.02 | DX15: =Constants!$D$13 -> 0 | DY15: =Constants!$D$14 -> 0.01 | DZ15: =Constants!$D$15 -> 0.002 | EA15: =Constants!$B$23 -> 1.57 | EB15: =DI15*DU15*$EA15 -> 0 | EC15: =DJ15*DV15*$EA15 -> 0.63982406 | ED15: =DK15*DW15*$EA15 -> 2.27493 | EE15: =DL15*DX15*$EA15 -> 0 | EF15: =DM15*DY15*$EA15 -> 1.137465 | EG15: =DN15*DZ15*$EA15 -> 0.085309875 | EH15: =DI15*(1-DO15-DU15) -> 24.451875 | EI15: =DJ15*(1-DP15-DV15) -> 64.797469 | EJ15: =DL15*(1-DR15-DX15) -> 54.3375 | EK15: =DM15*(1-DS15-DY15) -> 62.66925 | EL15: =DN15*(1-DT15-DZ15) -> 20.322225 | EM15: =$EH15*Z15+$EI15*AE15+$EJ15*AJ15+$EK15*AO15+$EL15*AT15 -> 47.398148 | EN15: =$EH15*AA15+$EI15*AF15+$EJ15*AK15+$EK15*AP15+$EL15*AU15 -> 37.31175 | EO15: =$EH15*AB15+$EI15*AG15+$EJ15*AL15+$EK15*AQ15+$EL15*AV15 -> 39.926742 | EP15: =$EH15*AC15+$EI15*AH15+$EJ15*AM15+$EK15*AR15+$EL15*AW15 -> 48.430561 | EQ15: =$EH15*AD15+$EI15*AI15+$EJ15*AN15+$EK15*AS15+$EL15*AX15 -> 53.511117 | ER15: =EM15*DU15*$EA15 -> 0 | ES15: =EN15*DV15*$EA15 -> 0.29289724 | ET15: =EO15*DX15*$EA15 -> 0 | EU15: =EP15*DZ15*$EA15 -> 0.15207196 | EV15: =EQ15*0*$EA15 -> 0 | EW15: =SUM(EB15:EG15,ER15:EV15)/1000 -> 0.0045824981 | EX15: =SUM(EW15:EW18) -> 0.12434009 | EY15: =DI15*DO15 -> 29.885625 | EZ15: =DJ15*DP15 -> 16.30125 | FA15: =DK15*DQ15 -> 21.735 | FB15: =DL15*DR15 -> 0 | FC15: =DM15*DS15 -> 9.05625 | FD15: =DN15*DT15 -> 6.7921875 | FE15: =EM15*DO15 -> 26.068982 | FF15: =EN15*DP15 -> 7.46235 | FG15: =EO15*DR15 -> 0 | FH15: =EP15*DT15 -> 12.10764 | FI15: =EQ15*0 -> 0 | FJ15: =SUM(EY15:FI15) -> 129.40928 | FK15: =_xlfn.XLOOKUP(C15, Constants!$D$19:$D$23, Constants!$E$19:$E$23) -> 0.0059 | FL15: =(EA15*FJ15*FK15)/1000 -> 0.0011987182 | FM15: =SUM(FL15:FL18) -> 0.032525651 | FN15: =Constants!$B$24 -> 0.011 | FO15: =IF(D15, 1, 0) -> 1 | FP15: =Constants!$B$25 -> 0.02 | FQ15: =DK15*FO15*FP15 -> 1.449 | FR15: =FQ15*FN15*EA15 -> 0.02502423 | FS15: =SUM(FR15:FR18)/1000 -> 0.00067899975
A16: NT | C16: Irrigated pasture | D16: TRUE | E16: sows | F16: 245 | G16: 290 | K16: 0.2 | L16: 0.1 | M16: 0.2 | N16: 0.2 | O16: 0.2 | P16: 0.1 | Q16: TRUE | T16: TRUE | W16: TRUE | AA16: 0.25 | AB16: 0.25 | AC16: 0.25 | AD16: 0.25 | AE16: 0.25 | AG16: 0.25 | AH16: 0.25 | AI16: 0.25 | AJ16: 0.25 | AK16: 0.25 | AM16: 0.25 | AN16: 0.25 | AO16: 0.2 | AP16: 0.2 | AQ16: 0.2 | AR16: 0.2 | AS16: 0.2 | AT16: 0.25 | AU16: 0.25 | AV16: 0.25 | AX16: 0.25 | AY16: =IF(H16<>"", H16, _xlfn.XLOOKUP($E16,Constants!$A$3:$A$6, Constants!B$3:B$6)) -> 2.62 | AZ16: =IF(I16<>"", I16, _xlfn.XLOOKUP($E16,Constants!$A$3:$A$6, Constants!C$3:C$6)) -> 0.46 | BA16: =IF(J16<>"", J16, _xlfn.XLOOKUP($E16,Constants!$A$3:$A$6, Constants!D$3:D$6)) -> 0.049 | BB16: =IF(R16<>"", R16, IF(Q16, Constants!$B$19, 0)) -> 0.25 | BC16: =IF(U16<>"", U16, IF(T16, Constants!$B$19, 0)) -> 0.25 | BD16: =IF(X16<>"", X16, IF(W16, Constants!$B$19, 0)) -> 0.25 | BE16: =IF(S16<>"", S16, IF(Q16, Constants!$B$20, 0)) -> 0.25 | BF16: =IF(V16<>"", V16, IF(T16, Constants!$B$20, 0)) -> 0.25 | BG16: =IF(Y16<>"", Y16, IF(W16, Constants!$B$20, 0)) -> 0.25 | BH16: =K16*(1-BB16) -> 0.15 | BI16: =L16+(K16*BB16)+(N16*BC16)+(P16*BD16) -> 0.225 | BJ16: =M16 -> 0.2 | BK16: =N16*(1-BC16) -> 0.15 | BL16: =O16 -> 0.2 | BM16: =P16*(1-BD16) -> 0.075 | BN16: =Constants!$B$21 -> 0.45 | BO16: =Constants!$B$22 -> 0.6784 | BP16: =_xlfn.XLOOKUP($A16,Constants!$F$9:$M$9,Constants!$F$10:$M$10) -> 0.78 | BQ16: =_xlfn.XLOOKUP($A16,Constants!$F$9:$M$9,Constants!$F$11:$M$11) -> 0.02 | BR16: =_xlfn.XLOOKUP($A16,Constants!$F$9:$M$9,Constants!$F$12:$M$12) -> 0.03 | BS16: =_xlfn.XLOOKUP($A16,Constants!$F$9:$M$9,Constants!$F$13:$M$13) -> 0.1 | BT16: =_xlfn.XLOOKUP($A16,Constants!$F$9:$M$9,Constants!$F$14:$M$14) -> 0.04 | BU16: =_xlfn.XLOOKUP($A16,Constants!$F$9:$M$9,Constants!$F$15:$M$15) -> 0.03 | BV16: =_xlfn.XLOOKUP($A16,Constants!$F$9:$M$9,Constants!$F$16:$M$16) -> 0 | BW16: =$AZ16*BH16*BP16*$BN16*$BO16 -> 0.01643017 | BX16: =$AZ16*BI16*BQ16*$BN16*$BO16 -> 0.0006319296 | BY16: =$AZ16*BJ16*BR16*$BN16*$BO16 -> 0.0008425728 | BZ16: =$AZ16*BK16*BS16*$BN16*$BO16 -> 0.002106432 | CA16: =$AZ16*BL16*BT16*$BN16*$BO16 -> 0.0011234304 | CB16: =$AZ16*BM16*BU16*$BN16*$BO16 -> 0.0003159648 | CC16: =(SUM(BW16:CB16)*F16*G16)/1000 -> 1.524058 | CD16: =Constants!$E$10 -> 0 | CE16: =Constants!$E$11 -> 0 | CF16: =Constants!$E$13 -> 0.75 | CG16: =Constants!$E$14 -> 0.05 | CH16: =Constants!$E$15 -> 0 | CI16: =(BH16*(1-CD16)) -> 0.15 | CJ16: =(BI16*(1-CE16)) -> 0.225 | CK16: =(BK16*(1-CF16)) -> 0.0375 | CL16: =(BL16*(1-CG16)) -> 0.19 | CM16: =(BM16*(1-CH16)) -> 0.075 | CN16: =SUM(CI16:CM16)*I16 -> 0 | CO16: =$CI16*Z16+$CJ16*AE16+$CK16*AJ16+$CL16*AO16+$CM16*AT16 -> 0.122375 | CP16: =$CI16*AA16+$CJ16*AF16+$CK16*AK16+$CL16*AP16+$CM16*AU16 -> 0.103625 | CQ16: =$CI16*AB16+$CJ16*AG16+$CK16*AL16+$CL16*AQ16+$CM16*AV16 -> 0.1505 | CR16: =$CI16*AC16+$CJ16*AH16+$CK16*AM16+$CL16*AR16+$CM16*AW16 -> 0.141125 | CS16: =$CI16*AD16+$CJ16*AI16+$CK16*AN16+$CL16*AS16+$CM16*AX16 -> 0.159875 | CT16: =CO16*$BN16*BP16*$BO16*$AZ16 -> 0.01340428 | CU16: =CP16*$BN16*BQ16*$BO16*$AZ16 -> 0.00029103869 | CV16: =CQ16*$BN16*BS16*$BO16*$AZ16 -> 0.0021134534 | CW16: =CR16*$BN16*BU16*$BO16*$AZ16 -> 0.00059454043 | CX16: =CS16*$BN16*BV16*$BO16*$AZ16 -> 0 | CY16: =(SUM(CT16:CX16)*F16*G16)/1000 -> 1.1654554 | CZ16: =CC16+CY16 -> 2.6895133 | DB16: =F16*G16*BA16 -> 3481.45 | DC16: =K16*(1-BE16) -> 0.15 | DD16: =L16+(K16*BE16)+(N16*BF16)+(P16*BG16) -> 0.225 | DE16: =M16 -> 0.2 | DF16: =N16*(1-BF16) -> 0.15 | DG16: =O16 -> 0.2 | DH16: =P16*(1-BG16) -> 0.075 | DI16: =$DB16*DC16 -> 522.2175 | DJ16: =$DB16*DD16 -> 783.32625 | DK16: =$DB16*DE16 -> 696.29 | DL16: =$DB16*DF16 -> 522.2175 | DM16: =$DB16*DG16 -> 696.29 | DN16: =$DB16*DH16 -> 261.10875 | DO16: =Constants!$C$10 -> 0.55 | DP16: =Constants!$C$11 -> 0.2 | DQ16: =Constants!$C$12 -> 0.3 | DR16: =Constants!$C$13 -> 0 | DS16: =Constants!$C$14 -> 0.125 | DT16: =Constants!$C$15 -> 0.25 | DU16: =Constants!$D$10 -> 0 | DV16: =Constants!$D$11 -> 0.005 | DW16: =Constants!$D$12 -> 0.02 | DX16: =Constants!$D$13 -> 0 | DY16: =Constants!$D$14 -> 0.01 | DZ16: =Constants!$D$15 -> 0.002 | EA16: =Constants!$B$23 -> 1.57 | EB16: =DI16*DU16*$EA16 -> 0 | EC16: =DJ16*DV16*$EA16 -> 6.1491111 | ED16: =DK16*DW16*$EA16 -> 21.863506 | EE16: =DL16*DX16*$EA16 -> 0 | EF16: =DM16*DY16*$EA16 -> 10.931753 | EG16: =DN16*DZ16*$EA16 -> 0.81988148 | EH16: =DI16*(1-DO16-DU16) -> 234.99788 | EI16: =DJ16*(1-DP16-DV16) -> 622.74437 | EJ16: =DL16*(1-DR16-DX16) -> 522.2175 | EK16: =DM16*(1-DS16-DY16) -> 602.29085 | EL16: =DN16*(1-DT16-DZ16) -> 195.30935 | EM16: =$EH16*Z16+$EI16*AE16+$EJ16*AJ16+$EK16*AO16+$EL16*AT16 -> 455.52597 | EN16: =$EH16*AA16+$EI16*AF16+$EJ16*AK16+$EK16*AP16+$EL16*AU16 -> 358.58935 | EO16: =$EH16*AB16+$EI16*AG16+$EJ16*AL16+$EK16*AQ16+$EL16*AV16 -> 383.72107 | EP16: =$EH16*AC16+$EI16*AH16+$EJ16*AM16+$EK16*AR16+$EL16*AW16 -> 465.44811 | EQ16: =$EH16*AD16+$EI16*AI16+$EJ16*AN16+$EK16*AS16+$EL16*AX16 -> 514.27544 | ER16: =EM16*DU16*$EA16 -> 0 | ES16: =EN16*DV16*$EA16 -> 2.8149264 | ET16: =EO16*DX16*$EA16 -> 0 | EU16: =EP16*DZ16*$EA16 -> 1.4615071 | EV16: =EQ16*0*$EA16 -> 0 | EW16: =SUM(EB16:EG16,ER16:EV16)/1000 -> 0.044040685 | EY16: =DI16*DO16 -> 287.21963 | EZ16: =DJ16*DP16 -> 156.66525 | FA16: =DK16*DQ16 -> 208.887 | FB16: =DL16*DR16 -> 0 | FC16: =DM16*DS16 -> 87.03625 | FD16: =DN16*DT16 -> 65.277188 | FE16: =EM16*DO16 -> 250.53929 | FF16: =EN16*DP16 -> 71.71787 | FG16: =EO16*DR16 -> 0 | FH16: =EP16*DT16 -> 116.36203 | FI16: =EQ16*0 -> 0 | FJ16: =SUM(EY16:FI16) -> 1243.7045 | FK16: =_xlfn.XLOOKUP(C16, Constants!$D$19:$D$23, Constants!$E$19:$E$23) -> 0.0059 | FL16: =(EA16*FJ16*FK16)/1000 -> 0.011520435 | FN16: =Constants!$B$24 -> 0.011 | FO16: =IF(D16, 1, 0) -> 1 | FP16: =Constants!$B$25 -> 0.02 | FQ16: =DK16*FO16*FP16 -> 13.9258 | FR16: =FQ16*FN16*EA16 -> 0.24049857
A17: NT | C17: Irrigated pasture | D17: TRUE | E17: gilts | F17: 434 | G17: 280 | K17: 0.2 | L17: 0.1 | M17: 0.2 | N17: 0.2 | O17: 0.2 | P17: 0.1 | Q17: TRUE | T17: TRUE | W17: TRUE | AA17: 0.25 | AB17: 0.25 | AC17: 0.25 | AD17: 0.25 | AE17: 0.25 | AG17: 0.25 | AH17: 0.25 | AI17: 0.25 | AJ17: 0.25 | AK17: 0.25 | AM17: 0.25 | AN17: 0.25 | AO17: 0.2 | AP17: 0.2 | AQ17: 0.2 | AR17: 0.2 | AS17: 0.2 | AT17: 0.25 | AU17: 0.25 | AV17: 0.25 | AX17: 0.25 | AY17: =IF(H17<>"", H17, _xlfn.XLOOKUP($E17,Constants!$A$3:$A$6, Constants!B$3:B$6)) -> 2.5 | AZ17: =IF(I17<>"", I17, _xlfn.XLOOKUP($E17,Constants!$A$3:$A$6, Constants!C$3:C$6)) -> 0.55 | BA17: =IF(J17<>"", J17, _xlfn.XLOOKUP($E17,Constants!$A$3:$A$6, Constants!D$3:D$6)) -> 0.046 | BB17: =IF(R17<>"", R17, IF(Q17, Constants!$B$19, 0)) -> 0.25 | BC17: =IF(U17<>"", U17, IF(T17, Constants!$B$19, 0)) -> 0.25 | BD17: =IF(X17<>"", X17, IF(W17, Constants!$B$19, 0)) -> 0.25 | BE17: =IF(S17<>"", S17, IF(Q17, Constants!$B$20, 0)) -> 0.25 | BF17: =IF(V17<>"", V17, IF(T17, Constants!$B$20, 0)) -> 0.25 | BG17: =IF(Y17<>"", Y17, IF(W17, Constants!$B$20, 0)) -> 0.25 | BH17: =K17*(1-BB17) -> 0.15 | BI17: =L17+(K17*BB17)+(N17*BC17)+(P17*BD17) -> 0.225 | BJ17: =M17 -> 0.2 | BK17: =N17*(1-BC17) -> 0.15 | BL17: =O17 -> 0.2 | BM17: =P17*(1-BD17) -> 0.075 | BN17: =Constants!$B$21 -> 0.45 | BO17: =Constants!$B$22 -> 0.6784 | BP17: =_xlfn.XLOOKUP($A17,Constants!$F$9:$M$9,Constants!$F$10:$M$10) -> 0.78 | BQ17: =_xlfn.XLOOKUP($A17,Constants!$F$9:$M$9,Constants!$F$11:$M$11) -> 0.02 | BR17: =_xlfn.XLOOKUP($A17,Constants!$F$9:$M$9,Constants!$F$12:$M$12) -> 0.03 | BS17: =_xlfn.XLOOKUP($A17,Constants!$F$9:$M$9,Constants!$F$13:$M$13) -> 0.1 | BT17: =_xlfn.XLOOKUP($A17,Constants!$F$9:$M$9,Constants!$F$14:$M$14) -> 0.04 | BU17: =_xlfn.XLOOKUP($A17,Constants!$F$9:$M$9,Constants!$F$15:$M$15) -> 0.03 | BV17: =_xlfn.XLOOKUP($A17,Constants!$F$9:$M$9,Constants!$F$16:$M$16) -> 0 | BW17: =$AZ17*BH17*BP17*$BN17*$BO17 -> 0.019644768 | BX17: =$AZ17*BI17*BQ17*$BN17*$BO17 -> 0.000755568 | BY17: =$AZ17*BJ17*BR17*$BN17*$BO17 -> 0.001007424 | BZ17: =$AZ17*BK17*BS17*$BN17*$BO17 -> 0.00251856 | CA17: =$AZ17*BL17*BT17*$BN17*$BO17 -> 0.001343232 | CB17: =$AZ17*BM17*BU17*$BN17*$BO17 -> 0.000377784 | CC17: =(SUM(BW17:CB17)*F17*G17)/1000 -> 3.1166643 | CD17: =Constants!$E$10 -> 0 | CE17: =Constants!$E$11 -> 0 | CF17: =Constants!$E$13 -> 0.75 | CG17: =Constants!$E$14 -> 0.05 | CH17: =Constants!$E$15 -> 0 | CI17: =(BH17*(1-CD17)) -> 0.15 | CJ17: =(BI17*(1-CE17)) -> 0.225 | CK17: =(BK17*(1-CF17)) -> 0.0375 | CL17: =(BL17*(1-CG17)) -> 0.19 | CM17: =(BM17*(1-CH17)) -> 0.075 | CN17: =SUM(CI17:CM17)*I17 -> 0 | CO17: =$CI17*Z17+$CJ17*AE17+$CK17*AJ17+$CL17*AO17+$CM17*AT17 -> 0.122375 | CP17: =$CI17*AA17+$CJ17*AF17+$CK17*AK17+$CL17*AP17+$CM17*AU17 -> 0.103625 | CQ17: =$CI17*AB17+$CJ17*AG17+$CK17*AL17+$CL17*AQ17+$CM17*AV17 -> 0.1505 | CR17: =$CI17*AC17+$CJ17*AH17+$CK17*AM17+$CL17*AR17+$CM17*AW17 -> 0.141125 | CS17: =$CI17*AD17+$CJ17*AI17+$CK17*AN17+$CL17*AS17+$CM17*AX17 -> 0.159875 | CT17: =CO17*$BN17*BP17*$BO17*$AZ17 -> 0.016026857 | CU17: =CP17*$BN17*BQ17*$BO17*$AZ17 -> 0.00034798104 | CV17: =CQ17*$BN17*BS17*$BO17*$AZ17 -> 0.0025269552 | CW17: =CR17*$BN17*BU17*$BO17*$AZ17 -> 0.00071086356 | CX17: =CS17*$BN17*BV17*$BO17*$AZ17 -> 0 | CY17: =(SUM(CT17:CX17)*F17*G17)/1000 -> 2.38333 | CZ17: =CC17+CY17 -> 5.4999943 | DB17: =F17*G17*BA17 -> 5589.92 | DC17: =K17*(1-BE17) -> 0.15 | DD17: =L17+(K17*BE17)+(N17*BF17)+(P17*BG17) -> 0.225 | DE17: =M17 -> 0.2 | DF17: =N17*(1-BF17) -> 0.15 | DG17: =O17 -> 0.2 | DH17: =P17*(1-BG17) -> 0.075 | DI17: =$DB17*DC17 -> 838.488 | DJ17: =$DB17*DD17 -> 1257.732 | DK17: =$DB17*DE17 -> 1117.984 | DL17: =$DB17*DF17 -> 838.488 | DM17: =$DB17*DG17 -> 1117.984 | DN17: =$DB17*DH17 -> 419.244 | DO17: =Constants!$C$10 -> 0.55 | DP17: =Constants!$C$11 -> 0.2 | DQ17: =Constants!$C$12 -> 0.3 | DR17: =Constants!$C$13 -> 0 | DS17: =Constants!$C$14 -> 0.125 | DT17: =Constants!$C$15 -> 0.25 | DU17: =Constants!$D$10 -> 0 | DV17: =Constants!$D$11 -> 0.005 | DW17: =Constants!$D$12 -> 0.02 | DX17: =Constants!$D$13 -> 0 | DY17: =Constants!$D$14 -> 0.01 | DZ17: =Constants!$D$15 -> 0.002 | EA17: =Constants!$B$23 -> 1.57 | EB17: =DI17*DU17*$EA17 -> 0 | EC17: =DJ17*DV17*$EA17 -> 9.8731962 | ED17: =DK17*DW17*$EA17 -> 35.104698 | EE17: =DL17*DX17*$EA17 -> 0 | EF17: =DM17*DY17*$EA17 -> 17.552349 | EG17: =DN17*DZ17*$EA17 -> 1.3164262 | EH17: =DI17*(1-DO17-DU17) -> 377.3196 | EI17: =DJ17*(1-DP17-DV17) -> 999.89694 | EJ17: =DL17*(1-DR17-DX17) -> 838.488 | EK17: =DM17*(1-DS17-DY17) -> 967.05616 | EL17: =DN17*(1-DT17-DZ17) -> 313.59451 | EM17: =$EH17*Z17+$EI17*AE17+$EJ17*AJ17+$EK17*AO17+$EL17*AT17 -> 731.4061 | EN17: =$EH17*AA17+$EI17*AF17+$EJ17*AK17+$EK17*AP17+$EL17*AU17 -> 575.76176 | EO17: =$EH17*AB17+$EI17*AG17+$EJ17*AL17+$EK17*AQ17+$EL17*AV17 -> 616.114 | EP17: =$EH17*AC17+$EI17*AH17+$EJ17*AM17+$EK17*AR17+$EL17*AW17 -> 747.33737 | EQ17: =$EH17*AD17+$EI17*AI17+$EJ17*AN17+$EK17*AS17+$EL17*AX17 -> 825.736 | ER17: =EM17*DU17*$EA17 -> 0 | ES17: =EN17*DV17*$EA17 -> 4.5197298 | ET17: =EO17*DX17*$EA17 -> 0 | EU17: =EP17*DZ17*$EA17 -> 2.3466393 | EV17: =EQ17*0*$EA17 -> 0 | EW17: =SUM(EB17:EG17,ER17:EV17)/1000 -> 0.070713038 | EY17: =DI17*DO17 -> 461.1684 | EZ17: =DJ17*DP17 -> 251.5464 | FA17: =DK17*DQ17 -> 335.3952 | FB17: =DL17*DR17 -> 0 | FC17: =DM17*DS17 -> 139.748 | FD17: =DN17*DT17 -> 104.811 | FE17: =EM17*DO17 -> 402.27335 | FF17: =EN17*DP17 -> 115.15235 | FG17: =EO17*DR17 -> 0 | FH17: =EP17*DT17 -> 186.83434 | FI17: =EQ17*0 -> 0 | FJ17: =SUM(EY17:FI17) -> 1996.929 | FK17: =_xlfn.XLOOKUP(C17, Constants!$D$19:$D$23, Constants!$E$19:$E$23) -> 0.0059 | FL17: =(EA17*FJ17*FK17)/1000 -> 0.018497554 | FN17: =Constants!$B$24 -> 0.011 | FO17: =IF(D17, 1, 0) -> 1 | FP17: =Constants!$B$25 -> 0.02 | FQ17: =DK17*FO17*FP17 -> 22.35968 | FR17: =FQ17*FN17*EA17 -> 0.38615167
A18: NT | C18: Irrigated pasture | D18: TRUE | E18: others | F18: 44 | G18: 290 | K18: 0.2 | L18: 0.1 | M18: 0.2 | N18: 0.2 | O18: 0.2 | P18: 0.1 | Q18: TRUE | T18: TRUE | W18: TRUE | AA18: 0.25 | AB18: 0.25 | AC18: 0.25 | AD18: 0.25 | AE18: 0.25 | AG18: 0.25 | AH18: 0.25 | AI18: 0.25 | AJ18: 0.25 | AK18: 0.25 | AM18: 0.25 | AN18: 0.25 | AO18: 0.2 | AP18: 0.2 | AQ18: 0.2 | AR18: 0.2 | AS18: 0.2 | AT18: 0.25 | AU18: 0.25 | AV18: 0.25 | AX18: 0.25 | AY18: =IF(H18<>"", H18, _xlfn.XLOOKUP($E18,Constants!$A$3:$A$6, Constants!B$3:B$6)) -> 1.71 | AZ18: =IF(I18<>"", I18, _xlfn.XLOOKUP($E18,Constants!$A$3:$A$6, Constants!C$3:C$6)) -> 0.39 | BA18: =IF(J18<>"", J18, _xlfn.XLOOKUP($E18,Constants!$A$3:$A$6, Constants!D$3:D$6)) -> 0.031 | BB18: =IF(R18<>"", R18, IF(Q18, Constants!$B$19, 0)) -> 0.25 | BC18: =IF(U18<>"", U18, IF(T18, Constants!$B$19, 0)) -> 0.25 | BD18: =IF(X18<>"", X18, IF(W18, Constants!$B$19, 0)) -> 0.25 | BE18: =IF(S18<>"", S18, IF(Q18, Constants!$B$20, 0)) -> 0.25 | BF18: =IF(V18<>"", V18, IF(T18, Constants!$B$20, 0)) -> 0.25 | BG18: =IF(Y18<>"", Y18, IF(W18, Constants!$B$20, 0)) -> 0.25 | BH18: =K18*(1-BB18) -> 0.15 | BI18: =L18+(K18*BB18)+(N18*BC18)+(P18*BD18) -> 0.225 | BJ18: =M18 -> 0.2 | BK18: =N18*(1-BC18) -> 0.15 | BL18: =O18 -> 0.2 | BM18: =P18*(1-BD18) -> 0.075 | BN18: =Constants!$B$21 -> 0.45 | BO18: =Constants!$B$22 -> 0.6784 | BP18: =_xlfn.XLOOKUP($A18,Constants!$F$9:$M$9,Constants!$F$10:$M$10) -> 0.78 | BQ18: =_xlfn.XLOOKUP($A18,Constants!$F$9:$M$9,Constants!$F$11:$M$11) -> 0.02 | BR18: =_xlfn.XLOOKUP($A18,Constants!$F$9:$M$9,Constants!$F$12:$M$12) -> 0.03 | BS18: =_xlfn.XLOOKUP($A18,Constants!$F$9:$M$9,Constants!$F$13:$M$13) -> 0.1 | BT18: =_xlfn.XLOOKUP($A18,Constants!$F$9:$M$9,Constants!$F$14:$M$14) -> 0.04 | BU18: =_xlfn.XLOOKUP($A18,Constants!$F$9:$M$9,Constants!$F$15:$M$15) -> 0.03 | BV18: =_xlfn.XLOOKUP($A18,Constants!$F$9:$M$9,Constants!$F$16:$M$16) -> 0 | BW18: =$AZ18*BH18*BP18*$BN18*$BO18 -> 0.013929926 | BX18: =$AZ18*BI18*BQ18*$BN18*$BO18 -> 0.0005357664 | BY18: =$AZ18*BJ18*BR18*$BN18*$BO18 -> 0.0007143552 | BZ18: =$AZ18*BK18*BS18*$BN18*$BO18 -> 0.001785888 | CA18: =$AZ18*BL18*BT18*$BN18*$BO18 -> 0.0009524736 | CB18: =$AZ18*BM18*BU18*$BN18*$BO18 -> 0.0002678832 | CC18: =(SUM(BW18:CB18)*F18*G18)/1000 -> 0.2320571 | CD18: =Constants!$E$10 -> 0 | CE18: =Constants!$E$11 -> 0 | CF18: =Constants!$E$13 -> 0.75 | CG18: =Constants!$E$14 -> 0.05 | CH18: =Constants!$E$15 -> 0 | CI18: =(BH18*(1-CD18)) -> 0.15 | CJ18: =(BI18*(1-CE18)) -> 0.225 | CK18: =(BK18*(1-CF18)) -> 0.0375 | CL18: =(BL18*(1-CG18)) -> 0.19 | CM18: =(BM18*(1-CH18)) -> 0.075 | CN18: =SUM(CI18:CM18)*I18 -> 0 | CO18: =$CI18*Z18+$CJ18*AE18+$CK18*AJ18+$CL18*AO18+$CM18*AT18 -> 0.122375 | CP18: =$CI18*AA18+$CJ18*AF18+$CK18*AK18+$CL18*AP18+$CM18*AU18 -> 0.103625 | CQ18: =$CI18*AB18+$CJ18*AG18+$CK18*AL18+$CL18*AQ18+$CM18*AV18 -> 0.1505 | CR18: =$CI18*AC18+$CJ18*AH18+$CK18*AM18+$CL18*AR18+$CM18*AW18 -> 0.141125 | CS18: =$CI18*AD18+$CJ18*AI18+$CK18*AN18+$CL18*AS18+$CM18*AX18 -> 0.159875 | CT18: =CO18*$BN18*BP18*$BO18*$AZ18 -> 0.011364498 | CU18: =CP18*$BN18*BQ18*$BO18*$AZ18 -> 0.00024675019 | CV18: =CQ18*$BN18*BS18*$BO18*$AZ18 -> 0.001791841 | CW18: =CR18*$BN18*BU18*$BO18*$AZ18 -> 0.00050406689 | CX18: =CS18*$BN18*BV18*$BO18*$AZ18 -> 0 | CY18: =(SUM(CT18:CX18)*F18*G18)/1000 -> 0.17745531 | CZ18: =CC18+CY18 -> 0.40951241 | DB18: =F18*G18*BA18 -> 395.56 | DC18: =K18*(1-BE18) -> 0.15 | DD18: =L18+(K18*BE18)+(N18*BF18)+(P18*BG18) -> 0.225 | DE18: =M18 -> 0.2 | DF18: =N18*(1-BF18) -> 0.15 | DG18: =O18 -> 0.2 | DH18: =P18*(1-BG18) -> 0.075 | DI18: =$DB18*DC18 -> 59.334 | DJ18: =$DB18*DD18 -> 89.001 | DK18: =$DB18*DE18 -> 79.112 | DL18: =$DB18*DF18 -> 59.334 | DM18: =$DB18*DG18 -> 79.112 | DN18: =$DB18*DH18 -> 29.667 | DO18: =Constants!$C$10 -> 0.55 | DP18: =Constants!$C$11 -> 0.2 | DQ18: =Constants!$C$12 -> 0.3 | DR18: =Constants!$C$13 -> 0 | DS18: =Constants!$C$14 -> 0.125 | DT18: =Constants!$C$15 -> 0.25 | DU18: =Constants!$D$10 -> 0 | DV18: =Constants!$D$11 -> 0.005 | DW18: =Constants!$D$12 -> 0.02 | DX18: =Constants!$D$13 -> 0 | DY18: =Constants!$D$14 -> 0.01 | DZ18: =Constants!$D$15 -> 0.002 | EA18: =Constants!$B$23 -> 1.57 | EB18: =DI18*DU18*$EA18 -> 0 | EC18: =DJ18*DV18*$EA18 -> 0.69865785 | ED18: =DK18*DW18*$EA18 -> 2.4841168 | EE18: =DL18*DX18*$EA18 -> 0 | EF18: =DM18*DY18*$EA18 -> 1.2420584 | EG18: =DN18*DZ18*$EA18 -> 0.09315438 | EH18: =DI18*(1-DO18-DU18) -> 26.7003 | EI18: =DJ18*(1-DP18-DV18) -> 70.755795 | EJ18: =DL18*(1-DR18-DX18) -> 59.334 | EK18: =DM18*(1-DS18-DY18) -> 68.43188 | EL18: =DN18*(1-DT18-DZ18) -> 22.190916 | EM18: =$EH18*Z18+$EI18*AE18+$EJ18*AJ18+$EK18*AO18+$EL18*AT18 -> 51.756554 | EN18: =$EH18*AA18+$EI18*AF18+$EJ18*AK18+$EK18*AP18+$EL18*AU18 -> 40.74268 | EO18: =$EH18*AB18+$EI18*AG18+$EJ18*AL18+$EK18*AQ18+$EL18*AV18 -> 43.598129 | EP18: =$EH18*AC18+$EI18*AH18+$EJ18*AM18+$EK18*AR18+$EL18*AW18 -> 52.8839 | EQ18: =$EH18*AD18+$EI18*AI18+$EJ18*AN18+$EK18*AS18+$EL18*AX18 -> 58.431629 | ER18: =EM18*DU18*$EA18 -> 0 | ES18: =EN18*DV18*$EA18 -> 0.31983004 | ET18: =EO18*DX18*$EA18 -> 0 | EU18: =EP18*DZ18*$EA18 -> 0.16605545 | EV18: =EQ18*0*$EA18 -> 0 | EW18: =SUM(EB18:EG18,ER18:EV18)/1000 -> 0.0050038729 | EY18: =DI18*DO18 -> 32.6337 | EZ18: =DJ18*DP18 -> 17.8002 | FA18: =DK18*DQ18 -> 23.7336 | FB18: =DL18*DR18 -> 0 | FC18: =DM18*DS18 -> 9.889 | FD18: =DN18*DT18 -> 7.41675 | FE18: =EM18*DO18 -> 28.466105 | FF18: =EN18*DP18 -> 8.148536 | FG18: =EO18*DR18 -> 0 | FH18: =EP18*DT18 -> 13.220975 | FI18: =EQ18*0 -> 0 | FJ18: =SUM(EY18:FI18) -> 141.30887 | FK18: =_xlfn.XLOOKUP(C18, Constants!$D$19:$D$23, Constants!$E$19:$E$23) -> 0.0059 | FL18: =(EA18*FJ18*FK18)/1000 -> 0.001308944 | FN18: =Constants!$B$24 -> 0.011 | FO18: =IF(D18, 1, 0) -> 1 | FP18: =Constants!$B$25 -> 0.02 | FQ18: =DK18*FO18*FP18 -> 1.58224 | FR18: =FQ18*FN18*EA18 -> 0.027325285
